--------------------------------------------------------------------------
WARNING: There are more than one active ports on host 'cr1cn06', but the
default subnet GID prefix was detected on more than one of these
ports.  If these ports are connected to different physical IB
networks, this configuration will fail in Open MPI.  This version of
Open MPI requires that every physically separate IB subnet that is
used between connected MPI processes must have different subnet ID
values.

Please see this FAQ entry for more details:

  http://www.open-mpi.org/faq/?category=openfabrics#ofa-default-subnet-gid

NOTE: You can turn off this warning by setting the MCA parameter
      btl_openib_warn_default_gid_prefix to 0.
--------------------------------------------------------------------------
2019-08-02 10:47:44.918597: E tensorflow/core/common_runtime/direct_session.cc:158] Internal: failed initializing StreamExecutor for CUDA device ordinal 0: Internal: failed call to cuDevicePrimaryCtxRetain: CUDA_ERROR_INVALID_DEVICE
/gpfs/pkgs/mhpcc/anaconda3-5.0.1/lib/python3.6/site-packages/h5py/__init__.py:34: FutureWarning: Conversion of the second argument of issubdtype from `float` to `np.floating` is deprecated. In future, it will be treated as `np.float64 == np.dtype(float).type`.
  from ._conv import register_converters as _register_converters
Using TensorFlow backend.
2019-08-02 10:47:44.946494: E tensorflow/core/common_runtime/direct_session.cc:158] Internal: failed initializing StreamExecutor for CUDA device ordinal 0: Internal: failed call to cuDevicePrimaryCtxRetain: CUDA_ERROR_INVALID_DEVICE
/gpfs/pkgs/mhpcc/anaconda3-5.0.1/lib/python3.6/site-packages/h5py/__init__.py:34: FutureWarning: Conversion of the second argument of issubdtype from `float` to `np.floating` is deprecated. In future, it will be treated as `np.float64 == np.dtype(float).type`.
  from ._conv import register_converters as _register_converters
Using TensorFlow backend.
2019-08-02 10:47:44.964829: E tensorflow/core/common_runtime/direct_session.cc:158] Internal: failed initializing StreamExecutor for CUDA device ordinal 0: Internal: failed call to cuDevicePrimaryCtxRetain: CUDA_ERROR_INVALID_DEVICE
/gpfs/pkgs/mhpcc/anaconda3-5.0.1/lib/python3.6/site-packages/h5py/__init__.py:34: FutureWarning: Conversion of the second argument of issubdtype from `float` to `np.floating` is deprecated. In future, it will be treated as `np.float64 == np.dtype(float).type`.
  from ._conv import register_converters as _register_converters
Using TensorFlow backend.
2019-08-02 10:47:45.113908: E tensorflow/core/common_runtime/direct_session.cc:158] Internal: failed initializing StreamExecutor for CUDA device ordinal 0: Internal: failed call to cuDevicePrimaryCtxRetain: CUDA_ERROR_INVALID_DEVICE
/gpfs/pkgs/mhpcc/anaconda3-5.0.1/lib/python3.6/site-packages/h5py/__init__.py:34: FutureWarning: Conversion of the second argument of issubdtype from `float` to `np.floating` is deprecated. In future, it will be treated as `np.float64 == np.dtype(float).type`.
  from ._conv import register_converters as _register_converters
Using TensorFlow backend.
2019-08-02 10:47:45.155935: E tensorflow/core/common_runtime/direct_session.cc:158] Internal: failed initializing StreamExecutor for CUDA device ordinal 0: Internal: failed call to cuDevicePrimaryCtxRetain: CUDA_ERROR_INVALID_DEVICE
/gpfs/pkgs/mhpcc/anaconda3-5.0.1/lib/python3.6/site-packages/h5py/__init__.py:34: FutureWarning: Conversion of the second argument of issubdtype from `float` to `np.floating` is deprecated. In future, it will be treated as `np.float64 == np.dtype(float).type`.
  from ._conv import register_converters as _register_converters
Using TensorFlow backend.
2019-08-02 10:47:45.168055: E tensorflow/core/common_runtime/direct_session.cc:158] Internal: failed initializing StreamExecutor for CUDA device ordinal 0: Internal: failed call to cuDevicePrimaryCtxRetain: CUDA_ERROR_INVALID_DEVICE
/gpfs/pkgs/mhpcc/anaconda3-5.0.1/lib/python3.6/site-packages/h5py/__init__.py:34: FutureWarning: Conversion of the second argument of issubdtype from `float` to `np.floating` is deprecated. In future, it will be treated as `np.float64 == np.dtype(float).type`.
  from ._conv import register_converters as _register_converters
Using TensorFlow backend.
2019-08-02 10:47:45.191119: E tensorflow/core/common_runtime/direct_session.cc:158] Internal: failed initializing StreamExecutor for CUDA device ordinal 0: Internal: failed call to cuDevicePrimaryCtxRetain: CUDA_ERROR_INVALID_DEVICE
/gpfs/pkgs/mhpcc/anaconda3-5.0.1/lib/python3.6/site-packages/h5py/__init__.py:34: FutureWarning: Conversion of the second argument of issubdtype from `float` to `np.floating` is deprecated. In future, it will be treated as `np.float64 == np.dtype(float).type`.
  from ._conv import register_converters as _register_converters
Using TensorFlow backend.
2019-08-02 10:47:45.194410: E tensorflow/core/common_runtime/direct_session.cc:158] Internal: failed initializing StreamExecutor for CUDA device ordinal 0: Internal: failed call to cuDevicePrimaryCtxRetain: CUDA_ERROR_INVALID_DEVICE
/gpfs/pkgs/mhpcc/anaconda3-5.0.1/lib/python3.6/site-packages/h5py/__init__.py:34: FutureWarning: Conversion of the second argument of issubdtype from `float` to `np.floating` is deprecated. In future, it will be treated as `np.float64 == np.dtype(float).type`.
  from ._conv import register_converters as _register_converters
Using TensorFlow backend.
2019-08-02 10:47:45.255717: E tensorflow/core/common_runtime/direct_session.cc:158] Internal: failed initializing StreamExecutor for CUDA device ordinal 0: Internal: failed call to cuDevicePrimaryCtxRetain: CUDA_ERROR_INVALID_DEVICE
/gpfs/pkgs/mhpcc/anaconda3-5.0.1/lib/python3.6/site-packages/h5py/__init__.py:34: FutureWarning: Conversion of the second argument of issubdtype from `float` to `np.floating` is deprecated. In future, it will be treated as `np.float64 == np.dtype(float).type`.
  from ._conv import register_converters as _register_converters
Using TensorFlow backend.
2019-08-02 10:47:45.260060: E tensorflow/core/common_runtime/direct_session.cc:158] Internal: failed initializing StreamExecutor for CUDA device ordinal 0: Internal: failed call to cuDevicePrimaryCtxRetain: CUDA_ERROR_INVALID_DEVICE
/gpfs/pkgs/mhpcc/anaconda3-5.0.1/lib/python3.6/site-packages/h5py/__init__.py:34: FutureWarning: Conversion of the second argument of issubdtype from `float` to `np.floating` is deprecated. In future, it will be treated as `np.float64 == np.dtype(float).type`.
  from ._conv import register_converters as _register_converters
Using TensorFlow backend.
2019-08-02 10:47:45.307509: I tensorflow/core/common_runtime/gpu/gpu_device.cc:1392] Found device 0 with properties: 
name: Tesla P100-SXM2-16GB major: 6 minor: 0 memoryClockRate(GHz): 1.4805
pciBusID: 0002:01:00.0
totalMemory: 15.90GiB freeMemory: 15.64GiB
2019-08-02 10:47:45.361836: E tensorflow/core/common_runtime/direct_session.cc:158] Internal: failed initializing StreamExecutor for CUDA device ordinal 0: Internal: failed call to cuDevicePrimaryCtxRetain: CUDA_ERROR_INVALID_DEVICE
/gpfs/pkgs/mhpcc/anaconda3-5.0.1/lib/python3.6/site-packages/h5py/__init__.py:34: FutureWarning: Conversion of the second argument of issubdtype from `float` to `np.floating` is deprecated. In future, it will be treated as `np.float64 == np.dtype(float).type`.
  from ._conv import register_converters as _register_converters
Using TensorFlow backend.
2019-08-02 10:47:45.376031: E tensorflow/core/common_runtime/direct_session.cc:158] Internal: failed initializing StreamExecutor for CUDA device ordinal 0: Internal: failed call to cuDevicePrimaryCtxRetain: CUDA_ERROR_INVALID_DEVICE
/gpfs/pkgs/mhpcc/anaconda3-5.0.1/lib/python3.6/site-packages/h5py/__init__.py:34: FutureWarning: Conversion of the second argument of issubdtype from `float` to `np.floating` is deprecated. In future, it will be treated as `np.float64 == np.dtype(float).type`.
  from ._conv import register_converters as _register_converters
Using TensorFlow backend.
2019-08-02 10:47:45.390258: E tensorflow/core/common_runtime/direct_session.cc:158] Internal: failed initializing StreamExecutor for CUDA device ordinal 0: Internal: failed call to cuDevicePrimaryCtxRetain: CUDA_ERROR_INVALID_DEVICE
/gpfs/pkgs/mhpcc/anaconda3-5.0.1/lib/python3.6/site-packages/h5py/__init__.py:34: FutureWarning: Conversion of the second argument of issubdtype from `float` to `np.floating` is deprecated. In future, it will be treated as `np.float64 == np.dtype(float).type`.
  from ._conv import register_converters as _register_converters
Using TensorFlow backend.
2019-08-02 10:47:45.397692: E tensorflow/core/common_runtime/direct_session.cc:158] Internal: failed initializing StreamExecutor for CUDA device ordinal 0: Internal: failed call to cuDevicePrimaryCtxRetain: CUDA_ERROR_INVALID_DEVICE
/gpfs/pkgs/mhpcc/anaconda3-5.0.1/lib/python3.6/site-packages/h5py/__init__.py:34: FutureWarning: Conversion of the second argument of issubdtype from `float` to `np.floating` is deprecated. In future, it will be treated as `np.float64 == np.dtype(float).type`.
  from ._conv import register_converters as _register_converters
Using TensorFlow backend.
2019-08-02 10:47:45.407366: E tensorflow/core/common_runtime/direct_session.cc:158] Internal: failed initializing StreamExecutor for CUDA device ordinal 0: Internal: failed call to cuDevicePrimaryCtxRetain: CUDA_ERROR_INVALID_DEVICE
/gpfs/pkgs/mhpcc/anaconda3-5.0.1/lib/python3.6/site-packages/h5py/__init__.py:34: FutureWarning: Conversion of the second argument of issubdtype from `float` to `np.floating` is deprecated. In future, it will be treated as `np.float64 == np.dtype(float).type`.
  from ._conv import register_converters as _register_converters
Using TensorFlow backend.
2019-08-02 10:47:45.431979: E tensorflow/core/common_runtime/direct_session.cc:158] Internal: failed initializing StreamExecutor for CUDA device ordinal 0: Internal: failed call to cuDevicePrimaryCtxRetain: CUDA_ERROR_INVALID_DEVICE
/gpfs/pkgs/mhpcc/anaconda3-5.0.1/lib/python3.6/site-packages/h5py/__init__.py:34: FutureWarning: Conversion of the second argument of issubdtype from `float` to `np.floating` is deprecated. In future, it will be treated as `np.float64 == np.dtype(float).type`.
  from ._conv import register_converters as _register_converters
Using TensorFlow backend.
2019-08-02 10:47:45.463101: E tensorflow/core/common_runtime/direct_session.cc:158] Internal: failed initializing StreamExecutor for CUDA device ordinal 0: Internal: failed call to cuDevicePrimaryCtxRetain: CUDA_ERROR_INVALID_DEVICE
/gpfs/pkgs/mhpcc/anaconda3-5.0.1/lib/python3.6/site-packages/h5py/__init__.py:34: FutureWarning: Conversion of the second argument of issubdtype from `float` to `np.floating` is deprecated. In future, it will be treated as `np.float64 == np.dtype(float).type`.
  from ._conv import register_converters as _register_converters
Using TensorFlow backend.
2019-08-02 10:47:45.483216: E tensorflow/core/common_runtime/direct_session.cc:158] Internal: failed initializing StreamExecutor for CUDA device ordinal 0: Internal: failed call to cuDevicePrimaryCtxRetain: CUDA_ERROR_INVALID_DEVICE
/gpfs/pkgs/mhpcc/anaconda3-5.0.1/lib/python3.6/site-packages/h5py/__init__.py:34: FutureWarning: Conversion of the second argument of issubdtype from `float` to `np.floating` is deprecated. In future, it will be treated as `np.float64 == np.dtype(float).type`.
  from ._conv import register_converters as _register_converters
Using TensorFlow backend.
2019-08-02 10:47:45.526429: E tensorflow/core/common_runtime/direct_session.cc:158] Internal: failed initializing StreamExecutor for CUDA device ordinal 0: Internal: failed call to cuDevicePrimaryCtxRetain: CUDA_ERROR_INVALID_DEVICE
/gpfs/pkgs/mhpcc/anaconda3-5.0.1/lib/python3.6/site-packages/h5py/__init__.py:34: FutureWarning: Conversion of the second argument of issubdtype from `float` to `np.floating` is deprecated. In future, it will be treated as `np.float64 == np.dtype(float).type`.
  from ._conv import register_converters as _register_converters
Using TensorFlow backend.
2019-08-02 10:47:45.539676: E tensorflow/core/common_runtime/direct_session.cc:158] Internal: failed initializing StreamExecutor for CUDA device ordinal 0: Internal: failed call to cuDevicePrimaryCtxRetain: CUDA_ERROR_INVALID_DEVICE
/gpfs/pkgs/mhpcc/anaconda3-5.0.1/lib/python3.6/site-packages/h5py/__init__.py:34: FutureWarning: Conversion of the second argument of issubdtype from `float` to `np.floating` is deprecated. In future, it will be treated as `np.float64 == np.dtype(float).type`.
  from ._conv import register_converters as _register_converters
Using TensorFlow backend.
2019-08-02 10:47:45.545150: E tensorflow/core/common_runtime/direct_session.cc:158] Internal: failed initializing StreamExecutor for CUDA device ordinal 0: Internal: failed call to cuDevicePrimaryCtxRetain: CUDA_ERROR_INVALID_DEVICE
/gpfs/pkgs/mhpcc/anaconda3-5.0.1/lib/python3.6/site-packages/h5py/__init__.py:34: FutureWarning: Conversion of the second argument of issubdtype from `float` to `np.floating` is deprecated. In future, it will be treated as `np.float64 == np.dtype(float).type`.
  from ._conv import register_converters as _register_converters
Using TensorFlow backend.
2019-08-02 10:47:45.565523: E tensorflow/core/common_runtime/direct_session.cc:158] Internal: failed initializing StreamExecutor for CUDA device ordinal 0: Internal: failed call to cuDevicePrimaryCtxRetain: CUDA_ERROR_INVALID_DEVICE
/gpfs/pkgs/mhpcc/anaconda3-5.0.1/lib/python3.6/site-packages/h5py/__init__.py:34: FutureWarning: Conversion of the second argument of issubdtype from `float` to `np.floating` is deprecated. In future, it will be treated as `np.float64 == np.dtype(float).type`.
  from ._conv import register_converters as _register_converters
Using TensorFlow backend.
Traceback (most recent call last):
  File "roundOneSubmit.py", line 23, in <module>
    l.learnThingsCPP(kind=0, file=f, weightFile=wf)
  File "/gpfs/home/m201560/chipboard/learn.py", line 130, in learnThingsCPP
    weights = self.getWeightArray()
  File "/gpfs/home/m201560/chipboard/learn.py", line 199, in getWeightArray
    return self.model.get_weights()[0].tolist()
  File "/gpfs/home/m201560/.local/lib/python3.6/site-packages/keras/engine/network.py", line 492, in get_weights
    return K.batch_get_value(weights)
  File "/gpfs/home/m201560/.local/lib/python3.6/site-packages/keras/backend/tensorflow_backend.py", line 2420, in batch_get_value
    return get_session().run(ops)
  File "/gpfs/home/m201560/.local/lib/python3.6/site-packages/keras/backend/tensorflow_backend.py", line 186, in get_session
    _SESSION = tf.Session(config=config)
  File "/gpfs/pkgs/mhpcc/anaconda3-5.0.1/lib/python3.6/site-packages/tensorflow/python/client/session.py", line 1563, in __init__
    super(Session, self).__init__(target, graph, config=config)
  File "/gpfs/pkgs/mhpcc/anaconda3-5.0.1/lib/python3.6/site-packages/tensorflow/python/client/session.py", line 633, in __init__
    self._session = tf_session.TF_NewSession(self._graph._c_graph, opts)
tensorflow.python.framework.errors_impl.InternalError: Failed to create session.
Traceback (most recent call last):
  File "roundOneSubmit.py", line 23, in <module>
    l.learnThingsCPP(kind=0, file=f, weightFile=wf)
  File "/gpfs/home/m201560/chipboard/learn.py", line 130, in learnThingsCPP
    weights = self.getWeightArray()
  File "/gpfs/home/m201560/chipboard/learn.py", line 199, in getWeightArray
    return self.model.get_weights()[0].tolist()
  File "/gpfs/home/m201560/.local/lib/python3.6/site-packages/keras/engine/network.py", line 492, in get_weights
    return K.batch_get_value(weights)
  File "/gpfs/home/m201560/.local/lib/python3.6/site-packages/keras/backend/tensorflow_backend.py", line 2420, in batch_get_value
    return get_session().run(ops)
  File "/gpfs/home/m201560/.local/lib/python3.6/site-packages/keras/backend/tensorflow_backend.py", line 186, in get_session
    _SESSION = tf.Session(config=config)
  File "/gpfs/pkgs/mhpcc/anaconda3-5.0.1/lib/python3.6/site-packages/tensorflow/python/client/session.py", line 1563, in __init__
    super(Session, self).__init__(target, graph, config=config)
  File "/gpfs/pkgs/mhpcc/anaconda3-5.0.1/lib/python3.6/site-packages/tensorflow/python/client/session.py", line 633, in __init__
    self._session = tf_session.TF_NewSession(self._graph._c_graph, opts)
tensorflow.python.framework.errors_impl.InternalError: Failed to create session.
Traceback (most recent call last):
  File "roundOneSubmit.py", line 23, in <module>
    l.learnThingsCPP(kind=0, file=f, weightFile=wf)
  File "/gpfs/home/m201560/chipboard/learn.py", line 130, in learnThingsCPP
    weights = self.getWeightArray()
  File "/gpfs/home/m201560/chipboard/learn.py", line 199, in getWeightArray
    return self.model.get_weights()[0].tolist()
  File "/gpfs/home/m201560/.local/lib/python3.6/site-packages/keras/engine/network.py", line 492, in get_weights
    return K.batch_get_value(weights)
  File "/gpfs/home/m201560/.local/lib/python3.6/site-packages/keras/backend/tensorflow_backend.py", line 2420, in batch_get_value
    return get_session().run(ops)
  File "/gpfs/home/m201560/.local/lib/python3.6/site-packages/keras/backend/tensorflow_backend.py", line 186, in get_session
    _SESSION = tf.Session(config=config)
  File "/gpfs/pkgs/mhpcc/anaconda3-5.0.1/lib/python3.6/site-packages/tensorflow/python/client/session.py", line 1563, in __init__
    super(Session, self).__init__(target, graph, config=config)
  File "/gpfs/pkgs/mhpcc/anaconda3-5.0.1/lib/python3.6/site-packages/tensorflow/python/client/session.py", line 633, in __init__
    self._session = tf_session.TF_NewSession(self._graph._c_graph, opts)
tensorflow.python.framework.errors_impl.InternalError: Failed to create session.
Traceback (most recent call last):
  File "roundOneSubmit.py", line 23, in <module>
    l.learnThingsCPP(kind=0, file=f, weightFile=wf)
  File "/gpfs/home/m201560/chipboard/learn.py", line 130, in learnThingsCPP
    weights = self.getWeightArray()
  File "/gpfs/home/m201560/chipboard/learn.py", line 199, in getWeightArray
    return self.model.get_weights()[0].tolist()
  File "/gpfs/home/m201560/.local/lib/python3.6/site-packages/keras/engine/network.py", line 492, in get_weights
    return K.batch_get_value(weights)
  File "/gpfs/home/m201560/.local/lib/python3.6/site-packages/keras/backend/tensorflow_backend.py", line 2420, in batch_get_value
    return get_session().run(ops)
  File "/gpfs/home/m201560/.local/lib/python3.6/site-packages/keras/backend/tensorflow_backend.py", line 186, in get_session
    _SESSION = tf.Session(config=config)
  File "/gpfs/pkgs/mhpcc/anaconda3-5.0.1/lib/python3.6/site-packages/tensorflow/python/client/session.py", line 1563, in __init__
    super(Session, self).__init__(target, graph, config=config)
  File "/gpfs/pkgs/mhpcc/anaconda3-5.0.1/lib/python3.6/site-packages/tensorflow/python/client/session.py", line 633, in __init__
    self._session = tf_session.TF_NewSession(self._graph._c_graph, opts)
tensorflow.python.framework.errors_impl.InternalError: Failed to create session.
Traceback (most recent call last):
  File "roundOneSubmit.py", line 23, in <module>
    l.learnThingsCPP(kind=0, file=f, weightFile=wf)
  File "/gpfs/home/m201560/chipboard/learn.py", line 130, in learnThingsCPP
    weights = self.getWeightArray()
  File "/gpfs/home/m201560/chipboard/learn.py", line 199, in getWeightArray
    return self.model.get_weights()[0].tolist()
  File "/gpfs/home/m201560/.local/lib/python3.6/site-packages/keras/engine/network.py", line 492, in get_weights
    return K.batch_get_value(weights)
  File "/gpfs/home/m201560/.local/lib/python3.6/site-packages/keras/backend/tensorflow_backend.py", line 2420, in batch_get_value
    return get_session().run(ops)
  File "/gpfs/home/m201560/.local/lib/python3.6/site-packages/keras/backend/tensorflow_backend.py", line 186, in get_session
    _SESSION = tf.Session(config=config)
  File "/gpfs/pkgs/mhpcc/anaconda3-5.0.1/lib/python3.6/site-packages/tensorflow/python/client/session.py", line 1563, in __init__
    super(Session, self).__init__(target, graph, config=config)
  File "/gpfs/pkgs/mhpcc/anaconda3-5.0.1/lib/python3.6/site-packages/tensorflow/python/client/session.py", line 633, in __init__
    self._session = tf_session.TF_NewSession(self._graph._c_graph, opts)
tensorflow.python.framework.errors_impl.InternalError: Failed to create session.
Traceback (most recent call last):
  File "roundOneSubmit.py", line 23, in <module>
    l.learnThingsCPP(kind=0, file=f, weightFile=wf)
  File "/gpfs/home/m201560/chipboard/learn.py", line 130, in learnThingsCPP
    weights = self.getWeightArray()
  File "/gpfs/home/m201560/chipboard/learn.py", line 199, in getWeightArray
    return self.model.get_weights()[0].tolist()
  File "/gpfs/home/m201560/.local/lib/python3.6/site-packages/keras/engine/network.py", line 492, in get_weights
    return K.batch_get_value(weights)
  File "/gpfs/home/m201560/.local/lib/python3.6/site-packages/keras/backend/tensorflow_backend.py", line 2420, in batch_get_value
    return get_session().run(ops)
  File "/gpfs/home/m201560/.local/lib/python3.6/site-packages/keras/backend/tensorflow_backend.py", line 186, in get_session
    _SESSION = tf.Session(config=config)
  File "/gpfs/pkgs/mhpcc/anaconda3-5.0.1/lib/python3.6/site-packages/tensorflow/python/client/session.py", line 1563, in __init__
    super(Session, self).__init__(target, graph, config=config)
  File "/gpfs/pkgs/mhpcc/anaconda3-5.0.1/lib/python3.6/site-packages/tensorflow/python/client/session.py", line 633, in __init__
    self._session = tf_session.TF_NewSession(self._graph._c_graph, opts)
tensorflow.python.framework.errors_impl.InternalError: Failed to create session.
Traceback (most recent call last):
  File "roundOneSubmit.py", line 23, in <module>
    l.learnThingsCPP(kind=0, file=f, weightFile=wf)
  File "/gpfs/home/m201560/chipboard/learn.py", line 130, in learnThingsCPP
    weights = self.getWeightArray()
  File "/gpfs/home/m201560/chipboard/learn.py", line 199, in getWeightArray
    return self.model.get_weights()[0].tolist()
  File "/gpfs/home/m201560/.local/lib/python3.6/site-packages/keras/engine/network.py", line 492, in get_weights
    return K.batch_get_value(weights)
  File "/gpfs/home/m201560/.local/lib/python3.6/site-packages/keras/backend/tensorflow_backend.py", line 2420, in batch_get_value
    return get_session().run(ops)
  File "/gpfs/home/m201560/.local/lib/python3.6/site-packages/keras/backend/tensorflow_backend.py", line 186, in get_session
    _SESSION = tf.Session(config=config)
  File "/gpfs/pkgs/mhpcc/anaconda3-5.0.1/lib/python3.6/site-packages/tensorflow/python/client/session.py", line 1563, in __init__
    super(Session, self).__init__(target, graph, config=config)
  File "/gpfs/pkgs/mhpcc/anaconda3-5.0.1/lib/python3.6/site-packages/tensorflow/python/client/session.py", line 633, in __init__
    self._session = tf_session.TF_NewSession(self._graph._c_graph, opts)
tensorflow.python.framework.errors_impl.InternalError: Failed to create session.
Traceback (most recent call last):
  File "roundOneSubmit.py", line 23, in <module>
    l.learnThingsCPP(kind=0, file=f, weightFile=wf)
  File "/gpfs/home/m201560/chipboard/learn.py", line 130, in learnThingsCPP
    weights = self.getWeightArray()
  File "/gpfs/home/m201560/chipboard/learn.py", line 199, in getWeightArray
    return self.model.get_weights()[0].tolist()
  File "/gpfs/home/m201560/.local/lib/python3.6/site-packages/keras/engine/network.py", line 492, in get_weights
    return K.batch_get_value(weights)
  File "/gpfs/home/m201560/.local/lib/python3.6/site-packages/keras/backend/tensorflow_backend.py", line 2420, in batch_get_value
    return get_session().run(ops)
  File "/gpfs/home/m201560/.local/lib/python3.6/site-packages/keras/backend/tensorflow_backend.py", line 186, in get_session
    _SESSION = tf.Session(config=config)
  File "/gpfs/pkgs/mhpcc/anaconda3-5.0.1/lib/python3.6/site-packages/tensorflow/python/client/session.py", line 1563, in __init__
    super(Session, self).__init__(target, graph, config=config)
  File "/gpfs/pkgs/mhpcc/anaconda3-5.0.1/lib/python3.6/site-packages/tensorflow/python/client/session.py", line 633, in __init__
    self._session = tf_session.TF_NewSession(self._graph._c_graph, opts)
tensorflow.python.framework.errors_impl.InternalError: Failed to create session.
Traceback (most recent call last):
  File "roundOneSubmit.py", line 23, in <module>
    l.learnThingsCPP(kind=0, file=f, weightFile=wf)
  File "/gpfs/home/m201560/chipboard/learn.py", line 130, in learnThingsCPP
    weights = self.getWeightArray()
  File "/gpfs/home/m201560/chipboard/learn.py", line 199, in getWeightArray
    return self.model.get_weights()[0].tolist()
  File "/gpfs/home/m201560/.local/lib/python3.6/site-packages/keras/engine/network.py", line 492, in get_weights
    return K.batch_get_value(weights)
  File "/gpfs/home/m201560/.local/lib/python3.6/site-packages/keras/backend/tensorflow_backend.py", line 2420, in batch_get_value
    return get_session().run(ops)
  File "/gpfs/home/m201560/.local/lib/python3.6/site-packages/keras/backend/tensorflow_backend.py", line 186, in get_session
    _SESSION = tf.Session(config=config)
  File "/gpfs/pkgs/mhpcc/anaconda3-5.0.1/lib/python3.6/site-packages/tensorflow/python/client/session.py", line 1563, in __init__
    super(Session, self).__init__(target, graph, config=config)
  File "/gpfs/pkgs/mhpcc/anaconda3-5.0.1/lib/python3.6/site-packages/tensorflow/python/client/session.py", line 633, in __init__
    self._session = tf_session.TF_NewSession(self._graph._c_graph, opts)
tensorflow.python.framework.errors_impl.InternalError: Failed to create session.
Traceback (most recent call last):
  File "roundOneSubmit.py", line 23, in <module>
    l.learnThingsCPP(kind=0, file=f, weightFile=wf)
  File "/gpfs/home/m201560/chipboard/learn.py", line 130, in learnThingsCPP
    weights = self.getWeightArray()
  File "/gpfs/home/m201560/chipboard/learn.py", line 199, in getWeightArray
    return self.model.get_weights()[0].tolist()
  File "/gpfs/home/m201560/.local/lib/python3.6/site-packages/keras/engine/network.py", line 492, in get_weights
    return K.batch_get_value(weights)
  File "/gpfs/home/m201560/.local/lib/python3.6/site-packages/keras/backend/tensorflow_backend.py", line 2420, in batch_get_value
    return get_session().run(ops)
  File "/gpfs/home/m201560/.local/lib/python3.6/site-packages/keras/backend/tensorflow_backend.py", line 186, in get_session
    _SESSION = tf.Session(config=config)
  File "/gpfs/pkgs/mhpcc/anaconda3-5.0.1/lib/python3.6/site-packages/tensorflow/python/client/session.py", line 1563, in __init__
    super(Session, self).__init__(target, graph, config=config)
  File "/gpfs/pkgs/mhpcc/anaconda3-5.0.1/lib/python3.6/site-packages/tensorflow/python/client/session.py", line 633, in __init__
    self._session = tf_session.TF_NewSession(self._graph._c_graph, opts)
tensorflow.python.framework.errors_impl.InternalError: Failed to create session.
Traceback (most recent call last):
  File "roundOneSubmit.py", line 23, in <module>
    l.learnThingsCPP(kind=0, file=f, weightFile=wf)
  File "/gpfs/home/m201560/chipboard/learn.py", line 130, in learnThingsCPP
    weights = self.getWeightArray()
  File "/gpfs/home/m201560/chipboard/learn.py", line 199, in getWeightArray
    return self.model.get_weights()[0].tolist()
  File "/gpfs/home/m201560/.local/lib/python3.6/site-packages/keras/engine/network.py", line 492, in get_weights
    return K.batch_get_value(weights)
  File "/gpfs/home/m201560/.local/lib/python3.6/site-packages/keras/backend/tensorflow_backend.py", line 2420, in batch_get_value
    return get_session().run(ops)
  File "/gpfs/home/m201560/.local/lib/python3.6/site-packages/keras/backend/tensorflow_backend.py", line 186, in get_session
    _SESSION = tf.Session(config=config)
  File "/gpfs/pkgs/mhpcc/anaconda3-5.0.1/lib/python3.6/site-packages/tensorflow/python/client/session.py", line 1563, in __init__
    super(Session, self).__init__(target, graph, config=config)
  File "/gpfs/pkgs/mhpcc/anaconda3-5.0.1/lib/python3.6/site-packages/tensorflow/python/client/session.py", line 633, in __init__
    self._session = tf_session.TF_NewSession(self._graph._c_graph, opts)
tensorflow.python.framework.errors_impl.InternalError: Failed to create session.
Traceback (most recent call last):
  File "roundOneSubmit.py", line 23, in <module>
    l.learnThingsCPP(kind=0, file=f, weightFile=wf)
  File "/gpfs/home/m201560/chipboard/learn.py", line 130, in learnThingsCPP
    weights = self.getWeightArray()
  File "/gpfs/home/m201560/chipboard/learn.py", line 199, in getWeightArray
    return self.model.get_weights()[0].tolist()
  File "/gpfs/home/m201560/.local/lib/python3.6/site-packages/keras/engine/network.py", line 492, in get_weights
    return K.batch_get_value(weights)
  File "/gpfs/home/m201560/.local/lib/python3.6/site-packages/keras/backend/tensorflow_backend.py", line 2420, in batch_get_value
    return get_session().run(ops)
  File "/gpfs/home/m201560/.local/lib/python3.6/site-packages/keras/backend/tensorflow_backend.py", line 186, in get_session
    _SESSION = tf.Session(config=config)
  File "/gpfs/pkgs/mhpcc/anaconda3-5.0.1/lib/python3.6/site-packages/tensorflow/python/client/session.py", line 1563, in __init__
    super(Session, self).__init__(target, graph, config=config)
  File "/gpfs/pkgs/mhpcc/anaconda3-5.0.1/lib/python3.6/site-packages/tensorflow/python/client/session.py", line 633, in __init__
    self._session = tf_session.TF_NewSession(self._graph._c_graph, opts)
tensorflow.python.framework.errors_impl.InternalError: Failed to create session.
Traceback (most recent call last):
  File "roundOneSubmit.py", line 23, in <module>
    l.learnThingsCPP(kind=0, file=f, weightFile=wf)
  File "/gpfs/home/m201560/chipboard/learn.py", line 130, in learnThingsCPP
    weights = self.getWeightArray()
  File "/gpfs/home/m201560/chipboard/learn.py", line 199, in getWeightArray
    return self.model.get_weights()[0].tolist()
  File "/gpfs/home/m201560/.local/lib/python3.6/site-packages/keras/engine/network.py", line 492, in get_weights
    return K.batch_get_value(weights)
  File "/gpfs/home/m201560/.local/lib/python3.6/site-packages/keras/backend/tensorflow_backend.py", line 2420, in batch_get_value
    return get_session().run(ops)
  File "/gpfs/home/m201560/.local/lib/python3.6/site-packages/keras/backend/tensorflow_backend.py", line 186, in get_session
    _SESSION = tf.Session(config=config)
  File "/gpfs/pkgs/mhpcc/anaconda3-5.0.1/lib/python3.6/site-packages/tensorflow/python/client/session.py", line 1563, in __init__
    super(Session, self).__init__(target, graph, config=config)
  File "/gpfs/pkgs/mhpcc/anaconda3-5.0.1/lib/python3.6/site-packages/tensorflow/python/client/session.py", line 633, in __init__
    self._session = tf_session.TF_NewSession(self._graph._c_graph, opts)
tensorflow.python.framework.errors_impl.InternalError: Failed to create session.
Traceback (most recent call last):
  File "roundOneSubmit.py", line 23, in <module>
    l.learnThingsCPP(kind=0, file=f, weightFile=wf)
  File "/gpfs/home/m201560/chipboard/learn.py", line 130, in learnThingsCPP
    weights = self.getWeightArray()
  File "/gpfs/home/m201560/chipboard/learn.py", line 199, in getWeightArray
    return self.model.get_weights()[0].tolist()
  File "/gpfs/home/m201560/.local/lib/python3.6/site-packages/keras/engine/network.py", line 492, in get_weights
    return K.batch_get_value(weights)
  File "/gpfs/home/m201560/.local/lib/python3.6/site-packages/keras/backend/tensorflow_backend.py", line 2420, in batch_get_value
    return get_session().run(ops)
  File "/gpfs/home/m201560/.local/lib/python3.6/site-packages/keras/backend/tensorflow_backend.py", line 186, in get_session
    _SESSION = tf.Session(config=config)
  File "/gpfs/pkgs/mhpcc/anaconda3-5.0.1/lib/python3.6/site-packages/tensorflow/python/client/session.py", line 1563, in __init__
    super(Session, self).__init__(target, graph, config=config)
  File "/gpfs/pkgs/mhpcc/anaconda3-5.0.1/lib/python3.6/site-packages/tensorflow/python/client/session.py", line 633, in __init__
    self._session = tf_session.TF_NewSession(self._graph._c_graph, opts)
tensorflow.python.framework.errors_impl.InternalError: Failed to create session.
Traceback (most recent call last):
  File "roundOneSubmit.py", line 23, in <module>
    l.learnThingsCPP(kind=0, file=f, weightFile=wf)
  File "/gpfs/home/m201560/chipboard/learn.py", line 130, in learnThingsCPP
    weights = self.getWeightArray()
  File "/gpfs/home/m201560/chipboard/learn.py", line 199, in getWeightArray
    return self.model.get_weights()[0].tolist()
  File "/gpfs/home/m201560/.local/lib/python3.6/site-packages/keras/engine/network.py", line 492, in get_weights
    return K.batch_get_value(weights)
  File "/gpfs/home/m201560/.local/lib/python3.6/site-packages/keras/backend/tensorflow_backend.py", line 2420, in batch_get_value
    return get_session().run(ops)
  File "/gpfs/home/m201560/.local/lib/python3.6/site-packages/keras/backend/tensorflow_backend.py", line 186, in get_session
    _SESSION = tf.Session(config=config)
  File "/gpfs/pkgs/mhpcc/anaconda3-5.0.1/lib/python3.6/site-packages/tensorflow/python/client/session.py", line 1563, in __init__
    super(Session, self).__init__(target, graph, config=config)
  File "/gpfs/pkgs/mhpcc/anaconda3-5.0.1/lib/python3.6/site-packages/tensorflow/python/client/session.py", line 633, in __init__
    self._session = tf_session.TF_NewSession(self._graph._c_graph, opts)
tensorflow.python.framework.errors_impl.InternalError: Failed to create session.
Traceback (most recent call last):
  File "roundOneSubmit.py", line 23, in <module>
    l.learnThingsCPP(kind=0, file=f, weightFile=wf)
  File "/gpfs/home/m201560/chipboard/learn.py", line 130, in learnThingsCPP
    weights = self.getWeightArray()
  File "/gpfs/home/m201560/chipboard/learn.py", line 199, in getWeightArray
    return self.model.get_weights()[0].tolist()
  File "/gpfs/home/m201560/.local/lib/python3.6/site-packages/keras/engine/network.py", line 492, in get_weights
    return K.batch_get_value(weights)
  File "/gpfs/home/m201560/.local/lib/python3.6/site-packages/keras/backend/tensorflow_backend.py", line 2420, in batch_get_value
    return get_session().run(ops)
  File "/gpfs/home/m201560/.local/lib/python3.6/site-packages/keras/backend/tensorflow_backend.py", line 186, in get_session
    _SESSION = tf.Session(config=config)
  File "/gpfs/pkgs/mhpcc/anaconda3-5.0.1/lib/python3.6/site-packages/tensorflow/python/client/session.py", line 1563, in __init__
    super(Session, self).__init__(target, graph, config=config)
  File "/gpfs/pkgs/mhpcc/anaconda3-5.0.1/lib/python3.6/site-packages/tensorflow/python/client/session.py", line 633, in __init__
    self._session = tf_session.TF_NewSession(self._graph._c_graph, opts)
tensorflow.python.framework.errors_impl.InternalError: Failed to create session.
Traceback (most recent call last):
  File "roundOneSubmit.py", line 23, in <module>
    l.learnThingsCPP(kind=0, file=f, weightFile=wf)
  File "/gpfs/home/m201560/chipboard/learn.py", line 130, in learnThingsCPP
    weights = self.getWeightArray()
  File "/gpfs/home/m201560/chipboard/learn.py", line 199, in getWeightArray
    return self.model.get_weights()[0].tolist()
  File "/gpfs/home/m201560/.local/lib/python3.6/site-packages/keras/engine/network.py", line 492, in get_weights
    return K.batch_get_value(weights)
  File "/gpfs/home/m201560/.local/lib/python3.6/site-packages/keras/backend/tensorflow_backend.py", line 2420, in batch_get_value
    return get_session().run(ops)
  File "/gpfs/home/m201560/.local/lib/python3.6/site-packages/keras/backend/tensorflow_backend.py", line 186, in get_session
    _SESSION = tf.Session(config=config)
  File "/gpfs/pkgs/mhpcc/anaconda3-5.0.1/lib/python3.6/site-packages/tensorflow/python/client/session.py", line 1563, in __init__
    super(Session, self).__init__(target, graph, config=config)
  File "/gpfs/pkgs/mhpcc/anaconda3-5.0.1/lib/python3.6/site-packages/tensorflow/python/client/session.py", line 633, in __init__
    self._session = tf_session.TF_NewSession(self._graph._c_graph, opts)
tensorflow.python.framework.errors_impl.InternalError: Failed to create session.
Traceback (most recent call last):
  File "roundOneSubmit.py", line 23, in <module>
    l.learnThingsCPP(kind=0, file=f, weightFile=wf)
  File "/gpfs/home/m201560/chipboard/learn.py", line 130, in learnThingsCPP
    weights = self.getWeightArray()
  File "/gpfs/home/m201560/chipboard/learn.py", line 199, in getWeightArray
    return self.model.get_weights()[0].tolist()
  File "/gpfs/home/m201560/.local/lib/python3.6/site-packages/keras/engine/network.py", line 492, in get_weights
    return K.batch_get_value(weights)
  File "/gpfs/home/m201560/.local/lib/python3.6/site-packages/keras/backend/tensorflow_backend.py", line 2420, in batch_get_value
    return get_session().run(ops)
  File "/gpfs/home/m201560/.local/lib/python3.6/site-packages/keras/backend/tensorflow_backend.py", line 186, in get_session
    _SESSION = tf.Session(config=config)
  File "/gpfs/pkgs/mhpcc/anaconda3-5.0.1/lib/python3.6/site-packages/tensorflow/python/client/session.py", line 1563, in __init__
    super(Session, self).__init__(target, graph, config=config)
  File "/gpfs/pkgs/mhpcc/anaconda3-5.0.1/lib/python3.6/site-packages/tensorflow/python/client/session.py", line 633, in __init__
    self._session = tf_session.TF_NewSession(self._graph._c_graph, opts)
tensorflow.python.framework.errors_impl.InternalError: Failed to create session.
Traceback (most recent call last):
  File "roundOneSubmit.py", line 23, in <module>
    l.learnThingsCPP(kind=0, file=f, weightFile=wf)
  File "/gpfs/home/m201560/chipboard/learn.py", line 130, in learnThingsCPP
    weights = self.getWeightArray()
  File "/gpfs/home/m201560/chipboard/learn.py", line 199, in getWeightArray
    return self.model.get_weights()[0].tolist()
  File "/gpfs/home/m201560/.local/lib/python3.6/site-packages/keras/engine/network.py", line 492, in get_weights
    return K.batch_get_value(weights)
  File "/gpfs/home/m201560/.local/lib/python3.6/site-packages/keras/backend/tensorflow_backend.py", line 2420, in batch_get_value
    return get_session().run(ops)
  File "/gpfs/home/m201560/.local/lib/python3.6/site-packages/keras/backend/tensorflow_backend.py", line 186, in get_session
    _SESSION = tf.Session(config=config)
  File "/gpfs/pkgs/mhpcc/anaconda3-5.0.1/lib/python3.6/site-packages/tensorflow/python/client/session.py", line 1563, in __init__
    super(Session, self).__init__(target, graph, config=config)
  File "/gpfs/pkgs/mhpcc/anaconda3-5.0.1/lib/python3.6/site-packages/tensorflow/python/client/session.py", line 633, in __init__
    self._session = tf_session.TF_NewSession(self._graph._c_graph, opts)
tensorflow.python.framework.errors_impl.InternalError: Failed to create session.
Traceback (most recent call last):
  File "roundOneSubmit.py", line 23, in <module>
    l.learnThingsCPP(kind=0, file=f, weightFile=wf)
  File "/gpfs/home/m201560/chipboard/learn.py", line 130, in learnThingsCPP
    weights = self.getWeightArray()
  File "/gpfs/home/m201560/chipboard/learn.py", line 199, in getWeightArray
    return self.model.get_weights()[0].tolist()
  File "/gpfs/home/m201560/.local/lib/python3.6/site-packages/keras/engine/network.py", line 492, in get_weights
    return K.batch_get_value(weights)
  File "/gpfs/home/m201560/.local/lib/python3.6/site-packages/keras/backend/tensorflow_backend.py", line 2420, in batch_get_value
    return get_session().run(ops)
  File "/gpfs/home/m201560/.local/lib/python3.6/site-packages/keras/backend/tensorflow_backend.py", line 186, in get_session
    _SESSION = tf.Session(config=config)
  File "/gpfs/pkgs/mhpcc/anaconda3-5.0.1/lib/python3.6/site-packages/tensorflow/python/client/session.py", line 1563, in __init__
    super(Session, self).__init__(target, graph, config=config)
  File "/gpfs/pkgs/mhpcc/anaconda3-5.0.1/lib/python3.6/site-packages/tensorflow/python/client/session.py", line 633, in __init__
    self._session = tf_session.TF_NewSession(self._graph._c_graph, opts)
tensorflow.python.framework.errors_impl.InternalError: Failed to create session.
Traceback (most recent call last):
  File "roundOneSubmit.py", line 23, in <module>
    l.learnThingsCPP(kind=0, file=f, weightFile=wf)
  File "/gpfs/home/m201560/chipboard/learn.py", line 130, in learnThingsCPP
    weights = self.getWeightArray()
  File "/gpfs/home/m201560/chipboard/learn.py", line 199, in getWeightArray
    return self.model.get_weights()[0].tolist()
  File "/gpfs/home/m201560/.local/lib/python3.6/site-packages/keras/engine/network.py", line 492, in get_weights
    return K.batch_get_value(weights)
  File "/gpfs/home/m201560/.local/lib/python3.6/site-packages/keras/backend/tensorflow_backend.py", line 2420, in batch_get_value
    return get_session().run(ops)
  File "/gpfs/home/m201560/.local/lib/python3.6/site-packages/keras/backend/tensorflow_backend.py", line 186, in get_session
    _SESSION = tf.Session(config=config)
  File "/gpfs/pkgs/mhpcc/anaconda3-5.0.1/lib/python3.6/site-packages/tensorflow/python/client/session.py", line 1563, in __init__
    super(Session, self).__init__(target, graph, config=config)
  File "/gpfs/pkgs/mhpcc/anaconda3-5.0.1/lib/python3.6/site-packages/tensorflow/python/client/session.py", line 633, in __init__
    self._session = tf_session.TF_NewSession(self._graph._c_graph, opts)
tensorflow.python.framework.errors_impl.InternalError: Failed to create session.
Traceback (most recent call last):
  File "roundOneSubmit.py", line 23, in <module>
    l.learnThingsCPP(kind=0, file=f, weightFile=wf)
  File "/gpfs/home/m201560/chipboard/learn.py", line 130, in learnThingsCPP
    weights = self.getWeightArray()
  File "/gpfs/home/m201560/chipboard/learn.py", line 199, in getWeightArray
    return self.model.get_weights()[0].tolist()
  File "/gpfs/home/m201560/.local/lib/python3.6/site-packages/keras/engine/network.py", line 492, in get_weights
    return K.batch_get_value(weights)
  File "/gpfs/home/m201560/.local/lib/python3.6/site-packages/keras/backend/tensorflow_backend.py", line 2420, in batch_get_value
    return get_session().run(ops)
  File "/gpfs/home/m201560/.local/lib/python3.6/site-packages/keras/backend/tensorflow_backend.py", line 186, in get_session
    _SESSION = tf.Session(config=config)
  File "/gpfs/pkgs/mhpcc/anaconda3-5.0.1/lib/python3.6/site-packages/tensorflow/python/client/session.py", line 1563, in __init__
    super(Session, self).__init__(target, graph, config=config)
  File "/gpfs/pkgs/mhpcc/anaconda3-5.0.1/lib/python3.6/site-packages/tensorflow/python/client/session.py", line 633, in __init__
    self._session = tf_session.TF_NewSession(self._graph._c_graph, opts)
tensorflow.python.framework.errors_impl.InternalError: Failed to create session.
2019-08-02 10:47:45.636283: E tensorflow/core/common_runtime/direct_session.cc:158] Internal: failed initializing StreamExecutor for CUDA device ordinal 0: Internal: failed call to cuDevicePrimaryCtxRetain: CUDA_ERROR_INVALID_DEVICE
/gpfs/pkgs/mhpcc/anaconda3-5.0.1/lib/python3.6/site-packages/h5py/__init__.py:34: FutureWarning: Conversion of the second argument of issubdtype from `float` to `np.floating` is deprecated. In future, it will be treated as `np.float64 == np.dtype(float).type`.
  from ._conv import register_converters as _register_converters
Using TensorFlow backend.
Traceback (most recent call last):
  File "roundOneSubmit.py", line 23, in <module>
    l.learnThingsCPP(kind=0, file=f, weightFile=wf)
  File "/gpfs/home/m201560/chipboard/learn.py", line 130, in learnThingsCPP
    weights = self.getWeightArray()
  File "/gpfs/home/m201560/chipboard/learn.py", line 199, in getWeightArray
    return self.model.get_weights()[0].tolist()
  File "/gpfs/home/m201560/.local/lib/python3.6/site-packages/keras/engine/network.py", line 492, in get_weights
    return K.batch_get_value(weights)
  File "/gpfs/home/m201560/.local/lib/python3.6/site-packages/keras/backend/tensorflow_backend.py", line 2420, in batch_get_value
    return get_session().run(ops)
  File "/gpfs/home/m201560/.local/lib/python3.6/site-packages/keras/backend/tensorflow_backend.py", line 186, in get_session
    _SESSION = tf.Session(config=config)
  File "/gpfs/pkgs/mhpcc/anaconda3-5.0.1/lib/python3.6/site-packages/tensorflow/python/client/session.py", line 1563, in __init__
    super(Session, self).__init__(target, graph, config=config)
  File "/gpfs/pkgs/mhpcc/anaconda3-5.0.1/lib/python3.6/site-packages/tensorflow/python/client/session.py", line 633, in __init__
    self._session = tf_session.TF_NewSession(self._graph._c_graph, opts)
tensorflow.python.framework.errors_impl.InternalError: Failed to create session.
2019-08-02 10:47:45.651474: E tensorflow/core/common_runtime/direct_session.cc:158] Internal: failed initializing StreamExecutor for CUDA device ordinal 0: Internal: failed call to cuDevicePrimaryCtxRetain: CUDA_ERROR_INVALID_DEVICE
/gpfs/pkgs/mhpcc/anaconda3-5.0.1/lib/python3.6/site-packages/h5py/__init__.py:34: FutureWarning: Conversion of the second argument of issubdtype from `float` to `np.floating` is deprecated. In future, it will be treated as `np.float64 == np.dtype(float).type`.
  from ._conv import register_converters as _register_converters
Using TensorFlow backend.
Traceback (most recent call last):
  File "roundOneSubmit.py", line 23, in <module>
    l.learnThingsCPP(kind=0, file=f, weightFile=wf)
  File "/gpfs/home/m201560/chipboard/learn.py", line 130, in learnThingsCPP
    weights = self.getWeightArray()
  File "/gpfs/home/m201560/chipboard/learn.py", line 199, in getWeightArray
    return self.model.get_weights()[0].tolist()
  File "/gpfs/home/m201560/.local/lib/python3.6/site-packages/keras/engine/network.py", line 492, in get_weights
    return K.batch_get_value(weights)
  File "/gpfs/home/m201560/.local/lib/python3.6/site-packages/keras/backend/tensorflow_backend.py", line 2420, in batch_get_value
    return get_session().run(ops)
  File "/gpfs/home/m201560/.local/lib/python3.6/site-packages/keras/backend/tensorflow_backend.py", line 186, in get_session
    _SESSION = tf.Session(config=config)
  File "/gpfs/pkgs/mhpcc/anaconda3-5.0.1/lib/python3.6/site-packages/tensorflow/python/client/session.py", line 1563, in __init__
    super(Session, self).__init__(target, graph, config=config)
  File "/gpfs/pkgs/mhpcc/anaconda3-5.0.1/lib/python3.6/site-packages/tensorflow/python/client/session.py", line 633, in __init__
    self._session = tf_session.TF_NewSession(self._graph._c_graph, opts)
tensorflow.python.framework.errors_impl.InternalError: Failed to create session.
2019-08-02 10:47:45.662321: E tensorflow/core/common_runtime/direct_session.cc:158] Internal: failed initializing StreamExecutor for CUDA device ordinal 0: Internal: failed call to cuDevicePrimaryCtxRetain: CUDA_ERROR_INVALID_DEVICE
/gpfs/pkgs/mhpcc/anaconda3-5.0.1/lib/python3.6/site-packages/h5py/__init__.py:34: FutureWarning: Conversion of the second argument of issubdtype from `float` to `np.floating` is deprecated. In future, it will be treated as `np.float64 == np.dtype(float).type`.
  from ._conv import register_converters as _register_converters
Using TensorFlow backend.
Traceback (most recent call last):
  File "roundOneSubmit.py", line 23, in <module>
    l.learnThingsCPP(kind=0, file=f, weightFile=wf)
  File "/gpfs/home/m201560/chipboard/learn.py", line 130, in learnThingsCPP
    weights = self.getWeightArray()
  File "/gpfs/home/m201560/chipboard/learn.py", line 199, in getWeightArray
    return self.model.get_weights()[0].tolist()
  File "/gpfs/home/m201560/.local/lib/python3.6/site-packages/keras/engine/network.py", line 492, in get_weights
    return K.batch_get_value(weights)
  File "/gpfs/home/m201560/.local/lib/python3.6/site-packages/keras/backend/tensorflow_backend.py", line 2420, in batch_get_value
    return get_session().run(ops)
  File "/gpfs/home/m201560/.local/lib/python3.6/site-packages/keras/backend/tensorflow_backend.py", line 186, in get_session
    _SESSION = tf.Session(config=config)
  File "/gpfs/pkgs/mhpcc/anaconda3-5.0.1/lib/python3.6/site-packages/tensorflow/python/client/session.py", line 1563, in __init__
    super(Session, self).__init__(target, graph, config=config)
  File "/gpfs/pkgs/mhpcc/anaconda3-5.0.1/lib/python3.6/site-packages/tensorflow/python/client/session.py", line 633, in __init__
    self._session = tf_session.TF_NewSession(self._graph._c_graph, opts)
tensorflow.python.framework.errors_impl.InternalError: Failed to create session.
2019-08-02 10:47:45.710094: E tensorflow/core/common_runtime/direct_session.cc:158] Internal: failed initializing StreamExecutor for CUDA device ordinal 0: Internal: failed call to cuDevicePrimaryCtxRetain: CUDA_ERROR_INVALID_DEVICE
/gpfs/pkgs/mhpcc/anaconda3-5.0.1/lib/python3.6/site-packages/h5py/__init__.py:34: FutureWarning: Conversion of the second argument of issubdtype from `float` to `np.floating` is deprecated. In future, it will be treated as `np.float64 == np.dtype(float).type`.
  from ._conv import register_converters as _register_converters
Using TensorFlow backend.
2019-08-02 10:47:45.712655: E tensorflow/core/common_runtime/direct_session.cc:158] Internal: failed initializing StreamExecutor for CUDA device ordinal 0: Internal: failed call to cuDevicePrimaryCtxRetain: CUDA_ERROR_INVALID_DEVICE
/gpfs/pkgs/mhpcc/anaconda3-5.0.1/lib/python3.6/site-packages/h5py/__init__.py:34: FutureWarning: Conversion of the second argument of issubdtype from `float` to `np.floating` is deprecated. In future, it will be treated as `np.float64 == np.dtype(float).type`.
  from ._conv import register_converters as _register_converters
Using TensorFlow backend.
2019-08-02 10:47:45.716773: E tensorflow/core/common_runtime/direct_session.cc:158] Internal: failed initializing StreamExecutor for CUDA device ordinal 0: Internal: failed call to cuDevicePrimaryCtxRetain: CUDA_ERROR_INVALID_DEVICE
/gpfs/pkgs/mhpcc/anaconda3-5.0.1/lib/python3.6/site-packages/h5py/__init__.py:34: FutureWarning: Conversion of the second argument of issubdtype from `float` to `np.floating` is deprecated. In future, it will be treated as `np.float64 == np.dtype(float).type`.
  from ._conv import register_converters as _register_converters
Using TensorFlow backend.
Traceback (most recent call last):
  File "roundOneSubmit.py", line 23, in <module>
    l.learnThingsCPP(kind=0, file=f, weightFile=wf)
  File "/gpfs/home/m201560/chipboard/learn.py", line 130, in learnThingsCPP
    weights = self.getWeightArray()
  File "/gpfs/home/m201560/chipboard/learn.py", line 199, in getWeightArray
    return self.model.get_weights()[0].tolist()
  File "/gpfs/home/m201560/.local/lib/python3.6/site-packages/keras/engine/network.py", line 492, in get_weights
    return K.batch_get_value(weights)
  File "/gpfs/home/m201560/.local/lib/python3.6/site-packages/keras/backend/tensorflow_backend.py", line 2420, in batch_get_value
    return get_session().run(ops)
  File "/gpfs/home/m201560/.local/lib/python3.6/site-packages/keras/backend/tensorflow_backend.py", line 186, in get_session
    _SESSION = tf.Session(config=config)
  File "/gpfs/pkgs/mhpcc/anaconda3-5.0.1/lib/python3.6/site-packages/tensorflow/python/client/session.py", line 1563, in __init__
    super(Session, self).__init__(target, graph, config=config)
  File "/gpfs/pkgs/mhpcc/anaconda3-5.0.1/lib/python3.6/site-packages/tensorflow/python/client/session.py", line 633, in __init__
    self._session = tf_session.TF_NewSession(self._graph._c_graph, opts)
tensorflow.python.framework.errors_impl.InternalError: Failed to create session.
Traceback (most recent call last):
  File "roundOneSubmit.py", line 23, in <module>
    l.learnThingsCPP(kind=0, file=f, weightFile=wf)
  File "/gpfs/home/m201560/chipboard/learn.py", line 130, in learnThingsCPP
    weights = self.getWeightArray()
  File "/gpfs/home/m201560/chipboard/learn.py", line 199, in getWeightArray
    return self.model.get_weights()[0].tolist()
  File "/gpfs/home/m201560/.local/lib/python3.6/site-packages/keras/engine/network.py", line 492, in get_weights
    return K.batch_get_value(weights)
  File "/gpfs/home/m201560/.local/lib/python3.6/site-packages/keras/backend/tensorflow_backend.py", line 2420, in batch_get_value
    return get_session().run(ops)
  File "/gpfs/home/m201560/.local/lib/python3.6/site-packages/keras/backend/tensorflow_backend.py", line 186, in get_session
    _SESSION = tf.Session(config=config)
  File "/gpfs/pkgs/mhpcc/anaconda3-5.0.1/lib/python3.6/site-packages/tensorflow/python/client/session.py", line 1563, in __init__
    super(Session, self).__init__(target, graph, config=config)
  File "/gpfs/pkgs/mhpcc/anaconda3-5.0.1/lib/python3.6/site-packages/tensorflow/python/client/session.py", line 633, in __init__
    self._session = tf_session.TF_NewSession(self._graph._c_graph, opts)
tensorflow.python.framework.errors_impl.InternalError: Failed to create session.
Traceback (most recent call last):
  File "roundOneSubmit.py", line 23, in <module>
    l.learnThingsCPP(kind=0, file=f, weightFile=wf)
  File "/gpfs/home/m201560/chipboard/learn.py", line 130, in learnThingsCPP
    weights = self.getWeightArray()
  File "/gpfs/home/m201560/chipboard/learn.py", line 199, in getWeightArray
    return self.model.get_weights()[0].tolist()
  File "/gpfs/home/m201560/.local/lib/python3.6/site-packages/keras/engine/network.py", line 492, in get_weights
    return K.batch_get_value(weights)
  File "/gpfs/home/m201560/.local/lib/python3.6/site-packages/keras/backend/tensorflow_backend.py", line 2420, in batch_get_value
    return get_session().run(ops)
  File "/gpfs/home/m201560/.local/lib/python3.6/site-packages/keras/backend/tensorflow_backend.py", line 186, in get_session
    _SESSION = tf.Session(config=config)
  File "/gpfs/pkgs/mhpcc/anaconda3-5.0.1/lib/python3.6/site-packages/tensorflow/python/client/session.py", line 1563, in __init__
    super(Session, self).__init__(target, graph, config=config)
  File "/gpfs/pkgs/mhpcc/anaconda3-5.0.1/lib/python3.6/site-packages/tensorflow/python/client/session.py", line 633, in __init__
    self._session = tf_session.TF_NewSession(self._graph._c_graph, opts)
tensorflow.python.framework.errors_impl.InternalError: Failed to create session.
2019-08-02 10:47:45.784072: E tensorflow/core/common_runtime/direct_session.cc:158] Internal: failed initializing StreamExecutor for CUDA device ordinal 0: Internal: failed call to cuDevicePrimaryCtxRetain: CUDA_ERROR_INVALID_DEVICE
/gpfs/pkgs/mhpcc/anaconda3-5.0.1/lib/python3.6/site-packages/h5py/__init__.py:34: FutureWarning: Conversion of the second argument of issubdtype from `float` to `np.floating` is deprecated. In future, it will be treated as `np.float64 == np.dtype(float).type`.
  from ._conv import register_converters as _register_converters
Using TensorFlow backend.
2019-08-02 10:47:45.785134: E tensorflow/core/common_runtime/direct_session.cc:158] Internal: failed initializing StreamExecutor for CUDA device ordinal 0: Internal: failed call to cuDevicePrimaryCtxRetain: CUDA_ERROR_INVALID_DEVICE
/gpfs/pkgs/mhpcc/anaconda3-5.0.1/lib/python3.6/site-packages/h5py/__init__.py:34: FutureWarning: Conversion of the second argument of issubdtype from `float` to `np.floating` is deprecated. In future, it will be treated as `np.float64 == np.dtype(float).type`.
  from ._conv import register_converters as _register_converters
Using TensorFlow backend.
Traceback (most recent call last):
  File "roundOneSubmit.py", line 23, in <module>
    l.learnThingsCPP(kind=0, file=f, weightFile=wf)
  File "/gpfs/home/m201560/chipboard/learn.py", line 130, in learnThingsCPP
    weights = self.getWeightArray()
  File "/gpfs/home/m201560/chipboard/learn.py", line 199, in getWeightArray
    return self.model.get_weights()[0].tolist()
  File "/gpfs/home/m201560/.local/lib/python3.6/site-packages/keras/engine/network.py", line 492, in get_weights
    return K.batch_get_value(weights)
  File "/gpfs/home/m201560/.local/lib/python3.6/site-packages/keras/backend/tensorflow_backend.py", line 2420, in batch_get_value
    return get_session().run(ops)
  File "/gpfs/home/m201560/.local/lib/python3.6/site-packages/keras/backend/tensorflow_backend.py", line 186, in get_session
    _SESSION = tf.Session(config=config)
  File "/gpfs/pkgs/mhpcc/anaconda3-5.0.1/lib/python3.6/site-packages/tensorflow/python/client/session.py", line 1563, in __init__
    super(Session, self).__init__(target, graph, config=config)
  File "/gpfs/pkgs/mhpcc/anaconda3-5.0.1/lib/python3.6/site-packages/tensorflow/python/client/session.py", line 633, in __init__
    self._session = tf_session.TF_NewSession(self._graph._c_graph, opts)
tensorflow.python.framework.errors_impl.InternalError: Failed to create session.
Traceback (most recent call last):
  File "roundOneSubmit.py", line 23, in <module>
    l.learnThingsCPP(kind=0, file=f, weightFile=wf)
  File "/gpfs/home/m201560/chipboard/learn.py", line 130, in learnThingsCPP
    weights = self.getWeightArray()
  File "/gpfs/home/m201560/chipboard/learn.py", line 199, in getWeightArray
    return self.model.get_weights()[0].tolist()
  File "/gpfs/home/m201560/.local/lib/python3.6/site-packages/keras/engine/network.py", line 492, in get_weights
    return K.batch_get_value(weights)
  File "/gpfs/home/m201560/.local/lib/python3.6/site-packages/keras/backend/tensorflow_backend.py", line 2420, in batch_get_value
    return get_session().run(ops)
  File "/gpfs/home/m201560/.local/lib/python3.6/site-packages/keras/backend/tensorflow_backend.py", line 186, in get_session
    _SESSION = tf.Session(config=config)
  File "/gpfs/pkgs/mhpcc/anaconda3-5.0.1/lib/python3.6/site-packages/tensorflow/python/client/session.py", line 1563, in __init__
    super(Session, self).__init__(target, graph, config=config)
  File "/gpfs/pkgs/mhpcc/anaconda3-5.0.1/lib/python3.6/site-packages/tensorflow/python/client/session.py", line 633, in __init__
    self._session = tf_session.TF_NewSession(self._graph._c_graph, opts)
tensorflow.python.framework.errors_impl.InternalError: Failed to create session.
2019-08-02 10:47:45.816805: E tensorflow/core/common_runtime/direct_session.cc:158] Internal: failed initializing StreamExecutor for CUDA device ordinal 0: Internal: failed call to cuDevicePrimaryCtxRetain: CUDA_ERROR_INVALID_DEVICE
/gpfs/pkgs/mhpcc/anaconda3-5.0.1/lib/python3.6/site-packages/h5py/__init__.py:34: FutureWarning: Conversion of the second argument of issubdtype from `float` to `np.floating` is deprecated. In future, it will be treated as `np.float64 == np.dtype(float).type`.
  from ._conv import register_converters as _register_converters
Using TensorFlow backend.
2019-08-02 10:47:45.820369: E tensorflow/core/common_runtime/direct_session.cc:158] Internal: failed initializing StreamExecutor for CUDA device ordinal 0: Internal: failed call to cuDevicePrimaryCtxRetain: CUDA_ERROR_INVALID_DEVICE
/gpfs/pkgs/mhpcc/anaconda3-5.0.1/lib/python3.6/site-packages/h5py/__init__.py:34: FutureWarning: Conversion of the second argument of issubdtype from `float` to `np.floating` is deprecated. In future, it will be treated as `np.float64 == np.dtype(float).type`.
  from ._conv import register_converters as _register_converters
Using TensorFlow backend.
Traceback (most recent call last):
  File "roundOneSubmit.py", line 23, in <module>
    l.learnThingsCPP(kind=0, file=f, weightFile=wf)
  File "/gpfs/home/m201560/chipboard/learn.py", line 130, in learnThingsCPP
    weights = self.getWeightArray()
  File "/gpfs/home/m201560/chipboard/learn.py", line 199, in getWeightArray
    return self.model.get_weights()[0].tolist()
  File "/gpfs/home/m201560/.local/lib/python3.6/site-packages/keras/engine/network.py", line 492, in get_weights
    return K.batch_get_value(weights)
  File "/gpfs/home/m201560/.local/lib/python3.6/site-packages/keras/backend/tensorflow_backend.py", line 2420, in batch_get_value
    return get_session().run(ops)
  File "/gpfs/home/m201560/.local/lib/python3.6/site-packages/keras/backend/tensorflow_backend.py", line 186, in get_session
    _SESSION = tf.Session(config=config)
  File "/gpfs/pkgs/mhpcc/anaconda3-5.0.1/lib/python3.6/site-packages/tensorflow/python/client/session.py", line 1563, in __init__
    super(Session, self).__init__(target, graph, config=config)
  File "/gpfs/pkgs/mhpcc/anaconda3-5.0.1/lib/python3.6/site-packages/tensorflow/python/client/session.py", line 633, in __init__
    self._session = tf_session.TF_NewSession(self._graph._c_graph, opts)
tensorflow.python.framework.errors_impl.InternalError: Failed to create session.
Traceback (most recent call last):
  File "roundOneSubmit.py", line 23, in <module>
    l.learnThingsCPP(kind=0, file=f, weightFile=wf)
  File "/gpfs/home/m201560/chipboard/learn.py", line 130, in learnThingsCPP
    weights = self.getWeightArray()
  File "/gpfs/home/m201560/chipboard/learn.py", line 199, in getWeightArray
    return self.model.get_weights()[0].tolist()
  File "/gpfs/home/m201560/.local/lib/python3.6/site-packages/keras/engine/network.py", line 492, in get_weights
    return K.batch_get_value(weights)
  File "/gpfs/home/m201560/.local/lib/python3.6/site-packages/keras/backend/tensorflow_backend.py", line 2420, in batch_get_value
    return get_session().run(ops)
  File "/gpfs/home/m201560/.local/lib/python3.6/site-packages/keras/backend/tensorflow_backend.py", line 186, in get_session
    _SESSION = tf.Session(config=config)
  File "/gpfs/pkgs/mhpcc/anaconda3-5.0.1/lib/python3.6/site-packages/tensorflow/python/client/session.py", line 1563, in __init__
    super(Session, self).__init__(target, graph, config=config)
  File "/gpfs/pkgs/mhpcc/anaconda3-5.0.1/lib/python3.6/site-packages/tensorflow/python/client/session.py", line 633, in __init__
    self._session = tf_session.TF_NewSession(self._graph._c_graph, opts)
tensorflow.python.framework.errors_impl.InternalError: Failed to create session.
2019-08-02 10:47:45.843032: E tensorflow/core/common_runtime/direct_session.cc:158] Internal: failed initializing StreamExecutor for CUDA device ordinal 0: Internal: failed call to cuDevicePrimaryCtxRetain: CUDA_ERROR_INVALID_DEVICE
/gpfs/pkgs/mhpcc/anaconda3-5.0.1/lib/python3.6/site-packages/h5py/__init__.py:34: FutureWarning: Conversion of the second argument of issubdtype from `float` to `np.floating` is deprecated. In future, it will be treated as `np.float64 == np.dtype(float).type`.
  from ._conv import register_converters as _register_converters
Using TensorFlow backend.
Traceback (most recent call last):
  File "roundOneSubmit.py", line 23, in <module>
    l.learnThingsCPP(kind=0, file=f, weightFile=wf)
  File "/gpfs/home/m201560/chipboard/learn.py", line 130, in learnThingsCPP
    weights = self.getWeightArray()
  File "/gpfs/home/m201560/chipboard/learn.py", line 199, in getWeightArray
    return self.model.get_weights()[0].tolist()
  File "/gpfs/home/m201560/.local/lib/python3.6/site-packages/keras/engine/network.py", line 492, in get_weights
    return K.batch_get_value(weights)
  File "/gpfs/home/m201560/.local/lib/python3.6/site-packages/keras/backend/tensorflow_backend.py", line 2420, in batch_get_value
    return get_session().run(ops)
  File "/gpfs/home/m201560/.local/lib/python3.6/site-packages/keras/backend/tensorflow_backend.py", line 186, in get_session
    _SESSION = tf.Session(config=config)
  File "/gpfs/pkgs/mhpcc/anaconda3-5.0.1/lib/python3.6/site-packages/tensorflow/python/client/session.py", line 1563, in __init__
    super(Session, self).__init__(target, graph, config=config)
  File "/gpfs/pkgs/mhpcc/anaconda3-5.0.1/lib/python3.6/site-packages/tensorflow/python/client/session.py", line 633, in __init__
    self._session = tf_session.TF_NewSession(self._graph._c_graph, opts)
tensorflow.python.framework.errors_impl.InternalError: Failed to create session.
2019-08-02 10:47:45.976336: I tensorflow/core/common_runtime/gpu/gpu_device.cc:1392] Found device 1 with properties: 
name: Tesla P100-SXM2-16GB major: 6 minor: 0 memoryClockRate(GHz): 1.4805
pciBusID: 0003:01:00.0
totalMemory: 15.90GiB freeMemory: 15.64GiB
2019-08-02 10:47:45.978377: E tensorflow/core/common_runtime/direct_session.cc:158] Internal: failed initializing StreamExecutor for CUDA device ordinal 0: Internal: failed call to cuDevicePrimaryCtxRetain: CUDA_ERROR_INVALID_DEVICE
/gpfs/pkgs/mhpcc/anaconda3-5.0.1/lib/python3.6/site-packages/h5py/__init__.py:34: FutureWarning: Conversion of the second argument of issubdtype from `float` to `np.floating` is deprecated. In future, it will be treated as `np.float64 == np.dtype(float).type`.
  from ._conv import register_converters as _register_converters
Using TensorFlow backend.
Traceback (most recent call last):
  File "roundOneSubmit.py", line 23, in <module>
    l.learnThingsCPP(kind=0, file=f, weightFile=wf)
  File "/gpfs/home/m201560/chipboard/learn.py", line 130, in learnThingsCPP
    weights = self.getWeightArray()
  File "/gpfs/home/m201560/chipboard/learn.py", line 199, in getWeightArray
    return self.model.get_weights()[0].tolist()
  File "/gpfs/home/m201560/.local/lib/python3.6/site-packages/keras/engine/network.py", line 492, in get_weights
    return K.batch_get_value(weights)
  File "/gpfs/home/m201560/.local/lib/python3.6/site-packages/keras/backend/tensorflow_backend.py", line 2420, in batch_get_value
    return get_session().run(ops)
  File "/gpfs/home/m201560/.local/lib/python3.6/site-packages/keras/backend/tensorflow_backend.py", line 186, in get_session
    _SESSION = tf.Session(config=config)
  File "/gpfs/pkgs/mhpcc/anaconda3-5.0.1/lib/python3.6/site-packages/tensorflow/python/client/session.py", line 1563, in __init__
    super(Session, self).__init__(target, graph, config=config)
  File "/gpfs/pkgs/mhpcc/anaconda3-5.0.1/lib/python3.6/site-packages/tensorflow/python/client/session.py", line 633, in __init__
    self._session = tf_session.TF_NewSession(self._graph._c_graph, opts)
tensorflow.python.framework.errors_impl.InternalError: Failed to create session.
2019-08-02 10:47:46.029414: E tensorflow/core/common_runtime/direct_session.cc:158] Internal: failed initializing StreamExecutor for CUDA device ordinal 0: Internal: failed call to cuDevicePrimaryCtxRetain: CUDA_ERROR_INVALID_DEVICE
/gpfs/pkgs/mhpcc/anaconda3-5.0.1/lib/python3.6/site-packages/h5py/__init__.py:34: FutureWarning: Conversion of the second argument of issubdtype from `float` to `np.floating` is deprecated. In future, it will be treated as `np.float64 == np.dtype(float).type`.
  from ._conv import register_converters as _register_converters
Using TensorFlow backend.
Traceback (most recent call last):
  File "roundOneSubmit.py", line 23, in <module>
    l.learnThingsCPP(kind=0, file=f, weightFile=wf)
  File "/gpfs/home/m201560/chipboard/learn.py", line 130, in learnThingsCPP
    weights = self.getWeightArray()
  File "/gpfs/home/m201560/chipboard/learn.py", line 199, in getWeightArray
    return self.model.get_weights()[0].tolist()
  File "/gpfs/home/m201560/.local/lib/python3.6/site-packages/keras/engine/network.py", line 492, in get_weights
    return K.batch_get_value(weights)
  File "/gpfs/home/m201560/.local/lib/python3.6/site-packages/keras/backend/tensorflow_backend.py", line 2420, in batch_get_value
    return get_session().run(ops)
  File "/gpfs/home/m201560/.local/lib/python3.6/site-packages/keras/backend/tensorflow_backend.py", line 186, in get_session
    _SESSION = tf.Session(config=config)
  File "/gpfs/pkgs/mhpcc/anaconda3-5.0.1/lib/python3.6/site-packages/tensorflow/python/client/session.py", line 1563, in __init__
    super(Session, self).__init__(target, graph, config=config)
  File "/gpfs/pkgs/mhpcc/anaconda3-5.0.1/lib/python3.6/site-packages/tensorflow/python/client/session.py", line 633, in __init__
    self._session = tf_session.TF_NewSession(self._graph._c_graph, opts)
tensorflow.python.framework.errors_impl.InternalError: Failed to create session.
2019-08-02 10:47:46.058510: E tensorflow/core/common_runtime/direct_session.cc:158] Internal: failed initializing StreamExecutor for CUDA device ordinal 0: Internal: failed call to cuDevicePrimaryCtxRetain: CUDA_ERROR_INVALID_DEVICE
/gpfs/pkgs/mhpcc/anaconda3-5.0.1/lib/python3.6/site-packages/h5py/__init__.py:34: FutureWarning: Conversion of the second argument of issubdtype from `float` to `np.floating` is deprecated. In future, it will be treated as `np.float64 == np.dtype(float).type`.
  from ._conv import register_converters as _register_converters
Using TensorFlow backend.
Traceback (most recent call last):
  File "roundOneSubmit.py", line 23, in <module>
    l.learnThingsCPP(kind=0, file=f, weightFile=wf)
  File "/gpfs/home/m201560/chipboard/learn.py", line 130, in learnThingsCPP
    weights = self.getWeightArray()
  File "/gpfs/home/m201560/chipboard/learn.py", line 199, in getWeightArray
    return self.model.get_weights()[0].tolist()
  File "/gpfs/home/m201560/.local/lib/python3.6/site-packages/keras/engine/network.py", line 492, in get_weights
    return K.batch_get_value(weights)
  File "/gpfs/home/m201560/.local/lib/python3.6/site-packages/keras/backend/tensorflow_backend.py", line 2420, in batch_get_value
    return get_session().run(ops)
  File "/gpfs/home/m201560/.local/lib/python3.6/site-packages/keras/backend/tensorflow_backend.py", line 186, in get_session
    _SESSION = tf.Session(config=config)
  File "/gpfs/pkgs/mhpcc/anaconda3-5.0.1/lib/python3.6/site-packages/tensorflow/python/client/session.py", line 1563, in __init__
    super(Session, self).__init__(target, graph, config=config)
  File "/gpfs/pkgs/mhpcc/anaconda3-5.0.1/lib/python3.6/site-packages/tensorflow/python/client/session.py", line 633, in __init__
    self._session = tf_session.TF_NewSession(self._graph._c_graph, opts)
tensorflow.python.framework.errors_impl.InternalError: Failed to create session.
2019-08-02 10:47:46.162443: E tensorflow/core/common_runtime/direct_session.cc:158] Internal: failed initializing StreamExecutor for CUDA device ordinal 0: Internal: failed call to cuDevicePrimaryCtxRetain: CUDA_ERROR_INVALID_DEVICE
/gpfs/pkgs/mhpcc/anaconda3-5.0.1/lib/python3.6/site-packages/h5py/__init__.py:34: FutureWarning: Conversion of the second argument of issubdtype from `float` to `np.floating` is deprecated. In future, it will be treated as `np.float64 == np.dtype(float).type`.
  from ._conv import register_converters as _register_converters
Using TensorFlow backend.
Traceback (most recent call last):
  File "roundOneSubmit.py", line 23, in <module>
    l.learnThingsCPP(kind=0, file=f, weightFile=wf)
  File "/gpfs/home/m201560/chipboard/learn.py", line 130, in learnThingsCPP
    weights = self.getWeightArray()
  File "/gpfs/home/m201560/chipboard/learn.py", line 199, in getWeightArray
    return self.model.get_weights()[0].tolist()
  File "/gpfs/home/m201560/.local/lib/python3.6/site-packages/keras/engine/network.py", line 492, in get_weights
    return K.batch_get_value(weights)
  File "/gpfs/home/m201560/.local/lib/python3.6/site-packages/keras/backend/tensorflow_backend.py", line 2420, in batch_get_value
    return get_session().run(ops)
  File "/gpfs/home/m201560/.local/lib/python3.6/site-packages/keras/backend/tensorflow_backend.py", line 186, in get_session
    _SESSION = tf.Session(config=config)
  File "/gpfs/pkgs/mhpcc/anaconda3-5.0.1/lib/python3.6/site-packages/tensorflow/python/client/session.py", line 1563, in __init__
    super(Session, self).__init__(target, graph, config=config)
  File "/gpfs/pkgs/mhpcc/anaconda3-5.0.1/lib/python3.6/site-packages/tensorflow/python/client/session.py", line 633, in __init__
    self._session = tf_session.TF_NewSession(self._graph._c_graph, opts)
tensorflow.python.framework.errors_impl.InternalError: Failed to create session.
2019-08-02 10:47:46.245396: E tensorflow/core/common_runtime/direct_session.cc:158] Internal: failed initializing StreamExecutor for CUDA device ordinal 0: Internal: failed call to cuDevicePrimaryCtxRetain: CUDA_ERROR_INVALID_DEVICE
/gpfs/pkgs/mhpcc/anaconda3-5.0.1/lib/python3.6/site-packages/h5py/__init__.py:34: FutureWarning: Conversion of the second argument of issubdtype from `float` to `np.floating` is deprecated. In future, it will be treated as `np.float64 == np.dtype(float).type`.
  from ._conv import register_converters as _register_converters
Using TensorFlow backend.
Traceback (most recent call last):
  File "roundOneSubmit.py", line 23, in <module>
    l.learnThingsCPP(kind=0, file=f, weightFile=wf)
  File "/gpfs/home/m201560/chipboard/learn.py", line 130, in learnThingsCPP
    weights = self.getWeightArray()
  File "/gpfs/home/m201560/chipboard/learn.py", line 199, in getWeightArray
    return self.model.get_weights()[0].tolist()
  File "/gpfs/home/m201560/.local/lib/python3.6/site-packages/keras/engine/network.py", line 492, in get_weights
    return K.batch_get_value(weights)
  File "/gpfs/home/m201560/.local/lib/python3.6/site-packages/keras/backend/tensorflow_backend.py", line 2420, in batch_get_value
    return get_session().run(ops)
  File "/gpfs/home/m201560/.local/lib/python3.6/site-packages/keras/backend/tensorflow_backend.py", line 186, in get_session
    _SESSION = tf.Session(config=config)
  File "/gpfs/pkgs/mhpcc/anaconda3-5.0.1/lib/python3.6/site-packages/tensorflow/python/client/session.py", line 1563, in __init__
    super(Session, self).__init__(target, graph, config=config)
  File "/gpfs/pkgs/mhpcc/anaconda3-5.0.1/lib/python3.6/site-packages/tensorflow/python/client/session.py", line 633, in __init__
    self._session = tf_session.TF_NewSession(self._graph._c_graph, opts)
tensorflow.python.framework.errors_impl.InternalError: Failed to create session.
2019-08-02 10:47:46.260253: E tensorflow/core/common_runtime/direct_session.cc:158] Internal: failed initializing StreamExecutor for CUDA device ordinal 0: Internal: failed call to cuDevicePrimaryCtxRetain: CUDA_ERROR_INVALID_DEVICE
/gpfs/pkgs/mhpcc/anaconda3-5.0.1/lib/python3.6/site-packages/h5py/__init__.py:34: FutureWarning: Conversion of the second argument of issubdtype from `float` to `np.floating` is deprecated. In future, it will be treated as `np.float64 == np.dtype(float).type`.
  from ._conv import register_converters as _register_converters
Using TensorFlow backend.
Traceback (most recent call last):
  File "roundOneSubmit.py", line 23, in <module>
    l.learnThingsCPP(kind=0, file=f, weightFile=wf)
  File "/gpfs/home/m201560/chipboard/learn.py", line 130, in learnThingsCPP
    weights = self.getWeightArray()
  File "/gpfs/home/m201560/chipboard/learn.py", line 199, in getWeightArray
    return self.model.get_weights()[0].tolist()
  File "/gpfs/home/m201560/.local/lib/python3.6/site-packages/keras/engine/network.py", line 492, in get_weights
    return K.batch_get_value(weights)
  File "/gpfs/home/m201560/.local/lib/python3.6/site-packages/keras/backend/tensorflow_backend.py", line 2420, in batch_get_value
    return get_session().run(ops)
  File "/gpfs/home/m201560/.local/lib/python3.6/site-packages/keras/backend/tensorflow_backend.py", line 186, in get_session
    _SESSION = tf.Session(config=config)
  File "/gpfs/pkgs/mhpcc/anaconda3-5.0.1/lib/python3.6/site-packages/tensorflow/python/client/session.py", line 1563, in __init__
    super(Session, self).__init__(target, graph, config=config)
  File "/gpfs/pkgs/mhpcc/anaconda3-5.0.1/lib/python3.6/site-packages/tensorflow/python/client/session.py", line 633, in __init__
    self._session = tf_session.TF_NewSession(self._graph._c_graph, opts)
tensorflow.python.framework.errors_impl.InternalError: Failed to create session.
2019-08-02 10:47:46.301103: E tensorflow/core/common_runtime/direct_session.cc:158] Internal: failed initializing StreamExecutor for CUDA device ordinal 0: Internal: failed call to cuDevicePrimaryCtxRetain: CUDA_ERROR_INVALID_DEVICE
/gpfs/pkgs/mhpcc/anaconda3-5.0.1/lib/python3.6/site-packages/h5py/__init__.py:34: FutureWarning: Conversion of the second argument of issubdtype from `float` to `np.floating` is deprecated. In future, it will be treated as `np.float64 == np.dtype(float).type`.
  from ._conv import register_converters as _register_converters
Using TensorFlow backend.
2019-08-02 10:47:46.304078: E tensorflow/core/common_runtime/direct_session.cc:158] Internal: failed initializing StreamExecutor for CUDA device ordinal 0: Internal: failed call to cuDevicePrimaryCtxRetain: CUDA_ERROR_INVALID_DEVICE
/gpfs/pkgs/mhpcc/anaconda3-5.0.1/lib/python3.6/site-packages/h5py/__init__.py:34: FutureWarning: Conversion of the second argument of issubdtype from `float` to `np.floating` is deprecated. In future, it will be treated as `np.float64 == np.dtype(float).type`.
  from ._conv import register_converters as _register_converters
Using TensorFlow backend.
Traceback (most recent call last):
  File "roundOneSubmit.py", line 23, in <module>
    l.learnThingsCPP(kind=0, file=f, weightFile=wf)
  File "/gpfs/home/m201560/chipboard/learn.py", line 130, in learnThingsCPP
    weights = self.getWeightArray()
  File "/gpfs/home/m201560/chipboard/learn.py", line 199, in getWeightArray
    return self.model.get_weights()[0].tolist()
  File "/gpfs/home/m201560/.local/lib/python3.6/site-packages/keras/engine/network.py", line 492, in get_weights
    return K.batch_get_value(weights)
  File "/gpfs/home/m201560/.local/lib/python3.6/site-packages/keras/backend/tensorflow_backend.py", line 2420, in batch_get_value
    return get_session().run(ops)
  File "/gpfs/home/m201560/.local/lib/python3.6/site-packages/keras/backend/tensorflow_backend.py", line 186, in get_session
    _SESSION = tf.Session(config=config)
  File "/gpfs/pkgs/mhpcc/anaconda3-5.0.1/lib/python3.6/site-packages/tensorflow/python/client/session.py", line 1563, in __init__
    super(Session, self).__init__(target, graph, config=config)
  File "/gpfs/pkgs/mhpcc/anaconda3-5.0.1/lib/python3.6/site-packages/tensorflow/python/client/session.py", line 633, in __init__
    self._session = tf_session.TF_NewSession(self._graph._c_graph, opts)
tensorflow.python.framework.errors_impl.InternalError: Failed to create session.
Traceback (most recent call last):
  File "roundOneSubmit.py", line 23, in <module>
    l.learnThingsCPP(kind=0, file=f, weightFile=wf)
  File "/gpfs/home/m201560/chipboard/learn.py", line 130, in learnThingsCPP
    weights = self.getWeightArray()
  File "/gpfs/home/m201560/chipboard/learn.py", line 199, in getWeightArray
    return self.model.get_weights()[0].tolist()
  File "/gpfs/home/m201560/.local/lib/python3.6/site-packages/keras/engine/network.py", line 492, in get_weights
    return K.batch_get_value(weights)
  File "/gpfs/home/m201560/.local/lib/python3.6/site-packages/keras/backend/tensorflow_backend.py", line 2420, in batch_get_value
    return get_session().run(ops)
  File "/gpfs/home/m201560/.local/lib/python3.6/site-packages/keras/backend/tensorflow_backend.py", line 186, in get_session
    _SESSION = tf.Session(config=config)
  File "/gpfs/pkgs/mhpcc/anaconda3-5.0.1/lib/python3.6/site-packages/tensorflow/python/client/session.py", line 1563, in __init__
    super(Session, self).__init__(target, graph, config=config)
  File "/gpfs/pkgs/mhpcc/anaconda3-5.0.1/lib/python3.6/site-packages/tensorflow/python/client/session.py", line 633, in __init__
    self._session = tf_session.TF_NewSession(self._graph._c_graph, opts)
tensorflow.python.framework.errors_impl.InternalError: Failed to create session.
2019-08-02 10:47:46.398182: E tensorflow/core/common_runtime/direct_session.cc:158] Internal: failed initializing StreamExecutor for CUDA device ordinal 0: Internal: failed call to cuDevicePrimaryCtxRetain: CUDA_ERROR_INVALID_DEVICE
/gpfs/pkgs/mhpcc/anaconda3-5.0.1/lib/python3.6/site-packages/h5py/__init__.py:34: FutureWarning: Conversion of the second argument of issubdtype from `float` to `np.floating` is deprecated. In future, it will be treated as `np.float64 == np.dtype(float).type`.
  from ._conv import register_converters as _register_converters
Using TensorFlow backend.
Traceback (most recent call last):
  File "roundOneSubmit.py", line 23, in <module>
    l.learnThingsCPP(kind=0, file=f, weightFile=wf)
  File "/gpfs/home/m201560/chipboard/learn.py", line 130, in learnThingsCPP
    weights = self.getWeightArray()
  File "/gpfs/home/m201560/chipboard/learn.py", line 199, in getWeightArray
    return self.model.get_weights()[0].tolist()
  File "/gpfs/home/m201560/.local/lib/python3.6/site-packages/keras/engine/network.py", line 492, in get_weights
    return K.batch_get_value(weights)
  File "/gpfs/home/m201560/.local/lib/python3.6/site-packages/keras/backend/tensorflow_backend.py", line 2420, in batch_get_value
    return get_session().run(ops)
  File "/gpfs/home/m201560/.local/lib/python3.6/site-packages/keras/backend/tensorflow_backend.py", line 186, in get_session
    _SESSION = tf.Session(config=config)
  File "/gpfs/pkgs/mhpcc/anaconda3-5.0.1/lib/python3.6/site-packages/tensorflow/python/client/session.py", line 1563, in __init__
    super(Session, self).__init__(target, graph, config=config)
  File "/gpfs/pkgs/mhpcc/anaconda3-5.0.1/lib/python3.6/site-packages/tensorflow/python/client/session.py", line 633, in __init__
    self._session = tf_session.TF_NewSession(self._graph._c_graph, opts)
tensorflow.python.framework.errors_impl.InternalError: Failed to create session.
2019-08-02 10:47:46.409597: E tensorflow/core/common_runtime/direct_session.cc:158] Internal: failed initializing StreamExecutor for CUDA device ordinal 0: Internal: failed call to cuDevicePrimaryCtxRetain: CUDA_ERROR_INVALID_DEVICE
/gpfs/pkgs/mhpcc/anaconda3-5.0.1/lib/python3.6/site-packages/h5py/__init__.py:34: FutureWarning: Conversion of the second argument of issubdtype from `float` to `np.floating` is deprecated. In future, it will be treated as `np.float64 == np.dtype(float).type`.
  from ._conv import register_converters as _register_converters
Using TensorFlow backend.
Traceback (most recent call last):
  File "roundOneSubmit.py", line 23, in <module>
    l.learnThingsCPP(kind=0, file=f, weightFile=wf)
  File "/gpfs/home/m201560/chipboard/learn.py", line 130, in learnThingsCPP
    weights = self.getWeightArray()
  File "/gpfs/home/m201560/chipboard/learn.py", line 199, in getWeightArray
    return self.model.get_weights()[0].tolist()
  File "/gpfs/home/m201560/.local/lib/python3.6/site-packages/keras/engine/network.py", line 492, in get_weights
    return K.batch_get_value(weights)
  File "/gpfs/home/m201560/.local/lib/python3.6/site-packages/keras/backend/tensorflow_backend.py", line 2420, in batch_get_value
    return get_session().run(ops)
  File "/gpfs/home/m201560/.local/lib/python3.6/site-packages/keras/backend/tensorflow_backend.py", line 186, in get_session
    _SESSION = tf.Session(config=config)
  File "/gpfs/pkgs/mhpcc/anaconda3-5.0.1/lib/python3.6/site-packages/tensorflow/python/client/session.py", line 1563, in __init__
    super(Session, self).__init__(target, graph, config=config)
  File "/gpfs/pkgs/mhpcc/anaconda3-5.0.1/lib/python3.6/site-packages/tensorflow/python/client/session.py", line 633, in __init__
    self._session = tf_session.TF_NewSession(self._graph._c_graph, opts)
tensorflow.python.framework.errors_impl.InternalError: Failed to create session.
2019-08-02 10:47:46.443315: E tensorflow/core/common_runtime/direct_session.cc:158] Internal: failed initializing StreamExecutor for CUDA device ordinal 0: Internal: failed call to cuDevicePrimaryCtxRetain: CUDA_ERROR_INVALID_DEVICE
/gpfs/pkgs/mhpcc/anaconda3-5.0.1/lib/python3.6/site-packages/h5py/__init__.py:34: FutureWarning: Conversion of the second argument of issubdtype from `float` to `np.floating` is deprecated. In future, it will be treated as `np.float64 == np.dtype(float).type`.
  from ._conv import register_converters as _register_converters
Using TensorFlow backend.
Traceback (most recent call last):
  File "roundOneSubmit.py", line 23, in <module>
    l.learnThingsCPP(kind=0, file=f, weightFile=wf)
  File "/gpfs/home/m201560/chipboard/learn.py", line 130, in learnThingsCPP
    weights = self.getWeightArray()
  File "/gpfs/home/m201560/chipboard/learn.py", line 199, in getWeightArray
    return self.model.get_weights()[0].tolist()
  File "/gpfs/home/m201560/.local/lib/python3.6/site-packages/keras/engine/network.py", line 492, in get_weights
    return K.batch_get_value(weights)
  File "/gpfs/home/m201560/.local/lib/python3.6/site-packages/keras/backend/tensorflow_backend.py", line 2420, in batch_get_value
    return get_session().run(ops)
  File "/gpfs/home/m201560/.local/lib/python3.6/site-packages/keras/backend/tensorflow_backend.py", line 186, in get_session
    _SESSION = tf.Session(config=config)
  File "/gpfs/pkgs/mhpcc/anaconda3-5.0.1/lib/python3.6/site-packages/tensorflow/python/client/session.py", line 1563, in __init__
    super(Session, self).__init__(target, graph, config=config)
  File "/gpfs/pkgs/mhpcc/anaconda3-5.0.1/lib/python3.6/site-packages/tensorflow/python/client/session.py", line 633, in __init__
    self._session = tf_session.TF_NewSession(self._graph._c_graph, opts)
tensorflow.python.framework.errors_impl.InternalError: Failed to create session.
2019-08-02 10:47:46.555926: E tensorflow/core/common_runtime/direct_session.cc:158] Internal: failed initializing StreamExecutor for CUDA device ordinal 0: Internal: failed call to cuDevicePrimaryCtxRetain: CUDA_ERROR_INVALID_DEVICE
/gpfs/pkgs/mhpcc/anaconda3-5.0.1/lib/python3.6/site-packages/h5py/__init__.py:34: FutureWarning: Conversion of the second argument of issubdtype from `float` to `np.floating` is deprecated. In future, it will be treated as `np.float64 == np.dtype(float).type`.
  from ._conv import register_converters as _register_converters
Using TensorFlow backend.
Traceback (most recent call last):
  File "roundOneSubmit.py", line 23, in <module>
    l.learnThingsCPP(kind=0, file=f, weightFile=wf)
  File "/gpfs/home/m201560/chipboard/learn.py", line 130, in learnThingsCPP
    weights = self.getWeightArray()
  File "/gpfs/home/m201560/chipboard/learn.py", line 199, in getWeightArray
    return self.model.get_weights()[0].tolist()
  File "/gpfs/home/m201560/.local/lib/python3.6/site-packages/keras/engine/network.py", line 492, in get_weights
    return K.batch_get_value(weights)
  File "/gpfs/home/m201560/.local/lib/python3.6/site-packages/keras/backend/tensorflow_backend.py", line 2420, in batch_get_value
    return get_session().run(ops)
  File "/gpfs/home/m201560/.local/lib/python3.6/site-packages/keras/backend/tensorflow_backend.py", line 186, in get_session
    _SESSION = tf.Session(config=config)
  File "/gpfs/pkgs/mhpcc/anaconda3-5.0.1/lib/python3.6/site-packages/tensorflow/python/client/session.py", line 1563, in __init__
    super(Session, self).__init__(target, graph, config=config)
  File "/gpfs/pkgs/mhpcc/anaconda3-5.0.1/lib/python3.6/site-packages/tensorflow/python/client/session.py", line 633, in __init__
    self._session = tf_session.TF_NewSession(self._graph._c_graph, opts)
tensorflow.python.framework.errors_impl.InternalError: Failed to create session.
2019-08-02 10:47:46.580208: E tensorflow/core/common_runtime/direct_session.cc:158] Internal: failed initializing StreamExecutor for CUDA device ordinal 0: Internal: failed call to cuDevicePrimaryCtxRetain: CUDA_ERROR_INVALID_DEVICE
2019-08-02 10:47:46.580316: E tensorflow/core/common_runtime/direct_session.cc:158] Internal: failed initializing StreamExecutor for CUDA device ordinal 0: Internal: failed call to cuDevicePrimaryCtxRetain: CUDA_ERROR_INVALID_DEVICE
/gpfs/pkgs/mhpcc/anaconda3-5.0.1/lib/python3.6/site-packages/h5py/__init__.py:34: FutureWarning: Conversion of the second argument of issubdtype from `float` to `np.floating` is deprecated. In future, it will be treated as `np.float64 == np.dtype(float).type`.
  from ._conv import register_converters as _register_converters
Using TensorFlow backend.
/gpfs/pkgs/mhpcc/anaconda3-5.0.1/lib/python3.6/site-packages/h5py/__init__.py:34: FutureWarning: Conversion of the second argument of issubdtype from `float` to `np.floating` is deprecated. In future, it will be treated as `np.float64 == np.dtype(float).type`.
  from ._conv import register_converters as _register_converters
Using TensorFlow backend.
Traceback (most recent call last):
  File "roundOneSubmit.py", line 23, in <module>
    l.learnThingsCPP(kind=0, file=f, weightFile=wf)
  File "/gpfs/home/m201560/chipboard/learn.py", line 130, in learnThingsCPP
    weights = self.getWeightArray()
  File "/gpfs/home/m201560/chipboard/learn.py", line 199, in getWeightArray
    return self.model.get_weights()[0].tolist()
  File "/gpfs/home/m201560/.local/lib/python3.6/site-packages/keras/engine/network.py", line 492, in get_weights
    return K.batch_get_value(weights)
  File "/gpfs/home/m201560/.local/lib/python3.6/site-packages/keras/backend/tensorflow_backend.py", line 2420, in batch_get_value
    return get_session().run(ops)
  File "/gpfs/home/m201560/.local/lib/python3.6/site-packages/keras/backend/tensorflow_backend.py", line 186, in get_session
    _SESSION = tf.Session(config=config)
  File "/gpfs/pkgs/mhpcc/anaconda3-5.0.1/lib/python3.6/site-packages/tensorflow/python/client/session.py", line 1563, in __init__
    super(Session, self).__init__(target, graph, config=config)
  File "/gpfs/pkgs/mhpcc/anaconda3-5.0.1/lib/python3.6/site-packages/tensorflow/python/client/session.py", line 633, in __init__
    self._session = tf_session.TF_NewSession(self._graph._c_graph, opts)
tensorflow.python.framework.errors_impl.InternalError: Failed to create session.
Traceback (most recent call last):
  File "roundOneSubmit.py", line 23, in <module>
    l.learnThingsCPP(kind=0, file=f, weightFile=wf)
  File "/gpfs/home/m201560/chipboard/learn.py", line 130, in learnThingsCPP
    weights = self.getWeightArray()
  File "/gpfs/home/m201560/chipboard/learn.py", line 199, in getWeightArray
    return self.model.get_weights()[0].tolist()
  File "/gpfs/home/m201560/.local/lib/python3.6/site-packages/keras/engine/network.py", line 492, in get_weights
    return K.batch_get_value(weights)
  File "/gpfs/home/m201560/.local/lib/python3.6/site-packages/keras/backend/tensorflow_backend.py", line 2420, in batch_get_value
    return get_session().run(ops)
  File "/gpfs/home/m201560/.local/lib/python3.6/site-packages/keras/backend/tensorflow_backend.py", line 186, in get_session
    _SESSION = tf.Session(config=config)
  File "/gpfs/pkgs/mhpcc/anaconda3-5.0.1/lib/python3.6/site-packages/tensorflow/python/client/session.py", line 1563, in __init__
    super(Session, self).__init__(target, graph, config=config)
  File "/gpfs/pkgs/mhpcc/anaconda3-5.0.1/lib/python3.6/site-packages/tensorflow/python/client/session.py", line 633, in __init__
    self._session = tf_session.TF_NewSession(self._graph._c_graph, opts)
tensorflow.python.framework.errors_impl.InternalError: Failed to create session.
2019-08-02 10:47:46.665101: E tensorflow/core/common_runtime/direct_session.cc:158] Internal: failed initializing StreamExecutor for CUDA device ordinal 0: Internal: failed call to cuDevicePrimaryCtxRetain: CUDA_ERROR_INVALID_DEVICE
/gpfs/pkgs/mhpcc/anaconda3-5.0.1/lib/python3.6/site-packages/h5py/__init__.py:34: FutureWarning: Conversion of the second argument of issubdtype from `float` to `np.floating` is deprecated. In future, it will be treated as `np.float64 == np.dtype(float).type`.
  from ._conv import register_converters as _register_converters
Using TensorFlow backend.
Traceback (most recent call last):
  File "roundOneSubmit.py", line 23, in <module>
    l.learnThingsCPP(kind=0, file=f, weightFile=wf)
  File "/gpfs/home/m201560/chipboard/learn.py", line 130, in learnThingsCPP
    weights = self.getWeightArray()
  File "/gpfs/home/m201560/chipboard/learn.py", line 199, in getWeightArray
    return self.model.get_weights()[0].tolist()
  File "/gpfs/home/m201560/.local/lib/python3.6/site-packages/keras/engine/network.py", line 492, in get_weights
    return K.batch_get_value(weights)
  File "/gpfs/home/m201560/.local/lib/python3.6/site-packages/keras/backend/tensorflow_backend.py", line 2420, in batch_get_value
    return get_session().run(ops)
  File "/gpfs/home/m201560/.local/lib/python3.6/site-packages/keras/backend/tensorflow_backend.py", line 186, in get_session
    _SESSION = tf.Session(config=config)
  File "/gpfs/pkgs/mhpcc/anaconda3-5.0.1/lib/python3.6/site-packages/tensorflow/python/client/session.py", line 1563, in __init__
    super(Session, self).__init__(target, graph, config=config)
  File "/gpfs/pkgs/mhpcc/anaconda3-5.0.1/lib/python3.6/site-packages/tensorflow/python/client/session.py", line 633, in __init__
    self._session = tf_session.TF_NewSession(self._graph._c_graph, opts)
tensorflow.python.framework.errors_impl.InternalError: Failed to create session.
2019-08-02 10:47:46.709692: E tensorflow/core/common_runtime/direct_session.cc:158] Internal: failed initializing StreamExecutor for CUDA device ordinal 0: Internal: failed call to cuDevicePrimaryCtxRetain: CUDA_ERROR_INVALID_DEVICE
/gpfs/pkgs/mhpcc/anaconda3-5.0.1/lib/python3.6/site-packages/h5py/__init__.py:34: FutureWarning: Conversion of the second argument of issubdtype from `float` to `np.floating` is deprecated. In future, it will be treated as `np.float64 == np.dtype(float).type`.
  from ._conv import register_converters as _register_converters
Using TensorFlow backend.
Traceback (most recent call last):
  File "roundOneSubmit.py", line 23, in <module>
    l.learnThingsCPP(kind=0, file=f, weightFile=wf)
  File "/gpfs/home/m201560/chipboard/learn.py", line 130, in learnThingsCPP
    weights = self.getWeightArray()
  File "/gpfs/home/m201560/chipboard/learn.py", line 199, in getWeightArray
    return self.model.get_weights()[0].tolist()
  File "/gpfs/home/m201560/.local/lib/python3.6/site-packages/keras/engine/network.py", line 492, in get_weights
    return K.batch_get_value(weights)
  File "/gpfs/home/m201560/.local/lib/python3.6/site-packages/keras/backend/tensorflow_backend.py", line 2420, in batch_get_value
    return get_session().run(ops)
  File "/gpfs/home/m201560/.local/lib/python3.6/site-packages/keras/backend/tensorflow_backend.py", line 186, in get_session
    _SESSION = tf.Session(config=config)
  File "/gpfs/pkgs/mhpcc/anaconda3-5.0.1/lib/python3.6/site-packages/tensorflow/python/client/session.py", line 1563, in __init__
    super(Session, self).__init__(target, graph, config=config)
  File "/gpfs/pkgs/mhpcc/anaconda3-5.0.1/lib/python3.6/site-packages/tensorflow/python/client/session.py", line 633, in __init__
    self._session = tf_session.TF_NewSession(self._graph._c_graph, opts)
tensorflow.python.framework.errors_impl.InternalError: Failed to create session.
2019-08-02 10:47:46.790540: E tensorflow/core/common_runtime/direct_session.cc:158] Internal: failed initializing StreamExecutor for CUDA device ordinal 0: Internal: failed call to cuDevicePrimaryCtxRetain: CUDA_ERROR_INVALID_DEVICE
/gpfs/pkgs/mhpcc/anaconda3-5.0.1/lib/python3.6/site-packages/h5py/__init__.py:34: FutureWarning: Conversion of the second argument of issubdtype from `float` to `np.floating` is deprecated. In future, it will be treated as `np.float64 == np.dtype(float).type`.
  from ._conv import register_converters as _register_converters
Using TensorFlow backend.
2019-08-02 10:47:46.798803: E tensorflow/core/common_runtime/direct_session.cc:158] Internal: failed initializing StreamExecutor for CUDA device ordinal 0: Internal: failed call to cuDevicePrimaryCtxRetain: CUDA_ERROR_INVALID_DEVICE
/gpfs/pkgs/mhpcc/anaconda3-5.0.1/lib/python3.6/site-packages/h5py/__init__.py:34: FutureWarning: Conversion of the second argument of issubdtype from `float` to `np.floating` is deprecated. In future, it will be treated as `np.float64 == np.dtype(float).type`.
  from ._conv import register_converters as _register_converters
Using TensorFlow backend.
Traceback (most recent call last):
  File "roundOneSubmit.py", line 23, in <module>
    l.learnThingsCPP(kind=0, file=f, weightFile=wf)
  File "/gpfs/home/m201560/chipboard/learn.py", line 130, in learnThingsCPP
    weights = self.getWeightArray()
  File "/gpfs/home/m201560/chipboard/learn.py", line 199, in getWeightArray
    return self.model.get_weights()[0].tolist()
  File "/gpfs/home/m201560/.local/lib/python3.6/site-packages/keras/engine/network.py", line 492, in get_weights
    return K.batch_get_value(weights)
  File "/gpfs/home/m201560/.local/lib/python3.6/site-packages/keras/backend/tensorflow_backend.py", line 2420, in batch_get_value
    return get_session().run(ops)
  File "/gpfs/home/m201560/.local/lib/python3.6/site-packages/keras/backend/tensorflow_backend.py", line 186, in get_session
    _SESSION = tf.Session(config=config)
  File "/gpfs/pkgs/mhpcc/anaconda3-5.0.1/lib/python3.6/site-packages/tensorflow/python/client/session.py", line 1563, in __init__
    super(Session, self).__init__(target, graph, config=config)
  File "/gpfs/pkgs/mhpcc/anaconda3-5.0.1/lib/python3.6/site-packages/tensorflow/python/client/session.py", line 633, in __init__
    self._session = tf_session.TF_NewSession(self._graph._c_graph, opts)
tensorflow.python.framework.errors_impl.InternalError: Failed to create session.
Traceback (most recent call last):
  File "roundOneSubmit.py", line 23, in <module>
    l.learnThingsCPP(kind=0, file=f, weightFile=wf)
  File "/gpfs/home/m201560/chipboard/learn.py", line 130, in learnThingsCPP
    weights = self.getWeightArray()
  File "/gpfs/home/m201560/chipboard/learn.py", line 199, in getWeightArray
    return self.model.get_weights()[0].tolist()
  File "/gpfs/home/m201560/.local/lib/python3.6/site-packages/keras/engine/network.py", line 492, in get_weights
    return K.batch_get_value(weights)
  File "/gpfs/home/m201560/.local/lib/python3.6/site-packages/keras/backend/tensorflow_backend.py", line 2420, in batch_get_value
    return get_session().run(ops)
  File "/gpfs/home/m201560/.local/lib/python3.6/site-packages/keras/backend/tensorflow_backend.py", line 186, in get_session
    _SESSION = tf.Session(config=config)
  File "/gpfs/pkgs/mhpcc/anaconda3-5.0.1/lib/python3.6/site-packages/tensorflow/python/client/session.py", line 1563, in __init__
    super(Session, self).__init__(target, graph, config=config)
  File "/gpfs/pkgs/mhpcc/anaconda3-5.0.1/lib/python3.6/site-packages/tensorflow/python/client/session.py", line 633, in __init__
    self._session = tf_session.TF_NewSession(self._graph._c_graph, opts)
tensorflow.python.framework.errors_impl.InternalError: Failed to create session.
2019-08-02 10:47:46.829399: E tensorflow/core/common_runtime/direct_session.cc:158] Internal: failed initializing StreamExecutor for CUDA device ordinal 0: Internal: failed call to cuDevicePrimaryCtxRetain: CUDA_ERROR_INVALID_DEVICE
/gpfs/pkgs/mhpcc/anaconda3-5.0.1/lib/python3.6/site-packages/h5py/__init__.py:34: FutureWarning: Conversion of the second argument of issubdtype from `float` to `np.floating` is deprecated. In future, it will be treated as `np.float64 == np.dtype(float).type`.
  from ._conv import register_converters as _register_converters
Using TensorFlow backend.
2019-08-02 10:47:46.835539: E tensorflow/core/common_runtime/direct_session.cc:158] Internal: failed initializing StreamExecutor for CUDA device ordinal 0: Internal: failed call to cuDevicePrimaryCtxRetain: CUDA_ERROR_INVALID_DEVICE
/gpfs/pkgs/mhpcc/anaconda3-5.0.1/lib/python3.6/site-packages/h5py/__init__.py:34: FutureWarning: Conversion of the second argument of issubdtype from `float` to `np.floating` is deprecated. In future, it will be treated as `np.float64 == np.dtype(float).type`.
  from ._conv import register_converters as _register_converters
Using TensorFlow backend.
Traceback (most recent call last):
  File "roundOneSubmit.py", line 23, in <module>
    l.learnThingsCPP(kind=0, file=f, weightFile=wf)
  File "/gpfs/home/m201560/chipboard/learn.py", line 130, in learnThingsCPP
    weights = self.getWeightArray()
  File "/gpfs/home/m201560/chipboard/learn.py", line 199, in getWeightArray
    return self.model.get_weights()[0].tolist()
  File "/gpfs/home/m201560/.local/lib/python3.6/site-packages/keras/engine/network.py", line 492, in get_weights
    return K.batch_get_value(weights)
  File "/gpfs/home/m201560/.local/lib/python3.6/site-packages/keras/backend/tensorflow_backend.py", line 2420, in batch_get_value
    return get_session().run(ops)
  File "/gpfs/home/m201560/.local/lib/python3.6/site-packages/keras/backend/tensorflow_backend.py", line 186, in get_session
    _SESSION = tf.Session(config=config)
  File "/gpfs/pkgs/mhpcc/anaconda3-5.0.1/lib/python3.6/site-packages/tensorflow/python/client/session.py", line 1563, in __init__
    super(Session, self).__init__(target, graph, config=config)
  File "/gpfs/pkgs/mhpcc/anaconda3-5.0.1/lib/python3.6/site-packages/tensorflow/python/client/session.py", line 633, in __init__
    self._session = tf_session.TF_NewSession(self._graph._c_graph, opts)
tensorflow.python.framework.errors_impl.InternalError: Failed to create session.
Traceback (most recent call last):
  File "roundOneSubmit.py", line 23, in <module>
    l.learnThingsCPP(kind=0, file=f, weightFile=wf)
  File "/gpfs/home/m201560/chipboard/learn.py", line 130, in learnThingsCPP
    weights = self.getWeightArray()
  File "/gpfs/home/m201560/chipboard/learn.py", line 199, in getWeightArray
    return self.model.get_weights()[0].tolist()
  File "/gpfs/home/m201560/.local/lib/python3.6/site-packages/keras/engine/network.py", line 492, in get_weights
    return K.batch_get_value(weights)
  File "/gpfs/home/m201560/.local/lib/python3.6/site-packages/keras/backend/tensorflow_backend.py", line 2420, in batch_get_value
    return get_session().run(ops)
  File "/gpfs/home/m201560/.local/lib/python3.6/site-packages/keras/backend/tensorflow_backend.py", line 186, in get_session
    _SESSION = tf.Session(config=config)
  File "/gpfs/pkgs/mhpcc/anaconda3-5.0.1/lib/python3.6/site-packages/tensorflow/python/client/session.py", line 1563, in __init__
    super(Session, self).__init__(target, graph, config=config)
  File "/gpfs/pkgs/mhpcc/anaconda3-5.0.1/lib/python3.6/site-packages/tensorflow/python/client/session.py", line 633, in __init__
    self._session = tf_session.TF_NewSession(self._graph._c_graph, opts)
tensorflow.python.framework.errors_impl.InternalError: Failed to create session.
2019-08-02 10:47:46.937787: E tensorflow/core/common_runtime/direct_session.cc:158] Internal: failed initializing StreamExecutor for CUDA device ordinal 0: Internal: failed call to cuDevicePrimaryCtxRetain: CUDA_ERROR_INVALID_DEVICE
/gpfs/pkgs/mhpcc/anaconda3-5.0.1/lib/python3.6/site-packages/h5py/__init__.py:34: FutureWarning: Conversion of the second argument of issubdtype from `float` to `np.floating` is deprecated. In future, it will be treated as `np.float64 == np.dtype(float).type`.
  from ._conv import register_converters as _register_converters
Using TensorFlow backend.
Traceback (most recent call last):
  File "roundOneSubmit.py", line 23, in <module>
    l.learnThingsCPP(kind=0, file=f, weightFile=wf)
  File "/gpfs/home/m201560/chipboard/learn.py", line 130, in learnThingsCPP
    weights = self.getWeightArray()
  File "/gpfs/home/m201560/chipboard/learn.py", line 199, in getWeightArray
    return self.model.get_weights()[0].tolist()
  File "/gpfs/home/m201560/.local/lib/python3.6/site-packages/keras/engine/network.py", line 492, in get_weights
    return K.batch_get_value(weights)
  File "/gpfs/home/m201560/.local/lib/python3.6/site-packages/keras/backend/tensorflow_backend.py", line 2420, in batch_get_value
    return get_session().run(ops)
  File "/gpfs/home/m201560/.local/lib/python3.6/site-packages/keras/backend/tensorflow_backend.py", line 186, in get_session
    _SESSION = tf.Session(config=config)
  File "/gpfs/pkgs/mhpcc/anaconda3-5.0.1/lib/python3.6/site-packages/tensorflow/python/client/session.py", line 1563, in __init__
    super(Session, self).__init__(target, graph, config=config)
  File "/gpfs/pkgs/mhpcc/anaconda3-5.0.1/lib/python3.6/site-packages/tensorflow/python/client/session.py", line 633, in __init__
    self._session = tf_session.TF_NewSession(self._graph._c_graph, opts)
tensorflow.python.framework.errors_impl.InternalError: Failed to create session.
2019-08-02 10:47:46.962390: E tensorflow/core/common_runtime/direct_session.cc:158] Internal: failed initializing StreamExecutor for CUDA device ordinal 0: Internal: failed call to cuDevicePrimaryCtxRetain: CUDA_ERROR_INVALID_DEVICE
/gpfs/pkgs/mhpcc/anaconda3-5.0.1/lib/python3.6/site-packages/h5py/__init__.py:34: FutureWarning: Conversion of the second argument of issubdtype from `float` to `np.floating` is deprecated. In future, it will be treated as `np.float64 == np.dtype(float).type`.
  from ._conv import register_converters as _register_converters
Using TensorFlow backend.
Traceback (most recent call last):
  File "roundOneSubmit.py", line 23, in <module>
    l.learnThingsCPP(kind=0, file=f, weightFile=wf)
  File "/gpfs/home/m201560/chipboard/learn.py", line 130, in learnThingsCPP
    weights = self.getWeightArray()
  File "/gpfs/home/m201560/chipboard/learn.py", line 199, in getWeightArray
    return self.model.get_weights()[0].tolist()
  File "/gpfs/home/m201560/.local/lib/python3.6/site-packages/keras/engine/network.py", line 492, in get_weights
    return K.batch_get_value(weights)
  File "/gpfs/home/m201560/.local/lib/python3.6/site-packages/keras/backend/tensorflow_backend.py", line 2420, in batch_get_value
    return get_session().run(ops)
  File "/gpfs/home/m201560/.local/lib/python3.6/site-packages/keras/backend/tensorflow_backend.py", line 186, in get_session
    _SESSION = tf.Session(config=config)
  File "/gpfs/pkgs/mhpcc/anaconda3-5.0.1/lib/python3.6/site-packages/tensorflow/python/client/session.py", line 1563, in __init__
    super(Session, self).__init__(target, graph, config=config)
  File "/gpfs/pkgs/mhpcc/anaconda3-5.0.1/lib/python3.6/site-packages/tensorflow/python/client/session.py", line 633, in __init__
    self._session = tf_session.TF_NewSession(self._graph._c_graph, opts)
tensorflow.python.framework.errors_impl.InternalError: Failed to create session.
2019-08-02 10:47:46.983993: E tensorflow/core/common_runtime/direct_session.cc:158] Internal: failed initializing StreamExecutor for CUDA device ordinal 0: Internal: failed call to cuDevicePrimaryCtxRetain: CUDA_ERROR_INVALID_DEVICE
/gpfs/pkgs/mhpcc/anaconda3-5.0.1/lib/python3.6/site-packages/h5py/__init__.py:34: FutureWarning: Conversion of the second argument of issubdtype from `float` to `np.floating` is deprecated. In future, it will be treated as `np.float64 == np.dtype(float).type`.
  from ._conv import register_converters as _register_converters
Using TensorFlow backend.
Traceback (most recent call last):
  File "roundOneSubmit.py", line 23, in <module>
    l.learnThingsCPP(kind=0, file=f, weightFile=wf)
  File "/gpfs/home/m201560/chipboard/learn.py", line 130, in learnThingsCPP
    weights = self.getWeightArray()
  File "/gpfs/home/m201560/chipboard/learn.py", line 199, in getWeightArray
    return self.model.get_weights()[0].tolist()
  File "/gpfs/home/m201560/.local/lib/python3.6/site-packages/keras/engine/network.py", line 492, in get_weights
    return K.batch_get_value(weights)
  File "/gpfs/home/m201560/.local/lib/python3.6/site-packages/keras/backend/tensorflow_backend.py", line 2420, in batch_get_value
    return get_session().run(ops)
  File "/gpfs/home/m201560/.local/lib/python3.6/site-packages/keras/backend/tensorflow_backend.py", line 186, in get_session
    _SESSION = tf.Session(config=config)
  File "/gpfs/pkgs/mhpcc/anaconda3-5.0.1/lib/python3.6/site-packages/tensorflow/python/client/session.py", line 1563, in __init__
    super(Session, self).__init__(target, graph, config=config)
  File "/gpfs/pkgs/mhpcc/anaconda3-5.0.1/lib/python3.6/site-packages/tensorflow/python/client/session.py", line 633, in __init__
    self._session = tf_session.TF_NewSession(self._graph._c_graph, opts)
tensorflow.python.framework.errors_impl.InternalError: Failed to create session.
2019-08-02 10:47:47.036725: E tensorflow/core/common_runtime/direct_session.cc:158] Internal: failed initializing StreamExecutor for CUDA device ordinal 0: Internal: failed call to cuDevicePrimaryCtxRetain: CUDA_ERROR_INVALID_DEVICE
/gpfs/pkgs/mhpcc/anaconda3-5.0.1/lib/python3.6/site-packages/h5py/__init__.py:34: FutureWarning: Conversion of the second argument of issubdtype from `float` to `np.floating` is deprecated. In future, it will be treated as `np.float64 == np.dtype(float).type`.
  from ._conv import register_converters as _register_converters
Using TensorFlow backend.
Traceback (most recent call last):
  File "roundOneSubmit.py", line 23, in <module>
    l.learnThingsCPP(kind=0, file=f, weightFile=wf)
  File "/gpfs/home/m201560/chipboard/learn.py", line 130, in learnThingsCPP
    weights = self.getWeightArray()
  File "/gpfs/home/m201560/chipboard/learn.py", line 199, in getWeightArray
    return self.model.get_weights()[0].tolist()
  File "/gpfs/home/m201560/.local/lib/python3.6/site-packages/keras/engine/network.py", line 492, in get_weights
    return K.batch_get_value(weights)
  File "/gpfs/home/m201560/.local/lib/python3.6/site-packages/keras/backend/tensorflow_backend.py", line 2420, in batch_get_value
    return get_session().run(ops)
  File "/gpfs/home/m201560/.local/lib/python3.6/site-packages/keras/backend/tensorflow_backend.py", line 186, in get_session
    _SESSION = tf.Session(config=config)
  File "/gpfs/pkgs/mhpcc/anaconda3-5.0.1/lib/python3.6/site-packages/tensorflow/python/client/session.py", line 1563, in __init__
    super(Session, self).__init__(target, graph, config=config)
  File "/gpfs/pkgs/mhpcc/anaconda3-5.0.1/lib/python3.6/site-packages/tensorflow/python/client/session.py", line 633, in __init__
    self._session = tf_session.TF_NewSession(self._graph._c_graph, opts)
tensorflow.python.framework.errors_impl.InternalError: Failed to create session.
2019-08-02 10:47:47.063382: E tensorflow/core/common_runtime/direct_session.cc:158] Internal: failed initializing StreamExecutor for CUDA device ordinal 0: Internal: failed call to cuDevicePrimaryCtxRetain: CUDA_ERROR_INVALID_DEVICE
/gpfs/pkgs/mhpcc/anaconda3-5.0.1/lib/python3.6/site-packages/h5py/__init__.py:34: FutureWarning: Conversion of the second argument of issubdtype from `float` to `np.floating` is deprecated. In future, it will be treated as `np.float64 == np.dtype(float).type`.
  from ._conv import register_converters as _register_converters
Using TensorFlow backend.
Traceback (most recent call last):
  File "roundOneSubmit.py", line 23, in <module>
    l.learnThingsCPP(kind=0, file=f, weightFile=wf)
  File "/gpfs/home/m201560/chipboard/learn.py", line 130, in learnThingsCPP
    weights = self.getWeightArray()
  File "/gpfs/home/m201560/chipboard/learn.py", line 199, in getWeightArray
    return self.model.get_weights()[0].tolist()
  File "/gpfs/home/m201560/.local/lib/python3.6/site-packages/keras/engine/network.py", line 492, in get_weights
    return K.batch_get_value(weights)
  File "/gpfs/home/m201560/.local/lib/python3.6/site-packages/keras/backend/tensorflow_backend.py", line 2420, in batch_get_value
    return get_session().run(ops)
  File "/gpfs/home/m201560/.local/lib/python3.6/site-packages/keras/backend/tensorflow_backend.py", line 186, in get_session
    _SESSION = tf.Session(config=config)
  File "/gpfs/pkgs/mhpcc/anaconda3-5.0.1/lib/python3.6/site-packages/tensorflow/python/client/session.py", line 1563, in __init__
    super(Session, self).__init__(target, graph, config=config)
  File "/gpfs/pkgs/mhpcc/anaconda3-5.0.1/lib/python3.6/site-packages/tensorflow/python/client/session.py", line 633, in __init__
    self._session = tf_session.TF_NewSession(self._graph._c_graph, opts)
tensorflow.python.framework.errors_impl.InternalError: Failed to create session.
2019-08-02 10:47:47.071483: E tensorflow/core/common_runtime/direct_session.cc:158] Internal: failed initializing StreamExecutor for CUDA device ordinal 0: Internal: failed call to cuDevicePrimaryCtxRetain: CUDA_ERROR_INVALID_DEVICE
/gpfs/pkgs/mhpcc/anaconda3-5.0.1/lib/python3.6/site-packages/h5py/__init__.py:34: FutureWarning: Conversion of the second argument of issubdtype from `float` to `np.floating` is deprecated. In future, it will be treated as `np.float64 == np.dtype(float).type`.
  from ._conv import register_converters as _register_converters
Using TensorFlow backend.
Traceback (most recent call last):
  File "roundOneSubmit.py", line 23, in <module>
    l.learnThingsCPP(kind=0, file=f, weightFile=wf)
  File "/gpfs/home/m201560/chipboard/learn.py", line 130, in learnThingsCPP
    weights = self.getWeightArray()
  File "/gpfs/home/m201560/chipboard/learn.py", line 199, in getWeightArray
    return self.model.get_weights()[0].tolist()
  File "/gpfs/home/m201560/.local/lib/python3.6/site-packages/keras/engine/network.py", line 492, in get_weights
    return K.batch_get_value(weights)
  File "/gpfs/home/m201560/.local/lib/python3.6/site-packages/keras/backend/tensorflow_backend.py", line 2420, in batch_get_value
    return get_session().run(ops)
  File "/gpfs/home/m201560/.local/lib/python3.6/site-packages/keras/backend/tensorflow_backend.py", line 186, in get_session
    _SESSION = tf.Session(config=config)
  File "/gpfs/pkgs/mhpcc/anaconda3-5.0.1/lib/python3.6/site-packages/tensorflow/python/client/session.py", line 1563, in __init__
    super(Session, self).__init__(target, graph, config=config)
  File "/gpfs/pkgs/mhpcc/anaconda3-5.0.1/lib/python3.6/site-packages/tensorflow/python/client/session.py", line 633, in __init__
    self._session = tf_session.TF_NewSession(self._graph._c_graph, opts)
tensorflow.python.framework.errors_impl.InternalError: Failed to create session.
2019-08-02 10:47:47.118930: E tensorflow/core/common_runtime/direct_session.cc:158] Internal: failed initializing StreamExecutor for CUDA device ordinal 0: Internal: failed call to cuDevicePrimaryCtxRetain: CUDA_ERROR_INVALID_DEVICE
/gpfs/pkgs/mhpcc/anaconda3-5.0.1/lib/python3.6/site-packages/h5py/__init__.py:34: FutureWarning: Conversion of the second argument of issubdtype from `float` to `np.floating` is deprecated. In future, it will be treated as `np.float64 == np.dtype(float).type`.
  from ._conv import register_converters as _register_converters
Using TensorFlow backend.
Traceback (most recent call last):
  File "roundOneSubmit.py", line 23, in <module>
    l.learnThingsCPP(kind=0, file=f, weightFile=wf)
  File "/gpfs/home/m201560/chipboard/learn.py", line 130, in learnThingsCPP
    weights = self.getWeightArray()
  File "/gpfs/home/m201560/chipboard/learn.py", line 199, in getWeightArray
    return self.model.get_weights()[0].tolist()
  File "/gpfs/home/m201560/.local/lib/python3.6/site-packages/keras/engine/network.py", line 492, in get_weights
    return K.batch_get_value(weights)
  File "/gpfs/home/m201560/.local/lib/python3.6/site-packages/keras/backend/tensorflow_backend.py", line 2420, in batch_get_value
    return get_session().run(ops)
  File "/gpfs/home/m201560/.local/lib/python3.6/site-packages/keras/backend/tensorflow_backend.py", line 186, in get_session
    _SESSION = tf.Session(config=config)
  File "/gpfs/pkgs/mhpcc/anaconda3-5.0.1/lib/python3.6/site-packages/tensorflow/python/client/session.py", line 1563, in __init__
    super(Session, self).__init__(target, graph, config=config)
  File "/gpfs/pkgs/mhpcc/anaconda3-5.0.1/lib/python3.6/site-packages/tensorflow/python/client/session.py", line 633, in __init__
    self._session = tf_session.TF_NewSession(self._graph._c_graph, opts)
tensorflow.python.framework.errors_impl.InternalError: Failed to create session.
2019-08-02 10:47:47.133621: E tensorflow/core/common_runtime/direct_session.cc:158] Internal: failed initializing StreamExecutor for CUDA device ordinal 0: Internal: failed call to cuDevicePrimaryCtxRetain: CUDA_ERROR_INVALID_DEVICE
/gpfs/pkgs/mhpcc/anaconda3-5.0.1/lib/python3.6/site-packages/h5py/__init__.py:34: FutureWarning: Conversion of the second argument of issubdtype from `float` to `np.floating` is deprecated. In future, it will be treated as `np.float64 == np.dtype(float).type`.
  from ._conv import register_converters as _register_converters
Using TensorFlow backend.
Traceback (most recent call last):
  File "roundOneSubmit.py", line 23, in <module>
    l.learnThingsCPP(kind=0, file=f, weightFile=wf)
  File "/gpfs/home/m201560/chipboard/learn.py", line 130, in learnThingsCPP
    weights = self.getWeightArray()
  File "/gpfs/home/m201560/chipboard/learn.py", line 199, in getWeightArray
    return self.model.get_weights()[0].tolist()
  File "/gpfs/home/m201560/.local/lib/python3.6/site-packages/keras/engine/network.py", line 492, in get_weights
    return K.batch_get_value(weights)
  File "/gpfs/home/m201560/.local/lib/python3.6/site-packages/keras/backend/tensorflow_backend.py", line 2420, in batch_get_value
    return get_session().run(ops)
  File "/gpfs/home/m201560/.local/lib/python3.6/site-packages/keras/backend/tensorflow_backend.py", line 186, in get_session
    _SESSION = tf.Session(config=config)
  File "/gpfs/pkgs/mhpcc/anaconda3-5.0.1/lib/python3.6/site-packages/tensorflow/python/client/session.py", line 1563, in __init__
    super(Session, self).__init__(target, graph, config=config)
  File "/gpfs/pkgs/mhpcc/anaconda3-5.0.1/lib/python3.6/site-packages/tensorflow/python/client/session.py", line 633, in __init__
    self._session = tf_session.TF_NewSession(self._graph._c_graph, opts)
tensorflow.python.framework.errors_impl.InternalError: Failed to create session.
2019-08-02 10:47:47.149244: E tensorflow/core/common_runtime/direct_session.cc:158] Internal: failed initializing StreamExecutor for CUDA device ordinal 0: Internal: failed call to cuDevicePrimaryCtxRetain: CUDA_ERROR_INVALID_DEVICE
/gpfs/pkgs/mhpcc/anaconda3-5.0.1/lib/python3.6/site-packages/h5py/__init__.py:34: FutureWarning: Conversion of the second argument of issubdtype from `float` to `np.floating` is deprecated. In future, it will be treated as `np.float64 == np.dtype(float).type`.
  from ._conv import register_converters as _register_converters
Using TensorFlow backend.
2019-08-02 10:47:47.152186: E tensorflow/core/common_runtime/direct_session.cc:158] Internal: failed initializing StreamExecutor for CUDA device ordinal 0: Internal: failed call to cuDevicePrimaryCtxRetain: CUDA_ERROR_INVALID_DEVICE
/gpfs/pkgs/mhpcc/anaconda3-5.0.1/lib/python3.6/site-packages/h5py/__init__.py:34: FutureWarning: Conversion of the second argument of issubdtype from `float` to `np.floating` is deprecated. In future, it will be treated as `np.float64 == np.dtype(float).type`.
  from ._conv import register_converters as _register_converters
Using TensorFlow backend.
Traceback (most recent call last):
  File "roundOneSubmit.py", line 23, in <module>
    l.learnThingsCPP(kind=0, file=f, weightFile=wf)
  File "/gpfs/home/m201560/chipboard/learn.py", line 130, in learnThingsCPP
    weights = self.getWeightArray()
  File "/gpfs/home/m201560/chipboard/learn.py", line 199, in getWeightArray
    return self.model.get_weights()[0].tolist()
  File "/gpfs/home/m201560/.local/lib/python3.6/site-packages/keras/engine/network.py", line 492, in get_weights
    return K.batch_get_value(weights)
  File "/gpfs/home/m201560/.local/lib/python3.6/site-packages/keras/backend/tensorflow_backend.py", line 2420, in batch_get_value
    return get_session().run(ops)
  File "/gpfs/home/m201560/.local/lib/python3.6/site-packages/keras/backend/tensorflow_backend.py", line 186, in get_session
    _SESSION = tf.Session(config=config)
  File "/gpfs/pkgs/mhpcc/anaconda3-5.0.1/lib/python3.6/site-packages/tensorflow/python/client/session.py", line 1563, in __init__
    super(Session, self).__init__(target, graph, config=config)
  File "/gpfs/pkgs/mhpcc/anaconda3-5.0.1/lib/python3.6/site-packages/tensorflow/python/client/session.py", line 633, in __init__
    self._session = tf_session.TF_NewSession(self._graph._c_graph, opts)
tensorflow.python.framework.errors_impl.InternalError: Failed to create session.
2019-08-02 10:47:47.159208: E tensorflow/core/common_runtime/direct_session.cc:158] Internal: failed initializing StreamExecutor for CUDA device ordinal 0: Internal: failed call to cuDevicePrimaryCtxRetain: CUDA_ERROR_INVALID_DEVICE
/gpfs/pkgs/mhpcc/anaconda3-5.0.1/lib/python3.6/site-packages/h5py/__init__.py:34: FutureWarning: Conversion of the second argument of issubdtype from `float` to `np.floating` is deprecated. In future, it will be treated as `np.float64 == np.dtype(float).type`.
  from ._conv import register_converters as _register_converters
Using TensorFlow backend.
Traceback (most recent call last):
  File "roundOneSubmit.py", line 23, in <module>
    l.learnThingsCPP(kind=0, file=f, weightFile=wf)
  File "/gpfs/home/m201560/chipboard/learn.py", line 130, in learnThingsCPP
    weights = self.getWeightArray()
  File "/gpfs/home/m201560/chipboard/learn.py", line 199, in getWeightArray
    return self.model.get_weights()[0].tolist()
  File "/gpfs/home/m201560/.local/lib/python3.6/site-packages/keras/engine/network.py", line 492, in get_weights
    return K.batch_get_value(weights)
  File "/gpfs/home/m201560/.local/lib/python3.6/site-packages/keras/backend/tensorflow_backend.py", line 2420, in batch_get_value
    return get_session().run(ops)
  File "/gpfs/home/m201560/.local/lib/python3.6/site-packages/keras/backend/tensorflow_backend.py", line 186, in get_session
    _SESSION = tf.Session(config=config)
  File "/gpfs/pkgs/mhpcc/anaconda3-5.0.1/lib/python3.6/site-packages/tensorflow/python/client/session.py", line 1563, in __init__
    super(Session, self).__init__(target, graph, config=config)
  File "/gpfs/pkgs/mhpcc/anaconda3-5.0.1/lib/python3.6/site-packages/tensorflow/python/client/session.py", line 633, in __init__
    self._session = tf_session.TF_NewSession(self._graph._c_graph, opts)
tensorflow.python.framework.errors_impl.InternalError: Failed to create session.
2019-08-02 10:47:47.163990: E tensorflow/core/common_runtime/direct_session.cc:158] Internal: failed initializing StreamExecutor for CUDA device ordinal 0: Internal: failed call to cuDevicePrimaryCtxRetain: CUDA_ERROR_INVALID_DEVICE
/gpfs/pkgs/mhpcc/anaconda3-5.0.1/lib/python3.6/site-packages/h5py/__init__.py:34: FutureWarning: Conversion of the second argument of issubdtype from `float` to `np.floating` is deprecated. In future, it will be treated as `np.float64 == np.dtype(float).type`.
  from ._conv import register_converters as _register_converters
Using TensorFlow backend.
2019-08-02 10:47:47.165221: E tensorflow/core/common_runtime/direct_session.cc:158] Internal: failed initializing StreamExecutor for CUDA device ordinal 0: Internal: failed call to cuDevicePrimaryCtxRetain: CUDA_ERROR_INVALID_DEVICE
/gpfs/pkgs/mhpcc/anaconda3-5.0.1/lib/python3.6/site-packages/h5py/__init__.py:34: FutureWarning: Conversion of the second argument of issubdtype from `float` to `np.floating` is deprecated. In future, it will be treated as `np.float64 == np.dtype(float).type`.
  from ._conv import register_converters as _register_converters
Using TensorFlow backend.
Traceback (most recent call last):
  File "roundOneSubmit.py", line 23, in <module>
    l.learnThingsCPP(kind=0, file=f, weightFile=wf)
  File "/gpfs/home/m201560/chipboard/learn.py", line 130, in learnThingsCPP
    weights = self.getWeightArray()
  File "/gpfs/home/m201560/chipboard/learn.py", line 199, in getWeightArray
    return self.model.get_weights()[0].tolist()
  File "/gpfs/home/m201560/.local/lib/python3.6/site-packages/keras/engine/network.py", line 492, in get_weights
    return K.batch_get_value(weights)
  File "/gpfs/home/m201560/.local/lib/python3.6/site-packages/keras/backend/tensorflow_backend.py", line 2420, in batch_get_value
    return get_session().run(ops)
  File "/gpfs/home/m201560/.local/lib/python3.6/site-packages/keras/backend/tensorflow_backend.py", line 186, in get_session
    _SESSION = tf.Session(config=config)
  File "/gpfs/pkgs/mhpcc/anaconda3-5.0.1/lib/python3.6/site-packages/tensorflow/python/client/session.py", line 1563, in __init__
    super(Session, self).__init__(target, graph, config=config)
  File "/gpfs/pkgs/mhpcc/anaconda3-5.0.1/lib/python3.6/site-packages/tensorflow/python/client/session.py", line 633, in __init__
    self._session = tf_session.TF_NewSession(self._graph._c_graph, opts)
tensorflow.python.framework.errors_impl.InternalError: Failed to create session.
Traceback (most recent call last):
  File "roundOneSubmit.py", line 23, in <module>
    l.learnThingsCPP(kind=0, file=f, weightFile=wf)
  File "/gpfs/home/m201560/chipboard/learn.py", line 130, in learnThingsCPP
    weights = self.getWeightArray()
  File "/gpfs/home/m201560/chipboard/learn.py", line 199, in getWeightArray
    return self.model.get_weights()[0].tolist()
  File "/gpfs/home/m201560/.local/lib/python3.6/site-packages/keras/engine/network.py", line 492, in get_weights
    return K.batch_get_value(weights)
  File "/gpfs/home/m201560/.local/lib/python3.6/site-packages/keras/backend/tensorflow_backend.py", line 2420, in batch_get_value
    return get_session().run(ops)
  File "/gpfs/home/m201560/.local/lib/python3.6/site-packages/keras/backend/tensorflow_backend.py", line 186, in get_session
    _SESSION = tf.Session(config=config)
  File "/gpfs/pkgs/mhpcc/anaconda3-5.0.1/lib/python3.6/site-packages/tensorflow/python/client/session.py", line 1563, in __init__
    super(Session, self).__init__(target, graph, config=config)
  File "/gpfs/pkgs/mhpcc/anaconda3-5.0.1/lib/python3.6/site-packages/tensorflow/python/client/session.py", line 633, in __init__
    self._session = tf_session.TF_NewSession(self._graph._c_graph, opts)
tensorflow.python.framework.errors_impl.InternalError: Failed to create session.
Traceback (most recent call last):
  File "roundOneSubmit.py", line 23, in <module>
    l.learnThingsCPP(kind=0, file=f, weightFile=wf)
  File "/gpfs/home/m201560/chipboard/learn.py", line 130, in learnThingsCPP
    weights = self.getWeightArray()
  File "/gpfs/home/m201560/chipboard/learn.py", line 199, in getWeightArray
    return self.model.get_weights()[0].tolist()
  File "/gpfs/home/m201560/.local/lib/python3.6/site-packages/keras/engine/network.py", line 492, in get_weights
    return K.batch_get_value(weights)
  File "/gpfs/home/m201560/.local/lib/python3.6/site-packages/keras/backend/tensorflow_backend.py", line 2420, in batch_get_value
    return get_session().run(ops)
  File "/gpfs/home/m201560/.local/lib/python3.6/site-packages/keras/backend/tensorflow_backend.py", line 186, in get_session
    _SESSION = tf.Session(config=config)
  File "/gpfs/pkgs/mhpcc/anaconda3-5.0.1/lib/python3.6/site-packages/tensorflow/python/client/session.py", line 1563, in __init__
    super(Session, self).__init__(target, graph, config=config)
  File "/gpfs/pkgs/mhpcc/anaconda3-5.0.1/lib/python3.6/site-packages/tensorflow/python/client/session.py", line 633, in __init__
    self._session = tf_session.TF_NewSession(self._graph._c_graph, opts)
tensorflow.python.framework.errors_impl.InternalError: Failed to create session.
2019-08-02 10:47:47.184321: E tensorflow/core/common_runtime/direct_session.cc:158] Internal: failed initializing StreamExecutor for CUDA device ordinal 0: Internal: failed call to cuDevicePrimaryCtxRetain: CUDA_ERROR_INVALID_DEVICE
/gpfs/pkgs/mhpcc/anaconda3-5.0.1/lib/python3.6/site-packages/h5py/__init__.py:34: FutureWarning: Conversion of the second argument of issubdtype from `float` to `np.floating` is deprecated. In future, it will be treated as `np.float64 == np.dtype(float).type`.
  from ._conv import register_converters as _register_converters
Using TensorFlow backend.
Traceback (most recent call last):
  File "roundOneSubmit.py", line 23, in <module>
    l.learnThingsCPP(kind=0, file=f, weightFile=wf)
  File "/gpfs/home/m201560/chipboard/learn.py", line 130, in learnThingsCPP
    weights = self.getWeightArray()
  File "/gpfs/home/m201560/chipboard/learn.py", line 199, in getWeightArray
    return self.model.get_weights()[0].tolist()
  File "/gpfs/home/m201560/.local/lib/python3.6/site-packages/keras/engine/network.py", line 492, in get_weights
    return K.batch_get_value(weights)
  File "/gpfs/home/m201560/.local/lib/python3.6/site-packages/keras/backend/tensorflow_backend.py", line 2420, in batch_get_value
    return get_session().run(ops)
  File "/gpfs/home/m201560/.local/lib/python3.6/site-packages/keras/backend/tensorflow_backend.py", line 186, in get_session
    _SESSION = tf.Session(config=config)
  File "/gpfs/pkgs/mhpcc/anaconda3-5.0.1/lib/python3.6/site-packages/tensorflow/python/client/session.py", line 1563, in __init__
    super(Session, self).__init__(target, graph, config=config)
  File "/gpfs/pkgs/mhpcc/anaconda3-5.0.1/lib/python3.6/site-packages/tensorflow/python/client/session.py", line 633, in __init__
    self._session = tf_session.TF_NewSession(self._graph._c_graph, opts)
tensorflow.python.framework.errors_impl.InternalError: Failed to create session.
2019-08-02 10:47:47.195077: E tensorflow/core/common_runtime/direct_session.cc:158] Internal: failed initializing StreamExecutor for CUDA device ordinal 0: Internal: failed call to cuDevicePrimaryCtxRetain: CUDA_ERROR_INVALID_DEVICE
/gpfs/pkgs/mhpcc/anaconda3-5.0.1/lib/python3.6/site-packages/h5py/__init__.py:34: FutureWarning: Conversion of the second argument of issubdtype from `float` to `np.floating` is deprecated. In future, it will be treated as `np.float64 == np.dtype(float).type`.
  from ._conv import register_converters as _register_converters
Using TensorFlow backend.
2019-08-02 10:47:47.200562: E tensorflow/core/common_runtime/direct_session.cc:158] Internal: failed initializing StreamExecutor for CUDA device ordinal 0: Internal: failed call to cuDevicePrimaryCtxRetain: CUDA_ERROR_INVALID_DEVICE
/gpfs/pkgs/mhpcc/anaconda3-5.0.1/lib/python3.6/site-packages/h5py/__init__.py:34: FutureWarning: Conversion of the second argument of issubdtype from `float` to `np.floating` is deprecated. In future, it will be treated as `np.float64 == np.dtype(float).type`.
  from ._conv import register_converters as _register_converters
Using TensorFlow backend.
2019-08-02 10:47:47.202659: E tensorflow/core/common_runtime/direct_session.cc:158] Internal: failed initializing StreamExecutor for CUDA device ordinal 0: Internal: failed call to cuDevicePrimaryCtxRetain: CUDA_ERROR_INVALID_DEVICE
/gpfs/pkgs/mhpcc/anaconda3-5.0.1/lib/python3.6/site-packages/h5py/__init__.py:34: FutureWarning: Conversion of the second argument of issubdtype from `float` to `np.floating` is deprecated. In future, it will be treated as `np.float64 == np.dtype(float).type`.
  from ._conv import register_converters as _register_converters
Using TensorFlow backend.
2019-08-02 10:47:47.207202: E tensorflow/core/common_runtime/direct_session.cc:158] Internal: failed initializing StreamExecutor for CUDA device ordinal 0: Internal: failed call to cuDevicePrimaryCtxRetain: CUDA_ERROR_INVALID_DEVICE
/gpfs/pkgs/mhpcc/anaconda3-5.0.1/lib/python3.6/site-packages/h5py/__init__.py:34: FutureWarning: Conversion of the second argument of issubdtype from `float` to `np.floating` is deprecated. In future, it will be treated as `np.float64 == np.dtype(float).type`.
  from ._conv import register_converters as _register_converters
Using TensorFlow backend.
Traceback (most recent call last):
  File "roundOneSubmit.py", line 23, in <module>
    l.learnThingsCPP(kind=0, file=f, weightFile=wf)
  File "/gpfs/home/m201560/chipboard/learn.py", line 130, in learnThingsCPP
    weights = self.getWeightArray()
  File "/gpfs/home/m201560/chipboard/learn.py", line 199, in getWeightArray
    return self.model.get_weights()[0].tolist()
  File "/gpfs/home/m201560/.local/lib/python3.6/site-packages/keras/engine/network.py", line 492, in get_weights
    return K.batch_get_value(weights)
  File "/gpfs/home/m201560/.local/lib/python3.6/site-packages/keras/backend/tensorflow_backend.py", line 2420, in batch_get_value
    return get_session().run(ops)
  File "/gpfs/home/m201560/.local/lib/python3.6/site-packages/keras/backend/tensorflow_backend.py", line 186, in get_session
    _SESSION = tf.Session(config=config)
  File "/gpfs/pkgs/mhpcc/anaconda3-5.0.1/lib/python3.6/site-packages/tensorflow/python/client/session.py", line 1563, in __init__
    super(Session, self).__init__(target, graph, config=config)
  File "/gpfs/pkgs/mhpcc/anaconda3-5.0.1/lib/python3.6/site-packages/tensorflow/python/client/session.py", line 633, in __init__
    self._session = tf_session.TF_NewSession(self._graph._c_graph, opts)
tensorflow.python.framework.errors_impl.InternalError: Failed to create session.
Traceback (most recent call last):
  File "roundOneSubmit.py", line 23, in <module>
    l.learnThingsCPP(kind=0, file=f, weightFile=wf)
  File "/gpfs/home/m201560/chipboard/learn.py", line 130, in learnThingsCPP
    weights = self.getWeightArray()
  File "/gpfs/home/m201560/chipboard/learn.py", line 199, in getWeightArray
    return self.model.get_weights()[0].tolist()
  File "/gpfs/home/m201560/.local/lib/python3.6/site-packages/keras/engine/network.py", line 492, in get_weights
    return K.batch_get_value(weights)
  File "/gpfs/home/m201560/.local/lib/python3.6/site-packages/keras/backend/tensorflow_backend.py", line 2420, in batch_get_value
    return get_session().run(ops)
  File "/gpfs/home/m201560/.local/lib/python3.6/site-packages/keras/backend/tensorflow_backend.py", line 186, in get_session
    _SESSION = tf.Session(config=config)
  File "/gpfs/pkgs/mhpcc/anaconda3-5.0.1/lib/python3.6/site-packages/tensorflow/python/client/session.py", line 1563, in __init__
    super(Session, self).__init__(target, graph, config=config)
  File "/gpfs/pkgs/mhpcc/anaconda3-5.0.1/lib/python3.6/site-packages/tensorflow/python/client/session.py", line 633, in __init__
    self._session = tf_session.TF_NewSession(self._graph._c_graph, opts)
tensorflow.python.framework.errors_impl.InternalError: Failed to create session.
Traceback (most recent call last):
  File "roundOneSubmit.py", line 23, in <module>
    l.learnThingsCPP(kind=0, file=f, weightFile=wf)
  File "/gpfs/home/m201560/chipboard/learn.py", line 130, in learnThingsCPP
    weights = self.getWeightArray()
  File "/gpfs/home/m201560/chipboard/learn.py", line 199, in getWeightArray
    return self.model.get_weights()[0].tolist()
  File "/gpfs/home/m201560/.local/lib/python3.6/site-packages/keras/engine/network.py", line 492, in get_weights
    return K.batch_get_value(weights)
  File "/gpfs/home/m201560/.local/lib/python3.6/site-packages/keras/backend/tensorflow_backend.py", line 2420, in batch_get_value
    return get_session().run(ops)
  File "/gpfs/home/m201560/.local/lib/python3.6/site-packages/keras/backend/tensorflow_backend.py", line 186, in get_session
    _SESSION = tf.Session(config=config)
  File "/gpfs/pkgs/mhpcc/anaconda3-5.0.1/lib/python3.6/site-packages/tensorflow/python/client/session.py", line 1563, in __init__
    super(Session, self).__init__(target, graph, config=config)
  File "/gpfs/pkgs/mhpcc/anaconda3-5.0.1/lib/python3.6/site-packages/tensorflow/python/client/session.py", line 633, in __init__
    self._session = tf_session.TF_NewSession(self._graph._c_graph, opts)
tensorflow.python.framework.errors_impl.InternalError: Failed to create session.
Traceback (most recent call last):
  File "roundOneSubmit.py", line 23, in <module>
    l.learnThingsCPP(kind=0, file=f, weightFile=wf)
  File "/gpfs/home/m201560/chipboard/learn.py", line 130, in learnThingsCPP
    weights = self.getWeightArray()
  File "/gpfs/home/m201560/chipboard/learn.py", line 199, in getWeightArray
    return self.model.get_weights()[0].tolist()
  File "/gpfs/home/m201560/.local/lib/python3.6/site-packages/keras/engine/network.py", line 492, in get_weights
    return K.batch_get_value(weights)
  File "/gpfs/home/m201560/.local/lib/python3.6/site-packages/keras/backend/tensorflow_backend.py", line 2420, in batch_get_value
    return get_session().run(ops)
  File "/gpfs/home/m201560/.local/lib/python3.6/site-packages/keras/backend/tensorflow_backend.py", line 186, in get_session
    _SESSION = tf.Session(config=config)
  File "/gpfs/pkgs/mhpcc/anaconda3-5.0.1/lib/python3.6/site-packages/tensorflow/python/client/session.py", line 1563, in __init__
    super(Session, self).__init__(target, graph, config=config)
  File "/gpfs/pkgs/mhpcc/anaconda3-5.0.1/lib/python3.6/site-packages/tensorflow/python/client/session.py", line 633, in __init__
    self._session = tf_session.TF_NewSession(self._graph._c_graph, opts)
tensorflow.python.framework.errors_impl.InternalError: Failed to create session.
2019-08-02 10:47:47.222165: E tensorflow/core/common_runtime/direct_session.cc:158] Internal: failed initializing StreamExecutor for CUDA device ordinal 0: Internal: failed call to cuDevicePrimaryCtxRetain: CUDA_ERROR_INVALID_DEVICE
/gpfs/pkgs/mhpcc/anaconda3-5.0.1/lib/python3.6/site-packages/h5py/__init__.py:34: FutureWarning: Conversion of the second argument of issubdtype from `float` to `np.floating` is deprecated. In future, it will be treated as `np.float64 == np.dtype(float).type`.
  from ._conv import register_converters as _register_converters
Using TensorFlow backend.
2019-08-02 10:47:47.222824: E tensorflow/core/common_runtime/direct_session.cc:158] Internal: failed initializing StreamExecutor for CUDA device ordinal 0: Internal: failed call to cuDevicePrimaryCtxRetain: CUDA_ERROR_INVALID_DEVICE
/gpfs/pkgs/mhpcc/anaconda3-5.0.1/lib/python3.6/site-packages/h5py/__init__.py:34: FutureWarning: Conversion of the second argument of issubdtype from `float` to `np.floating` is deprecated. In future, it will be treated as `np.float64 == np.dtype(float).type`.
  from ._conv import register_converters as _register_converters
Using TensorFlow backend.
2019-08-02 10:47:47.227210: E tensorflow/core/common_runtime/direct_session.cc:158] Internal: failed initializing StreamExecutor for CUDA device ordinal 0: Internal: failed call to cuDevicePrimaryCtxRetain: CUDA_ERROR_INVALID_DEVICE
/gpfs/pkgs/mhpcc/anaconda3-5.0.1/lib/python3.6/site-packages/h5py/__init__.py:34: FutureWarning: Conversion of the second argument of issubdtype from `float` to `np.floating` is deprecated. In future, it will be treated as `np.float64 == np.dtype(float).type`.
  from ._conv import register_converters as _register_converters
Using TensorFlow backend.
Traceback (most recent call last):
  File "roundOneSubmit.py", line 23, in <module>
    l.learnThingsCPP(kind=0, file=f, weightFile=wf)
  File "/gpfs/home/m201560/chipboard/learn.py", line 130, in learnThingsCPP
    weights = self.getWeightArray()
  File "/gpfs/home/m201560/chipboard/learn.py", line 199, in getWeightArray
    return self.model.get_weights()[0].tolist()
  File "/gpfs/home/m201560/.local/lib/python3.6/site-packages/keras/engine/network.py", line 492, in get_weights
    return K.batch_get_value(weights)
  File "/gpfs/home/m201560/.local/lib/python3.6/site-packages/keras/backend/tensorflow_backend.py", line 2420, in batch_get_value
    return get_session().run(ops)
  File "/gpfs/home/m201560/.local/lib/python3.6/site-packages/keras/backend/tensorflow_backend.py", line 186, in get_session
    _SESSION = tf.Session(config=config)
  File "/gpfs/pkgs/mhpcc/anaconda3-5.0.1/lib/python3.6/site-packages/tensorflow/python/client/session.py", line 1563, in __init__
    super(Session, self).__init__(target, graph, config=config)
  File "/gpfs/pkgs/mhpcc/anaconda3-5.0.1/lib/python3.6/site-packages/tensorflow/python/client/session.py", line 633, in __init__
    self._session = tf_session.TF_NewSession(self._graph._c_graph, opts)
tensorflow.python.framework.errors_impl.InternalError: Failed to create session.
Traceback (most recent call last):
  File "roundOneSubmit.py", line 23, in <module>
    l.learnThingsCPP(kind=0, file=f, weightFile=wf)
  File "/gpfs/home/m201560/chipboard/learn.py", line 130, in learnThingsCPP
    weights = self.getWeightArray()
  File "/gpfs/home/m201560/chipboard/learn.py", line 199, in getWeightArray
    return self.model.get_weights()[0].tolist()
  File "/gpfs/home/m201560/.local/lib/python3.6/site-packages/keras/engine/network.py", line 492, in get_weights
    return K.batch_get_value(weights)
  File "/gpfs/home/m201560/.local/lib/python3.6/site-packages/keras/backend/tensorflow_backend.py", line 2420, in batch_get_value
    return get_session().run(ops)
  File "/gpfs/home/m201560/.local/lib/python3.6/site-packages/keras/backend/tensorflow_backend.py", line 186, in get_session
    _SESSION = tf.Session(config=config)
  File "/gpfs/pkgs/mhpcc/anaconda3-5.0.1/lib/python3.6/site-packages/tensorflow/python/client/session.py", line 1563, in __init__
    super(Session, self).__init__(target, graph, config=config)
  File "/gpfs/pkgs/mhpcc/anaconda3-5.0.1/lib/python3.6/site-packages/tensorflow/python/client/session.py", line 633, in __init__
    self._session = tf_session.TF_NewSession(self._graph._c_graph, opts)
tensorflow.python.framework.errors_impl.InternalError: Failed to create session.
2019-08-02 10:47:47.235118: E tensorflow/core/common_runtime/direct_session.cc:158] Internal: failed initializing StreamExecutor for CUDA device ordinal 0: Internal: failed call to cuDevicePrimaryCtxRetain: CUDA_ERROR_INVALID_DEVICE
/gpfs/pkgs/mhpcc/anaconda3-5.0.1/lib/python3.6/site-packages/h5py/__init__.py:34: FutureWarning: Conversion of the second argument of issubdtype from `float` to `np.floating` is deprecated. In future, it will be treated as `np.float64 == np.dtype(float).type`.
  from ._conv import register_converters as _register_converters
Using TensorFlow backend.
Traceback (most recent call last):
  File "roundOneSubmit.py", line 23, in <module>
    l.learnThingsCPP(kind=0, file=f, weightFile=wf)
  File "/gpfs/home/m201560/chipboard/learn.py", line 130, in learnThingsCPP
    weights = self.getWeightArray()
  File "/gpfs/home/m201560/chipboard/learn.py", line 199, in getWeightArray
    return self.model.get_weights()[0].tolist()
  File "/gpfs/home/m201560/.local/lib/python3.6/site-packages/keras/engine/network.py", line 492, in get_weights
    return K.batch_get_value(weights)
  File "/gpfs/home/m201560/.local/lib/python3.6/site-packages/keras/backend/tensorflow_backend.py", line 2420, in batch_get_value
    return get_session().run(ops)
  File "/gpfs/home/m201560/.local/lib/python3.6/site-packages/keras/backend/tensorflow_backend.py", line 186, in get_session
    _SESSION = tf.Session(config=config)
  File "/gpfs/pkgs/mhpcc/anaconda3-5.0.1/lib/python3.6/site-packages/tensorflow/python/client/session.py", line 1563, in __init__
    super(Session, self).__init__(target, graph, config=config)
  File "/gpfs/pkgs/mhpcc/anaconda3-5.0.1/lib/python3.6/site-packages/tensorflow/python/client/session.py", line 633, in __init__
    self._session = tf_session.TF_NewSession(self._graph._c_graph, opts)
tensorflow.python.framework.errors_impl.InternalError: Failed to create session.
2019-08-02 10:47:47.240453: E tensorflow/core/common_runtime/direct_session.cc:158] Internal: failed initializing StreamExecutor for CUDA device ordinal 0: Internal: failed call to cuDevicePrimaryCtxRetain: CUDA_ERROR_INVALID_DEVICE
/gpfs/pkgs/mhpcc/anaconda3-5.0.1/lib/python3.6/site-packages/h5py/__init__.py:34: FutureWarning: Conversion of the second argument of issubdtype from `float` to `np.floating` is deprecated. In future, it will be treated as `np.float64 == np.dtype(float).type`.
  from ._conv import register_converters as _register_converters
Using TensorFlow backend.
2019-08-02 10:47:47.241659: E tensorflow/core/common_runtime/direct_session.cc:158] Internal: failed initializing StreamExecutor for CUDA device ordinal 0: Internal: failed call to cuDevicePrimaryCtxRetain: CUDA_ERROR_INVALID_DEVICE
/gpfs/pkgs/mhpcc/anaconda3-5.0.1/lib/python3.6/site-packages/h5py/__init__.py:34: FutureWarning: Conversion of the second argument of issubdtype from `float` to `np.floating` is deprecated. In future, it will be treated as `np.float64 == np.dtype(float).type`.
  from ._conv import register_converters as _register_converters
Using TensorFlow backend.
2019-08-02 10:47:47.248367: E tensorflow/core/common_runtime/direct_session.cc:158] Internal: failed initializing StreamExecutor for CUDA device ordinal 0: Internal: failed call to cuDevicePrimaryCtxRetain: CUDA_ERROR_INVALID_DEVICE
/gpfs/pkgs/mhpcc/anaconda3-5.0.1/lib/python3.6/site-packages/h5py/__init__.py:34: FutureWarning: Conversion of the second argument of issubdtype from `float` to `np.floating` is deprecated. In future, it will be treated as `np.float64 == np.dtype(float).type`.
  from ._conv import register_converters as _register_converters
Using TensorFlow backend.
2019-08-02 10:47:47.248668: E tensorflow/core/common_runtime/direct_session.cc:158] Internal: failed initializing StreamExecutor for CUDA device ordinal 0: Internal: failed call to cuDevicePrimaryCtxRetain: CUDA_ERROR_INVALID_DEVICE
/gpfs/pkgs/mhpcc/anaconda3-5.0.1/lib/python3.6/site-packages/h5py/__init__.py:34: FutureWarning: Conversion of the second argument of issubdtype from `float` to `np.floating` is deprecated. In future, it will be treated as `np.float64 == np.dtype(float).type`.
  from ._conv import register_converters as _register_converters
Using TensorFlow backend.
Traceback (most recent call last):
  File "roundOneSubmit.py", line 23, in <module>
    l.learnThingsCPP(kind=0, file=f, weightFile=wf)
  File "/gpfs/home/m201560/chipboard/learn.py", line 130, in learnThingsCPP
    weights = self.getWeightArray()
  File "/gpfs/home/m201560/chipboard/learn.py", line 199, in getWeightArray
    return self.model.get_weights()[0].tolist()
  File "/gpfs/home/m201560/.local/lib/python3.6/site-packages/keras/engine/network.py", line 492, in get_weights
    return K.batch_get_value(weights)
  File "/gpfs/home/m201560/.local/lib/python3.6/site-packages/keras/backend/tensorflow_backend.py", line 2420, in batch_get_value
    return get_session().run(ops)
  File "/gpfs/home/m201560/.local/lib/python3.6/site-packages/keras/backend/tensorflow_backend.py", line 186, in get_session
    _SESSION = tf.Session(config=config)
  File "/gpfs/pkgs/mhpcc/anaconda3-5.0.1/lib/python3.6/site-packages/tensorflow/python/client/session.py", line 1563, in __init__
    super(Session, self).__init__(target, graph, config=config)
  File "/gpfs/pkgs/mhpcc/anaconda3-5.0.1/lib/python3.6/site-packages/tensorflow/python/client/session.py", line 633, in __init__
    self._session = tf_session.TF_NewSession(self._graph._c_graph, opts)
tensorflow.python.framework.errors_impl.InternalError: Failed to create session.
Traceback (most recent call last):
  File "roundOneSubmit.py", line 23, in <module>
    l.learnThingsCPP(kind=0, file=f, weightFile=wf)
  File "/gpfs/home/m201560/chipboard/learn.py", line 130, in learnThingsCPP
    weights = self.getWeightArray()
  File "/gpfs/home/m201560/chipboard/learn.py", line 199, in getWeightArray
    return self.model.get_weights()[0].tolist()
  File "/gpfs/home/m201560/.local/lib/python3.6/site-packages/keras/engine/network.py", line 492, in get_weights
    return K.batch_get_value(weights)
  File "/gpfs/home/m201560/.local/lib/python3.6/site-packages/keras/backend/tensorflow_backend.py", line 2420, in batch_get_value
    return get_session().run(ops)
  File "/gpfs/home/m201560/.local/lib/python3.6/site-packages/keras/backend/tensorflow_backend.py", line 186, in get_session
    _SESSION = tf.Session(config=config)
  File "/gpfs/pkgs/mhpcc/anaconda3-5.0.1/lib/python3.6/site-packages/tensorflow/python/client/session.py", line 1563, in __init__
    super(Session, self).__init__(target, graph, config=config)
  File "/gpfs/pkgs/mhpcc/anaconda3-5.0.1/lib/python3.6/site-packages/tensorflow/python/client/session.py", line 633, in __init__
    self._session = tf_session.TF_NewSession(self._graph._c_graph, opts)
tensorflow.python.framework.errors_impl.InternalError: Failed to create session.
Traceback (most recent call last):
  File "roundOneSubmit.py", line 23, in <module>
    l.learnThingsCPP(kind=0, file=f, weightFile=wf)
  File "/gpfs/home/m201560/chipboard/learn.py", line 130, in learnThingsCPP
    weights = self.getWeightArray()
  File "/gpfs/home/m201560/chipboard/learn.py", line 199, in getWeightArray
    return self.model.get_weights()[0].tolist()
  File "/gpfs/home/m201560/.local/lib/python3.6/site-packages/keras/engine/network.py", line 492, in get_weights
    return K.batch_get_value(weights)
  File "/gpfs/home/m201560/.local/lib/python3.6/site-packages/keras/backend/tensorflow_backend.py", line 2420, in batch_get_value
    return get_session().run(ops)
  File "/gpfs/home/m201560/.local/lib/python3.6/site-packages/keras/backend/tensorflow_backend.py", line 186, in get_session
    _SESSION = tf.Session(config=config)
  File "/gpfs/pkgs/mhpcc/anaconda3-5.0.1/lib/python3.6/site-packages/tensorflow/python/client/session.py", line 1563, in __init__
    super(Session, self).__init__(target, graph, config=config)
  File "/gpfs/pkgs/mhpcc/anaconda3-5.0.1/lib/python3.6/site-packages/tensorflow/python/client/session.py", line 633, in __init__
    self._session = tf_session.TF_NewSession(self._graph._c_graph, opts)
tensorflow.python.framework.errors_impl.InternalError: Failed to create session.
Traceback (most recent call last):
  File "roundOneSubmit.py", line 23, in <module>
    l.learnThingsCPP(kind=0, file=f, weightFile=wf)
  File "/gpfs/home/m201560/chipboard/learn.py", line 130, in learnThingsCPP
    weights = self.getWeightArray()
  File "/gpfs/home/m201560/chipboard/learn.py", line 199, in getWeightArray
    return self.model.get_weights()[0].tolist()
  File "/gpfs/home/m201560/.local/lib/python3.6/site-packages/keras/engine/network.py", line 492, in get_weights
    return K.batch_get_value(weights)
  File "/gpfs/home/m201560/.local/lib/python3.6/site-packages/keras/backend/tensorflow_backend.py", line 2420, in batch_get_value
    return get_session().run(ops)
  File "/gpfs/home/m201560/.local/lib/python3.6/site-packages/keras/backend/tensorflow_backend.py", line 186, in get_session
    _SESSION = tf.Session(config=config)
  File "/gpfs/pkgs/mhpcc/anaconda3-5.0.1/lib/python3.6/site-packages/tensorflow/python/client/session.py", line 1563, in __init__
    super(Session, self).__init__(target, graph, config=config)
  File "/gpfs/pkgs/mhpcc/anaconda3-5.0.1/lib/python3.6/site-packages/tensorflow/python/client/session.py", line 633, in __init__
    self._session = tf_session.TF_NewSession(self._graph._c_graph, opts)
tensorflow.python.framework.errors_impl.InternalError: Failed to create session.
Traceback (most recent call last):
  File "roundOneSubmit.py", line 23, in <module>
    l.learnThingsCPP(kind=0, file=f, weightFile=wf)
  File "/gpfs/home/m201560/chipboard/learn.py", line 130, in learnThingsCPP
    weights = self.getWeightArray()
  File "/gpfs/home/m201560/chipboard/learn.py", line 199, in getWeightArray
    return self.model.get_weights()[0].tolist()
  File "/gpfs/home/m201560/.local/lib/python3.6/site-packages/keras/engine/network.py", line 492, in get_weights
    return K.batch_get_value(weights)
  File "/gpfs/home/m201560/.local/lib/python3.6/site-packages/keras/backend/tensorflow_backend.py", line 2420, in batch_get_value
    return get_session().run(ops)
  File "/gpfs/home/m201560/.local/lib/python3.6/site-packages/keras/backend/tensorflow_backend.py", line 186, in get_session
    _SESSION = tf.Session(config=config)
  File "/gpfs/pkgs/mhpcc/anaconda3-5.0.1/lib/python3.6/site-packages/tensorflow/python/client/session.py", line 1563, in __init__
    super(Session, self).__init__(target, graph, config=config)
  File "/gpfs/pkgs/mhpcc/anaconda3-5.0.1/lib/python3.6/site-packages/tensorflow/python/client/session.py", line 633, in __init__
    self._session = tf_session.TF_NewSession(self._graph._c_graph, opts)
tensorflow.python.framework.errors_impl.InternalError: Failed to create session.
2019-08-02 10:47:47.301322: I tensorflow/core/common_runtime/gpu/gpu_device.cc:1392] Found device 2 with properties: 
name: Tesla P100-SXM2-16GB major: 6 minor: 0 memoryClockRate(GHz): 1.4805
pciBusID: 0006:01:00.0
totalMemory: 15.90GiB freeMemory: 15.64GiB
2019-08-02 10:47:47.496777: I tensorflow/core/common_runtime/gpu/gpu_device.cc:1392] Found device 3 with properties: 
name: Tesla P100-SXM2-16GB major: 6 minor: 0 memoryClockRate(GHz): 1.4805
pciBusID: 0007:01:00.0
totalMemory: 15.90GiB freeMemory: 15.64GiB
2019-08-02 10:47:47.497855: I tensorflow/core/common_runtime/gpu/gpu_device.cc:1471] Adding visible gpu devices: 0, 1, 2, 3
[cr1cn06:55876] 79 more processes have sent help message help-mpi-btl-openib.txt / default subnet prefix
[cr1cn06:55876] Set MCA parameter "orte_base_help_aggregate" to 0 to see all help / error messages
2019-08-02 10:47:51.273571: I tensorflow/core/common_runtime/gpu/gpu_device.cc:952] Device interconnect StreamExecutor with strength 1 edge matrix:
2019-08-02 10:47:51.273622: I tensorflow/core/common_runtime/gpu/gpu_device.cc:958]      0 1 2 3 
2019-08-02 10:47:51.273638: I tensorflow/core/common_runtime/gpu/gpu_device.cc:971] 0:   N Y N N 
2019-08-02 10:47:51.273649: I tensorflow/core/common_runtime/gpu/gpu_device.cc:971] 1:   Y N N N 
2019-08-02 10:47:51.273660: I tensorflow/core/common_runtime/gpu/gpu_device.cc:971] 2:   N N N Y 
2019-08-02 10:47:51.273671: I tensorflow/core/common_runtime/gpu/gpu_device.cc:971] 3:   N N Y N 
2019-08-02 10:47:51.274372: I tensorflow/core/common_runtime/gpu/gpu_device.cc:1084] Created TensorFlow device (/job:localhost/replica:0/task:0/device:GPU:0 with 15163 MB memory) -> physical GPU (device: 0, name: Tesla P100-SXM2-16GB, pci bus id: 0002:01:00.0, compute capability: 6.0)
2019-08-02 10:47:51.434431: I tensorflow/core/common_runtime/gpu/gpu_device.cc:1084] Created TensorFlow device (/job:localhost/replica:0/task:0/device:GPU:1 with 15163 MB memory) -> physical GPU (device: 1, name: Tesla P100-SXM2-16GB, pci bus id: 0003:01:00.0, compute capability: 6.0)
2019-08-02 10:47:51.594464: I tensorflow/core/common_runtime/gpu/gpu_device.cc:1084] Created TensorFlow device (/job:localhost/replica:0/task:0/device:GPU:2 with 15163 MB memory) -> physical GPU (device: 2, name: Tesla P100-SXM2-16GB, pci bus id: 0006:01:00.0, compute capability: 6.0)
2019-08-02 10:47:51.775394: I tensorflow/core/common_runtime/gpu/gpu_device.cc:1084] Created TensorFlow device (/job:localhost/replica:0/task:0/device:GPU:3 with 15163 MB memory) -> physical GPU (device: 3, name: Tesla P100-SXM2-16GB, pci bus id: 0007:01:00.0, compute capability: 6.0)
=>> PBS: job killed: walltime 1823 exceeded limit 1800
[warn] Epoll ADD(4) on fd 0 failed.  Old events were 0; read change was 0 (none); write change was 1 (add): Bad file descriptor
[warn] Epoll ADD(4) on fd 308 failed.  Old events were 0; read change was 0 (none); write change was 1 (add): Bad file descriptor
[warn] Epoll ADD(4) on fd 302 failed.  Old events were 0; read change was 0 (none); write change was 1 (add): Bad file descriptor
[warn] Epoll ADD(4) on fd 342 failed.  Old events were 0; read change was 0 (none); write change was 1 (add): Bad file descriptor
[warn] Epoll ADD(4) on fd 298 failed.  Old events were 0; read change was 0 (none); write change was 1 (add): Bad file descriptor
[warn] Epoll ADD(4) on fd 299 failed.  Old events were 0; read change was 0 (none); write change was 1 (add): Bad file descriptor
[warn] Epoll ADD(4) on fd 324 failed.  Old events were 0; read change was 0 (none); write change was 1 (add): Bad file descriptor
[warn] Epoll ADD(4) on fd 312 failed.  Old events were 0; read change was 0 (none); write change was 1 (add): Bad file descriptor
[warn] Epoll ADD(4) on fd 334 failed.  Old events were 0; read change was 0 (none); write change was 1 (add): Bad file descriptor
[warn] Epoll ADD(4) on fd 316 failed.  Old events were 0; read change was 0 (none); write change was 1 (add): Bad file descriptor
[warn] Epoll ADD(4) on fd 373 failed.  Old events were 0; read change was 0 (none); write change was 1 (add): Bad file descriptor
[warn] Epoll ADD(4) on fd 347 failed.  Old events were 0; read change was 0 (none); write change was 1 (add): Bad file descriptor
[warn] Epoll ADD(4) on fd 379 failed.  Old events were 0; read change was 0 (none); write change was 1 (add): Bad file descriptor
[warn] Epoll ADD(4) on fd 332 failed.  Old events were 0; read change was 0 (none); write change was 1 (add): Bad file descriptor
[warn] Epoll ADD(4) on fd 362 failed.  Old events were 0; read change was 0 (none); write change was 1 (add): Bad file descriptor
[warn] Epoll ADD(4) on fd 385 failed.  Old events were 0; read change was 0 (none); write change was 1 (add): Bad file descriptor
[warn] Epoll ADD(4) on fd 315 failed.  Old events were 0; read change was 0 (none); write change was 1 (add): Bad file descriptor
[warn] Epoll ADD(4) on fd 296 failed.  Old events were 0; read change was 0 (none); write change was 1 (add): Bad file descriptor
[warn] Epoll ADD(4) on fd 300 failed.  Old events were 0; read change was 0 (none); write change was 1 (add): Bad file descriptor
[warn] Epoll ADD(4) on fd 297 failed.  Old events were 0; read change was 0 (none); write change was 1 (add): Bad file descriptor
[warn] Epoll ADD(4) on fd 289 failed.  Old events were 0; read change was 0 (none); write change was 1 (add): Bad file descriptor
[warn] Epoll ADD(4) on fd 341 failed.  Old events were 0; read change was 0 (none); write change was 1 (add): Bad file descriptor
[warn] Epoll ADD(4) on fd 351 failed.  Old events were 0; read change was 0 (none); write change was 1 (add): Bad file descriptor
[warn] Epoll ADD(4) on fd 343 failed.  Old events were 0; read change was 0 (none); write change was 1 (add): Bad file descriptor
[warn] Epoll ADD(4) on fd 280 failed.  Old events were 0; read change was 0 (none); write change was 1 (add): Bad file descriptor
[warn] Epoll ADD(4) on fd 374 failed.  Old events were 0; read change was 0 (none); write change was 1 (add): Bad file descriptor
[warn] Epoll ADD(4) on fd 301 failed.  Old events were 0; read change was 0 (none); write change was 1 (add): Bad file descriptor
[warn] Epoll ADD(4) on fd 309 failed.  Old events were 0; read change was 0 (none); write change was 1 (add): Bad file descriptor
[cr1cn06:55876] pmix_usock_msg_send_bytes: write failed: Broken pipe (32) [sd = 346]
