--------------------------------------------------------------------------
WARNING: There are more than one active ports on host 'cr2cn15', but the
default subnet GID prefix was detected on more than one of these
ports.  If these ports are connected to different physical IB
networks, this configuration will fail in Open MPI.  This version of
Open MPI requires that every physically separate IB subnet that is
used between connected MPI processes must have different subnet ID
values.

Please see this FAQ entry for more details:

  http://www.open-mpi.org/faq/?category=openfabrics#ofa-default-subnet-gid

NOTE: You can turn off this warning by setting the MCA parameter
      btl_openib_warn_default_gid_prefix to 0.
--------------------------------------------------------------------------
/gpfs/pkgs/mhpcc/anaconda3-5.0.1/lib/python3.6/site-packages/h5py/__init__.py:34: FutureWarning: Conversion of the second argument of issubdtype from `float` to `np.floating` is deprecated. In future, it will be treated as `np.float64 == np.dtype(float).type`.
  from ._conv import register_converters as _register_converters
Using TensorFlow backend.
/gpfs/pkgs/mhpcc/anaconda3-5.0.1/lib/python3.6/site-packages/h5py/__init__.py:34: FutureWarning: Conversion of the second argument of issubdtype from `float` to `np.floating` is deprecated. In future, it will be treated as `np.float64 == np.dtype(float).type`.
  from ._conv import register_converters as _register_converters
Using TensorFlow backend.
/gpfs/pkgs/mhpcc/anaconda3-5.0.1/lib/python3.6/site-packages/h5py/__init__.py:34: FutureWarning: Conversion of the second argument of issubdtype from `float` to `np.floating` is deprecated. In future, it will be treated as `np.float64 == np.dtype(float).type`.
  from ._conv import register_converters as _register_converters
Using TensorFlow backend.
/gpfs/pkgs/mhpcc/anaconda3-5.0.1/lib/python3.6/site-packages/h5py/__init__.py:34: FutureWarning: Conversion of the second argument of issubdtype from `float` to `np.floating` is deprecated. In future, it will be treated as `np.float64 == np.dtype(float).type`.
  from ._conv import register_converters as _register_converters
Using TensorFlow backend.
/gpfs/pkgs/mhpcc/anaconda3-5.0.1/lib/python3.6/site-packages/h5py/__init__.py:34: FutureWarning: Conversion of the second argument of issubdtype from `float` to `np.floating` is deprecated. In future, it will be treated as `np.float64 == np.dtype(float).type`.
  from ._conv import register_converters as _register_converters
Using TensorFlow backend.
/gpfs/pkgs/mhpcc/anaconda3-5.0.1/lib/python3.6/site-packages/h5py/__init__.py:34: FutureWarning: Conversion of the second argument of issubdtype from `float` to `np.floating` is deprecated. In future, it will be treated as `np.float64 == np.dtype(float).type`.
  from ._conv import register_converters as _register_converters
Using TensorFlow backend.
/gpfs/pkgs/mhpcc/anaconda3-5.0.1/lib/python3.6/site-packages/h5py/__init__.py:34: FutureWarning: Conversion of the second argument of issubdtype from `float` to `np.floating` is deprecated. In future, it will be treated as `np.float64 == np.dtype(float).type`.
  from ._conv import register_converters as _register_converters
Using TensorFlow backend.
/gpfs/pkgs/mhpcc/anaconda3-5.0.1/lib/python3.6/site-packages/h5py/__init__.py:34: FutureWarning: Conversion of the second argument of issubdtype from `float` to `np.floating` is deprecated. In future, it will be treated as `np.float64 == np.dtype(float).type`.
  from ._conv import register_converters as _register_converters
Using TensorFlow backend.
/gpfs/pkgs/mhpcc/anaconda3-5.0.1/lib/python3.6/site-packages/h5py/__init__.py:34: FutureWarning: Conversion of the second argument of issubdtype from `float` to `np.floating` is deprecated. In future, it will be treated as `np.float64 == np.dtype(float).type`.
  from ._conv import register_converters as _register_converters
Using TensorFlow backend.
/gpfs/pkgs/mhpcc/anaconda3-5.0.1/lib/python3.6/site-packages/h5py/__init__.py:34: FutureWarning: Conversion of the second argument of issubdtype from `float` to `np.floating` is deprecated. In future, it will be treated as `np.float64 == np.dtype(float).type`.
  from ._conv import register_converters as _register_converters
Using TensorFlow backend.
/gpfs/pkgs/mhpcc/anaconda3-5.0.1/lib/python3.6/site-packages/h5py/__init__.py:34: FutureWarning: Conversion of the second argument of issubdtype from `float` to `np.floating` is deprecated. In future, it will be treated as `np.float64 == np.dtype(float).type`.
  from ._conv import register_converters as _register_converters
Using TensorFlow backend.
/gpfs/pkgs/mhpcc/anaconda3-5.0.1/lib/python3.6/site-packages/h5py/__init__.py:34: FutureWarning: Conversion of the second argument of issubdtype from `float` to `np.floating` is deprecated. In future, it will be treated as `np.float64 == np.dtype(float).type`.
  from ._conv import register_converters as _register_converters
Using TensorFlow backend.
/gpfs/pkgs/mhpcc/anaconda3-5.0.1/lib/python3.6/site-packages/h5py/__init__.py:34: FutureWarning: Conversion of the second argument of issubdtype from `float` to `np.floating` is deprecated. In future, it will be treated as `np.float64 == np.dtype(float).type`.
  from ._conv import register_converters as _register_converters
Using TensorFlow backend.
/gpfs/pkgs/mhpcc/anaconda3-5.0.1/lib/python3.6/site-packages/h5py/__init__.py:34: FutureWarning: Conversion of the second argument of issubdtype from `float` to `np.floating` is deprecated. In future, it will be treated as `np.float64 == np.dtype(float).type`.
  from ._conv import register_converters as _register_converters
Using TensorFlow backend.
/gpfs/pkgs/mhpcc/anaconda3-5.0.1/lib/python3.6/site-packages/h5py/__init__.py:34: FutureWarning: Conversion of the second argument of issubdtype from `float` to `np.floating` is deprecated. In future, it will be treated as `np.float64 == np.dtype(float).type`.
  from ._conv import register_converters as _register_converters
Using TensorFlow backend.
2019-08-02 11:20:22.764472: E tensorflow/core/common_runtime/direct_session.cc:158] Internal: failed initializing StreamExecutor for CUDA device ordinal 0: Internal: failed call to cuDevicePrimaryCtxRetain: CUDA_ERROR_INVALID_DEVICE
/gpfs/pkgs/mhpcc/anaconda3-5.0.1/lib/python3.6/site-packages/h5py/__init__.py:34: FutureWarning: Conversion of the second argument of issubdtype from `float` to `np.floating` is deprecated. In future, it will be treated as `np.float64 == np.dtype(float).type`.
  from ._conv import register_converters as _register_converters
Using TensorFlow backend.
2019-08-02 11:20:22.876270: E tensorflow/core/common_runtime/direct_session.cc:158] Internal: failed initializing StreamExecutor for CUDA device ordinal 0: Internal: failed call to cuDevicePrimaryCtxRetain: CUDA_ERROR_INVALID_DEVICE
/gpfs/pkgs/mhpcc/anaconda3-5.0.1/lib/python3.6/site-packages/h5py/__init__.py:34: FutureWarning: Conversion of the second argument of issubdtype from `float` to `np.floating` is deprecated. In future, it will be treated as `np.float64 == np.dtype(float).type`.
  from ._conv import register_converters as _register_converters
Using TensorFlow backend.
2019-08-02 11:20:22.936314: E tensorflow/core/common_runtime/direct_session.cc:158] Internal: failed initializing StreamExecutor for CUDA device ordinal 0: Internal: failed call to cuDevicePrimaryCtxRetain: CUDA_ERROR_INVALID_DEVICE
/gpfs/pkgs/mhpcc/anaconda3-5.0.1/lib/python3.6/site-packages/h5py/__init__.py:34: FutureWarning: Conversion of the second argument of issubdtype from `float` to `np.floating` is deprecated. In future, it will be treated as `np.float64 == np.dtype(float).type`.
  from ._conv import register_converters as _register_converters
Using TensorFlow backend.
2019-08-02 11:20:22.945287: E tensorflow/core/common_runtime/direct_session.cc:158] Internal: failed initializing StreamExecutor for CUDA device ordinal 0: Internal: failed call to cuDevicePrimaryCtxRetain: CUDA_ERROR_INVALID_DEVICE
/gpfs/pkgs/mhpcc/anaconda3-5.0.1/lib/python3.6/site-packages/h5py/__init__.py:34: FutureWarning: Conversion of the second argument of issubdtype from `float` to `np.floating` is deprecated. In future, it will be treated as `np.float64 == np.dtype(float).type`.
  from ._conv import register_converters as _register_converters
Using TensorFlow backend.
2019-08-02 11:20:22.953793: E tensorflow/core/common_runtime/direct_session.cc:158] Internal: failed initializing StreamExecutor for CUDA device ordinal 0: Internal: failed call to cuDevicePrimaryCtxRetain: CUDA_ERROR_INVALID_DEVICE
/gpfs/pkgs/mhpcc/anaconda3-5.0.1/lib/python3.6/site-packages/h5py/__init__.py:34: FutureWarning: Conversion of the second argument of issubdtype from `float` to `np.floating` is deprecated. In future, it will be treated as `np.float64 == np.dtype(float).type`.
  from ._conv import register_converters as _register_converters
Using TensorFlow backend.
2019-08-02 11:20:23.040908: E tensorflow/core/common_runtime/direct_session.cc:158] Internal: failed initializing StreamExecutor for CUDA device ordinal 0: Internal: failed call to cuDevicePrimaryCtxRetain: CUDA_ERROR_INVALID_DEVICE
/gpfs/pkgs/mhpcc/anaconda3-5.0.1/lib/python3.6/site-packages/h5py/__init__.py:34: FutureWarning: Conversion of the second argument of issubdtype from `float` to `np.floating` is deprecated. In future, it will be treated as `np.float64 == np.dtype(float).type`.
  from ._conv import register_converters as _register_converters
Using TensorFlow backend.
2019-08-02 11:20:23.086873: E tensorflow/core/common_runtime/direct_session.cc:158] Internal: failed initializing StreamExecutor for CUDA device ordinal 0: Internal: failed call to cuDevicePrimaryCtxRetain: CUDA_ERROR_INVALID_DEVICE
/gpfs/pkgs/mhpcc/anaconda3-5.0.1/lib/python3.6/site-packages/h5py/__init__.py:34: FutureWarning: Conversion of the second argument of issubdtype from `float` to `np.floating` is deprecated. In future, it will be treated as `np.float64 == np.dtype(float).type`.
  from ._conv import register_converters as _register_converters
Using TensorFlow backend.
2019-08-02 11:20:23.099755: E tensorflow/core/common_runtime/direct_session.cc:158] Internal: failed initializing StreamExecutor for CUDA device ordinal 0: Internal: failed call to cuDevicePrimaryCtxRetain: CUDA_ERROR_INVALID_DEVICE
/gpfs/pkgs/mhpcc/anaconda3-5.0.1/lib/python3.6/site-packages/h5py/__init__.py:34: FutureWarning: Conversion of the second argument of issubdtype from `float` to `np.floating` is deprecated. In future, it will be treated as `np.float64 == np.dtype(float).type`.
  from ._conv import register_converters as _register_converters
Using TensorFlow backend.
2019-08-02 11:20:23.112701: E tensorflow/core/common_runtime/direct_session.cc:158] Internal: failed initializing StreamExecutor for CUDA device ordinal 0: Internal: failed call to cuDevicePrimaryCtxRetain: CUDA_ERROR_INVALID_DEVICE
/gpfs/pkgs/mhpcc/anaconda3-5.0.1/lib/python3.6/site-packages/h5py/__init__.py:34: FutureWarning: Conversion of the second argument of issubdtype from `float` to `np.floating` is deprecated. In future, it will be treated as `np.float64 == np.dtype(float).type`.
  from ._conv import register_converters as _register_converters
Using TensorFlow backend.
2019-08-02 11:20:23.124062: E tensorflow/core/common_runtime/direct_session.cc:158] Internal: failed initializing StreamExecutor for CUDA device ordinal 0: Internal: failed call to cuDevicePrimaryCtxRetain: CUDA_ERROR_INVALID_DEVICE
/gpfs/pkgs/mhpcc/anaconda3-5.0.1/lib/python3.6/site-packages/h5py/__init__.py:34: FutureWarning: Conversion of the second argument of issubdtype from `float` to `np.floating` is deprecated. In future, it will be treated as `np.float64 == np.dtype(float).type`.
  from ._conv import register_converters as _register_converters
Using TensorFlow backend.
2019-08-02 11:20:23.133440: I tensorflow/core/common_runtime/gpu/gpu_device.cc:1392] Found device 0 with properties: 
name: Tesla P100-SXM2-16GB major: 6 minor: 0 memoryClockRate(GHz): 1.4805
pciBusID: 0002:01:00.0
totalMemory: 15.90GiB freeMemory: 15.64GiB
Traceback (most recent call last):
  File "roundOneSubmit.py", line 23, in <module>
    l.learnThingsCPP(kind=0, file=f, weightFile=wf)
  File "/gpfs/home/m201560/chipboard/learn.py", line 130, in learnThingsCPP
    weights = self.getWeightArray()
  File "/gpfs/home/m201560/chipboard/learn.py", line 199, in getWeightArray
    return self.model.get_weights()[0].tolist()
  File "/gpfs/home/m201560/.local/lib/python3.6/site-packages/keras/engine/network.py", line 492, in get_weights
    return K.batch_get_value(weights)
  File "/gpfs/home/m201560/.local/lib/python3.6/site-packages/keras/backend/tensorflow_backend.py", line 2420, in batch_get_value
    return get_session().run(ops)
  File "/gpfs/home/m201560/.local/lib/python3.6/site-packages/keras/backend/tensorflow_backend.py", line 186, in get_session
    _SESSION = tf.Session(config=config)
  File "/gpfs/pkgs/mhpcc/anaconda3-5.0.1/lib/python3.6/site-packages/tensorflow/python/client/session.py", line 1563, in __init__
    super(Session, self).__init__(target, graph, config=config)
  File "/gpfs/pkgs/mhpcc/anaconda3-5.0.1/lib/python3.6/site-packages/tensorflow/python/client/session.py", line 633, in __init__
    self._session = tf_session.TF_NewSession(self._graph._c_graph, opts)
tensorflow.python.framework.errors_impl.InternalError: Failed to create session.
Traceback (most recent call last):
  File "roundOneSubmit.py", line 23, in <module>
    l.learnThingsCPP(kind=0, file=f, weightFile=wf)
  File "/gpfs/home/m201560/chipboard/learn.py", line 130, in learnThingsCPP
    weights = self.getWeightArray()
  File "/gpfs/home/m201560/chipboard/learn.py", line 199, in getWeightArray
    return self.model.get_weights()[0].tolist()
  File "/gpfs/home/m201560/.local/lib/python3.6/site-packages/keras/engine/network.py", line 492, in get_weights
    return K.batch_get_value(weights)
  File "/gpfs/home/m201560/.local/lib/python3.6/site-packages/keras/backend/tensorflow_backend.py", line 2420, in batch_get_value
    return get_session().run(ops)
  File "/gpfs/home/m201560/.local/lib/python3.6/site-packages/keras/backend/tensorflow_backend.py", line 186, in get_session
    _SESSION = tf.Session(config=config)
  File "/gpfs/pkgs/mhpcc/anaconda3-5.0.1/lib/python3.6/site-packages/tensorflow/python/client/session.py", line 1563, in __init__
    super(Session, self).__init__(target, graph, config=config)
  File "/gpfs/pkgs/mhpcc/anaconda3-5.0.1/lib/python3.6/site-packages/tensorflow/python/client/session.py", line 633, in __init__
    self._session = tf_session.TF_NewSession(self._graph._c_graph, opts)
tensorflow.python.framework.errors_impl.InternalError: Failed to create session.
Traceback (most recent call last):
  File "roundOneSubmit.py", line 23, in <module>
    l.learnThingsCPP(kind=0, file=f, weightFile=wf)
  File "/gpfs/home/m201560/chipboard/learn.py", line 130, in learnThingsCPP
    weights = self.getWeightArray()
  File "/gpfs/home/m201560/chipboard/learn.py", line 199, in getWeightArray
    return self.model.get_weights()[0].tolist()
  File "/gpfs/home/m201560/.local/lib/python3.6/site-packages/keras/engine/network.py", line 492, in get_weights
    return K.batch_get_value(weights)
  File "/gpfs/home/m201560/.local/lib/python3.6/site-packages/keras/backend/tensorflow_backend.py", line 2420, in batch_get_value
    return get_session().run(ops)
  File "/gpfs/home/m201560/.local/lib/python3.6/site-packages/keras/backend/tensorflow_backend.py", line 186, in get_session
    _SESSION = tf.Session(config=config)
  File "/gpfs/pkgs/mhpcc/anaconda3-5.0.1/lib/python3.6/site-packages/tensorflow/python/client/session.py", line 1563, in __init__
    super(Session, self).__init__(target, graph, config=config)
  File "/gpfs/pkgs/mhpcc/anaconda3-5.0.1/lib/python3.6/site-packages/tensorflow/python/client/session.py", line 633, in __init__
    self._session = tf_session.TF_NewSession(self._graph._c_graph, opts)
tensorflow.python.framework.errors_impl.InternalError: Failed to create session.
Traceback (most recent call last):
  File "roundOneSubmit.py", line 23, in <module>
    l.learnThingsCPP(kind=0, file=f, weightFile=wf)
  File "/gpfs/home/m201560/chipboard/learn.py", line 130, in learnThingsCPP
    weights = self.getWeightArray()
  File "/gpfs/home/m201560/chipboard/learn.py", line 199, in getWeightArray
    return self.model.get_weights()[0].tolist()
  File "/gpfs/home/m201560/.local/lib/python3.6/site-packages/keras/engine/network.py", line 492, in get_weights
    return K.batch_get_value(weights)
  File "/gpfs/home/m201560/.local/lib/python3.6/site-packages/keras/backend/tensorflow_backend.py", line 2420, in batch_get_value
    return get_session().run(ops)
  File "/gpfs/home/m201560/.local/lib/python3.6/site-packages/keras/backend/tensorflow_backend.py", line 186, in get_session
    _SESSION = tf.Session(config=config)
  File "/gpfs/pkgs/mhpcc/anaconda3-5.0.1/lib/python3.6/site-packages/tensorflow/python/client/session.py", line 1563, in __init__
    super(Session, self).__init__(target, graph, config=config)
  File "/gpfs/pkgs/mhpcc/anaconda3-5.0.1/lib/python3.6/site-packages/tensorflow/python/client/session.py", line 633, in __init__
    self._session = tf_session.TF_NewSession(self._graph._c_graph, opts)
tensorflow.python.framework.errors_impl.InternalError: Failed to create session.
Traceback (most recent call last):
  File "roundOneSubmit.py", line 23, in <module>
    l.learnThingsCPP(kind=0, file=f, weightFile=wf)
  File "/gpfs/home/m201560/chipboard/learn.py", line 130, in learnThingsCPP
    weights = self.getWeightArray()
  File "/gpfs/home/m201560/chipboard/learn.py", line 199, in getWeightArray
    return self.model.get_weights()[0].tolist()
  File "/gpfs/home/m201560/.local/lib/python3.6/site-packages/keras/engine/network.py", line 492, in get_weights
    return K.batch_get_value(weights)
  File "/gpfs/home/m201560/.local/lib/python3.6/site-packages/keras/backend/tensorflow_backend.py", line 2420, in batch_get_value
    return get_session().run(ops)
  File "/gpfs/home/m201560/.local/lib/python3.6/site-packages/keras/backend/tensorflow_backend.py", line 186, in get_session
    _SESSION = tf.Session(config=config)
  File "/gpfs/pkgs/mhpcc/anaconda3-5.0.1/lib/python3.6/site-packages/tensorflow/python/client/session.py", line 1563, in __init__
    super(Session, self).__init__(target, graph, config=config)
  File "/gpfs/pkgs/mhpcc/anaconda3-5.0.1/lib/python3.6/site-packages/tensorflow/python/client/session.py", line 633, in __init__
    self._session = tf_session.TF_NewSession(self._graph._c_graph, opts)
tensorflow.python.framework.errors_impl.InternalError: Failed to create session.
2019-08-02 11:20:23.230770: E tensorflow/core/common_runtime/direct_session.cc:158] Internal: failed initializing StreamExecutor for CUDA device ordinal 0: Internal: failed call to cuDevicePrimaryCtxRetain: CUDA_ERROR_INVALID_DEVICE
/gpfs/pkgs/mhpcc/anaconda3-5.0.1/lib/python3.6/site-packages/h5py/__init__.py:34: FutureWarning: Conversion of the second argument of issubdtype from `float` to `np.floating` is deprecated. In future, it will be treated as `np.float64 == np.dtype(float).type`.
  from ._conv import register_converters as _register_converters
Using TensorFlow backend.
Traceback (most recent call last):
  File "roundOneSubmit.py", line 23, in <module>
    l.learnThingsCPP(kind=0, file=f, weightFile=wf)
  File "/gpfs/home/m201560/chipboard/learn.py", line 130, in learnThingsCPP
    weights = self.getWeightArray()
  File "/gpfs/home/m201560/chipboard/learn.py", line 199, in getWeightArray
    return self.model.get_weights()[0].tolist()
  File "/gpfs/home/m201560/.local/lib/python3.6/site-packages/keras/engine/network.py", line 492, in get_weights
    return K.batch_get_value(weights)
  File "/gpfs/home/m201560/.local/lib/python3.6/site-packages/keras/backend/tensorflow_backend.py", line 2420, in batch_get_value
    return get_session().run(ops)
  File "/gpfs/home/m201560/.local/lib/python3.6/site-packages/keras/backend/tensorflow_backend.py", line 186, in get_session
    _SESSION = tf.Session(config=config)
  File "/gpfs/pkgs/mhpcc/anaconda3-5.0.1/lib/python3.6/site-packages/tensorflow/python/client/session.py", line 1563, in __init__
    super(Session, self).__init__(target, graph, config=config)
  File "/gpfs/pkgs/mhpcc/anaconda3-5.0.1/lib/python3.6/site-packages/tensorflow/python/client/session.py", line 633, in __init__
    self._session = tf_session.TF_NewSession(self._graph._c_graph, opts)
tensorflow.python.framework.errors_impl.InternalError: Failed to create session.
2019-08-02 11:20:23.260937: E tensorflow/core/common_runtime/direct_session.cc:158] Internal: failed initializing StreamExecutor for CUDA device ordinal 0: Internal: failed call to cuDevicePrimaryCtxRetain: CUDA_ERROR_INVALID_DEVICE
/gpfs/pkgs/mhpcc/anaconda3-5.0.1/lib/python3.6/site-packages/h5py/__init__.py:34: FutureWarning: Conversion of the second argument of issubdtype from `float` to `np.floating` is deprecated. In future, it will be treated as `np.float64 == np.dtype(float).type`.
  from ._conv import register_converters as _register_converters
Using TensorFlow backend.
Traceback (most recent call last):
  File "roundOneSubmit.py", line 23, in <module>
    l.learnThingsCPP(kind=0, file=f, weightFile=wf)
  File "/gpfs/home/m201560/chipboard/learn.py", line 130, in learnThingsCPP
    weights = self.getWeightArray()
  File "/gpfs/home/m201560/chipboard/learn.py", line 199, in getWeightArray
    return self.model.get_weights()[0].tolist()
  File "/gpfs/home/m201560/.local/lib/python3.6/site-packages/keras/engine/network.py", line 492, in get_weights
    return K.batch_get_value(weights)
  File "/gpfs/home/m201560/.local/lib/python3.6/site-packages/keras/backend/tensorflow_backend.py", line 2420, in batch_get_value
    return get_session().run(ops)
  File "/gpfs/home/m201560/.local/lib/python3.6/site-packages/keras/backend/tensorflow_backend.py", line 186, in get_session
    _SESSION = tf.Session(config=config)
  File "/gpfs/pkgs/mhpcc/anaconda3-5.0.1/lib/python3.6/site-packages/tensorflow/python/client/session.py", line 1563, in __init__
    super(Session, self).__init__(target, graph, config=config)
  File "/gpfs/pkgs/mhpcc/anaconda3-5.0.1/lib/python3.6/site-packages/tensorflow/python/client/session.py", line 633, in __init__
    self._session = tf_session.TF_NewSession(self._graph._c_graph, opts)
tensorflow.python.framework.errors_impl.InternalError: Failed to create session.
2019-08-02 11:20:23.311089: E tensorflow/core/common_runtime/direct_session.cc:158] Internal: failed initializing StreamExecutor for CUDA device ordinal 0: Internal: failed call to cuDevicePrimaryCtxRetain: CUDA_ERROR_INVALID_DEVICE
/gpfs/pkgs/mhpcc/anaconda3-5.0.1/lib/python3.6/site-packages/h5py/__init__.py:34: FutureWarning: Conversion of the second argument of issubdtype from `float` to `np.floating` is deprecated. In future, it will be treated as `np.float64 == np.dtype(float).type`.
  from ._conv import register_converters as _register_converters
Using TensorFlow backend.
Traceback (most recent call last):
  File "roundOneSubmit.py", line 23, in <module>
    l.learnThingsCPP(kind=0, file=f, weightFile=wf)
  File "/gpfs/home/m201560/chipboard/learn.py", line 130, in learnThingsCPP
    weights = self.getWeightArray()
  File "/gpfs/home/m201560/chipboard/learn.py", line 199, in getWeightArray
    return self.model.get_weights()[0].tolist()
  File "/gpfs/home/m201560/.local/lib/python3.6/site-packages/keras/engine/network.py", line 492, in get_weights
    return K.batch_get_value(weights)
  File "/gpfs/home/m201560/.local/lib/python3.6/site-packages/keras/backend/tensorflow_backend.py", line 2420, in batch_get_value
    return get_session().run(ops)
  File "/gpfs/home/m201560/.local/lib/python3.6/site-packages/keras/backend/tensorflow_backend.py", line 186, in get_session
    _SESSION = tf.Session(config=config)
  File "/gpfs/pkgs/mhpcc/anaconda3-5.0.1/lib/python3.6/site-packages/tensorflow/python/client/session.py", line 1563, in __init__
    super(Session, self).__init__(target, graph, config=config)
  File "/gpfs/pkgs/mhpcc/anaconda3-5.0.1/lib/python3.6/site-packages/tensorflow/python/client/session.py", line 633, in __init__
    self._session = tf_session.TF_NewSession(self._graph._c_graph, opts)
tensorflow.python.framework.errors_impl.InternalError: Failed to create session.
Traceback (most recent call last):
  File "roundOneSubmit.py", line 23, in <module>
    l.learnThingsCPP(kind=0, file=f, weightFile=wf)
  File "/gpfs/home/m201560/chipboard/learn.py", line 130, in learnThingsCPP
    weights = self.getWeightArray()
  File "/gpfs/home/m201560/chipboard/learn.py", line 199, in getWeightArray
    return self.model.get_weights()[0].tolist()
  File "/gpfs/home/m201560/.local/lib/python3.6/site-packages/keras/engine/network.py", line 492, in get_weights
    return K.batch_get_value(weights)
  File "/gpfs/home/m201560/.local/lib/python3.6/site-packages/keras/backend/tensorflow_backend.py", line 2420, in batch_get_value
    return get_session().run(ops)
  File "/gpfs/home/m201560/.local/lib/python3.6/site-packages/keras/backend/tensorflow_backend.py", line 186, in get_session
    _SESSION = tf.Session(config=config)
  File "/gpfs/pkgs/mhpcc/anaconda3-5.0.1/lib/python3.6/site-packages/tensorflow/python/client/session.py", line 1563, in __init__
    super(Session, self).__init__(target, graph, config=config)
  File "/gpfs/pkgs/mhpcc/anaconda3-5.0.1/lib/python3.6/site-packages/tensorflow/python/client/session.py", line 633, in __init__
    self._session = tf_session.TF_NewSession(self._graph._c_graph, opts)
tensorflow.python.framework.errors_impl.InternalError: Failed to create session.
2019-08-02 11:20:23.342752: E tensorflow/core/common_runtime/direct_session.cc:158] Internal: failed initializing StreamExecutor for CUDA device ordinal 0: Internal: failed call to cuDevicePrimaryCtxRetain: CUDA_ERROR_INVALID_DEVICE
/gpfs/pkgs/mhpcc/anaconda3-5.0.1/lib/python3.6/site-packages/h5py/__init__.py:34: FutureWarning: Conversion of the second argument of issubdtype from `float` to `np.floating` is deprecated. In future, it will be treated as `np.float64 == np.dtype(float).type`.
  from ._conv import register_converters as _register_converters
Using TensorFlow backend.
Traceback (most recent call last):
  File "roundOneSubmit.py", line 23, in <module>
    l.learnThingsCPP(kind=0, file=f, weightFile=wf)
  File "/gpfs/home/m201560/chipboard/learn.py", line 130, in learnThingsCPP
    weights = self.getWeightArray()
  File "/gpfs/home/m201560/chipboard/learn.py", line 199, in getWeightArray
    return self.model.get_weights()[0].tolist()
  File "/gpfs/home/m201560/.local/lib/python3.6/site-packages/keras/engine/network.py", line 492, in get_weights
    return K.batch_get_value(weights)
  File "/gpfs/home/m201560/.local/lib/python3.6/site-packages/keras/backend/tensorflow_backend.py", line 2420, in batch_get_value
    return get_session().run(ops)
  File "/gpfs/home/m201560/.local/lib/python3.6/site-packages/keras/backend/tensorflow_backend.py", line 186, in get_session
    _SESSION = tf.Session(config=config)
  File "/gpfs/pkgs/mhpcc/anaconda3-5.0.1/lib/python3.6/site-packages/tensorflow/python/client/session.py", line 1563, in __init__
    super(Session, self).__init__(target, graph, config=config)
  File "/gpfs/pkgs/mhpcc/anaconda3-5.0.1/lib/python3.6/site-packages/tensorflow/python/client/session.py", line 633, in __init__
    self._session = tf_session.TF_NewSession(self._graph._c_graph, opts)
tensorflow.python.framework.errors_impl.InternalError: Failed to create session.
2019-08-02 11:20:23.367073: E tensorflow/core/common_runtime/direct_session.cc:158] Internal: failed initializing StreamExecutor for CUDA device ordinal 0: Internal: failed call to cuDevicePrimaryCtxRetain: CUDA_ERROR_INVALID_DEVICE
/gpfs/pkgs/mhpcc/anaconda3-5.0.1/lib/python3.6/site-packages/h5py/__init__.py:34: FutureWarning: Conversion of the second argument of issubdtype from `float` to `np.floating` is deprecated. In future, it will be treated as `np.float64 == np.dtype(float).type`.
  from ._conv import register_converters as _register_converters
Using TensorFlow backend.
Traceback (most recent call last):
  File "roundOneSubmit.py", line 23, in <module>
    l.learnThingsCPP(kind=0, file=f, weightFile=wf)
  File "/gpfs/home/m201560/chipboard/learn.py", line 130, in learnThingsCPP
    weights = self.getWeightArray()
  File "/gpfs/home/m201560/chipboard/learn.py", line 199, in getWeightArray
    return self.model.get_weights()[0].tolist()
  File "/gpfs/home/m201560/.local/lib/python3.6/site-packages/keras/engine/network.py", line 492, in get_weights
    return K.batch_get_value(weights)
  File "/gpfs/home/m201560/.local/lib/python3.6/site-packages/keras/backend/tensorflow_backend.py", line 2420, in batch_get_value
    return get_session().run(ops)
  File "/gpfs/home/m201560/.local/lib/python3.6/site-packages/keras/backend/tensorflow_backend.py", line 186, in get_session
    _SESSION = tf.Session(config=config)
  File "/gpfs/pkgs/mhpcc/anaconda3-5.0.1/lib/python3.6/site-packages/tensorflow/python/client/session.py", line 1563, in __init__
    super(Session, self).__init__(target, graph, config=config)
  File "/gpfs/pkgs/mhpcc/anaconda3-5.0.1/lib/python3.6/site-packages/tensorflow/python/client/session.py", line 633, in __init__
    self._session = tf_session.TF_NewSession(self._graph._c_graph, opts)
tensorflow.python.framework.errors_impl.InternalError: Failed to create session.
2019-08-02 11:20:23.399879: I tensorflow/core/common_runtime/gpu/gpu_device.cc:1392] Found device 1 with properties: 
name: Tesla P100-SXM2-16GB major: 6 minor: 0 memoryClockRate(GHz): 1.4805
pciBusID: 0003:01:00.0
totalMemory: 15.90GiB freeMemory: 15.64GiB
2019-08-02 11:20:23.422903: E tensorflow/core/common_runtime/direct_session.cc:158] Internal: failed initializing StreamExecutor for CUDA device ordinal 0: Internal: failed call to cuDevicePrimaryCtxRetain: CUDA_ERROR_INVALID_DEVICE
/gpfs/pkgs/mhpcc/anaconda3-5.0.1/lib/python3.6/site-packages/h5py/__init__.py:34: FutureWarning: Conversion of the second argument of issubdtype from `float` to `np.floating` is deprecated. In future, it will be treated as `np.float64 == np.dtype(float).type`.
  from ._conv import register_converters as _register_converters
Using TensorFlow backend.
Traceback (most recent call last):
  File "roundOneSubmit.py", line 23, in <module>
    l.learnThingsCPP(kind=0, file=f, weightFile=wf)
  File "/gpfs/home/m201560/chipboard/learn.py", line 130, in learnThingsCPP
    weights = self.getWeightArray()
  File "/gpfs/home/m201560/chipboard/learn.py", line 199, in getWeightArray
    return self.model.get_weights()[0].tolist()
  File "/gpfs/home/m201560/.local/lib/python3.6/site-packages/keras/engine/network.py", line 492, in get_weights
    return K.batch_get_value(weights)
  File "/gpfs/home/m201560/.local/lib/python3.6/site-packages/keras/backend/tensorflow_backend.py", line 2420, in batch_get_value
    return get_session().run(ops)
  File "/gpfs/home/m201560/.local/lib/python3.6/site-packages/keras/backend/tensorflow_backend.py", line 186, in get_session
    _SESSION = tf.Session(config=config)
  File "/gpfs/pkgs/mhpcc/anaconda3-5.0.1/lib/python3.6/site-packages/tensorflow/python/client/session.py", line 1563, in __init__
    super(Session, self).__init__(target, graph, config=config)
  File "/gpfs/pkgs/mhpcc/anaconda3-5.0.1/lib/python3.6/site-packages/tensorflow/python/client/session.py", line 633, in __init__
    self._session = tf_session.TF_NewSession(self._graph._c_graph, opts)
tensorflow.python.framework.errors_impl.InternalError: Failed to create session.
2019-08-02 11:20:23.450893: E tensorflow/core/common_runtime/direct_session.cc:158] Internal: failed initializing StreamExecutor for CUDA device ordinal 0: Internal: failed call to cuDevicePrimaryCtxRetain: CUDA_ERROR_INVALID_DEVICE
/gpfs/pkgs/mhpcc/anaconda3-5.0.1/lib/python3.6/site-packages/h5py/__init__.py:34: FutureWarning: Conversion of the second argument of issubdtype from `float` to `np.floating` is deprecated. In future, it will be treated as `np.float64 == np.dtype(float).type`.
  from ._conv import register_converters as _register_converters
Using TensorFlow backend.
Traceback (most recent call last):
  File "roundOneSubmit.py", line 23, in <module>
    l.learnThingsCPP(kind=0, file=f, weightFile=wf)
  File "/gpfs/home/m201560/chipboard/learn.py", line 130, in learnThingsCPP
    weights = self.getWeightArray()
  File "/gpfs/home/m201560/chipboard/learn.py", line 199, in getWeightArray
    return self.model.get_weights()[0].tolist()
  File "/gpfs/home/m201560/.local/lib/python3.6/site-packages/keras/engine/network.py", line 492, in get_weights
    return K.batch_get_value(weights)
  File "/gpfs/home/m201560/.local/lib/python3.6/site-packages/keras/backend/tensorflow_backend.py", line 2420, in batch_get_value
    return get_session().run(ops)
  File "/gpfs/home/m201560/.local/lib/python3.6/site-packages/keras/backend/tensorflow_backend.py", line 186, in get_session
    _SESSION = tf.Session(config=config)
  File "/gpfs/pkgs/mhpcc/anaconda3-5.0.1/lib/python3.6/site-packages/tensorflow/python/client/session.py", line 1563, in __init__
    super(Session, self).__init__(target, graph, config=config)
  File "/gpfs/pkgs/mhpcc/anaconda3-5.0.1/lib/python3.6/site-packages/tensorflow/python/client/session.py", line 633, in __init__
    self._session = tf_session.TF_NewSession(self._graph._c_graph, opts)
tensorflow.python.framework.errors_impl.InternalError: Failed to create session.
2019-08-02 11:20:23.457987: E tensorflow/core/common_runtime/direct_session.cc:158] Internal: failed initializing StreamExecutor for CUDA device ordinal 0: Internal: failed call to cuDevicePrimaryCtxRetain: CUDA_ERROR_INVALID_DEVICE
/gpfs/pkgs/mhpcc/anaconda3-5.0.1/lib/python3.6/site-packages/h5py/__init__.py:34: FutureWarning: Conversion of the second argument of issubdtype from `float` to `np.floating` is deprecated. In future, it will be treated as `np.float64 == np.dtype(float).type`.
  from ._conv import register_converters as _register_converters
Using TensorFlow backend.
2019-08-02 11:20:23.459518: E tensorflow/core/common_runtime/direct_session.cc:158] Internal: failed initializing StreamExecutor for CUDA device ordinal 0: Internal: failed call to cuDevicePrimaryCtxRetain: CUDA_ERROR_INVALID_DEVICE
/gpfs/pkgs/mhpcc/anaconda3-5.0.1/lib/python3.6/site-packages/h5py/__init__.py:34: FutureWarning: Conversion of the second argument of issubdtype from `float` to `np.floating` is deprecated. In future, it will be treated as `np.float64 == np.dtype(float).type`.
  from ._conv import register_converters as _register_converters
Using TensorFlow backend.
Traceback (most recent call last):
  File "roundOneSubmit.py", line 23, in <module>
    l.learnThingsCPP(kind=0, file=f, weightFile=wf)
  File "/gpfs/home/m201560/chipboard/learn.py", line 130, in learnThingsCPP
    weights = self.getWeightArray()
  File "/gpfs/home/m201560/chipboard/learn.py", line 199, in getWeightArray
    return self.model.get_weights()[0].tolist()
  File "/gpfs/home/m201560/.local/lib/python3.6/site-packages/keras/engine/network.py", line 492, in get_weights
    return K.batch_get_value(weights)
  File "/gpfs/home/m201560/.local/lib/python3.6/site-packages/keras/backend/tensorflow_backend.py", line 2420, in batch_get_value
    return get_session().run(ops)
  File "/gpfs/home/m201560/.local/lib/python3.6/site-packages/keras/backend/tensorflow_backend.py", line 186, in get_session
    _SESSION = tf.Session(config=config)
  File "/gpfs/pkgs/mhpcc/anaconda3-5.0.1/lib/python3.6/site-packages/tensorflow/python/client/session.py", line 1563, in __init__
    super(Session, self).__init__(target, graph, config=config)
  File "/gpfs/pkgs/mhpcc/anaconda3-5.0.1/lib/python3.6/site-packages/tensorflow/python/client/session.py", line 633, in __init__
    self._session = tf_session.TF_NewSession(self._graph._c_graph, opts)
tensorflow.python.framework.errors_impl.InternalError: Failed to create session.
Traceback (most recent call last):
  File "roundOneSubmit.py", line 23, in <module>
    l.learnThingsCPP(kind=0, file=f, weightFile=wf)
  File "/gpfs/home/m201560/chipboard/learn.py", line 130, in learnThingsCPP
    weights = self.getWeightArray()
  File "/gpfs/home/m201560/chipboard/learn.py", line 199, in getWeightArray
    return self.model.get_weights()[0].tolist()
  File "/gpfs/home/m201560/.local/lib/python3.6/site-packages/keras/engine/network.py", line 492, in get_weights
    return K.batch_get_value(weights)
  File "/gpfs/home/m201560/.local/lib/python3.6/site-packages/keras/backend/tensorflow_backend.py", line 2420, in batch_get_value
    return get_session().run(ops)
  File "/gpfs/home/m201560/.local/lib/python3.6/site-packages/keras/backend/tensorflow_backend.py", line 186, in get_session
    _SESSION = tf.Session(config=config)
  File "/gpfs/pkgs/mhpcc/anaconda3-5.0.1/lib/python3.6/site-packages/tensorflow/python/client/session.py", line 1563, in __init__
    super(Session, self).__init__(target, graph, config=config)
  File "/gpfs/pkgs/mhpcc/anaconda3-5.0.1/lib/python3.6/site-packages/tensorflow/python/client/session.py", line 633, in __init__
    self._session = tf_session.TF_NewSession(self._graph._c_graph, opts)
tensorflow.python.framework.errors_impl.InternalError: Failed to create session.
Traceback (most recent call last):
  File "roundOneSubmit.py", line 23, in <module>
    l.learnThingsCPP(kind=0, file=f, weightFile=wf)
  File "/gpfs/home/m201560/chipboard/learn.py", line 130, in learnThingsCPP
    weights = self.getWeightArray()
  File "/gpfs/home/m201560/chipboard/learn.py", line 199, in getWeightArray
    return self.model.get_weights()[0].tolist()
  File "/gpfs/home/m201560/.local/lib/python3.6/site-packages/keras/engine/network.py", line 492, in get_weights
    return K.batch_get_value(weights)
  File "/gpfs/home/m201560/.local/lib/python3.6/site-packages/keras/backend/tensorflow_backend.py", line 2420, in batch_get_value
    return get_session().run(ops)
  File "/gpfs/home/m201560/.local/lib/python3.6/site-packages/keras/backend/tensorflow_backend.py", line 186, in get_session
    _SESSION = tf.Session(config=config)
  File "/gpfs/pkgs/mhpcc/anaconda3-5.0.1/lib/python3.6/site-packages/tensorflow/python/client/session.py", line 1563, in __init__
    super(Session, self).__init__(target, graph, config=config)
  File "/gpfs/pkgs/mhpcc/anaconda3-5.0.1/lib/python3.6/site-packages/tensorflow/python/client/session.py", line 633, in __init__
    self._session = tf_session.TF_NewSession(self._graph._c_graph, opts)
tensorflow.python.framework.errors_impl.InternalError: Failed to create session.
2019-08-02 11:20:23.561627: E tensorflow/core/common_runtime/direct_session.cc:158] Internal: failed initializing StreamExecutor for CUDA device ordinal 0: Internal: failed call to cuDevicePrimaryCtxRetain: CUDA_ERROR_INVALID_DEVICE
/gpfs/pkgs/mhpcc/anaconda3-5.0.1/lib/python3.6/site-packages/h5py/__init__.py:34: FutureWarning: Conversion of the second argument of issubdtype from `float` to `np.floating` is deprecated. In future, it will be treated as `np.float64 == np.dtype(float).type`.
  from ._conv import register_converters as _register_converters
Using TensorFlow backend.
Traceback (most recent call last):
  File "roundOneSubmit.py", line 23, in <module>
    l.learnThingsCPP(kind=0, file=f, weightFile=wf)
  File "/gpfs/home/m201560/chipboard/learn.py", line 130, in learnThingsCPP
    weights = self.getWeightArray()
  File "/gpfs/home/m201560/chipboard/learn.py", line 199, in getWeightArray
    return self.model.get_weights()[0].tolist()
  File "/gpfs/home/m201560/.local/lib/python3.6/site-packages/keras/engine/network.py", line 492, in get_weights
    return K.batch_get_value(weights)
  File "/gpfs/home/m201560/.local/lib/python3.6/site-packages/keras/backend/tensorflow_backend.py", line 2420, in batch_get_value
    return get_session().run(ops)
  File "/gpfs/home/m201560/.local/lib/python3.6/site-packages/keras/backend/tensorflow_backend.py", line 186, in get_session
    _SESSION = tf.Session(config=config)
  File "/gpfs/pkgs/mhpcc/anaconda3-5.0.1/lib/python3.6/site-packages/tensorflow/python/client/session.py", line 1563, in __init__
    super(Session, self).__init__(target, graph, config=config)
  File "/gpfs/pkgs/mhpcc/anaconda3-5.0.1/lib/python3.6/site-packages/tensorflow/python/client/session.py", line 633, in __init__
    self._session = tf_session.TF_NewSession(self._graph._c_graph, opts)
tensorflow.python.framework.errors_impl.InternalError: Failed to create session.
2019-08-02 11:20:23.584424: E tensorflow/core/common_runtime/direct_session.cc:158] Internal: failed initializing StreamExecutor for CUDA device ordinal 0: Internal: failed call to cuDevicePrimaryCtxRetain: CUDA_ERROR_INVALID_DEVICE
/gpfs/pkgs/mhpcc/anaconda3-5.0.1/lib/python3.6/site-packages/h5py/__init__.py:34: FutureWarning: Conversion of the second argument of issubdtype from `float` to `np.floating` is deprecated. In future, it will be treated as `np.float64 == np.dtype(float).type`.
  from ._conv import register_converters as _register_converters
Using TensorFlow backend.
Traceback (most recent call last):
  File "roundOneSubmit.py", line 23, in <module>
    l.learnThingsCPP(kind=0, file=f, weightFile=wf)
  File "/gpfs/home/m201560/chipboard/learn.py", line 130, in learnThingsCPP
    weights = self.getWeightArray()
  File "/gpfs/home/m201560/chipboard/learn.py", line 199, in getWeightArray
    return self.model.get_weights()[0].tolist()
  File "/gpfs/home/m201560/.local/lib/python3.6/site-packages/keras/engine/network.py", line 492, in get_weights
    return K.batch_get_value(weights)
  File "/gpfs/home/m201560/.local/lib/python3.6/site-packages/keras/backend/tensorflow_backend.py", line 2420, in batch_get_value
    return get_session().run(ops)
  File "/gpfs/home/m201560/.local/lib/python3.6/site-packages/keras/backend/tensorflow_backend.py", line 186, in get_session
    _SESSION = tf.Session(config=config)
  File "/gpfs/pkgs/mhpcc/anaconda3-5.0.1/lib/python3.6/site-packages/tensorflow/python/client/session.py", line 1563, in __init__
    super(Session, self).__init__(target, graph, config=config)
  File "/gpfs/pkgs/mhpcc/anaconda3-5.0.1/lib/python3.6/site-packages/tensorflow/python/client/session.py", line 633, in __init__
    self._session = tf_session.TF_NewSession(self._graph._c_graph, opts)
tensorflow.python.framework.errors_impl.InternalError: Failed to create session.
2019-08-02 11:20:23.599180: E tensorflow/core/common_runtime/direct_session.cc:158] Internal: failed initializing StreamExecutor for CUDA device ordinal 0: Internal: failed call to cuDevicePrimaryCtxRetain: CUDA_ERROR_INVALID_DEVICE
/gpfs/pkgs/mhpcc/anaconda3-5.0.1/lib/python3.6/site-packages/h5py/__init__.py:34: FutureWarning: Conversion of the second argument of issubdtype from `float` to `np.floating` is deprecated. In future, it will be treated as `np.float64 == np.dtype(float).type`.
  from ._conv import register_converters as _register_converters
Using TensorFlow backend.
2019-08-02 11:20:23.601613: E tensorflow/core/common_runtime/direct_session.cc:158] Internal: failed initializing StreamExecutor for CUDA device ordinal 0: Internal: failed call to cuDevicePrimaryCtxRetain: CUDA_ERROR_INVALID_DEVICE
/gpfs/pkgs/mhpcc/anaconda3-5.0.1/lib/python3.6/site-packages/h5py/__init__.py:34: FutureWarning: Conversion of the second argument of issubdtype from `float` to `np.floating` is deprecated. In future, it will be treated as `np.float64 == np.dtype(float).type`.
  from ._conv import register_converters as _register_converters
Using TensorFlow backend.
Traceback (most recent call last):
  File "roundOneSubmit.py", line 23, in <module>
    l.learnThingsCPP(kind=0, file=f, weightFile=wf)
  File "/gpfs/home/m201560/chipboard/learn.py", line 130, in learnThingsCPP
    weights = self.getWeightArray()
  File "/gpfs/home/m201560/chipboard/learn.py", line 199, in getWeightArray
    return self.model.get_weights()[0].tolist()
  File "/gpfs/home/m201560/.local/lib/python3.6/site-packages/keras/engine/network.py", line 492, in get_weights
    return K.batch_get_value(weights)
  File "/gpfs/home/m201560/.local/lib/python3.6/site-packages/keras/backend/tensorflow_backend.py", line 2420, in batch_get_value
    return get_session().run(ops)
  File "/gpfs/home/m201560/.local/lib/python3.6/site-packages/keras/backend/tensorflow_backend.py", line 186, in get_session
    _SESSION = tf.Session(config=config)
  File "/gpfs/pkgs/mhpcc/anaconda3-5.0.1/lib/python3.6/site-packages/tensorflow/python/client/session.py", line 1563, in __init__
    super(Session, self).__init__(target, graph, config=config)
  File "/gpfs/pkgs/mhpcc/anaconda3-5.0.1/lib/python3.6/site-packages/tensorflow/python/client/session.py", line 633, in __init__
    self._session = tf_session.TF_NewSession(self._graph._c_graph, opts)
tensorflow.python.framework.errors_impl.InternalError: Failed to create session.
Traceback (most recent call last):
  File "roundOneSubmit.py", line 23, in <module>
    l.learnThingsCPP(kind=0, file=f, weightFile=wf)
  File "/gpfs/home/m201560/chipboard/learn.py", line 130, in learnThingsCPP
    weights = self.getWeightArray()
  File "/gpfs/home/m201560/chipboard/learn.py", line 199, in getWeightArray
    return self.model.get_weights()[0].tolist()
  File "/gpfs/home/m201560/.local/lib/python3.6/site-packages/keras/engine/network.py", line 492, in get_weights
    return K.batch_get_value(weights)
  File "/gpfs/home/m201560/.local/lib/python3.6/site-packages/keras/backend/tensorflow_backend.py", line 2420, in batch_get_value
    return get_session().run(ops)
  File "/gpfs/home/m201560/.local/lib/python3.6/site-packages/keras/backend/tensorflow_backend.py", line 186, in get_session
    _SESSION = tf.Session(config=config)
  File "/gpfs/pkgs/mhpcc/anaconda3-5.0.1/lib/python3.6/site-packages/tensorflow/python/client/session.py", line 1563, in __init__
    super(Session, self).__init__(target, graph, config=config)
  File "/gpfs/pkgs/mhpcc/anaconda3-5.0.1/lib/python3.6/site-packages/tensorflow/python/client/session.py", line 633, in __init__
    self._session = tf_session.TF_NewSession(self._graph._c_graph, opts)
tensorflow.python.framework.errors_impl.InternalError: Failed to create session.
Traceback (most recent call last):
  File "roundOneSubmit.py", line 23, in <module>
    l.learnThingsCPP(kind=0, file=f, weightFile=wf)
  File "/gpfs/home/m201560/chipboard/learn.py", line 130, in learnThingsCPP
    weights = self.getWeightArray()
  File "/gpfs/home/m201560/chipboard/learn.py", line 199, in getWeightArray
    return self.model.get_weights()[0].tolist()
  File "/gpfs/home/m201560/.local/lib/python3.6/site-packages/keras/engine/network.py", line 492, in get_weights
    return K.batch_get_value(weights)
  File "/gpfs/home/m201560/.local/lib/python3.6/site-packages/keras/backend/tensorflow_backend.py", line 2420, in batch_get_value
    return get_session().run(ops)
  File "/gpfs/home/m201560/.local/lib/python3.6/site-packages/keras/backend/tensorflow_backend.py", line 186, in get_session
    _SESSION = tf.Session(config=config)
  File "/gpfs/pkgs/mhpcc/anaconda3-5.0.1/lib/python3.6/site-packages/tensorflow/python/client/session.py", line 1563, in __init__
    super(Session, self).__init__(target, graph, config=config)
  File "/gpfs/pkgs/mhpcc/anaconda3-5.0.1/lib/python3.6/site-packages/tensorflow/python/client/session.py", line 633, in __init__
    self._session = tf_session.TF_NewSession(self._graph._c_graph, opts)
tensorflow.python.framework.errors_impl.InternalError: Failed to create session.
2019-08-02 11:20:23.639958: I tensorflow/core/common_runtime/gpu/gpu_device.cc:1392] Found device 2 with properties: 
name: Tesla P100-SXM2-16GB major: 6 minor: 0 memoryClockRate(GHz): 1.4805
pciBusID: 0006:01:00.0
totalMemory: 15.90GiB freeMemory: 15.64GiB
Traceback (most recent call last):
  File "roundOneSubmit.py", line 23, in <module>
    l.learnThingsCPP(kind=0, file=f, weightFile=wf)
  File "/gpfs/home/m201560/chipboard/learn.py", line 130, in learnThingsCPP
    weights = self.getWeightArray()
  File "/gpfs/home/m201560/chipboard/learn.py", line 199, in getWeightArray
    return self.model.get_weights()[0].tolist()
  File "/gpfs/home/m201560/.local/lib/python3.6/site-packages/keras/engine/network.py", line 492, in get_weights
    return K.batch_get_value(weights)
  File "/gpfs/home/m201560/.local/lib/python3.6/site-packages/keras/backend/tensorflow_backend.py", line 2420, in batch_get_value
    return get_session().run(ops)
  File "/gpfs/home/m201560/.local/lib/python3.6/site-packages/keras/backend/tensorflow_backend.py", line 186, in get_session
    _SESSION = tf.Session(config=config)
  File "/gpfs/pkgs/mhpcc/anaconda3-5.0.1/lib/python3.6/site-packages/tensorflow/python/client/session.py", line 1563, in __init__
    super(Session, self).__init__(target, graph, config=config)
  File "/gpfs/pkgs/mhpcc/anaconda3-5.0.1/lib/python3.6/site-packages/tensorflow/python/client/session.py", line 633, in __init__
    self._session = tf_session.TF_NewSession(self._graph._c_graph, opts)
tensorflow.python.framework.errors_impl.InternalError: Failed to create session.
2019-08-02 11:20:23.700842: E tensorflow/core/common_runtime/direct_session.cc:158] Internal: failed initializing StreamExecutor for CUDA device ordinal 0: Internal: failed call to cuDevicePrimaryCtxRetain: CUDA_ERROR_INVALID_DEVICE
/gpfs/pkgs/mhpcc/anaconda3-5.0.1/lib/python3.6/site-packages/h5py/__init__.py:34: FutureWarning: Conversion of the second argument of issubdtype from `float` to `np.floating` is deprecated. In future, it will be treated as `np.float64 == np.dtype(float).type`.
  from ._conv import register_converters as _register_converters
Using TensorFlow backend.
Traceback (most recent call last):
  File "roundOneSubmit.py", line 23, in <module>
    l.learnThingsCPP(kind=0, file=f, weightFile=wf)
  File "/gpfs/home/m201560/chipboard/learn.py", line 130, in learnThingsCPP
    weights = self.getWeightArray()
  File "/gpfs/home/m201560/chipboard/learn.py", line 199, in getWeightArray
    return self.model.get_weights()[0].tolist()
  File "/gpfs/home/m201560/.local/lib/python3.6/site-packages/keras/engine/network.py", line 492, in get_weights
    return K.batch_get_value(weights)
  File "/gpfs/home/m201560/.local/lib/python3.6/site-packages/keras/backend/tensorflow_backend.py", line 2420, in batch_get_value
    return get_session().run(ops)
  File "/gpfs/home/m201560/.local/lib/python3.6/site-packages/keras/backend/tensorflow_backend.py", line 186, in get_session
    _SESSION = tf.Session(config=config)
  File "/gpfs/pkgs/mhpcc/anaconda3-5.0.1/lib/python3.6/site-packages/tensorflow/python/client/session.py", line 1563, in __init__
    super(Session, self).__init__(target, graph, config=config)
  File "/gpfs/pkgs/mhpcc/anaconda3-5.0.1/lib/python3.6/site-packages/tensorflow/python/client/session.py", line 633, in __init__
    self._session = tf_session.TF_NewSession(self._graph._c_graph, opts)
tensorflow.python.framework.errors_impl.InternalError: Failed to create session.
Traceback (most recent call last):
  File "roundOneSubmit.py", line 23, in <module>
    l.learnThingsCPP(kind=0, file=f, weightFile=wf)
  File "/gpfs/home/m201560/chipboard/learn.py", line 130, in learnThingsCPP
    weights = self.getWeightArray()
  File "/gpfs/home/m201560/chipboard/learn.py", line 199, in getWeightArray
    return self.model.get_weights()[0].tolist()
  File "/gpfs/home/m201560/.local/lib/python3.6/site-packages/keras/engine/network.py", line 492, in get_weights
    return K.batch_get_value(weights)
  File "/gpfs/home/m201560/.local/lib/python3.6/site-packages/keras/backend/tensorflow_backend.py", line 2420, in batch_get_value
    return get_session().run(ops)
  File "/gpfs/home/m201560/.local/lib/python3.6/site-packages/keras/backend/tensorflow_backend.py", line 186, in get_session
    _SESSION = tf.Session(config=config)
  File "/gpfs/pkgs/mhpcc/anaconda3-5.0.1/lib/python3.6/site-packages/tensorflow/python/client/session.py", line 1563, in __init__
    super(Session, self).__init__(target, graph, config=config)
  File "/gpfs/pkgs/mhpcc/anaconda3-5.0.1/lib/python3.6/site-packages/tensorflow/python/client/session.py", line 633, in __init__
    self._session = tf_session.TF_NewSession(self._graph._c_graph, opts)
tensorflow.python.framework.errors_impl.InternalError: Failed to create session.
2019-08-02 11:20:23.883199: E tensorflow/core/common_runtime/direct_session.cc:158] Internal: failed initializing StreamExecutor for CUDA device ordinal 0: Internal: failed call to cuDevicePrimaryCtxRetain: CUDA_ERROR_INVALID_DEVICE
/gpfs/pkgs/mhpcc/anaconda3-5.0.1/lib/python3.6/site-packages/h5py/__init__.py:34: FutureWarning: Conversion of the second argument of issubdtype from `float` to `np.floating` is deprecated. In future, it will be treated as `np.float64 == np.dtype(float).type`.
  from ._conv import register_converters as _register_converters
Using TensorFlow backend.
Traceback (most recent call last):
  File "roundOneSubmit.py", line 23, in <module>
    l.learnThingsCPP(kind=0, file=f, weightFile=wf)
  File "/gpfs/home/m201560/chipboard/learn.py", line 130, in learnThingsCPP
    weights = self.getWeightArray()
  File "/gpfs/home/m201560/chipboard/learn.py", line 199, in getWeightArray
    return self.model.get_weights()[0].tolist()
  File "/gpfs/home/m201560/.local/lib/python3.6/site-packages/keras/engine/network.py", line 492, in get_weights
    return K.batch_get_value(weights)
  File "/gpfs/home/m201560/.local/lib/python3.6/site-packages/keras/backend/tensorflow_backend.py", line 2420, in batch_get_value
    return get_session().run(ops)
  File "/gpfs/home/m201560/.local/lib/python3.6/site-packages/keras/backend/tensorflow_backend.py", line 186, in get_session
    _SESSION = tf.Session(config=config)
  File "/gpfs/pkgs/mhpcc/anaconda3-5.0.1/lib/python3.6/site-packages/tensorflow/python/client/session.py", line 1563, in __init__
    super(Session, self).__init__(target, graph, config=config)
  File "/gpfs/pkgs/mhpcc/anaconda3-5.0.1/lib/python3.6/site-packages/tensorflow/python/client/session.py", line 633, in __init__
    self._session = tf_session.TF_NewSession(self._graph._c_graph, opts)
tensorflow.python.framework.errors_impl.InternalError: Failed to create session.
2019-08-02 11:20:23.955924: E tensorflow/core/common_runtime/direct_session.cc:158] Internal: failed initializing StreamExecutor for CUDA device ordinal 0: Internal: failed call to cuDevicePrimaryCtxRetain: CUDA_ERROR_INVALID_DEVICE
/gpfs/pkgs/mhpcc/anaconda3-5.0.1/lib/python3.6/site-packages/h5py/__init__.py:34: FutureWarning: Conversion of the second argument of issubdtype from `float` to `np.floating` is deprecated. In future, it will be treated as `np.float64 == np.dtype(float).type`.
  from ._conv import register_converters as _register_converters
Using TensorFlow backend.
Traceback (most recent call last):
  File "roundOneSubmit.py", line 23, in <module>
    l.learnThingsCPP(kind=0, file=f, weightFile=wf)
  File "/gpfs/home/m201560/chipboard/learn.py", line 130, in learnThingsCPP
    weights = self.getWeightArray()
  File "/gpfs/home/m201560/chipboard/learn.py", line 199, in getWeightArray
    return self.model.get_weights()[0].tolist()
  File "/gpfs/home/m201560/.local/lib/python3.6/site-packages/keras/engine/network.py", line 492, in get_weights
    return K.batch_get_value(weights)
  File "/gpfs/home/m201560/.local/lib/python3.6/site-packages/keras/backend/tensorflow_backend.py", line 2420, in batch_get_value
    return get_session().run(ops)
  File "/gpfs/home/m201560/.local/lib/python3.6/site-packages/keras/backend/tensorflow_backend.py", line 186, in get_session
    _SESSION = tf.Session(config=config)
  File "/gpfs/pkgs/mhpcc/anaconda3-5.0.1/lib/python3.6/site-packages/tensorflow/python/client/session.py", line 1563, in __init__
    super(Session, self).__init__(target, graph, config=config)
  File "/gpfs/pkgs/mhpcc/anaconda3-5.0.1/lib/python3.6/site-packages/tensorflow/python/client/session.py", line 633, in __init__
    self._session = tf_session.TF_NewSession(self._graph._c_graph, opts)
tensorflow.python.framework.errors_impl.InternalError: Failed to create session.
2019-08-02 11:20:23.979873: E tensorflow/core/common_runtime/direct_session.cc:158] Internal: failed initializing StreamExecutor for CUDA device ordinal 0: Internal: failed call to cuDevicePrimaryCtxRetain: CUDA_ERROR_INVALID_DEVICE
/gpfs/pkgs/mhpcc/anaconda3-5.0.1/lib/python3.6/site-packages/h5py/__init__.py:34: FutureWarning: Conversion of the second argument of issubdtype from `float` to `np.floating` is deprecated. In future, it will be treated as `np.float64 == np.dtype(float).type`.
  from ._conv import register_converters as _register_converters
Using TensorFlow backend.
Traceback (most recent call last):
  File "roundOneSubmit.py", line 23, in <module>
    l.learnThingsCPP(kind=0, file=f, weightFile=wf)
  File "/gpfs/home/m201560/chipboard/learn.py", line 130, in learnThingsCPP
    weights = self.getWeightArray()
  File "/gpfs/home/m201560/chipboard/learn.py", line 199, in getWeightArray
    return self.model.get_weights()[0].tolist()
  File "/gpfs/home/m201560/.local/lib/python3.6/site-packages/keras/engine/network.py", line 492, in get_weights
    return K.batch_get_value(weights)
  File "/gpfs/home/m201560/.local/lib/python3.6/site-packages/keras/backend/tensorflow_backend.py", line 2420, in batch_get_value
    return get_session().run(ops)
  File "/gpfs/home/m201560/.local/lib/python3.6/site-packages/keras/backend/tensorflow_backend.py", line 186, in get_session
    _SESSION = tf.Session(config=config)
  File "/gpfs/pkgs/mhpcc/anaconda3-5.0.1/lib/python3.6/site-packages/tensorflow/python/client/session.py", line 1563, in __init__
    super(Session, self).__init__(target, graph, config=config)
  File "/gpfs/pkgs/mhpcc/anaconda3-5.0.1/lib/python3.6/site-packages/tensorflow/python/client/session.py", line 633, in __init__
    self._session = tf_session.TF_NewSession(self._graph._c_graph, opts)
tensorflow.python.framework.errors_impl.InternalError: Failed to create session.
2019-08-02 11:20:24.004448: E tensorflow/core/common_runtime/direct_session.cc:158] Internal: failed initializing StreamExecutor for CUDA device ordinal 0: Internal: failed call to cuDevicePrimaryCtxRetain: CUDA_ERROR_INVALID_DEVICE
/gpfs/pkgs/mhpcc/anaconda3-5.0.1/lib/python3.6/site-packages/h5py/__init__.py:34: FutureWarning: Conversion of the second argument of issubdtype from `float` to `np.floating` is deprecated. In future, it will be treated as `np.float64 == np.dtype(float).type`.
  from ._conv import register_converters as _register_converters
Using TensorFlow backend.
Traceback (most recent call last):
  File "roundOneSubmit.py", line 23, in <module>
    l.learnThingsCPP(kind=0, file=f, weightFile=wf)
  File "/gpfs/home/m201560/chipboard/learn.py", line 130, in learnThingsCPP
    weights = self.getWeightArray()
  File "/gpfs/home/m201560/chipboard/learn.py", line 199, in getWeightArray
    return self.model.get_weights()[0].tolist()
  File "/gpfs/home/m201560/.local/lib/python3.6/site-packages/keras/engine/network.py", line 492, in get_weights
    return K.batch_get_value(weights)
  File "/gpfs/home/m201560/.local/lib/python3.6/site-packages/keras/backend/tensorflow_backend.py", line 2420, in batch_get_value
    return get_session().run(ops)
  File "/gpfs/home/m201560/.local/lib/python3.6/site-packages/keras/backend/tensorflow_backend.py", line 186, in get_session
    _SESSION = tf.Session(config=config)
  File "/gpfs/pkgs/mhpcc/anaconda3-5.0.1/lib/python3.6/site-packages/tensorflow/python/client/session.py", line 1563, in __init__
    super(Session, self).__init__(target, graph, config=config)
  File "/gpfs/pkgs/mhpcc/anaconda3-5.0.1/lib/python3.6/site-packages/tensorflow/python/client/session.py", line 633, in __init__
    self._session = tf_session.TF_NewSession(self._graph._c_graph, opts)
tensorflow.python.framework.errors_impl.InternalError: Failed to create session.
2019-08-02 11:20:24.023692: E tensorflow/core/common_runtime/direct_session.cc:158] Internal: failed initializing StreamExecutor for CUDA device ordinal 0: Internal: failed call to cuDevicePrimaryCtxRetain: CUDA_ERROR_INVALID_DEVICE
/gpfs/pkgs/mhpcc/anaconda3-5.0.1/lib/python3.6/site-packages/h5py/__init__.py:34: FutureWarning: Conversion of the second argument of issubdtype from `float` to `np.floating` is deprecated. In future, it will be treated as `np.float64 == np.dtype(float).type`.
  from ._conv import register_converters as _register_converters
Using TensorFlow backend.
Traceback (most recent call last):
  File "roundOneSubmit.py", line 23, in <module>
    l.learnThingsCPP(kind=0, file=f, weightFile=wf)
  File "/gpfs/home/m201560/chipboard/learn.py", line 130, in learnThingsCPP
    weights = self.getWeightArray()
  File "/gpfs/home/m201560/chipboard/learn.py", line 199, in getWeightArray
    return self.model.get_weights()[0].tolist()
  File "/gpfs/home/m201560/.local/lib/python3.6/site-packages/keras/engine/network.py", line 492, in get_weights
    return K.batch_get_value(weights)
  File "/gpfs/home/m201560/.local/lib/python3.6/site-packages/keras/backend/tensorflow_backend.py", line 2420, in batch_get_value
    return get_session().run(ops)
  File "/gpfs/home/m201560/.local/lib/python3.6/site-packages/keras/backend/tensorflow_backend.py", line 186, in get_session
    _SESSION = tf.Session(config=config)
  File "/gpfs/pkgs/mhpcc/anaconda3-5.0.1/lib/python3.6/site-packages/tensorflow/python/client/session.py", line 1563, in __init__
    super(Session, self).__init__(target, graph, config=config)
  File "/gpfs/pkgs/mhpcc/anaconda3-5.0.1/lib/python3.6/site-packages/tensorflow/python/client/session.py", line 633, in __init__
    self._session = tf_session.TF_NewSession(self._graph._c_graph, opts)
tensorflow.python.framework.errors_impl.InternalError: Failed to create session.
2019-08-02 11:20:24.043798: E tensorflow/core/common_runtime/direct_session.cc:158] Internal: failed initializing StreamExecutor for CUDA device ordinal 0: Internal: failed call to cuDevicePrimaryCtxRetain: CUDA_ERROR_INVALID_DEVICE
/gpfs/pkgs/mhpcc/anaconda3-5.0.1/lib/python3.6/site-packages/h5py/__init__.py:34: FutureWarning: Conversion of the second argument of issubdtype from `float` to `np.floating` is deprecated. In future, it will be treated as `np.float64 == np.dtype(float).type`.
  from ._conv import register_converters as _register_converters
Using TensorFlow backend.
2019-08-02 11:20:24.049718: E tensorflow/core/common_runtime/direct_session.cc:158] Internal: failed initializing StreamExecutor for CUDA device ordinal 0: Internal: failed call to cuDevicePrimaryCtxRetain: CUDA_ERROR_INVALID_DEVICE
/gpfs/pkgs/mhpcc/anaconda3-5.0.1/lib/python3.6/site-packages/h5py/__init__.py:34: FutureWarning: Conversion of the second argument of issubdtype from `float` to `np.floating` is deprecated. In future, it will be treated as `np.float64 == np.dtype(float).type`.
  from ._conv import register_converters as _register_converters
Using TensorFlow backend.
Traceback (most recent call last):
  File "roundOneSubmit.py", line 23, in <module>
    l.learnThingsCPP(kind=0, file=f, weightFile=wf)
  File "/gpfs/home/m201560/chipboard/learn.py", line 130, in learnThingsCPP
    weights = self.getWeightArray()
  File "/gpfs/home/m201560/chipboard/learn.py", line 199, in getWeightArray
    return self.model.get_weights()[0].tolist()
  File "/gpfs/home/m201560/.local/lib/python3.6/site-packages/keras/engine/network.py", line 492, in get_weights
    return K.batch_get_value(weights)
  File "/gpfs/home/m201560/.local/lib/python3.6/site-packages/keras/backend/tensorflow_backend.py", line 2420, in batch_get_value
    return get_session().run(ops)
  File "/gpfs/home/m201560/.local/lib/python3.6/site-packages/keras/backend/tensorflow_backend.py", line 186, in get_session
    _SESSION = tf.Session(config=config)
  File "/gpfs/pkgs/mhpcc/anaconda3-5.0.1/lib/python3.6/site-packages/tensorflow/python/client/session.py", line 1563, in __init__
    super(Session, self).__init__(target, graph, config=config)
  File "/gpfs/pkgs/mhpcc/anaconda3-5.0.1/lib/python3.6/site-packages/tensorflow/python/client/session.py", line 633, in __init__
    self._session = tf_session.TF_NewSession(self._graph._c_graph, opts)
tensorflow.python.framework.errors_impl.InternalError: Failed to create session.
Traceback (most recent call last):
  File "roundOneSubmit.py", line 23, in <module>
    l.learnThingsCPP(kind=0, file=f, weightFile=wf)
  File "/gpfs/home/m201560/chipboard/learn.py", line 130, in learnThingsCPP
    weights = self.getWeightArray()
  File "/gpfs/home/m201560/chipboard/learn.py", line 199, in getWeightArray
    return self.model.get_weights()[0].tolist()
  File "/gpfs/home/m201560/.local/lib/python3.6/site-packages/keras/engine/network.py", line 492, in get_weights
    return K.batch_get_value(weights)
  File "/gpfs/home/m201560/.local/lib/python3.6/site-packages/keras/backend/tensorflow_backend.py", line 2420, in batch_get_value
    return get_session().run(ops)
  File "/gpfs/home/m201560/.local/lib/python3.6/site-packages/keras/backend/tensorflow_backend.py", line 186, in get_session
    _SESSION = tf.Session(config=config)
  File "/gpfs/pkgs/mhpcc/anaconda3-5.0.1/lib/python3.6/site-packages/tensorflow/python/client/session.py", line 1563, in __init__
    super(Session, self).__init__(target, graph, config=config)
  File "/gpfs/pkgs/mhpcc/anaconda3-5.0.1/lib/python3.6/site-packages/tensorflow/python/client/session.py", line 633, in __init__
    self._session = tf_session.TF_NewSession(self._graph._c_graph, opts)
tensorflow.python.framework.errors_impl.InternalError: Failed to create session.
2019-08-02 11:20:24.074633: E tensorflow/core/common_runtime/direct_session.cc:158] Internal: failed initializing StreamExecutor for CUDA device ordinal 0: Internal: failed call to cuDevicePrimaryCtxRetain: CUDA_ERROR_INVALID_DEVICE
/gpfs/pkgs/mhpcc/anaconda3-5.0.1/lib/python3.6/site-packages/h5py/__init__.py:34: FutureWarning: Conversion of the second argument of issubdtype from `float` to `np.floating` is deprecated. In future, it will be treated as `np.float64 == np.dtype(float).type`.
  from ._conv import register_converters as _register_converters
Using TensorFlow backend.
Traceback (most recent call last):
  File "roundOneSubmit.py", line 23, in <module>
    l.learnThingsCPP(kind=0, file=f, weightFile=wf)
  File "/gpfs/home/m201560/chipboard/learn.py", line 130, in learnThingsCPP
    weights = self.getWeightArray()
  File "/gpfs/home/m201560/chipboard/learn.py", line 199, in getWeightArray
    return self.model.get_weights()[0].tolist()
  File "/gpfs/home/m201560/.local/lib/python3.6/site-packages/keras/engine/network.py", line 492, in get_weights
    return K.batch_get_value(weights)
  File "/gpfs/home/m201560/.local/lib/python3.6/site-packages/keras/backend/tensorflow_backend.py", line 2420, in batch_get_value
    return get_session().run(ops)
  File "/gpfs/home/m201560/.local/lib/python3.6/site-packages/keras/backend/tensorflow_backend.py", line 186, in get_session
    _SESSION = tf.Session(config=config)
  File "/gpfs/pkgs/mhpcc/anaconda3-5.0.1/lib/python3.6/site-packages/tensorflow/python/client/session.py", line 1563, in __init__
    super(Session, self).__init__(target, graph, config=config)
  File "/gpfs/pkgs/mhpcc/anaconda3-5.0.1/lib/python3.6/site-packages/tensorflow/python/client/session.py", line 633, in __init__
    self._session = tf_session.TF_NewSession(self._graph._c_graph, opts)
tensorflow.python.framework.errors_impl.InternalError: Failed to create session.
2019-08-02 11:20:24.089433: E tensorflow/core/common_runtime/direct_session.cc:158] Internal: failed initializing StreamExecutor for CUDA device ordinal 0: Internal: failed call to cuDevicePrimaryCtxRetain: CUDA_ERROR_INVALID_DEVICE
/gpfs/pkgs/mhpcc/anaconda3-5.0.1/lib/python3.6/site-packages/h5py/__init__.py:34: FutureWarning: Conversion of the second argument of issubdtype from `float` to `np.floating` is deprecated. In future, it will be treated as `np.float64 == np.dtype(float).type`.
  from ._conv import register_converters as _register_converters
Using TensorFlow backend.
2019-08-02 11:20:24.090762: E tensorflow/core/common_runtime/direct_session.cc:158] Internal: failed initializing StreamExecutor for CUDA device ordinal 0: Internal: failed call to cuDevicePrimaryCtxRetain: CUDA_ERROR_INVALID_DEVICE
/gpfs/pkgs/mhpcc/anaconda3-5.0.1/lib/python3.6/site-packages/h5py/__init__.py:34: FutureWarning: Conversion of the second argument of issubdtype from `float` to `np.floating` is deprecated. In future, it will be treated as `np.float64 == np.dtype(float).type`.
  from ._conv import register_converters as _register_converters
Using TensorFlow backend.
Traceback (most recent call last):
  File "roundOneSubmit.py", line 23, in <module>
    l.learnThingsCPP(kind=0, file=f, weightFile=wf)
  File "/gpfs/home/m201560/chipboard/learn.py", line 130, in learnThingsCPP
    weights = self.getWeightArray()
  File "/gpfs/home/m201560/chipboard/learn.py", line 199, in getWeightArray
    return self.model.get_weights()[0].tolist()
  File "/gpfs/home/m201560/.local/lib/python3.6/site-packages/keras/engine/network.py", line 492, in get_weights
    return K.batch_get_value(weights)
  File "/gpfs/home/m201560/.local/lib/python3.6/site-packages/keras/backend/tensorflow_backend.py", line 2420, in batch_get_value
    return get_session().run(ops)
  File "/gpfs/home/m201560/.local/lib/python3.6/site-packages/keras/backend/tensorflow_backend.py", line 186, in get_session
    _SESSION = tf.Session(config=config)
  File "/gpfs/pkgs/mhpcc/anaconda3-5.0.1/lib/python3.6/site-packages/tensorflow/python/client/session.py", line 1563, in __init__
    super(Session, self).__init__(target, graph, config=config)
  File "/gpfs/pkgs/mhpcc/anaconda3-5.0.1/lib/python3.6/site-packages/tensorflow/python/client/session.py", line 633, in __init__
    self._session = tf_session.TF_NewSession(self._graph._c_graph, opts)
tensorflow.python.framework.errors_impl.InternalError: Failed to create session.
Traceback (most recent call last):
  File "roundOneSubmit.py", line 23, in <module>
    l.learnThingsCPP(kind=0, file=f, weightFile=wf)
  File "/gpfs/home/m201560/chipboard/learn.py", line 130, in learnThingsCPP
    weights = self.getWeightArray()
  File "/gpfs/home/m201560/chipboard/learn.py", line 199, in getWeightArray
    return self.model.get_weights()[0].tolist()
  File "/gpfs/home/m201560/.local/lib/python3.6/site-packages/keras/engine/network.py", line 492, in get_weights
    return K.batch_get_value(weights)
  File "/gpfs/home/m201560/.local/lib/python3.6/site-packages/keras/backend/tensorflow_backend.py", line 2420, in batch_get_value
    return get_session().run(ops)
  File "/gpfs/home/m201560/.local/lib/python3.6/site-packages/keras/backend/tensorflow_backend.py", line 186, in get_session
    _SESSION = tf.Session(config=config)
  File "/gpfs/pkgs/mhpcc/anaconda3-5.0.1/lib/python3.6/site-packages/tensorflow/python/client/session.py", line 1563, in __init__
    super(Session, self).__init__(target, graph, config=config)
  File "/gpfs/pkgs/mhpcc/anaconda3-5.0.1/lib/python3.6/site-packages/tensorflow/python/client/session.py", line 633, in __init__
    self._session = tf_session.TF_NewSession(self._graph._c_graph, opts)
tensorflow.python.framework.errors_impl.InternalError: Failed to create session.
2019-08-02 11:20:24.405972: I tensorflow/core/common_runtime/gpu/gpu_device.cc:1392] Found device 3 with properties: 
name: Tesla P100-SXM2-16GB major: 6 minor: 0 memoryClockRate(GHz): 1.4805
pciBusID: 0007:01:00.0
totalMemory: 15.90GiB freeMemory: 15.64GiB
2019-08-02 11:20:24.419161: I tensorflow/core/common_runtime/gpu/gpu_device.cc:1471] Adding visible gpu devices: 0, 1, 2, 3
2019-08-02 11:20:24.434684: E tensorflow/core/common_runtime/direct_session.cc:158] Internal: failed initializing StreamExecutor for CUDA device ordinal 0: Internal: failed call to cuDevicePrimaryCtxRetain: CUDA_ERROR_INVALID_DEVICE
/gpfs/pkgs/mhpcc/anaconda3-5.0.1/lib/python3.6/site-packages/h5py/__init__.py:34: FutureWarning: Conversion of the second argument of issubdtype from `float` to `np.floating` is deprecated. In future, it will be treated as `np.float64 == np.dtype(float).type`.
  from ._conv import register_converters as _register_converters
Using TensorFlow backend.
Traceback (most recent call last):
  File "roundOneSubmit.py", line 23, in <module>
    l.learnThingsCPP(kind=0, file=f, weightFile=wf)
  File "/gpfs/home/m201560/chipboard/learn.py", line 130, in learnThingsCPP
    weights = self.getWeightArray()
  File "/gpfs/home/m201560/chipboard/learn.py", line 199, in getWeightArray
    return self.model.get_weights()[0].tolist()
  File "/gpfs/home/m201560/.local/lib/python3.6/site-packages/keras/engine/network.py", line 492, in get_weights
    return K.batch_get_value(weights)
  File "/gpfs/home/m201560/.local/lib/python3.6/site-packages/keras/backend/tensorflow_backend.py", line 2420, in batch_get_value
    return get_session().run(ops)
  File "/gpfs/home/m201560/.local/lib/python3.6/site-packages/keras/backend/tensorflow_backend.py", line 186, in get_session
    _SESSION = tf.Session(config=config)
  File "/gpfs/pkgs/mhpcc/anaconda3-5.0.1/lib/python3.6/site-packages/tensorflow/python/client/session.py", line 1563, in __init__
    super(Session, self).__init__(target, graph, config=config)
  File "/gpfs/pkgs/mhpcc/anaconda3-5.0.1/lib/python3.6/site-packages/tensorflow/python/client/session.py", line 633, in __init__
    self._session = tf_session.TF_NewSession(self._graph._c_graph, opts)
tensorflow.python.framework.errors_impl.InternalError: Failed to create session.
2019-08-02 11:20:24.472416: E tensorflow/core/common_runtime/direct_session.cc:158] Internal: failed initializing StreamExecutor for CUDA device ordinal 0: Internal: failed call to cuDevicePrimaryCtxRetain: CUDA_ERROR_INVALID_DEVICE
/gpfs/pkgs/mhpcc/anaconda3-5.0.1/lib/python3.6/site-packages/h5py/__init__.py:34: FutureWarning: Conversion of the second argument of issubdtype from `float` to `np.floating` is deprecated. In future, it will be treated as `np.float64 == np.dtype(float).type`.
  from ._conv import register_converters as _register_converters
Using TensorFlow backend.
Traceback (most recent call last):
  File "roundOneSubmit.py", line 23, in <module>
    l.learnThingsCPP(kind=0, file=f, weightFile=wf)
  File "/gpfs/home/m201560/chipboard/learn.py", line 130, in learnThingsCPP
    weights = self.getWeightArray()
  File "/gpfs/home/m201560/chipboard/learn.py", line 199, in getWeightArray
    return self.model.get_weights()[0].tolist()
  File "/gpfs/home/m201560/.local/lib/python3.6/site-packages/keras/engine/network.py", line 492, in get_weights
    return K.batch_get_value(weights)
  File "/gpfs/home/m201560/.local/lib/python3.6/site-packages/keras/backend/tensorflow_backend.py", line 2420, in batch_get_value
    return get_session().run(ops)
  File "/gpfs/home/m201560/.local/lib/python3.6/site-packages/keras/backend/tensorflow_backend.py", line 186, in get_session
    _SESSION = tf.Session(config=config)
  File "/gpfs/pkgs/mhpcc/anaconda3-5.0.1/lib/python3.6/site-packages/tensorflow/python/client/session.py", line 1563, in __init__
    super(Session, self).__init__(target, graph, config=config)
  File "/gpfs/pkgs/mhpcc/anaconda3-5.0.1/lib/python3.6/site-packages/tensorflow/python/client/session.py", line 633, in __init__
    self._session = tf_session.TF_NewSession(self._graph._c_graph, opts)
tensorflow.python.framework.errors_impl.InternalError: Failed to create session.
2019-08-02 11:20:24.531381: E tensorflow/core/common_runtime/direct_session.cc:158] Internal: failed initializing StreamExecutor for CUDA device ordinal 0: Internal: failed call to cuDevicePrimaryCtxRetain: CUDA_ERROR_INVALID_DEVICE
/gpfs/pkgs/mhpcc/anaconda3-5.0.1/lib/python3.6/site-packages/h5py/__init__.py:34: FutureWarning: Conversion of the second argument of issubdtype from `float` to `np.floating` is deprecated. In future, it will be treated as `np.float64 == np.dtype(float).type`.
  from ._conv import register_converters as _register_converters
Using TensorFlow backend.
Traceback (most recent call last):
  File "roundOneSubmit.py", line 23, in <module>
    l.learnThingsCPP(kind=0, file=f, weightFile=wf)
  File "/gpfs/home/m201560/chipboard/learn.py", line 130, in learnThingsCPP
    weights = self.getWeightArray()
  File "/gpfs/home/m201560/chipboard/learn.py", line 199, in getWeightArray
    return self.model.get_weights()[0].tolist()
  File "/gpfs/home/m201560/.local/lib/python3.6/site-packages/keras/engine/network.py", line 492, in get_weights
    return K.batch_get_value(weights)
  File "/gpfs/home/m201560/.local/lib/python3.6/site-packages/keras/backend/tensorflow_backend.py", line 2420, in batch_get_value
    return get_session().run(ops)
  File "/gpfs/home/m201560/.local/lib/python3.6/site-packages/keras/backend/tensorflow_backend.py", line 186, in get_session
    _SESSION = tf.Session(config=config)
  File "/gpfs/pkgs/mhpcc/anaconda3-5.0.1/lib/python3.6/site-packages/tensorflow/python/client/session.py", line 1563, in __init__
    super(Session, self).__init__(target, graph, config=config)
  File "/gpfs/pkgs/mhpcc/anaconda3-5.0.1/lib/python3.6/site-packages/tensorflow/python/client/session.py", line 633, in __init__
    self._session = tf_session.TF_NewSession(self._graph._c_graph, opts)
tensorflow.python.framework.errors_impl.InternalError: Failed to create session.
2019-08-02 11:20:24.562633: E tensorflow/core/common_runtime/direct_session.cc:158] Internal: failed initializing StreamExecutor for CUDA device ordinal 0: Internal: failed call to cuDevicePrimaryCtxRetain: CUDA_ERROR_INVALID_DEVICE
/gpfs/pkgs/mhpcc/anaconda3-5.0.1/lib/python3.6/site-packages/h5py/__init__.py:34: FutureWarning: Conversion of the second argument of issubdtype from `float` to `np.floating` is deprecated. In future, it will be treated as `np.float64 == np.dtype(float).type`.
  from ._conv import register_converters as _register_converters
Using TensorFlow backend.
Traceback (most recent call last):
  File "roundOneSubmit.py", line 23, in <module>
    l.learnThingsCPP(kind=0, file=f, weightFile=wf)
  File "/gpfs/home/m201560/chipboard/learn.py", line 130, in learnThingsCPP
    weights = self.getWeightArray()
  File "/gpfs/home/m201560/chipboard/learn.py", line 199, in getWeightArray
    return self.model.get_weights()[0].tolist()
  File "/gpfs/home/m201560/.local/lib/python3.6/site-packages/keras/engine/network.py", line 492, in get_weights
    return K.batch_get_value(weights)
  File "/gpfs/home/m201560/.local/lib/python3.6/site-packages/keras/backend/tensorflow_backend.py", line 2420, in batch_get_value
    return get_session().run(ops)
  File "/gpfs/home/m201560/.local/lib/python3.6/site-packages/keras/backend/tensorflow_backend.py", line 186, in get_session
    _SESSION = tf.Session(config=config)
  File "/gpfs/pkgs/mhpcc/anaconda3-5.0.1/lib/python3.6/site-packages/tensorflow/python/client/session.py", line 1563, in __init__
    super(Session, self).__init__(target, graph, config=config)
  File "/gpfs/pkgs/mhpcc/anaconda3-5.0.1/lib/python3.6/site-packages/tensorflow/python/client/session.py", line 633, in __init__
    self._session = tf_session.TF_NewSession(self._graph._c_graph, opts)
tensorflow.python.framework.errors_impl.InternalError: Failed to create session.
2019-08-02 11:20:24.702639: E tensorflow/core/common_runtime/direct_session.cc:158] Internal: failed initializing StreamExecutor for CUDA device ordinal 0: Internal: failed call to cuDevicePrimaryCtxRetain: CUDA_ERROR_INVALID_DEVICE
/gpfs/pkgs/mhpcc/anaconda3-5.0.1/lib/python3.6/site-packages/h5py/__init__.py:34: FutureWarning: Conversion of the second argument of issubdtype from `float` to `np.floating` is deprecated. In future, it will be treated as `np.float64 == np.dtype(float).type`.
  from ._conv import register_converters as _register_converters
Using TensorFlow backend.
Traceback (most recent call last):
  File "roundOneSubmit.py", line 23, in <module>
    l.learnThingsCPP(kind=0, file=f, weightFile=wf)
  File "/gpfs/home/m201560/chipboard/learn.py", line 130, in learnThingsCPP
    weights = self.getWeightArray()
  File "/gpfs/home/m201560/chipboard/learn.py", line 199, in getWeightArray
    return self.model.get_weights()[0].tolist()
  File "/gpfs/home/m201560/.local/lib/python3.6/site-packages/keras/engine/network.py", line 492, in get_weights
    return K.batch_get_value(weights)
  File "/gpfs/home/m201560/.local/lib/python3.6/site-packages/keras/backend/tensorflow_backend.py", line 2420, in batch_get_value
    return get_session().run(ops)
  File "/gpfs/home/m201560/.local/lib/python3.6/site-packages/keras/backend/tensorflow_backend.py", line 186, in get_session
    _SESSION = tf.Session(config=config)
  File "/gpfs/pkgs/mhpcc/anaconda3-5.0.1/lib/python3.6/site-packages/tensorflow/python/client/session.py", line 1563, in __init__
    super(Session, self).__init__(target, graph, config=config)
  File "/gpfs/pkgs/mhpcc/anaconda3-5.0.1/lib/python3.6/site-packages/tensorflow/python/client/session.py", line 633, in __init__
    self._session = tf_session.TF_NewSession(self._graph._c_graph, opts)
tensorflow.python.framework.errors_impl.InternalError: Failed to create session.
2019-08-02 11:20:24.724794: E tensorflow/core/common_runtime/direct_session.cc:158] Internal: failed initializing StreamExecutor for CUDA device ordinal 0: Internal: failed call to cuDevicePrimaryCtxRetain: CUDA_ERROR_INVALID_DEVICE
/gpfs/pkgs/mhpcc/anaconda3-5.0.1/lib/python3.6/site-packages/h5py/__init__.py:34: FutureWarning: Conversion of the second argument of issubdtype from `float` to `np.floating` is deprecated. In future, it will be treated as `np.float64 == np.dtype(float).type`.
  from ._conv import register_converters as _register_converters
Using TensorFlow backend.
Traceback (most recent call last):
  File "roundOneSubmit.py", line 23, in <module>
    l.learnThingsCPP(kind=0, file=f, weightFile=wf)
  File "/gpfs/home/m201560/chipboard/learn.py", line 130, in learnThingsCPP
    weights = self.getWeightArray()
  File "/gpfs/home/m201560/chipboard/learn.py", line 199, in getWeightArray
    return self.model.get_weights()[0].tolist()
  File "/gpfs/home/m201560/.local/lib/python3.6/site-packages/keras/engine/network.py", line 492, in get_weights
    return K.batch_get_value(weights)
  File "/gpfs/home/m201560/.local/lib/python3.6/site-packages/keras/backend/tensorflow_backend.py", line 2420, in batch_get_value
    return get_session().run(ops)
  File "/gpfs/home/m201560/.local/lib/python3.6/site-packages/keras/backend/tensorflow_backend.py", line 186, in get_session
    _SESSION = tf.Session(config=config)
  File "/gpfs/pkgs/mhpcc/anaconda3-5.0.1/lib/python3.6/site-packages/tensorflow/python/client/session.py", line 1563, in __init__
    super(Session, self).__init__(target, graph, config=config)
  File "/gpfs/pkgs/mhpcc/anaconda3-5.0.1/lib/python3.6/site-packages/tensorflow/python/client/session.py", line 633, in __init__
    self._session = tf_session.TF_NewSession(self._graph._c_graph, opts)
tensorflow.python.framework.errors_impl.InternalError: Failed to create session.
2019-08-02 11:20:24.743139: E tensorflow/core/common_runtime/direct_session.cc:158] Internal: failed initializing StreamExecutor for CUDA device ordinal 0: Internal: failed call to cuDevicePrimaryCtxRetain: CUDA_ERROR_INVALID_DEVICE
/gpfs/pkgs/mhpcc/anaconda3-5.0.1/lib/python3.6/site-packages/h5py/__init__.py:34: FutureWarning: Conversion of the second argument of issubdtype from `float` to `np.floating` is deprecated. In future, it will be treated as `np.float64 == np.dtype(float).type`.
  from ._conv import register_converters as _register_converters
Using TensorFlow backend.
Traceback (most recent call last):
  File "roundOneSubmit.py", line 23, in <module>
    l.learnThingsCPP(kind=0, file=f, weightFile=wf)
  File "/gpfs/home/m201560/chipboard/learn.py", line 130, in learnThingsCPP
    weights = self.getWeightArray()
  File "/gpfs/home/m201560/chipboard/learn.py", line 199, in getWeightArray
    return self.model.get_weights()[0].tolist()
  File "/gpfs/home/m201560/.local/lib/python3.6/site-packages/keras/engine/network.py", line 492, in get_weights
    return K.batch_get_value(weights)
  File "/gpfs/home/m201560/.local/lib/python3.6/site-packages/keras/backend/tensorflow_backend.py", line 2420, in batch_get_value
    return get_session().run(ops)
  File "/gpfs/home/m201560/.local/lib/python3.6/site-packages/keras/backend/tensorflow_backend.py", line 186, in get_session
    _SESSION = tf.Session(config=config)
  File "/gpfs/pkgs/mhpcc/anaconda3-5.0.1/lib/python3.6/site-packages/tensorflow/python/client/session.py", line 1563, in __init__
    super(Session, self).__init__(target, graph, config=config)
  File "/gpfs/pkgs/mhpcc/anaconda3-5.0.1/lib/python3.6/site-packages/tensorflow/python/client/session.py", line 633, in __init__
    self._session = tf_session.TF_NewSession(self._graph._c_graph, opts)
tensorflow.python.framework.errors_impl.InternalError: Failed to create session.
2019-08-02 11:20:24.774305: E tensorflow/core/common_runtime/direct_session.cc:158] Internal: failed initializing StreamExecutor for CUDA device ordinal 0: Internal: failed call to cuDevicePrimaryCtxRetain: CUDA_ERROR_INVALID_DEVICE
/gpfs/pkgs/mhpcc/anaconda3-5.0.1/lib/python3.6/site-packages/h5py/__init__.py:34: FutureWarning: Conversion of the second argument of issubdtype from `float` to `np.floating` is deprecated. In future, it will be treated as `np.float64 == np.dtype(float).type`.
  from ._conv import register_converters as _register_converters
Using TensorFlow backend.
2019-08-02 11:20:24.779275: E tensorflow/core/common_runtime/direct_session.cc:158] Internal: failed initializing StreamExecutor for CUDA device ordinal 0: Internal: failed call to cuDevicePrimaryCtxRetain: CUDA_ERROR_INVALID_DEVICE
/gpfs/pkgs/mhpcc/anaconda3-5.0.1/lib/python3.6/site-packages/h5py/__init__.py:34: FutureWarning: Conversion of the second argument of issubdtype from `float` to `np.floating` is deprecated. In future, it will be treated as `np.float64 == np.dtype(float).type`.
  from ._conv import register_converters as _register_converters
Using TensorFlow backend.
Traceback (most recent call last):
  File "roundOneSubmit.py", line 23, in <module>
    l.learnThingsCPP(kind=0, file=f, weightFile=wf)
  File "/gpfs/home/m201560/chipboard/learn.py", line 130, in learnThingsCPP
    weights = self.getWeightArray()
  File "/gpfs/home/m201560/chipboard/learn.py", line 199, in getWeightArray
    return self.model.get_weights()[0].tolist()
  File "/gpfs/home/m201560/.local/lib/python3.6/site-packages/keras/engine/network.py", line 492, in get_weights
    return K.batch_get_value(weights)
  File "/gpfs/home/m201560/.local/lib/python3.6/site-packages/keras/backend/tensorflow_backend.py", line 2420, in batch_get_value
    return get_session().run(ops)
  File "/gpfs/home/m201560/.local/lib/python3.6/site-packages/keras/backend/tensorflow_backend.py", line 186, in get_session
    _SESSION = tf.Session(config=config)
  File "/gpfs/pkgs/mhpcc/anaconda3-5.0.1/lib/python3.6/site-packages/tensorflow/python/client/session.py", line 1563, in __init__
    super(Session, self).__init__(target, graph, config=config)
  File "/gpfs/pkgs/mhpcc/anaconda3-5.0.1/lib/python3.6/site-packages/tensorflow/python/client/session.py", line 633, in __init__
    self._session = tf_session.TF_NewSession(self._graph._c_graph, opts)
tensorflow.python.framework.errors_impl.InternalError: Failed to create session.
Traceback (most recent call last):
  File "roundOneSubmit.py", line 23, in <module>
    l.learnThingsCPP(kind=0, file=f, weightFile=wf)
  File "/gpfs/home/m201560/chipboard/learn.py", line 130, in learnThingsCPP
    weights = self.getWeightArray()
  File "/gpfs/home/m201560/chipboard/learn.py", line 199, in getWeightArray
    return self.model.get_weights()[0].tolist()
  File "/gpfs/home/m201560/.local/lib/python3.6/site-packages/keras/engine/network.py", line 492, in get_weights
    return K.batch_get_value(weights)
  File "/gpfs/home/m201560/.local/lib/python3.6/site-packages/keras/backend/tensorflow_backend.py", line 2420, in batch_get_value
    return get_session().run(ops)
  File "/gpfs/home/m201560/.local/lib/python3.6/site-packages/keras/backend/tensorflow_backend.py", line 186, in get_session
    _SESSION = tf.Session(config=config)
  File "/gpfs/pkgs/mhpcc/anaconda3-5.0.1/lib/python3.6/site-packages/tensorflow/python/client/session.py", line 1563, in __init__
    super(Session, self).__init__(target, graph, config=config)
  File "/gpfs/pkgs/mhpcc/anaconda3-5.0.1/lib/python3.6/site-packages/tensorflow/python/client/session.py", line 633, in __init__
    self._session = tf_session.TF_NewSession(self._graph._c_graph, opts)
tensorflow.python.framework.errors_impl.InternalError: Failed to create session.
2019-08-02 11:20:24.835262: E tensorflow/core/common_runtime/direct_session.cc:158] Internal: failed initializing StreamExecutor for CUDA device ordinal 0: Internal: failed call to cuDevicePrimaryCtxRetain: CUDA_ERROR_INVALID_DEVICE
/gpfs/pkgs/mhpcc/anaconda3-5.0.1/lib/python3.6/site-packages/h5py/__init__.py:34: FutureWarning: Conversion of the second argument of issubdtype from `float` to `np.floating` is deprecated. In future, it will be treated as `np.float64 == np.dtype(float).type`.
  from ._conv import register_converters as _register_converters
Using TensorFlow backend.
Traceback (most recent call last):
  File "roundOneSubmit.py", line 23, in <module>
    l.learnThingsCPP(kind=0, file=f, weightFile=wf)
  File "/gpfs/home/m201560/chipboard/learn.py", line 130, in learnThingsCPP
    weights = self.getWeightArray()
  File "/gpfs/home/m201560/chipboard/learn.py", line 199, in getWeightArray
    return self.model.get_weights()[0].tolist()
  File "/gpfs/home/m201560/.local/lib/python3.6/site-packages/keras/engine/network.py", line 492, in get_weights
    return K.batch_get_value(weights)
  File "/gpfs/home/m201560/.local/lib/python3.6/site-packages/keras/backend/tensorflow_backend.py", line 2420, in batch_get_value
    return get_session().run(ops)
  File "/gpfs/home/m201560/.local/lib/python3.6/site-packages/keras/backend/tensorflow_backend.py", line 186, in get_session
    _SESSION = tf.Session(config=config)
  File "/gpfs/pkgs/mhpcc/anaconda3-5.0.1/lib/python3.6/site-packages/tensorflow/python/client/session.py", line 1563, in __init__
    super(Session, self).__init__(target, graph, config=config)
  File "/gpfs/pkgs/mhpcc/anaconda3-5.0.1/lib/python3.6/site-packages/tensorflow/python/client/session.py", line 633, in __init__
    self._session = tf_session.TF_NewSession(self._graph._c_graph, opts)
tensorflow.python.framework.errors_impl.InternalError: Failed to create session.
2019-08-02 11:20:24.855884: E tensorflow/core/common_runtime/direct_session.cc:158] Internal: failed initializing StreamExecutor for CUDA device ordinal 0: Internal: failed call to cuDevicePrimaryCtxRetain: CUDA_ERROR_INVALID_DEVICE
/gpfs/pkgs/mhpcc/anaconda3-5.0.1/lib/python3.6/site-packages/h5py/__init__.py:34: FutureWarning: Conversion of the second argument of issubdtype from `float` to `np.floating` is deprecated. In future, it will be treated as `np.float64 == np.dtype(float).type`.
  from ._conv import register_converters as _register_converters
Using TensorFlow backend.
Traceback (most recent call last):
  File "roundOneSubmit.py", line 23, in <module>
    l.learnThingsCPP(kind=0, file=f, weightFile=wf)
  File "/gpfs/home/m201560/chipboard/learn.py", line 130, in learnThingsCPP
    weights = self.getWeightArray()
  File "/gpfs/home/m201560/chipboard/learn.py", line 199, in getWeightArray
    return self.model.get_weights()[0].tolist()
  File "/gpfs/home/m201560/.local/lib/python3.6/site-packages/keras/engine/network.py", line 492, in get_weights
    return K.batch_get_value(weights)
  File "/gpfs/home/m201560/.local/lib/python3.6/site-packages/keras/backend/tensorflow_backend.py", line 2420, in batch_get_value
    return get_session().run(ops)
  File "/gpfs/home/m201560/.local/lib/python3.6/site-packages/keras/backend/tensorflow_backend.py", line 186, in get_session
    _SESSION = tf.Session(config=config)
  File "/gpfs/pkgs/mhpcc/anaconda3-5.0.1/lib/python3.6/site-packages/tensorflow/python/client/session.py", line 1563, in __init__
    super(Session, self).__init__(target, graph, config=config)
  File "/gpfs/pkgs/mhpcc/anaconda3-5.0.1/lib/python3.6/site-packages/tensorflow/python/client/session.py", line 633, in __init__
    self._session = tf_session.TF_NewSession(self._graph._c_graph, opts)
tensorflow.python.framework.errors_impl.InternalError: Failed to create session.
2019-08-02 11:20:24.881181: E tensorflow/core/common_runtime/direct_session.cc:158] Internal: failed initializing StreamExecutor for CUDA device ordinal 0: Internal: failed call to cuDevicePrimaryCtxRetain: CUDA_ERROR_INVALID_DEVICE
/gpfs/pkgs/mhpcc/anaconda3-5.0.1/lib/python3.6/site-packages/h5py/__init__.py:34: FutureWarning: Conversion of the second argument of issubdtype from `float` to `np.floating` is deprecated. In future, it will be treated as `np.float64 == np.dtype(float).type`.
  from ._conv import register_converters as _register_converters
Using TensorFlow backend.
Traceback (most recent call last):
  File "roundOneSubmit.py", line 23, in <module>
    l.learnThingsCPP(kind=0, file=f, weightFile=wf)
  File "/gpfs/home/m201560/chipboard/learn.py", line 130, in learnThingsCPP
    weights = self.getWeightArray()
  File "/gpfs/home/m201560/chipboard/learn.py", line 199, in getWeightArray
    return self.model.get_weights()[0].tolist()
  File "/gpfs/home/m201560/.local/lib/python3.6/site-packages/keras/engine/network.py", line 492, in get_weights
    return K.batch_get_value(weights)
  File "/gpfs/home/m201560/.local/lib/python3.6/site-packages/keras/backend/tensorflow_backend.py", line 2420, in batch_get_value
    return get_session().run(ops)
  File "/gpfs/home/m201560/.local/lib/python3.6/site-packages/keras/backend/tensorflow_backend.py", line 186, in get_session
    _SESSION = tf.Session(config=config)
  File "/gpfs/pkgs/mhpcc/anaconda3-5.0.1/lib/python3.6/site-packages/tensorflow/python/client/session.py", line 1563, in __init__
    super(Session, self).__init__(target, graph, config=config)
  File "/gpfs/pkgs/mhpcc/anaconda3-5.0.1/lib/python3.6/site-packages/tensorflow/python/client/session.py", line 633, in __init__
    self._session = tf_session.TF_NewSession(self._graph._c_graph, opts)
tensorflow.python.framework.errors_impl.InternalError: Failed to create session.
2019-08-02 11:20:24.908622: E tensorflow/core/common_runtime/direct_session.cc:158] Internal: failed initializing StreamExecutor for CUDA device ordinal 0: Internal: failed call to cuDevicePrimaryCtxRetain: CUDA_ERROR_INVALID_DEVICE
/gpfs/pkgs/mhpcc/anaconda3-5.0.1/lib/python3.6/site-packages/h5py/__init__.py:34: FutureWarning: Conversion of the second argument of issubdtype from `float` to `np.floating` is deprecated. In future, it will be treated as `np.float64 == np.dtype(float).type`.
  from ._conv import register_converters as _register_converters
Using TensorFlow backend.
Traceback (most recent call last):
  File "roundOneSubmit.py", line 23, in <module>
    l.learnThingsCPP(kind=0, file=f, weightFile=wf)
  File "/gpfs/home/m201560/chipboard/learn.py", line 130, in learnThingsCPP
    weights = self.getWeightArray()
  File "/gpfs/home/m201560/chipboard/learn.py", line 199, in getWeightArray
    return self.model.get_weights()[0].tolist()
  File "/gpfs/home/m201560/.local/lib/python3.6/site-packages/keras/engine/network.py", line 492, in get_weights
    return K.batch_get_value(weights)
  File "/gpfs/home/m201560/.local/lib/python3.6/site-packages/keras/backend/tensorflow_backend.py", line 2420, in batch_get_value
    return get_session().run(ops)
  File "/gpfs/home/m201560/.local/lib/python3.6/site-packages/keras/backend/tensorflow_backend.py", line 186, in get_session
    _SESSION = tf.Session(config=config)
  File "/gpfs/pkgs/mhpcc/anaconda3-5.0.1/lib/python3.6/site-packages/tensorflow/python/client/session.py", line 1563, in __init__
    super(Session, self).__init__(target, graph, config=config)
  File "/gpfs/pkgs/mhpcc/anaconda3-5.0.1/lib/python3.6/site-packages/tensorflow/python/client/session.py", line 633, in __init__
    self._session = tf_session.TF_NewSession(self._graph._c_graph, opts)
tensorflow.python.framework.errors_impl.InternalError: Failed to create session.
2019-08-02 11:20:24.918618: E tensorflow/core/common_runtime/direct_session.cc:158] Internal: failed initializing StreamExecutor for CUDA device ordinal 0: Internal: failed call to cuDevicePrimaryCtxRetain: CUDA_ERROR_INVALID_DEVICE
/gpfs/pkgs/mhpcc/anaconda3-5.0.1/lib/python3.6/site-packages/h5py/__init__.py:34: FutureWarning: Conversion of the second argument of issubdtype from `float` to `np.floating` is deprecated. In future, it will be treated as `np.float64 == np.dtype(float).type`.
  from ._conv import register_converters as _register_converters
Using TensorFlow backend.
2019-08-02 11:20:24.929866: E tensorflow/core/common_runtime/direct_session.cc:158] Internal: failed initializing StreamExecutor for CUDA device ordinal 0: Internal: failed call to cuDevicePrimaryCtxRetain: CUDA_ERROR_INVALID_DEVICE
/gpfs/pkgs/mhpcc/anaconda3-5.0.1/lib/python3.6/site-packages/h5py/__init__.py:34: FutureWarning: Conversion of the second argument of issubdtype from `float` to `np.floating` is deprecated. In future, it will be treated as `np.float64 == np.dtype(float).type`.
  from ._conv import register_converters as _register_converters
Using TensorFlow backend.
Traceback (most recent call last):
  File "roundOneSubmit.py", line 23, in <module>
    l.learnThingsCPP(kind=0, file=f, weightFile=wf)
  File "/gpfs/home/m201560/chipboard/learn.py", line 130, in learnThingsCPP
    weights = self.getWeightArray()
  File "/gpfs/home/m201560/chipboard/learn.py", line 199, in getWeightArray
    return self.model.get_weights()[0].tolist()
  File "/gpfs/home/m201560/.local/lib/python3.6/site-packages/keras/engine/network.py", line 492, in get_weights
    return K.batch_get_value(weights)
  File "/gpfs/home/m201560/.local/lib/python3.6/site-packages/keras/backend/tensorflow_backend.py", line 2420, in batch_get_value
    return get_session().run(ops)
  File "/gpfs/home/m201560/.local/lib/python3.6/site-packages/keras/backend/tensorflow_backend.py", line 186, in get_session
    _SESSION = tf.Session(config=config)
  File "/gpfs/pkgs/mhpcc/anaconda3-5.0.1/lib/python3.6/site-packages/tensorflow/python/client/session.py", line 1563, in __init__
    super(Session, self).__init__(target, graph, config=config)
  File "/gpfs/pkgs/mhpcc/anaconda3-5.0.1/lib/python3.6/site-packages/tensorflow/python/client/session.py", line 633, in __init__
    self._session = tf_session.TF_NewSession(self._graph._c_graph, opts)
tensorflow.python.framework.errors_impl.InternalError: Failed to create session.
Traceback (most recent call last):
  File "roundOneSubmit.py", line 23, in <module>
    l.learnThingsCPP(kind=0, file=f, weightFile=wf)
  File "/gpfs/home/m201560/chipboard/learn.py", line 130, in learnThingsCPP
    weights = self.getWeightArray()
  File "/gpfs/home/m201560/chipboard/learn.py", line 199, in getWeightArray
    return self.model.get_weights()[0].tolist()
  File "/gpfs/home/m201560/.local/lib/python3.6/site-packages/keras/engine/network.py", line 492, in get_weights
    return K.batch_get_value(weights)
  File "/gpfs/home/m201560/.local/lib/python3.6/site-packages/keras/backend/tensorflow_backend.py", line 2420, in batch_get_value
    return get_session().run(ops)
  File "/gpfs/home/m201560/.local/lib/python3.6/site-packages/keras/backend/tensorflow_backend.py", line 186, in get_session
    _SESSION = tf.Session(config=config)
  File "/gpfs/pkgs/mhpcc/anaconda3-5.0.1/lib/python3.6/site-packages/tensorflow/python/client/session.py", line 1563, in __init__
    super(Session, self).__init__(target, graph, config=config)
  File "/gpfs/pkgs/mhpcc/anaconda3-5.0.1/lib/python3.6/site-packages/tensorflow/python/client/session.py", line 633, in __init__
    self._session = tf_session.TF_NewSession(self._graph._c_graph, opts)
tensorflow.python.framework.errors_impl.InternalError: Failed to create session.
2019-08-02 11:20:24.948330: E tensorflow/core/common_runtime/direct_session.cc:158] Internal: failed initializing StreamExecutor for CUDA device ordinal 0: Internal: failed call to cuDevicePrimaryCtxRetain: CUDA_ERROR_INVALID_DEVICE
/gpfs/pkgs/mhpcc/anaconda3-5.0.1/lib/python3.6/site-packages/h5py/__init__.py:34: FutureWarning: Conversion of the second argument of issubdtype from `float` to `np.floating` is deprecated. In future, it will be treated as `np.float64 == np.dtype(float).type`.
  from ._conv import register_converters as _register_converters
Using TensorFlow backend.
Traceback (most recent call last):
  File "roundOneSubmit.py", line 23, in <module>
    l.learnThingsCPP(kind=0, file=f, weightFile=wf)
  File "/gpfs/home/m201560/chipboard/learn.py", line 130, in learnThingsCPP
    weights = self.getWeightArray()
  File "/gpfs/home/m201560/chipboard/learn.py", line 199, in getWeightArray
    return self.model.get_weights()[0].tolist()
  File "/gpfs/home/m201560/.local/lib/python3.6/site-packages/keras/engine/network.py", line 492, in get_weights
    return K.batch_get_value(weights)
  File "/gpfs/home/m201560/.local/lib/python3.6/site-packages/keras/backend/tensorflow_backend.py", line 2420, in batch_get_value
    return get_session().run(ops)
  File "/gpfs/home/m201560/.local/lib/python3.6/site-packages/keras/backend/tensorflow_backend.py", line 186, in get_session
    _SESSION = tf.Session(config=config)
  File "/gpfs/pkgs/mhpcc/anaconda3-5.0.1/lib/python3.6/site-packages/tensorflow/python/client/session.py", line 1563, in __init__
    super(Session, self).__init__(target, graph, config=config)
  File "/gpfs/pkgs/mhpcc/anaconda3-5.0.1/lib/python3.6/site-packages/tensorflow/python/client/session.py", line 633, in __init__
    self._session = tf_session.TF_NewSession(self._graph._c_graph, opts)
tensorflow.python.framework.errors_impl.InternalError: Failed to create session.
2019-08-02 11:20:24.971779: E tensorflow/core/common_runtime/direct_session.cc:158] Internal: failed initializing StreamExecutor for CUDA device ordinal 0: Internal: failed call to cuDevicePrimaryCtxRetain: CUDA_ERROR_INVALID_DEVICE
/gpfs/pkgs/mhpcc/anaconda3-5.0.1/lib/python3.6/site-packages/h5py/__init__.py:34: FutureWarning: Conversion of the second argument of issubdtype from `float` to `np.floating` is deprecated. In future, it will be treated as `np.float64 == np.dtype(float).type`.
  from ._conv import register_converters as _register_converters
Using TensorFlow backend.
Traceback (most recent call last):
  File "roundOneSubmit.py", line 23, in <module>
    l.learnThingsCPP(kind=0, file=f, weightFile=wf)
  File "/gpfs/home/m201560/chipboard/learn.py", line 130, in learnThingsCPP
    weights = self.getWeightArray()
  File "/gpfs/home/m201560/chipboard/learn.py", line 199, in getWeightArray
    return self.model.get_weights()[0].tolist()
  File "/gpfs/home/m201560/.local/lib/python3.6/site-packages/keras/engine/network.py", line 492, in get_weights
    return K.batch_get_value(weights)
  File "/gpfs/home/m201560/.local/lib/python3.6/site-packages/keras/backend/tensorflow_backend.py", line 2420, in batch_get_value
    return get_session().run(ops)
  File "/gpfs/home/m201560/.local/lib/python3.6/site-packages/keras/backend/tensorflow_backend.py", line 186, in get_session
    _SESSION = tf.Session(config=config)
  File "/gpfs/pkgs/mhpcc/anaconda3-5.0.1/lib/python3.6/site-packages/tensorflow/python/client/session.py", line 1563, in __init__
    super(Session, self).__init__(target, graph, config=config)
  File "/gpfs/pkgs/mhpcc/anaconda3-5.0.1/lib/python3.6/site-packages/tensorflow/python/client/session.py", line 633, in __init__
    self._session = tf_session.TF_NewSession(self._graph._c_graph, opts)
tensorflow.python.framework.errors_impl.InternalError: Failed to create session.
2019-08-02 11:20:24.993102: E tensorflow/core/common_runtime/direct_session.cc:158] Internal: failed initializing StreamExecutor for CUDA device ordinal 0: Internal: failed call to cuDevicePrimaryCtxRetain: CUDA_ERROR_INVALID_DEVICE
/gpfs/pkgs/mhpcc/anaconda3-5.0.1/lib/python3.6/site-packages/h5py/__init__.py:34: FutureWarning: Conversion of the second argument of issubdtype from `float` to `np.floating` is deprecated. In future, it will be treated as `np.float64 == np.dtype(float).type`.
  from ._conv import register_converters as _register_converters
Using TensorFlow backend.
Traceback (most recent call last):
  File "roundOneSubmit.py", line 23, in <module>
    l.learnThingsCPP(kind=0, file=f, weightFile=wf)
  File "/gpfs/home/m201560/chipboard/learn.py", line 130, in learnThingsCPP
    weights = self.getWeightArray()
  File "/gpfs/home/m201560/chipboard/learn.py", line 199, in getWeightArray
    return self.model.get_weights()[0].tolist()
  File "/gpfs/home/m201560/.local/lib/python3.6/site-packages/keras/engine/network.py", line 492, in get_weights
    return K.batch_get_value(weights)
  File "/gpfs/home/m201560/.local/lib/python3.6/site-packages/keras/backend/tensorflow_backend.py", line 2420, in batch_get_value
    return get_session().run(ops)
  File "/gpfs/home/m201560/.local/lib/python3.6/site-packages/keras/backend/tensorflow_backend.py", line 186, in get_session
    _SESSION = tf.Session(config=config)
  File "/gpfs/pkgs/mhpcc/anaconda3-5.0.1/lib/python3.6/site-packages/tensorflow/python/client/session.py", line 1563, in __init__
    super(Session, self).__init__(target, graph, config=config)
  File "/gpfs/pkgs/mhpcc/anaconda3-5.0.1/lib/python3.6/site-packages/tensorflow/python/client/session.py", line 633, in __init__
    self._session = tf_session.TF_NewSession(self._graph._c_graph, opts)
tensorflow.python.framework.errors_impl.InternalError: Failed to create session.
2019-08-02 11:20:25.007989: E tensorflow/core/common_runtime/direct_session.cc:158] Internal: failed initializing StreamExecutor for CUDA device ordinal 0: Internal: failed call to cuDevicePrimaryCtxRetain: CUDA_ERROR_INVALID_DEVICE
/gpfs/pkgs/mhpcc/anaconda3-5.0.1/lib/python3.6/site-packages/h5py/__init__.py:34: FutureWarning: Conversion of the second argument of issubdtype from `float` to `np.floating` is deprecated. In future, it will be treated as `np.float64 == np.dtype(float).type`.
  from ._conv import register_converters as _register_converters
Using TensorFlow backend.
2019-08-02 11:20:25.012928: E tensorflow/core/common_runtime/direct_session.cc:158] Internal: failed initializing StreamExecutor for CUDA device ordinal 0: Internal: failed call to cuDevicePrimaryCtxRetain: CUDA_ERROR_INVALID_DEVICE
/gpfs/pkgs/mhpcc/anaconda3-5.0.1/lib/python3.6/site-packages/h5py/__init__.py:34: FutureWarning: Conversion of the second argument of issubdtype from `float` to `np.floating` is deprecated. In future, it will be treated as `np.float64 == np.dtype(float).type`.
  from ._conv import register_converters as _register_converters
Using TensorFlow backend.
Traceback (most recent call last):
  File "roundOneSubmit.py", line 23, in <module>
    l.learnThingsCPP(kind=0, file=f, weightFile=wf)
  File "/gpfs/home/m201560/chipboard/learn.py", line 130, in learnThingsCPP
    weights = self.getWeightArray()
  File "/gpfs/home/m201560/chipboard/learn.py", line 199, in getWeightArray
    return self.model.get_weights()[0].tolist()
  File "/gpfs/home/m201560/.local/lib/python3.6/site-packages/keras/engine/network.py", line 492, in get_weights
    return K.batch_get_value(weights)
  File "/gpfs/home/m201560/.local/lib/python3.6/site-packages/keras/backend/tensorflow_backend.py", line 2420, in batch_get_value
    return get_session().run(ops)
  File "/gpfs/home/m201560/.local/lib/python3.6/site-packages/keras/backend/tensorflow_backend.py", line 186, in get_session
    _SESSION = tf.Session(config=config)
  File "/gpfs/pkgs/mhpcc/anaconda3-5.0.1/lib/python3.6/site-packages/tensorflow/python/client/session.py", line 1563, in __init__
    super(Session, self).__init__(target, graph, config=config)
  File "/gpfs/pkgs/mhpcc/anaconda3-5.0.1/lib/python3.6/site-packages/tensorflow/python/client/session.py", line 633, in __init__
    self._session = tf_session.TF_NewSession(self._graph._c_graph, opts)
tensorflow.python.framework.errors_impl.InternalError: Failed to create session.
Traceback (most recent call last):
  File "roundOneSubmit.py", line 23, in <module>
    l.learnThingsCPP(kind=0, file=f, weightFile=wf)
  File "/gpfs/home/m201560/chipboard/learn.py", line 130, in learnThingsCPP
    weights = self.getWeightArray()
  File "/gpfs/home/m201560/chipboard/learn.py", line 199, in getWeightArray
    return self.model.get_weights()[0].tolist()
  File "/gpfs/home/m201560/.local/lib/python3.6/site-packages/keras/engine/network.py", line 492, in get_weights
    return K.batch_get_value(weights)
  File "/gpfs/home/m201560/.local/lib/python3.6/site-packages/keras/backend/tensorflow_backend.py", line 2420, in batch_get_value
    return get_session().run(ops)
  File "/gpfs/home/m201560/.local/lib/python3.6/site-packages/keras/backend/tensorflow_backend.py", line 186, in get_session
    _SESSION = tf.Session(config=config)
  File "/gpfs/pkgs/mhpcc/anaconda3-5.0.1/lib/python3.6/site-packages/tensorflow/python/client/session.py", line 1563, in __init__
    super(Session, self).__init__(target, graph, config=config)
  File "/gpfs/pkgs/mhpcc/anaconda3-5.0.1/lib/python3.6/site-packages/tensorflow/python/client/session.py", line 633, in __init__
    self._session = tf_session.TF_NewSession(self._graph._c_graph, opts)
tensorflow.python.framework.errors_impl.InternalError: Failed to create session.
2019-08-02 11:20:25.029295: E tensorflow/core/common_runtime/direct_session.cc:158] Internal: failed initializing StreamExecutor for CUDA device ordinal 0: Internal: failed call to cuDevicePrimaryCtxRetain: CUDA_ERROR_INVALID_DEVICE
/gpfs/pkgs/mhpcc/anaconda3-5.0.1/lib/python3.6/site-packages/h5py/__init__.py:34: FutureWarning: Conversion of the second argument of issubdtype from `float` to `np.floating` is deprecated. In future, it will be treated as `np.float64 == np.dtype(float).type`.
  from ._conv import register_converters as _register_converters
Using TensorFlow backend.
2019-08-02 11:20:25.030992: E tensorflow/core/common_runtime/direct_session.cc:158] Internal: failed initializing StreamExecutor for CUDA device ordinal 0: Internal: failed call to cuDevicePrimaryCtxRetain: CUDA_ERROR_INVALID_DEVICE
/gpfs/pkgs/mhpcc/anaconda3-5.0.1/lib/python3.6/site-packages/h5py/__init__.py:34: FutureWarning: Conversion of the second argument of issubdtype from `float` to `np.floating` is deprecated. In future, it will be treated as `np.float64 == np.dtype(float).type`.
  from ._conv import register_converters as _register_converters
Using TensorFlow backend.
Traceback (most recent call last):
  File "roundOneSubmit.py", line 23, in <module>
    l.learnThingsCPP(kind=0, file=f, weightFile=wf)
  File "/gpfs/home/m201560/chipboard/learn.py", line 130, in learnThingsCPP
    weights = self.getWeightArray()
  File "/gpfs/home/m201560/chipboard/learn.py", line 199, in getWeightArray
    return self.model.get_weights()[0].tolist()
  File "/gpfs/home/m201560/.local/lib/python3.6/site-packages/keras/engine/network.py", line 492, in get_weights
    return K.batch_get_value(weights)
  File "/gpfs/home/m201560/.local/lib/python3.6/site-packages/keras/backend/tensorflow_backend.py", line 2420, in batch_get_value
    return get_session().run(ops)
  File "/gpfs/home/m201560/.local/lib/python3.6/site-packages/keras/backend/tensorflow_backend.py", line 186, in get_session
    _SESSION = tf.Session(config=config)
  File "/gpfs/pkgs/mhpcc/anaconda3-5.0.1/lib/python3.6/site-packages/tensorflow/python/client/session.py", line 1563, in __init__
    super(Session, self).__init__(target, graph, config=config)
  File "/gpfs/pkgs/mhpcc/anaconda3-5.0.1/lib/python3.6/site-packages/tensorflow/python/client/session.py", line 633, in __init__
    self._session = tf_session.TF_NewSession(self._graph._c_graph, opts)
tensorflow.python.framework.errors_impl.InternalError: Failed to create session.
Traceback (most recent call last):
  File "roundOneSubmit.py", line 23, in <module>
    l.learnThingsCPP(kind=0, file=f, weightFile=wf)
  File "/gpfs/home/m201560/chipboard/learn.py", line 130, in learnThingsCPP
    weights = self.getWeightArray()
  File "/gpfs/home/m201560/chipboard/learn.py", line 199, in getWeightArray
    return self.model.get_weights()[0].tolist()
  File "/gpfs/home/m201560/.local/lib/python3.6/site-packages/keras/engine/network.py", line 492, in get_weights
    return K.batch_get_value(weights)
  File "/gpfs/home/m201560/.local/lib/python3.6/site-packages/keras/backend/tensorflow_backend.py", line 2420, in batch_get_value
    return get_session().run(ops)
  File "/gpfs/home/m201560/.local/lib/python3.6/site-packages/keras/backend/tensorflow_backend.py", line 186, in get_session
    _SESSION = tf.Session(config=config)
  File "/gpfs/pkgs/mhpcc/anaconda3-5.0.1/lib/python3.6/site-packages/tensorflow/python/client/session.py", line 1563, in __init__
    super(Session, self).__init__(target, graph, config=config)
  File "/gpfs/pkgs/mhpcc/anaconda3-5.0.1/lib/python3.6/site-packages/tensorflow/python/client/session.py", line 633, in __init__
    self._session = tf_session.TF_NewSession(self._graph._c_graph, opts)
tensorflow.python.framework.errors_impl.InternalError: Failed to create session.
2019-08-02 11:20:25.039047: E tensorflow/core/common_runtime/direct_session.cc:158] Internal: failed initializing StreamExecutor for CUDA device ordinal 0: Internal: failed call to cuDevicePrimaryCtxRetain: CUDA_ERROR_INVALID_DEVICE
/gpfs/pkgs/mhpcc/anaconda3-5.0.1/lib/python3.6/site-packages/h5py/__init__.py:34: FutureWarning: Conversion of the second argument of issubdtype from `float` to `np.floating` is deprecated. In future, it will be treated as `np.float64 == np.dtype(float).type`.
  from ._conv import register_converters as _register_converters
Using TensorFlow backend.
2019-08-02 11:20:25.045215: E tensorflow/core/common_runtime/direct_session.cc:158] Internal: failed initializing StreamExecutor for CUDA device ordinal 0: Internal: failed call to cuDevicePrimaryCtxRetain: CUDA_ERROR_INVALID_DEVICE
/gpfs/pkgs/mhpcc/anaconda3-5.0.1/lib/python3.6/site-packages/h5py/__init__.py:34: FutureWarning: Conversion of the second argument of issubdtype from `float` to `np.floating` is deprecated. In future, it will be treated as `np.float64 == np.dtype(float).type`.
  from ._conv import register_converters as _register_converters
Using TensorFlow backend.
2019-08-02 11:20:25.049318: E tensorflow/core/common_runtime/direct_session.cc:158] Internal: failed initializing StreamExecutor for CUDA device ordinal 0: Internal: failed call to cuDevicePrimaryCtxRetain: CUDA_ERROR_INVALID_DEVICE
/gpfs/pkgs/mhpcc/anaconda3-5.0.1/lib/python3.6/site-packages/h5py/__init__.py:34: FutureWarning: Conversion of the second argument of issubdtype from `float` to `np.floating` is deprecated. In future, it will be treated as `np.float64 == np.dtype(float).type`.
  from ._conv import register_converters as _register_converters
Using TensorFlow backend.
Traceback (most recent call last):
  File "roundOneSubmit.py", line 23, in <module>
    l.learnThingsCPP(kind=0, file=f, weightFile=wf)
  File "/gpfs/home/m201560/chipboard/learn.py", line 130, in learnThingsCPP
    weights = self.getWeightArray()
  File "/gpfs/home/m201560/chipboard/learn.py", line 199, in getWeightArray
    return self.model.get_weights()[0].tolist()
  File "/gpfs/home/m201560/.local/lib/python3.6/site-packages/keras/engine/network.py", line 492, in get_weights
    return K.batch_get_value(weights)
  File "/gpfs/home/m201560/.local/lib/python3.6/site-packages/keras/backend/tensorflow_backend.py", line 2420, in batch_get_value
    return get_session().run(ops)
  File "/gpfs/home/m201560/.local/lib/python3.6/site-packages/keras/backend/tensorflow_backend.py", line 186, in get_session
    _SESSION = tf.Session(config=config)
  File "/gpfs/pkgs/mhpcc/anaconda3-5.0.1/lib/python3.6/site-packages/tensorflow/python/client/session.py", line 1563, in __init__
    super(Session, self).__init__(target, graph, config=config)
  File "/gpfs/pkgs/mhpcc/anaconda3-5.0.1/lib/python3.6/site-packages/tensorflow/python/client/session.py", line 633, in __init__
    self._session = tf_session.TF_NewSession(self._graph._c_graph, opts)
tensorflow.python.framework.errors_impl.InternalError: Failed to create session.
2019-08-02 11:20:25.054260: E tensorflow/core/common_runtime/direct_session.cc:158] Internal: failed initializing StreamExecutor for CUDA device ordinal 0: Internal: failed call to cuDevicePrimaryCtxRetain: CUDA_ERROR_INVALID_DEVICE
/gpfs/pkgs/mhpcc/anaconda3-5.0.1/lib/python3.6/site-packages/h5py/__init__.py:34: FutureWarning: Conversion of the second argument of issubdtype from `float` to `np.floating` is deprecated. In future, it will be treated as `np.float64 == np.dtype(float).type`.
  from ._conv import register_converters as _register_converters
Using TensorFlow backend.
Traceback (most recent call last):
  File "roundOneSubmit.py", line 23, in <module>
    l.learnThingsCPP(kind=0, file=f, weightFile=wf)
  File "/gpfs/home/m201560/chipboard/learn.py", line 130, in learnThingsCPP
    weights = self.getWeightArray()
  File "/gpfs/home/m201560/chipboard/learn.py", line 199, in getWeightArray
    return self.model.get_weights()[0].tolist()
  File "/gpfs/home/m201560/.local/lib/python3.6/site-packages/keras/engine/network.py", line 492, in get_weights
    return K.batch_get_value(weights)
  File "/gpfs/home/m201560/.local/lib/python3.6/site-packages/keras/backend/tensorflow_backend.py", line 2420, in batch_get_value
    return get_session().run(ops)
  File "/gpfs/home/m201560/.local/lib/python3.6/site-packages/keras/backend/tensorflow_backend.py", line 186, in get_session
    _SESSION = tf.Session(config=config)
  File "/gpfs/pkgs/mhpcc/anaconda3-5.0.1/lib/python3.6/site-packages/tensorflow/python/client/session.py", line 1563, in __init__
    super(Session, self).__init__(target, graph, config=config)
  File "/gpfs/pkgs/mhpcc/anaconda3-5.0.1/lib/python3.6/site-packages/tensorflow/python/client/session.py", line 633, in __init__
    self._session = tf_session.TF_NewSession(self._graph._c_graph, opts)
tensorflow.python.framework.errors_impl.InternalError: Failed to create session.
2019-08-02 11:20:25.061400: E tensorflow/core/common_runtime/direct_session.cc:158] Internal: failed initializing StreamExecutor for CUDA device ordinal 0: Internal: failed call to cuDevicePrimaryCtxRetain: CUDA_ERROR_INVALID_DEVICE
/gpfs/pkgs/mhpcc/anaconda3-5.0.1/lib/python3.6/site-packages/h5py/__init__.py:34: FutureWarning: Conversion of the second argument of issubdtype from `float` to `np.floating` is deprecated. In future, it will be treated as `np.float64 == np.dtype(float).type`.
  from ._conv import register_converters as _register_converters
Using TensorFlow backend.
2019-08-02 11:20:25.063074: E tensorflow/core/common_runtime/direct_session.cc:158] Internal: failed initializing StreamExecutor for CUDA device ordinal 0: Internal: failed call to cuDevicePrimaryCtxRetain: CUDA_ERROR_INVALID_DEVICE
/gpfs/pkgs/mhpcc/anaconda3-5.0.1/lib/python3.6/site-packages/h5py/__init__.py:34: FutureWarning: Conversion of the second argument of issubdtype from `float` to `np.floating` is deprecated. In future, it will be treated as `np.float64 == np.dtype(float).type`.
  from ._conv import register_converters as _register_converters
Using TensorFlow backend.
2019-08-02 11:20:25.063512: E tensorflow/core/common_runtime/direct_session.cc:158] Internal: failed initializing StreamExecutor for CUDA device ordinal 0: Internal: failed call to cuDevicePrimaryCtxRetain: CUDA_ERROR_INVALID_DEVICE
/gpfs/pkgs/mhpcc/anaconda3-5.0.1/lib/python3.6/site-packages/h5py/__init__.py:34: FutureWarning: Conversion of the second argument of issubdtype from `float` to `np.floating` is deprecated. In future, it will be treated as `np.float64 == np.dtype(float).type`.
  from ._conv import register_converters as _register_converters
Using TensorFlow backend.
2019-08-02 11:20:25.064996: E tensorflow/core/common_runtime/direct_session.cc:158] Internal: failed initializing StreamExecutor for CUDA device ordinal 0: Internal: failed call to cuDevicePrimaryCtxRetain: CUDA_ERROR_INVALID_DEVICE
/gpfs/pkgs/mhpcc/anaconda3-5.0.1/lib/python3.6/site-packages/h5py/__init__.py:34: FutureWarning: Conversion of the second argument of issubdtype from `float` to `np.floating` is deprecated. In future, it will be treated as `np.float64 == np.dtype(float).type`.
  from ._conv import register_converters as _register_converters
Using TensorFlow backend.
Traceback (most recent call last):
  File "roundOneSubmit.py", line 23, in <module>
    l.learnThingsCPP(kind=0, file=f, weightFile=wf)
  File "/gpfs/home/m201560/chipboard/learn.py", line 130, in learnThingsCPP
    weights = self.getWeightArray()
  File "/gpfs/home/m201560/chipboard/learn.py", line 199, in getWeightArray
    return self.model.get_weights()[0].tolist()
  File "/gpfs/home/m201560/.local/lib/python3.6/site-packages/keras/engine/network.py", line 492, in get_weights
    return K.batch_get_value(weights)
  File "/gpfs/home/m201560/.local/lib/python3.6/site-packages/keras/backend/tensorflow_backend.py", line 2420, in batch_get_value
    return get_session().run(ops)
  File "/gpfs/home/m201560/.local/lib/python3.6/site-packages/keras/backend/tensorflow_backend.py", line 186, in get_session
    _SESSION = tf.Session(config=config)
  File "/gpfs/pkgs/mhpcc/anaconda3-5.0.1/lib/python3.6/site-packages/tensorflow/python/client/session.py", line 1563, in __init__
    super(Session, self).__init__(target, graph, config=config)
  File "/gpfs/pkgs/mhpcc/anaconda3-5.0.1/lib/python3.6/site-packages/tensorflow/python/client/session.py", line 633, in __init__
    self._session = tf_session.TF_NewSession(self._graph._c_graph, opts)
tensorflow.python.framework.errors_impl.InternalError: Failed to create session.
Traceback (most recent call last):
  File "roundOneSubmit.py", line 23, in <module>
    l.learnThingsCPP(kind=0, file=f, weightFile=wf)
  File "/gpfs/home/m201560/chipboard/learn.py", line 130, in learnThingsCPP
    weights = self.getWeightArray()
  File "/gpfs/home/m201560/chipboard/learn.py", line 199, in getWeightArray
    return self.model.get_weights()[0].tolist()
  File "/gpfs/home/m201560/.local/lib/python3.6/site-packages/keras/engine/network.py", line 492, in get_weights
    return K.batch_get_value(weights)
  File "/gpfs/home/m201560/.local/lib/python3.6/site-packages/keras/backend/tensorflow_backend.py", line 2420, in batch_get_value
    return get_session().run(ops)
  File "/gpfs/home/m201560/.local/lib/python3.6/site-packages/keras/backend/tensorflow_backend.py", line 186, in get_session
    _SESSION = tf.Session(config=config)
  File "/gpfs/pkgs/mhpcc/anaconda3-5.0.1/lib/python3.6/site-packages/tensorflow/python/client/session.py", line 1563, in __init__
    super(Session, self).__init__(target, graph, config=config)
  File "/gpfs/pkgs/mhpcc/anaconda3-5.0.1/lib/python3.6/site-packages/tensorflow/python/client/session.py", line 633, in __init__
    self._session = tf_session.TF_NewSession(self._graph._c_graph, opts)
tensorflow.python.framework.errors_impl.InternalError: Failed to create session.
Traceback (most recent call last):
  File "roundOneSubmit.py", line 23, in <module>
    l.learnThingsCPP(kind=0, file=f, weightFile=wf)
  File "/gpfs/home/m201560/chipboard/learn.py", line 130, in learnThingsCPP
    weights = self.getWeightArray()
  File "/gpfs/home/m201560/chipboard/learn.py", line 199, in getWeightArray
    return self.model.get_weights()[0].tolist()
  File "/gpfs/home/m201560/.local/lib/python3.6/site-packages/keras/engine/network.py", line 492, in get_weights
    return K.batch_get_value(weights)
  File "/gpfs/home/m201560/.local/lib/python3.6/site-packages/keras/backend/tensorflow_backend.py", line 2420, in batch_get_value
    return get_session().run(ops)
  File "/gpfs/home/m201560/.local/lib/python3.6/site-packages/keras/backend/tensorflow_backend.py", line 186, in get_session
    _SESSION = tf.Session(config=config)
  File "/gpfs/pkgs/mhpcc/anaconda3-5.0.1/lib/python3.6/site-packages/tensorflow/python/client/session.py", line 1563, in __init__
    super(Session, self).__init__(target, graph, config=config)
  File "/gpfs/pkgs/mhpcc/anaconda3-5.0.1/lib/python3.6/site-packages/tensorflow/python/client/session.py", line 633, in __init__
    self._session = tf_session.TF_NewSession(self._graph._c_graph, opts)
tensorflow.python.framework.errors_impl.InternalError: Failed to create session.
Traceback (most recent call last):
  File "roundOneSubmit.py", line 23, in <module>
    l.learnThingsCPP(kind=0, file=f, weightFile=wf)
  File "/gpfs/home/m201560/chipboard/learn.py", line 130, in learnThingsCPP
    weights = self.getWeightArray()
  File "/gpfs/home/m201560/chipboard/learn.py", line 199, in getWeightArray
    return self.model.get_weights()[0].tolist()
  File "/gpfs/home/m201560/.local/lib/python3.6/site-packages/keras/engine/network.py", line 492, in get_weights
    return K.batch_get_value(weights)
  File "/gpfs/home/m201560/.local/lib/python3.6/site-packages/keras/backend/tensorflow_backend.py", line 2420, in batch_get_value
    return get_session().run(ops)
  File "/gpfs/home/m201560/.local/lib/python3.6/site-packages/keras/backend/tensorflow_backend.py", line 186, in get_session
    _SESSION = tf.Session(config=config)
  File "/gpfs/pkgs/mhpcc/anaconda3-5.0.1/lib/python3.6/site-packages/tensorflow/python/client/session.py", line 1563, in __init__
    super(Session, self).__init__(target, graph, config=config)
  File "/gpfs/pkgs/mhpcc/anaconda3-5.0.1/lib/python3.6/site-packages/tensorflow/python/client/session.py", line 633, in __init__
    self._session = tf_session.TF_NewSession(self._graph._c_graph, opts)
tensorflow.python.framework.errors_impl.InternalError: Failed to create session.
Traceback (most recent call last):
  File "roundOneSubmit.py", line 23, in <module>
    l.learnThingsCPP(kind=0, file=f, weightFile=wf)
  File "/gpfs/home/m201560/chipboard/learn.py", line 130, in learnThingsCPP
    weights = self.getWeightArray()
  File "/gpfs/home/m201560/chipboard/learn.py", line 199, in getWeightArray
    return self.model.get_weights()[0].tolist()
  File "/gpfs/home/m201560/.local/lib/python3.6/site-packages/keras/engine/network.py", line 492, in get_weights
    return K.batch_get_value(weights)
  File "/gpfs/home/m201560/.local/lib/python3.6/site-packages/keras/backend/tensorflow_backend.py", line 2420, in batch_get_value
    return get_session().run(ops)
  File "/gpfs/home/m201560/.local/lib/python3.6/site-packages/keras/backend/tensorflow_backend.py", line 186, in get_session
    _SESSION = tf.Session(config=config)
  File "/gpfs/pkgs/mhpcc/anaconda3-5.0.1/lib/python3.6/site-packages/tensorflow/python/client/session.py", line 1563, in __init__
    super(Session, self).__init__(target, graph, config=config)
  File "/gpfs/pkgs/mhpcc/anaconda3-5.0.1/lib/python3.6/site-packages/tensorflow/python/client/session.py", line 633, in __init__
    self._session = tf_session.TF_NewSession(self._graph._c_graph, opts)
tensorflow.python.framework.errors_impl.InternalError: Failed to create session.
Traceback (most recent call last):
  File "roundOneSubmit.py", line 23, in <module>
    l.learnThingsCPP(kind=0, file=f, weightFile=wf)
  File "/gpfs/home/m201560/chipboard/learn.py", line 130, in learnThingsCPP
    weights = self.getWeightArray()
  File "/gpfs/home/m201560/chipboard/learn.py", line 199, in getWeightArray
    return self.model.get_weights()[0].tolist()
  File "/gpfs/home/m201560/.local/lib/python3.6/site-packages/keras/engine/network.py", line 492, in get_weights
    return K.batch_get_value(weights)
  File "/gpfs/home/m201560/.local/lib/python3.6/site-packages/keras/backend/tensorflow_backend.py", line 2420, in batch_get_value
    return get_session().run(ops)
  File "/gpfs/home/m201560/.local/lib/python3.6/site-packages/keras/backend/tensorflow_backend.py", line 186, in get_session
    _SESSION = tf.Session(config=config)
  File "/gpfs/pkgs/mhpcc/anaconda3-5.0.1/lib/python3.6/site-packages/tensorflow/python/client/session.py", line 1563, in __init__
    super(Session, self).__init__(target, graph, config=config)
  File "/gpfs/pkgs/mhpcc/anaconda3-5.0.1/lib/python3.6/site-packages/tensorflow/python/client/session.py", line 633, in __init__
    self._session = tf_session.TF_NewSession(self._graph._c_graph, opts)
tensorflow.python.framework.errors_impl.InternalError: Failed to create session.
[cr2cn15:90444] 79 more processes have sent help message help-mpi-btl-openib.txt / default subnet prefix
[cr2cn15:90444] Set MCA parameter "orte_base_help_aggregate" to 0 to see all help / error messages
2019-08-02 11:20:28.558673: I tensorflow/core/common_runtime/gpu/gpu_device.cc:952] Device interconnect StreamExecutor with strength 1 edge matrix:
2019-08-02 11:20:28.558718: I tensorflow/core/common_runtime/gpu/gpu_device.cc:958]      0 1 2 3 
2019-08-02 11:20:28.558733: I tensorflow/core/common_runtime/gpu/gpu_device.cc:971] 0:   N Y N N 
2019-08-02 11:20:28.558743: I tensorflow/core/common_runtime/gpu/gpu_device.cc:971] 1:   Y N N N 
2019-08-02 11:20:28.558753: I tensorflow/core/common_runtime/gpu/gpu_device.cc:971] 2:   N N N Y 
2019-08-02 11:20:28.558763: I tensorflow/core/common_runtime/gpu/gpu_device.cc:971] 3:   N N Y N 
2019-08-02 11:20:28.559504: I tensorflow/core/common_runtime/gpu/gpu_device.cc:1084] Created TensorFlow device (/job:localhost/replica:0/task:0/device:GPU:0 with 15163 MB memory) -> physical GPU (device: 0, name: Tesla P100-SXM2-16GB, pci bus id: 0002:01:00.0, compute capability: 6.0)
2019-08-02 11:20:28.726624: I tensorflow/core/common_runtime/gpu/gpu_device.cc:1084] Created TensorFlow device (/job:localhost/replica:0/task:0/device:GPU:1 with 15163 MB memory) -> physical GPU (device: 1, name: Tesla P100-SXM2-16GB, pci bus id: 0003:01:00.0, compute capability: 6.0)
2019-08-02 11:20:28.893670: I tensorflow/core/common_runtime/gpu/gpu_device.cc:1084] Created TensorFlow device (/job:localhost/replica:0/task:0/device:GPU:2 with 15163 MB memory) -> physical GPU (device: 2, name: Tesla P100-SXM2-16GB, pci bus id: 0006:01:00.0, compute capability: 6.0)
2019-08-02 11:20:29.060214: I tensorflow/core/common_runtime/gpu/gpu_device.cc:1084] Created TensorFlow device (/job:localhost/replica:0/task:0/device:GPU:3 with 15163 MB memory) -> physical GPU (device: 3, name: Tesla P100-SXM2-16GB, pci bus id: 0007:01:00.0, compute capability: 6.0)
=>> PBS: job killed: walltime 1827 exceeded limit 1800
[warn] Epoll ADD(4) on fd 309 failed.  Old events were 0; read change was 0 (none); write change was 1 (add): Bad file descriptor
-bash: line 1: 90350 Terminated              /var/spool/pbs/mom_priv/jobs/71048\[8\].ir1utl01.SC
mpirun: abort is already in progress...hit ctrl-c again to forcibly terminate

