--------------------------------------------------------------------------
WARNING: There are more than one active ports on host 'cr1cn06', but the
default subnet GID prefix was detected on more than one of these
ports.  If these ports are connected to different physical IB
networks, this configuration will fail in Open MPI.  This version of
Open MPI requires that every physically separate IB subnet that is
used between connected MPI processes must have different subnet ID
values.

Please see this FAQ entry for more details:

  http://www.open-mpi.org/faq/?category=openfabrics#ofa-default-subnet-gid

NOTE: You can turn off this warning by setting the MCA parameter
      btl_openib_warn_default_gid_prefix to 0.
--------------------------------------------------------------------------
2019-08-02 11:20:22.609263: E tensorflow/core/common_runtime/direct_session.cc:158] Internal: failed initializing StreamExecutor for CUDA device ordinal 0: Internal: failed call to cuDevicePrimaryCtxRetain: CUDA_ERROR_INVALID_DEVICE
/gpfs/pkgs/mhpcc/anaconda3-5.0.1/lib/python3.6/site-packages/h5py/__init__.py:34: FutureWarning: Conversion of the second argument of issubdtype from `float` to `np.floating` is deprecated. In future, it will be treated as `np.float64 == np.dtype(float).type`.
  from ._conv import register_converters as _register_converters
Using TensorFlow backend.
2019-08-02 11:20:22.666935: E tensorflow/core/common_runtime/direct_session.cc:158] Internal: failed initializing StreamExecutor for CUDA device ordinal 0: Internal: failed call to cuDevicePrimaryCtxRetain: CUDA_ERROR_INVALID_DEVICE
/gpfs/pkgs/mhpcc/anaconda3-5.0.1/lib/python3.6/site-packages/h5py/__init__.py:34: FutureWarning: Conversion of the second argument of issubdtype from `float` to `np.floating` is deprecated. In future, it will be treated as `np.float64 == np.dtype(float).type`.
  from ._conv import register_converters as _register_converters
Using TensorFlow backend.
2019-08-02 11:20:22.683481: E tensorflow/core/common_runtime/direct_session.cc:158] Internal: failed initializing StreamExecutor for CUDA device ordinal 0: Internal: failed call to cuDevicePrimaryCtxRetain: CUDA_ERROR_INVALID_DEVICE
/gpfs/pkgs/mhpcc/anaconda3-5.0.1/lib/python3.6/site-packages/h5py/__init__.py:34: FutureWarning: Conversion of the second argument of issubdtype from `float` to `np.floating` is deprecated. In future, it will be treated as `np.float64 == np.dtype(float).type`.
  from ._conv import register_converters as _register_converters
Using TensorFlow backend.
2019-08-02 11:20:22.832568: E tensorflow/core/common_runtime/direct_session.cc:158] Internal: failed initializing StreamExecutor for CUDA device ordinal 0: Internal: failed call to cuDevicePrimaryCtxRetain: CUDA_ERROR_INVALID_DEVICE
/gpfs/pkgs/mhpcc/anaconda3-5.0.1/lib/python3.6/site-packages/h5py/__init__.py:34: FutureWarning: Conversion of the second argument of issubdtype from `float` to `np.floating` is deprecated. In future, it will be treated as `np.float64 == np.dtype(float).type`.
  from ._conv import register_converters as _register_converters
Using TensorFlow backend.
2019-08-02 11:20:22.861998: E tensorflow/core/common_runtime/direct_session.cc:158] Internal: failed initializing StreamExecutor for CUDA device ordinal 0: Internal: failed call to cuDevicePrimaryCtxRetain: CUDA_ERROR_INVALID_DEVICE
/gpfs/pkgs/mhpcc/anaconda3-5.0.1/lib/python3.6/site-packages/h5py/__init__.py:34: FutureWarning: Conversion of the second argument of issubdtype from `float` to `np.floating` is deprecated. In future, it will be treated as `np.float64 == np.dtype(float).type`.
  from ._conv import register_converters as _register_converters
Using TensorFlow backend.
2019-08-02 11:20:22.905206: E tensorflow/core/common_runtime/direct_session.cc:158] Internal: failed initializing StreamExecutor for CUDA device ordinal 0: Internal: failed call to cuDevicePrimaryCtxRetain: CUDA_ERROR_INVALID_DEVICE
/gpfs/pkgs/mhpcc/anaconda3-5.0.1/lib/python3.6/site-packages/h5py/__init__.py:34: FutureWarning: Conversion of the second argument of issubdtype from `float` to `np.floating` is deprecated. In future, it will be treated as `np.float64 == np.dtype(float).type`.
  from ._conv import register_converters as _register_converters
Using TensorFlow backend.
2019-08-02 11:20:22.921506: E tensorflow/core/common_runtime/direct_session.cc:158] Internal: failed initializing StreamExecutor for CUDA device ordinal 0: Internal: failed call to cuDevicePrimaryCtxRetain: CUDA_ERROR_INVALID_DEVICE
/gpfs/pkgs/mhpcc/anaconda3-5.0.1/lib/python3.6/site-packages/h5py/__init__.py:34: FutureWarning: Conversion of the second argument of issubdtype from `float` to `np.floating` is deprecated. In future, it will be treated as `np.float64 == np.dtype(float).type`.
  from ._conv import register_converters as _register_converters
Using TensorFlow backend.
2019-08-02 11:20:22.983525: E tensorflow/core/common_runtime/direct_session.cc:158] Internal: failed initializing StreamExecutor for CUDA device ordinal 0: Internal: failed call to cuDevicePrimaryCtxRetain: CUDA_ERROR_INVALID_DEVICE
/gpfs/pkgs/mhpcc/anaconda3-5.0.1/lib/python3.6/site-packages/h5py/__init__.py:34: FutureWarning: Conversion of the second argument of issubdtype from `float` to `np.floating` is deprecated. In future, it will be treated as `np.float64 == np.dtype(float).type`.
  from ._conv import register_converters as _register_converters
Using TensorFlow backend.
2019-08-02 11:20:23.000545: E tensorflow/core/common_runtime/direct_session.cc:158] Internal: failed initializing StreamExecutor for CUDA device ordinal 0: Internal: failed call to cuDevicePrimaryCtxRetain: CUDA_ERROR_INVALID_DEVICE
/gpfs/pkgs/mhpcc/anaconda3-5.0.1/lib/python3.6/site-packages/h5py/__init__.py:34: FutureWarning: Conversion of the second argument of issubdtype from `float` to `np.floating` is deprecated. In future, it will be treated as `np.float64 == np.dtype(float).type`.
  from ._conv import register_converters as _register_converters
Using TensorFlow backend.
2019-08-02 11:20:23.073428: E tensorflow/core/common_runtime/direct_session.cc:158] Internal: failed initializing StreamExecutor for CUDA device ordinal 0: Internal: failed call to cuDevicePrimaryCtxRetain: CUDA_ERROR_INVALID_DEVICE
/gpfs/pkgs/mhpcc/anaconda3-5.0.1/lib/python3.6/site-packages/h5py/__init__.py:34: FutureWarning: Conversion of the second argument of issubdtype from `float` to `np.floating` is deprecated. In future, it will be treated as `np.float64 == np.dtype(float).type`.
  from ._conv import register_converters as _register_converters
Using TensorFlow backend.
2019-08-02 11:20:23.077027: E tensorflow/core/common_runtime/direct_session.cc:158] Internal: failed initializing StreamExecutor for CUDA device ordinal 0: Internal: failed call to cuDevicePrimaryCtxRetain: CUDA_ERROR_INVALID_DEVICE
/gpfs/pkgs/mhpcc/anaconda3-5.0.1/lib/python3.6/site-packages/h5py/__init__.py:34: FutureWarning: Conversion of the second argument of issubdtype from `float` to `np.floating` is deprecated. In future, it will be treated as `np.float64 == np.dtype(float).type`.
  from ._conv import register_converters as _register_converters
Using TensorFlow backend.
2019-08-02 11:20:23.122541: E tensorflow/core/common_runtime/direct_session.cc:158] Internal: failed initializing StreamExecutor for CUDA device ordinal 0: Internal: failed call to cuDevicePrimaryCtxRetain: CUDA_ERROR_INVALID_DEVICE
/gpfs/pkgs/mhpcc/anaconda3-5.0.1/lib/python3.6/site-packages/h5py/__init__.py:34: FutureWarning: Conversion of the second argument of issubdtype from `float` to `np.floating` is deprecated. In future, it will be treated as `np.float64 == np.dtype(float).type`.
  from ._conv import register_converters as _register_converters
Using TensorFlow backend.
Traceback (most recent call last):
  File "roundOneSubmit.py", line 23, in <module>
    l.learnThingsCPP(kind=0, file=f, weightFile=wf)
  File "/gpfs/home/m201560/chipboard/learn.py", line 130, in learnThingsCPP
    weights = self.getWeightArray()
  File "/gpfs/home/m201560/chipboard/learn.py", line 199, in getWeightArray
    return self.model.get_weights()[0].tolist()
  File "/gpfs/home/m201560/.local/lib/python3.6/site-packages/keras/engine/network.py", line 492, in get_weights
    return K.batch_get_value(weights)
  File "/gpfs/home/m201560/.local/lib/python3.6/site-packages/keras/backend/tensorflow_backend.py", line 2420, in batch_get_value
    return get_session().run(ops)
  File "/gpfs/home/m201560/.local/lib/python3.6/site-packages/keras/backend/tensorflow_backend.py", line 186, in get_session
    _SESSION = tf.Session(config=config)
  File "/gpfs/pkgs/mhpcc/anaconda3-5.0.1/lib/python3.6/site-packages/tensorflow/python/client/session.py", line 1563, in __init__
    super(Session, self).__init__(target, graph, config=config)
  File "/gpfs/pkgs/mhpcc/anaconda3-5.0.1/lib/python3.6/site-packages/tensorflow/python/client/session.py", line 633, in __init__
    self._session = tf_session.TF_NewSession(self._graph._c_graph, opts)
tensorflow.python.framework.errors_impl.InternalError: Failed to create session.
Traceback (most recent call last):
  File "roundOneSubmit.py", line 23, in <module>
    l.learnThingsCPP(kind=0, file=f, weightFile=wf)
  File "/gpfs/home/m201560/chipboard/learn.py", line 130, in learnThingsCPP
    weights = self.getWeightArray()
  File "/gpfs/home/m201560/chipboard/learn.py", line 199, in getWeightArray
    return self.model.get_weights()[0].tolist()
  File "/gpfs/home/m201560/.local/lib/python3.6/site-packages/keras/engine/network.py", line 492, in get_weights
    return K.batch_get_value(weights)
  File "/gpfs/home/m201560/.local/lib/python3.6/site-packages/keras/backend/tensorflow_backend.py", line 2420, in batch_get_value
    return get_session().run(ops)
  File "/gpfs/home/m201560/.local/lib/python3.6/site-packages/keras/backend/tensorflow_backend.py", line 186, in get_session
    _SESSION = tf.Session(config=config)
  File "/gpfs/pkgs/mhpcc/anaconda3-5.0.1/lib/python3.6/site-packages/tensorflow/python/client/session.py", line 1563, in __init__
    super(Session, self).__init__(target, graph, config=config)
  File "/gpfs/pkgs/mhpcc/anaconda3-5.0.1/lib/python3.6/site-packages/tensorflow/python/client/session.py", line 633, in __init__
    self._session = tf_session.TF_NewSession(self._graph._c_graph, opts)
tensorflow.python.framework.errors_impl.InternalError: Failed to create session.
Traceback (most recent call last):
  File "roundOneSubmit.py", line 23, in <module>
    l.learnThingsCPP(kind=0, file=f, weightFile=wf)
  File "/gpfs/home/m201560/chipboard/learn.py", line 130, in learnThingsCPP
    weights = self.getWeightArray()
  File "/gpfs/home/m201560/chipboard/learn.py", line 199, in getWeightArray
    return self.model.get_weights()[0].tolist()
  File "/gpfs/home/m201560/.local/lib/python3.6/site-packages/keras/engine/network.py", line 492, in get_weights
    return K.batch_get_value(weights)
  File "/gpfs/home/m201560/.local/lib/python3.6/site-packages/keras/backend/tensorflow_backend.py", line 2420, in batch_get_value
    return get_session().run(ops)
  File "/gpfs/home/m201560/.local/lib/python3.6/site-packages/keras/backend/tensorflow_backend.py", line 186, in get_session
    _SESSION = tf.Session(config=config)
  File "/gpfs/pkgs/mhpcc/anaconda3-5.0.1/lib/python3.6/site-packages/tensorflow/python/client/session.py", line 1563, in __init__
    super(Session, self).__init__(target, graph, config=config)
  File "/gpfs/pkgs/mhpcc/anaconda3-5.0.1/lib/python3.6/site-packages/tensorflow/python/client/session.py", line 633, in __init__
    self._session = tf_session.TF_NewSession(self._graph._c_graph, opts)
tensorflow.python.framework.errors_impl.InternalError: Failed to create session.
2019-08-02 11:20:23.136701: I tensorflow/core/common_runtime/gpu/gpu_device.cc:1392] Found device 0 with properties: 
name: Tesla P100-SXM2-16GB major: 6 minor: 0 memoryClockRate(GHz): 1.4805
pciBusID: 0002:01:00.0
totalMemory: 15.90GiB freeMemory: 15.64GiB
Traceback (most recent call last):
  File "roundOneSubmit.py", line 23, in <module>
    l.learnThingsCPP(kind=0, file=f, weightFile=wf)
  File "/gpfs/home/m201560/chipboard/learn.py", line 130, in learnThingsCPP
    weights = self.getWeightArray()
  File "/gpfs/home/m201560/chipboard/learn.py", line 199, in getWeightArray
    return self.model.get_weights()[0].tolist()
  File "/gpfs/home/m201560/.local/lib/python3.6/site-packages/keras/engine/network.py", line 492, in get_weights
    return K.batch_get_value(weights)
  File "/gpfs/home/m201560/.local/lib/python3.6/site-packages/keras/backend/tensorflow_backend.py", line 2420, in batch_get_value
    return get_session().run(ops)
  File "/gpfs/home/m201560/.local/lib/python3.6/site-packages/keras/backend/tensorflow_backend.py", line 186, in get_session
    _SESSION = tf.Session(config=config)
  File "/gpfs/pkgs/mhpcc/anaconda3-5.0.1/lib/python3.6/site-packages/tensorflow/python/client/session.py", line 1563, in __init__
    super(Session, self).__init__(target, graph, config=config)
  File "/gpfs/pkgs/mhpcc/anaconda3-5.0.1/lib/python3.6/site-packages/tensorflow/python/client/session.py", line 633, in __init__
    self._session = tf_session.TF_NewSession(self._graph._c_graph, opts)
tensorflow.python.framework.errors_impl.InternalError: Failed to create session.
Traceback (most recent call last):
  File "roundOneSubmit.py", line 23, in <module>
    l.learnThingsCPP(kind=0, file=f, weightFile=wf)
  File "/gpfs/home/m201560/chipboard/learn.py", line 130, in learnThingsCPP
    weights = self.getWeightArray()
  File "/gpfs/home/m201560/chipboard/learn.py", line 199, in getWeightArray
    return self.model.get_weights()[0].tolist()
  File "/gpfs/home/m201560/.local/lib/python3.6/site-packages/keras/engine/network.py", line 492, in get_weights
    return K.batch_get_value(weights)
  File "/gpfs/home/m201560/.local/lib/python3.6/site-packages/keras/backend/tensorflow_backend.py", line 2420, in batch_get_value
    return get_session().run(ops)
  File "/gpfs/home/m201560/.local/lib/python3.6/site-packages/keras/backend/tensorflow_backend.py", line 186, in get_session
    _SESSION = tf.Session(config=config)
  File "/gpfs/pkgs/mhpcc/anaconda3-5.0.1/lib/python3.6/site-packages/tensorflow/python/client/session.py", line 1563, in __init__
    super(Session, self).__init__(target, graph, config=config)
  File "/gpfs/pkgs/mhpcc/anaconda3-5.0.1/lib/python3.6/site-packages/tensorflow/python/client/session.py", line 633, in __init__
    self._session = tf_session.TF_NewSession(self._graph._c_graph, opts)
tensorflow.python.framework.errors_impl.InternalError: Failed to create session.
Traceback (most recent call last):
  File "roundOneSubmit.py", line 23, in <module>
    l.learnThingsCPP(kind=0, file=f, weightFile=wf)
  File "/gpfs/home/m201560/chipboard/learn.py", line 130, in learnThingsCPP
    weights = self.getWeightArray()
  File "/gpfs/home/m201560/chipboard/learn.py", line 199, in getWeightArray
    return self.model.get_weights()[0].tolist()
  File "/gpfs/home/m201560/.local/lib/python3.6/site-packages/keras/engine/network.py", line 492, in get_weights
    return K.batch_get_value(weights)
  File "/gpfs/home/m201560/.local/lib/python3.6/site-packages/keras/backend/tensorflow_backend.py", line 2420, in batch_get_value
    return get_session().run(ops)
  File "/gpfs/home/m201560/.local/lib/python3.6/site-packages/keras/backend/tensorflow_backend.py", line 186, in get_session
    _SESSION = tf.Session(config=config)
  File "/gpfs/pkgs/mhpcc/anaconda3-5.0.1/lib/python3.6/site-packages/tensorflow/python/client/session.py", line 1563, in __init__
    super(Session, self).__init__(target, graph, config=config)
  File "/gpfs/pkgs/mhpcc/anaconda3-5.0.1/lib/python3.6/site-packages/tensorflow/python/client/session.py", line 633, in __init__
    self._session = tf_session.TF_NewSession(self._graph._c_graph, opts)
tensorflow.python.framework.errors_impl.InternalError: Failed to create session.
Traceback (most recent call last):
  File "roundOneSubmit.py", line 23, in <module>
    l.learnThingsCPP(kind=0, file=f, weightFile=wf)
  File "/gpfs/home/m201560/chipboard/learn.py", line 130, in learnThingsCPP
    weights = self.getWeightArray()
  File "/gpfs/home/m201560/chipboard/learn.py", line 199, in getWeightArray
    return self.model.get_weights()[0].tolist()
  File "/gpfs/home/m201560/.local/lib/python3.6/site-packages/keras/engine/network.py", line 492, in get_weights
    return K.batch_get_value(weights)
  File "/gpfs/home/m201560/.local/lib/python3.6/site-packages/keras/backend/tensorflow_backend.py", line 2420, in batch_get_value
    return get_session().run(ops)
  File "/gpfs/home/m201560/.local/lib/python3.6/site-packages/keras/backend/tensorflow_backend.py", line 186, in get_session
    _SESSION = tf.Session(config=config)
  File "/gpfs/pkgs/mhpcc/anaconda3-5.0.1/lib/python3.6/site-packages/tensorflow/python/client/session.py", line 1563, in __init__
    super(Session, self).__init__(target, graph, config=config)
  File "/gpfs/pkgs/mhpcc/anaconda3-5.0.1/lib/python3.6/site-packages/tensorflow/python/client/session.py", line 633, in __init__
    self._session = tf_session.TF_NewSession(self._graph._c_graph, opts)
tensorflow.python.framework.errors_impl.InternalError: Failed to create session.
Traceback (most recent call last):
  File "roundOneSubmit.py", line 23, in <module>
    l.learnThingsCPP(kind=0, file=f, weightFile=wf)
  File "/gpfs/home/m201560/chipboard/learn.py", line 130, in learnThingsCPP
    weights = self.getWeightArray()
  File "/gpfs/home/m201560/chipboard/learn.py", line 199, in getWeightArray
    return self.model.get_weights()[0].tolist()
  File "/gpfs/home/m201560/.local/lib/python3.6/site-packages/keras/engine/network.py", line 492, in get_weights
    return K.batch_get_value(weights)
  File "/gpfs/home/m201560/.local/lib/python3.6/site-packages/keras/backend/tensorflow_backend.py", line 2420, in batch_get_value
    return get_session().run(ops)
  File "/gpfs/home/m201560/.local/lib/python3.6/site-packages/keras/backend/tensorflow_backend.py", line 186, in get_session
    _SESSION = tf.Session(config=config)
  File "/gpfs/pkgs/mhpcc/anaconda3-5.0.1/lib/python3.6/site-packages/tensorflow/python/client/session.py", line 1563, in __init__
    super(Session, self).__init__(target, graph, config=config)
  File "/gpfs/pkgs/mhpcc/anaconda3-5.0.1/lib/python3.6/site-packages/tensorflow/python/client/session.py", line 633, in __init__
    self._session = tf_session.TF_NewSession(self._graph._c_graph, opts)
tensorflow.python.framework.errors_impl.InternalError: Failed to create session.
Traceback (most recent call last):
  File "roundOneSubmit.py", line 23, in <module>
    l.learnThingsCPP(kind=0, file=f, weightFile=wf)
  File "/gpfs/home/m201560/chipboard/learn.py", line 130, in learnThingsCPP
    weights = self.getWeightArray()
  File "/gpfs/home/m201560/chipboard/learn.py", line 199, in getWeightArray
    return self.model.get_weights()[0].tolist()
  File "/gpfs/home/m201560/.local/lib/python3.6/site-packages/keras/engine/network.py", line 492, in get_weights
    return K.batch_get_value(weights)
  File "/gpfs/home/m201560/.local/lib/python3.6/site-packages/keras/backend/tensorflow_backend.py", line 2420, in batch_get_value
    return get_session().run(ops)
  File "/gpfs/home/m201560/.local/lib/python3.6/site-packages/keras/backend/tensorflow_backend.py", line 186, in get_session
    _SESSION = tf.Session(config=config)
  File "/gpfs/pkgs/mhpcc/anaconda3-5.0.1/lib/python3.6/site-packages/tensorflow/python/client/session.py", line 1563, in __init__
    super(Session, self).__init__(target, graph, config=config)
  File "/gpfs/pkgs/mhpcc/anaconda3-5.0.1/lib/python3.6/site-packages/tensorflow/python/client/session.py", line 633, in __init__
    self._session = tf_session.TF_NewSession(self._graph._c_graph, opts)
tensorflow.python.framework.errors_impl.InternalError: Failed to create session.
Traceback (most recent call last):
  File "roundOneSubmit.py", line 23, in <module>
    l.learnThingsCPP(kind=0, file=f, weightFile=wf)
  File "/gpfs/home/m201560/chipboard/learn.py", line 130, in learnThingsCPP
    weights = self.getWeightArray()
  File "/gpfs/home/m201560/chipboard/learn.py", line 199, in getWeightArray
    return self.model.get_weights()[0].tolist()
  File "/gpfs/home/m201560/.local/lib/python3.6/site-packages/keras/engine/network.py", line 492, in get_weights
    return K.batch_get_value(weights)
  File "/gpfs/home/m201560/.local/lib/python3.6/site-packages/keras/backend/tensorflow_backend.py", line 2420, in batch_get_value
    return get_session().run(ops)
  File "/gpfs/home/m201560/.local/lib/python3.6/site-packages/keras/backend/tensorflow_backend.py", line 186, in get_session
    _SESSION = tf.Session(config=config)
  File "/gpfs/pkgs/mhpcc/anaconda3-5.0.1/lib/python3.6/site-packages/tensorflow/python/client/session.py", line 1563, in __init__
    super(Session, self).__init__(target, graph, config=config)
  File "/gpfs/pkgs/mhpcc/anaconda3-5.0.1/lib/python3.6/site-packages/tensorflow/python/client/session.py", line 633, in __init__
    self._session = tf_session.TF_NewSession(self._graph._c_graph, opts)
tensorflow.python.framework.errors_impl.InternalError: Failed to create session.
Traceback (most recent call last):
  File "roundOneSubmit.py", line 23, in <module>
    l.learnThingsCPP(kind=0, file=f, weightFile=wf)
  File "/gpfs/home/m201560/chipboard/learn.py", line 130, in learnThingsCPP
    weights = self.getWeightArray()
  File "/gpfs/home/m201560/chipboard/learn.py", line 199, in getWeightArray
    return self.model.get_weights()[0].tolist()
  File "/gpfs/home/m201560/.local/lib/python3.6/site-packages/keras/engine/network.py", line 492, in get_weights
    return K.batch_get_value(weights)
  File "/gpfs/home/m201560/.local/lib/python3.6/site-packages/keras/backend/tensorflow_backend.py", line 2420, in batch_get_value
    return get_session().run(ops)
  File "/gpfs/home/m201560/.local/lib/python3.6/site-packages/keras/backend/tensorflow_backend.py", line 186, in get_session
    _SESSION = tf.Session(config=config)
  File "/gpfs/pkgs/mhpcc/anaconda3-5.0.1/lib/python3.6/site-packages/tensorflow/python/client/session.py", line 1563, in __init__
    super(Session, self).__init__(target, graph, config=config)
  File "/gpfs/pkgs/mhpcc/anaconda3-5.0.1/lib/python3.6/site-packages/tensorflow/python/client/session.py", line 633, in __init__
    self._session = tf_session.TF_NewSession(self._graph._c_graph, opts)
tensorflow.python.framework.errors_impl.InternalError: Failed to create session.
Traceback (most recent call last):
  File "roundOneSubmit.py", line 23, in <module>
    l.learnThingsCPP(kind=0, file=f, weightFile=wf)
  File "/gpfs/home/m201560/chipboard/learn.py", line 130, in learnThingsCPP
    weights = self.getWeightArray()
  File "/gpfs/home/m201560/chipboard/learn.py", line 199, in getWeightArray
    return self.model.get_weights()[0].tolist()
  File "/gpfs/home/m201560/.local/lib/python3.6/site-packages/keras/engine/network.py", line 492, in get_weights
    return K.batch_get_value(weights)
  File "/gpfs/home/m201560/.local/lib/python3.6/site-packages/keras/backend/tensorflow_backend.py", line 2420, in batch_get_value
    return get_session().run(ops)
  File "/gpfs/home/m201560/.local/lib/python3.6/site-packages/keras/backend/tensorflow_backend.py", line 186, in get_session
    _SESSION = tf.Session(config=config)
  File "/gpfs/pkgs/mhpcc/anaconda3-5.0.1/lib/python3.6/site-packages/tensorflow/python/client/session.py", line 1563, in __init__
    super(Session, self).__init__(target, graph, config=config)
  File "/gpfs/pkgs/mhpcc/anaconda3-5.0.1/lib/python3.6/site-packages/tensorflow/python/client/session.py", line 633, in __init__
    self._session = tf_session.TF_NewSession(self._graph._c_graph, opts)
tensorflow.python.framework.errors_impl.InternalError: Failed to create session.
2019-08-02 11:20:23.147267: E tensorflow/core/common_runtime/direct_session.cc:158] Internal: failed initializing StreamExecutor for CUDA device ordinal 0: Internal: failed call to cuDevicePrimaryCtxRetain: CUDA_ERROR_INVALID_DEVICE
/gpfs/pkgs/mhpcc/anaconda3-5.0.1/lib/python3.6/site-packages/h5py/__init__.py:34: FutureWarning: Conversion of the second argument of issubdtype from `float` to `np.floating` is deprecated. In future, it will be treated as `np.float64 == np.dtype(float).type`.
  from ._conv import register_converters as _register_converters
Using TensorFlow backend.
Traceback (most recent call last):
  File "roundOneSubmit.py", line 23, in <module>
    l.learnThingsCPP(kind=0, file=f, weightFile=wf)
  File "/gpfs/home/m201560/chipboard/learn.py", line 130, in learnThingsCPP
    weights = self.getWeightArray()
  File "/gpfs/home/m201560/chipboard/learn.py", line 199, in getWeightArray
    return self.model.get_weights()[0].tolist()
  File "/gpfs/home/m201560/.local/lib/python3.6/site-packages/keras/engine/network.py", line 492, in get_weights
    return K.batch_get_value(weights)
  File "/gpfs/home/m201560/.local/lib/python3.6/site-packages/keras/backend/tensorflow_backend.py", line 2420, in batch_get_value
    return get_session().run(ops)
  File "/gpfs/home/m201560/.local/lib/python3.6/site-packages/keras/backend/tensorflow_backend.py", line 186, in get_session
    _SESSION = tf.Session(config=config)
  File "/gpfs/pkgs/mhpcc/anaconda3-5.0.1/lib/python3.6/site-packages/tensorflow/python/client/session.py", line 1563, in __init__
    super(Session, self).__init__(target, graph, config=config)
  File "/gpfs/pkgs/mhpcc/anaconda3-5.0.1/lib/python3.6/site-packages/tensorflow/python/client/session.py", line 633, in __init__
    self._session = tf_session.TF_NewSession(self._graph._c_graph, opts)
tensorflow.python.framework.errors_impl.InternalError: Failed to create session.
2019-08-02 11:20:23.227497: E tensorflow/core/common_runtime/direct_session.cc:158] Internal: failed initializing StreamExecutor for CUDA device ordinal 0: Internal: failed call to cuDevicePrimaryCtxRetain: CUDA_ERROR_INVALID_DEVICE
/gpfs/pkgs/mhpcc/anaconda3-5.0.1/lib/python3.6/site-packages/h5py/__init__.py:34: FutureWarning: Conversion of the second argument of issubdtype from `float` to `np.floating` is deprecated. In future, it will be treated as `np.float64 == np.dtype(float).type`.
  from ._conv import register_converters as _register_converters
Using TensorFlow backend.
Traceback (most recent call last):
  File "roundOneSubmit.py", line 23, in <module>
    l.learnThingsCPP(kind=0, file=f, weightFile=wf)
  File "/gpfs/home/m201560/chipboard/learn.py", line 130, in learnThingsCPP
    weights = self.getWeightArray()
  File "/gpfs/home/m201560/chipboard/learn.py", line 199, in getWeightArray
    return self.model.get_weights()[0].tolist()
  File "/gpfs/home/m201560/.local/lib/python3.6/site-packages/keras/engine/network.py", line 492, in get_weights
    return K.batch_get_value(weights)
  File "/gpfs/home/m201560/.local/lib/python3.6/site-packages/keras/backend/tensorflow_backend.py", line 2420, in batch_get_value
    return get_session().run(ops)
  File "/gpfs/home/m201560/.local/lib/python3.6/site-packages/keras/backend/tensorflow_backend.py", line 186, in get_session
    _SESSION = tf.Session(config=config)
  File "/gpfs/pkgs/mhpcc/anaconda3-5.0.1/lib/python3.6/site-packages/tensorflow/python/client/session.py", line 1563, in __init__
    super(Session, self).__init__(target, graph, config=config)
  File "/gpfs/pkgs/mhpcc/anaconda3-5.0.1/lib/python3.6/site-packages/tensorflow/python/client/session.py", line 633, in __init__
    self._session = tf_session.TF_NewSession(self._graph._c_graph, opts)
tensorflow.python.framework.errors_impl.InternalError: Failed to create session.
2019-08-02 11:20:23.256417: E tensorflow/core/common_runtime/direct_session.cc:158] Internal: failed initializing StreamExecutor for CUDA device ordinal 0: Internal: failed call to cuDevicePrimaryCtxRetain: CUDA_ERROR_INVALID_DEVICE
/gpfs/pkgs/mhpcc/anaconda3-5.0.1/lib/python3.6/site-packages/h5py/__init__.py:34: FutureWarning: Conversion of the second argument of issubdtype from `float` to `np.floating` is deprecated. In future, it will be treated as `np.float64 == np.dtype(float).type`.
  from ._conv import register_converters as _register_converters
Using TensorFlow backend.
Traceback (most recent call last):
  File "roundOneSubmit.py", line 23, in <module>
    l.learnThingsCPP(kind=0, file=f, weightFile=wf)
  File "/gpfs/home/m201560/chipboard/learn.py", line 130, in learnThingsCPP
    weights = self.getWeightArray()
  File "/gpfs/home/m201560/chipboard/learn.py", line 199, in getWeightArray
    return self.model.get_weights()[0].tolist()
  File "/gpfs/home/m201560/.local/lib/python3.6/site-packages/keras/engine/network.py", line 492, in get_weights
    return K.batch_get_value(weights)
  File "/gpfs/home/m201560/.local/lib/python3.6/site-packages/keras/backend/tensorflow_backend.py", line 2420, in batch_get_value
    return get_session().run(ops)
  File "/gpfs/home/m201560/.local/lib/python3.6/site-packages/keras/backend/tensorflow_backend.py", line 186, in get_session
    _SESSION = tf.Session(config=config)
  File "/gpfs/pkgs/mhpcc/anaconda3-5.0.1/lib/python3.6/site-packages/tensorflow/python/client/session.py", line 1563, in __init__
    super(Session, self).__init__(target, graph, config=config)
  File "/gpfs/pkgs/mhpcc/anaconda3-5.0.1/lib/python3.6/site-packages/tensorflow/python/client/session.py", line 633, in __init__
    self._session = tf_session.TF_NewSession(self._graph._c_graph, opts)
tensorflow.python.framework.errors_impl.InternalError: Failed to create session.
2019-08-02 11:20:23.289965: I tensorflow/core/common_runtime/gpu/gpu_device.cc:1392] Found device 1 with properties: 
name: Tesla P100-SXM2-16GB major: 6 minor: 0 memoryClockRate(GHz): 1.4805
pciBusID: 0003:01:00.0
totalMemory: 15.90GiB freeMemory: 15.64GiB
2019-08-02 11:20:23.372380: E tensorflow/core/common_runtime/direct_session.cc:158] Internal: failed initializing StreamExecutor for CUDA device ordinal 0: Internal: failed call to cuDevicePrimaryCtxRetain: CUDA_ERROR_INVALID_DEVICE
/gpfs/pkgs/mhpcc/anaconda3-5.0.1/lib/python3.6/site-packages/h5py/__init__.py:34: FutureWarning: Conversion of the second argument of issubdtype from `float` to `np.floating` is deprecated. In future, it will be treated as `np.float64 == np.dtype(float).type`.
  from ._conv import register_converters as _register_converters
Using TensorFlow backend.
Traceback (most recent call last):
  File "roundOneSubmit.py", line 23, in <module>
    l.learnThingsCPP(kind=0, file=f, weightFile=wf)
  File "/gpfs/home/m201560/chipboard/learn.py", line 130, in learnThingsCPP
    weights = self.getWeightArray()
  File "/gpfs/home/m201560/chipboard/learn.py", line 199, in getWeightArray
    return self.model.get_weights()[0].tolist()
  File "/gpfs/home/m201560/.local/lib/python3.6/site-packages/keras/engine/network.py", line 492, in get_weights
    return K.batch_get_value(weights)
  File "/gpfs/home/m201560/.local/lib/python3.6/site-packages/keras/backend/tensorflow_backend.py", line 2420, in batch_get_value
    return get_session().run(ops)
  File "/gpfs/home/m201560/.local/lib/python3.6/site-packages/keras/backend/tensorflow_backend.py", line 186, in get_session
    _SESSION = tf.Session(config=config)
  File "/gpfs/pkgs/mhpcc/anaconda3-5.0.1/lib/python3.6/site-packages/tensorflow/python/client/session.py", line 1563, in __init__
    super(Session, self).__init__(target, graph, config=config)
  File "/gpfs/pkgs/mhpcc/anaconda3-5.0.1/lib/python3.6/site-packages/tensorflow/python/client/session.py", line 633, in __init__
    self._session = tf_session.TF_NewSession(self._graph._c_graph, opts)
tensorflow.python.framework.errors_impl.InternalError: Failed to create session.
2019-08-02 11:20:23.384377: E tensorflow/core/common_runtime/direct_session.cc:158] Internal: failed initializing StreamExecutor for CUDA device ordinal 0: Internal: failed call to cuDevicePrimaryCtxRetain: CUDA_ERROR_INVALID_DEVICE
/gpfs/pkgs/mhpcc/anaconda3-5.0.1/lib/python3.6/site-packages/h5py/__init__.py:34: FutureWarning: Conversion of the second argument of issubdtype from `float` to `np.floating` is deprecated. In future, it will be treated as `np.float64 == np.dtype(float).type`.
  from ._conv import register_converters as _register_converters
Using TensorFlow backend.
Traceback (most recent call last):
  File "roundOneSubmit.py", line 23, in <module>
    l.learnThingsCPP(kind=0, file=f, weightFile=wf)
  File "/gpfs/home/m201560/chipboard/learn.py", line 130, in learnThingsCPP
    weights = self.getWeightArray()
  File "/gpfs/home/m201560/chipboard/learn.py", line 199, in getWeightArray
    return self.model.get_weights()[0].tolist()
  File "/gpfs/home/m201560/.local/lib/python3.6/site-packages/keras/engine/network.py", line 492, in get_weights
    return K.batch_get_value(weights)
  File "/gpfs/home/m201560/.local/lib/python3.6/site-packages/keras/backend/tensorflow_backend.py", line 2420, in batch_get_value
    return get_session().run(ops)
  File "/gpfs/home/m201560/.local/lib/python3.6/site-packages/keras/backend/tensorflow_backend.py", line 186, in get_session
    _SESSION = tf.Session(config=config)
  File "/gpfs/pkgs/mhpcc/anaconda3-5.0.1/lib/python3.6/site-packages/tensorflow/python/client/session.py", line 1563, in __init__
    super(Session, self).__init__(target, graph, config=config)
  File "/gpfs/pkgs/mhpcc/anaconda3-5.0.1/lib/python3.6/site-packages/tensorflow/python/client/session.py", line 633, in __init__
    self._session = tf_session.TF_NewSession(self._graph._c_graph, opts)
tensorflow.python.framework.errors_impl.InternalError: Failed to create session.
2019-08-02 11:20:23.410822: E tensorflow/core/common_runtime/direct_session.cc:158] Internal: failed initializing StreamExecutor for CUDA device ordinal 0: Internal: failed call to cuDevicePrimaryCtxRetain: CUDA_ERROR_INVALID_DEVICE
/gpfs/pkgs/mhpcc/anaconda3-5.0.1/lib/python3.6/site-packages/h5py/__init__.py:34: FutureWarning: Conversion of the second argument of issubdtype from `float` to `np.floating` is deprecated. In future, it will be treated as `np.float64 == np.dtype(float).type`.
  from ._conv import register_converters as _register_converters
Using TensorFlow backend.
Traceback (most recent call last):
  File "roundOneSubmit.py", line 23, in <module>
    l.learnThingsCPP(kind=0, file=f, weightFile=wf)
  File "/gpfs/home/m201560/chipboard/learn.py", line 130, in learnThingsCPP
    weights = self.getWeightArray()
  File "/gpfs/home/m201560/chipboard/learn.py", line 199, in getWeightArray
    return self.model.get_weights()[0].tolist()
  File "/gpfs/home/m201560/.local/lib/python3.6/site-packages/keras/engine/network.py", line 492, in get_weights
    return K.batch_get_value(weights)
  File "/gpfs/home/m201560/.local/lib/python3.6/site-packages/keras/backend/tensorflow_backend.py", line 2420, in batch_get_value
    return get_session().run(ops)
  File "/gpfs/home/m201560/.local/lib/python3.6/site-packages/keras/backend/tensorflow_backend.py", line 186, in get_session
    _SESSION = tf.Session(config=config)
  File "/gpfs/pkgs/mhpcc/anaconda3-5.0.1/lib/python3.6/site-packages/tensorflow/python/client/session.py", line 1563, in __init__
    super(Session, self).__init__(target, graph, config=config)
  File "/gpfs/pkgs/mhpcc/anaconda3-5.0.1/lib/python3.6/site-packages/tensorflow/python/client/session.py", line 633, in __init__
    self._session = tf_session.TF_NewSession(self._graph._c_graph, opts)
tensorflow.python.framework.errors_impl.InternalError: Failed to create session.
2019-08-02 11:20:23.434005: E tensorflow/core/common_runtime/direct_session.cc:158] Internal: failed initializing StreamExecutor for CUDA device ordinal 0: Internal: failed call to cuDevicePrimaryCtxRetain: CUDA_ERROR_INVALID_DEVICE
/gpfs/pkgs/mhpcc/anaconda3-5.0.1/lib/python3.6/site-packages/h5py/__init__.py:34: FutureWarning: Conversion of the second argument of issubdtype from `float` to `np.floating` is deprecated. In future, it will be treated as `np.float64 == np.dtype(float).type`.
  from ._conv import register_converters as _register_converters
Using TensorFlow backend.
2019-08-02 11:20:23.436800: E tensorflow/core/common_runtime/direct_session.cc:158] Internal: failed initializing StreamExecutor for CUDA device ordinal 0: Internal: failed call to cuDevicePrimaryCtxRetain: CUDA_ERROR_INVALID_DEVICE
/gpfs/pkgs/mhpcc/anaconda3-5.0.1/lib/python3.6/site-packages/h5py/__init__.py:34: FutureWarning: Conversion of the second argument of issubdtype from `float` to `np.floating` is deprecated. In future, it will be treated as `np.float64 == np.dtype(float).type`.
  from ._conv import register_converters as _register_converters
Using TensorFlow backend.
Traceback (most recent call last):
  File "roundOneSubmit.py", line 23, in <module>
    l.learnThingsCPP(kind=0, file=f, weightFile=wf)
  File "/gpfs/home/m201560/chipboard/learn.py", line 130, in learnThingsCPP
    weights = self.getWeightArray()
  File "/gpfs/home/m201560/chipboard/learn.py", line 199, in getWeightArray
    return self.model.get_weights()[0].tolist()
  File "/gpfs/home/m201560/.local/lib/python3.6/site-packages/keras/engine/network.py", line 492, in get_weights
    return K.batch_get_value(weights)
  File "/gpfs/home/m201560/.local/lib/python3.6/site-packages/keras/backend/tensorflow_backend.py", line 2420, in batch_get_value
    return get_session().run(ops)
  File "/gpfs/home/m201560/.local/lib/python3.6/site-packages/keras/backend/tensorflow_backend.py", line 186, in get_session
    _SESSION = tf.Session(config=config)
  File "/gpfs/pkgs/mhpcc/anaconda3-5.0.1/lib/python3.6/site-packages/tensorflow/python/client/session.py", line 1563, in __init__
    super(Session, self).__init__(target, graph, config=config)
  File "/gpfs/pkgs/mhpcc/anaconda3-5.0.1/lib/python3.6/site-packages/tensorflow/python/client/session.py", line 633, in __init__
    self._session = tf_session.TF_NewSession(self._graph._c_graph, opts)
tensorflow.python.framework.errors_impl.InternalError: Failed to create session.
Traceback (most recent call last):
  File "roundOneSubmit.py", line 23, in <module>
    l.learnThingsCPP(kind=0, file=f, weightFile=wf)
  File "/gpfs/home/m201560/chipboard/learn.py", line 130, in learnThingsCPP
    weights = self.getWeightArray()
  File "/gpfs/home/m201560/chipboard/learn.py", line 199, in getWeightArray
    return self.model.get_weights()[0].tolist()
  File "/gpfs/home/m201560/.local/lib/python3.6/site-packages/keras/engine/network.py", line 492, in get_weights
    return K.batch_get_value(weights)
  File "/gpfs/home/m201560/.local/lib/python3.6/site-packages/keras/backend/tensorflow_backend.py", line 2420, in batch_get_value
    return get_session().run(ops)
  File "/gpfs/home/m201560/.local/lib/python3.6/site-packages/keras/backend/tensorflow_backend.py", line 186, in get_session
    _SESSION = tf.Session(config=config)
  File "/gpfs/pkgs/mhpcc/anaconda3-5.0.1/lib/python3.6/site-packages/tensorflow/python/client/session.py", line 1563, in __init__
    super(Session, self).__init__(target, graph, config=config)
  File "/gpfs/pkgs/mhpcc/anaconda3-5.0.1/lib/python3.6/site-packages/tensorflow/python/client/session.py", line 633, in __init__
    self._session = tf_session.TF_NewSession(self._graph._c_graph, opts)
tensorflow.python.framework.errors_impl.InternalError: Failed to create session.
2019-08-02 11:20:23.452070: E tensorflow/core/common_runtime/direct_session.cc:158] Internal: failed initializing StreamExecutor for CUDA device ordinal 0: Internal: failed call to cuDevicePrimaryCtxRetain: CUDA_ERROR_INVALID_DEVICE
/gpfs/pkgs/mhpcc/anaconda3-5.0.1/lib/python3.6/site-packages/h5py/__init__.py:34: FutureWarning: Conversion of the second argument of issubdtype from `float` to `np.floating` is deprecated. In future, it will be treated as `np.float64 == np.dtype(float).type`.
  from ._conv import register_converters as _register_converters
Using TensorFlow backend.
Traceback (most recent call last):
  File "roundOneSubmit.py", line 23, in <module>
    l.learnThingsCPP(kind=0, file=f, weightFile=wf)
  File "/gpfs/home/m201560/chipboard/learn.py", line 130, in learnThingsCPP
    weights = self.getWeightArray()
  File "/gpfs/home/m201560/chipboard/learn.py", line 199, in getWeightArray
    return self.model.get_weights()[0].tolist()
  File "/gpfs/home/m201560/.local/lib/python3.6/site-packages/keras/engine/network.py", line 492, in get_weights
    return K.batch_get_value(weights)
  File "/gpfs/home/m201560/.local/lib/python3.6/site-packages/keras/backend/tensorflow_backend.py", line 2420, in batch_get_value
    return get_session().run(ops)
  File "/gpfs/home/m201560/.local/lib/python3.6/site-packages/keras/backend/tensorflow_backend.py", line 186, in get_session
    _SESSION = tf.Session(config=config)
  File "/gpfs/pkgs/mhpcc/anaconda3-5.0.1/lib/python3.6/site-packages/tensorflow/python/client/session.py", line 1563, in __init__
    super(Session, self).__init__(target, graph, config=config)
  File "/gpfs/pkgs/mhpcc/anaconda3-5.0.1/lib/python3.6/site-packages/tensorflow/python/client/session.py", line 633, in __init__
    self._session = tf_session.TF_NewSession(self._graph._c_graph, opts)
tensorflow.python.framework.errors_impl.InternalError: Failed to create session.
2019-08-02 11:20:23.489325: E tensorflow/core/common_runtime/direct_session.cc:158] Internal: failed initializing StreamExecutor for CUDA device ordinal 0: Internal: failed call to cuDevicePrimaryCtxRetain: CUDA_ERROR_INVALID_DEVICE
/gpfs/pkgs/mhpcc/anaconda3-5.0.1/lib/python3.6/site-packages/h5py/__init__.py:34: FutureWarning: Conversion of the second argument of issubdtype from `float` to `np.floating` is deprecated. In future, it will be treated as `np.float64 == np.dtype(float).type`.
  from ._conv import register_converters as _register_converters
Using TensorFlow backend.
Traceback (most recent call last):
  File "roundOneSubmit.py", line 23, in <module>
    l.learnThingsCPP(kind=0, file=f, weightFile=wf)
  File "/gpfs/home/m201560/chipboard/learn.py", line 130, in learnThingsCPP
    weights = self.getWeightArray()
  File "/gpfs/home/m201560/chipboard/learn.py", line 199, in getWeightArray
    return self.model.get_weights()[0].tolist()
  File "/gpfs/home/m201560/.local/lib/python3.6/site-packages/keras/engine/network.py", line 492, in get_weights
    return K.batch_get_value(weights)
  File "/gpfs/home/m201560/.local/lib/python3.6/site-packages/keras/backend/tensorflow_backend.py", line 2420, in batch_get_value
    return get_session().run(ops)
  File "/gpfs/home/m201560/.local/lib/python3.6/site-packages/keras/backend/tensorflow_backend.py", line 186, in get_session
    _SESSION = tf.Session(config=config)
  File "/gpfs/pkgs/mhpcc/anaconda3-5.0.1/lib/python3.6/site-packages/tensorflow/python/client/session.py", line 1563, in __init__
    super(Session, self).__init__(target, graph, config=config)
  File "/gpfs/pkgs/mhpcc/anaconda3-5.0.1/lib/python3.6/site-packages/tensorflow/python/client/session.py", line 633, in __init__
    self._session = tf_session.TF_NewSession(self._graph._c_graph, opts)
tensorflow.python.framework.errors_impl.InternalError: Failed to create session.
2019-08-02 11:20:23.523318: I tensorflow/core/common_runtime/gpu/gpu_device.cc:1392] Found device 2 with properties: 
name: Tesla P100-SXM2-16GB major: 6 minor: 0 memoryClockRate(GHz): 1.4805
pciBusID: 0006:01:00.0
totalMemory: 15.90GiB freeMemory: 15.64GiB
2019-08-02 11:20:23.546604: E tensorflow/core/common_runtime/direct_session.cc:158] Internal: failed initializing StreamExecutor for CUDA device ordinal 0: Internal: failed call to cuDevicePrimaryCtxRetain: CUDA_ERROR_INVALID_DEVICE
/gpfs/pkgs/mhpcc/anaconda3-5.0.1/lib/python3.6/site-packages/h5py/__init__.py:34: FutureWarning: Conversion of the second argument of issubdtype from `float` to `np.floating` is deprecated. In future, it will be treated as `np.float64 == np.dtype(float).type`.
  from ._conv import register_converters as _register_converters
Using TensorFlow backend.
Traceback (most recent call last):
  File "roundOneSubmit.py", line 23, in <module>
    l.learnThingsCPP(kind=0, file=f, weightFile=wf)
  File "/gpfs/home/m201560/chipboard/learn.py", line 130, in learnThingsCPP
    weights = self.getWeightArray()
  File "/gpfs/home/m201560/chipboard/learn.py", line 199, in getWeightArray
    return self.model.get_weights()[0].tolist()
  File "/gpfs/home/m201560/.local/lib/python3.6/site-packages/keras/engine/network.py", line 492, in get_weights
    return K.batch_get_value(weights)
  File "/gpfs/home/m201560/.local/lib/python3.6/site-packages/keras/backend/tensorflow_backend.py", line 2420, in batch_get_value
    return get_session().run(ops)
  File "/gpfs/home/m201560/.local/lib/python3.6/site-packages/keras/backend/tensorflow_backend.py", line 186, in get_session
    _SESSION = tf.Session(config=config)
  File "/gpfs/pkgs/mhpcc/anaconda3-5.0.1/lib/python3.6/site-packages/tensorflow/python/client/session.py", line 1563, in __init__
    super(Session, self).__init__(target, graph, config=config)
  File "/gpfs/pkgs/mhpcc/anaconda3-5.0.1/lib/python3.6/site-packages/tensorflow/python/client/session.py", line 633, in __init__
    self._session = tf_session.TF_NewSession(self._graph._c_graph, opts)
tensorflow.python.framework.errors_impl.InternalError: Failed to create session.
2019-08-02 11:20:23.647062: I tensorflow/core/common_runtime/gpu/gpu_device.cc:1392] Found device 3 with properties: 
name: Tesla P100-SXM2-16GB major: 6 minor: 0 memoryClockRate(GHz): 1.4805
pciBusID: 0007:01:00.0
totalMemory: 15.90GiB freeMemory: 15.64GiB
2019-08-02 11:20:23.648442: I tensorflow/core/common_runtime/gpu/gpu_device.cc:1471] Adding visible gpu devices: 0, 1, 2, 3
2019-08-02 11:20:23.678211: E tensorflow/core/common_runtime/direct_session.cc:158] Internal: failed initializing StreamExecutor for CUDA device ordinal 0: Internal: failed call to cuDevicePrimaryCtxRetain: CUDA_ERROR_INVALID_DEVICE
/gpfs/pkgs/mhpcc/anaconda3-5.0.1/lib/python3.6/site-packages/h5py/__init__.py:34: FutureWarning: Conversion of the second argument of issubdtype from `float` to `np.floating` is deprecated. In future, it will be treated as `np.float64 == np.dtype(float).type`.
  from ._conv import register_converters as _register_converters
Using TensorFlow backend.
Traceback (most recent call last):
  File "roundOneSubmit.py", line 23, in <module>
    l.learnThingsCPP(kind=0, file=f, weightFile=wf)
  File "/gpfs/home/m201560/chipboard/learn.py", line 130, in learnThingsCPP
    weights = self.getWeightArray()
  File "/gpfs/home/m201560/chipboard/learn.py", line 199, in getWeightArray
    return self.model.get_weights()[0].tolist()
  File "/gpfs/home/m201560/.local/lib/python3.6/site-packages/keras/engine/network.py", line 492, in get_weights
    return K.batch_get_value(weights)
  File "/gpfs/home/m201560/.local/lib/python3.6/site-packages/keras/backend/tensorflow_backend.py", line 2420, in batch_get_value
    return get_session().run(ops)
  File "/gpfs/home/m201560/.local/lib/python3.6/site-packages/keras/backend/tensorflow_backend.py", line 186, in get_session
    _SESSION = tf.Session(config=config)
  File "/gpfs/pkgs/mhpcc/anaconda3-5.0.1/lib/python3.6/site-packages/tensorflow/python/client/session.py", line 1563, in __init__
    super(Session, self).__init__(target, graph, config=config)
  File "/gpfs/pkgs/mhpcc/anaconda3-5.0.1/lib/python3.6/site-packages/tensorflow/python/client/session.py", line 633, in __init__
    self._session = tf_session.TF_NewSession(self._graph._c_graph, opts)
tensorflow.python.framework.errors_impl.InternalError: Failed to create session.
2019-08-02 11:20:23.726213: E tensorflow/core/common_runtime/direct_session.cc:158] Internal: failed initializing StreamExecutor for CUDA device ordinal 0: Internal: failed call to cuDevicePrimaryCtxRetain: CUDA_ERROR_INVALID_DEVICE
/gpfs/pkgs/mhpcc/anaconda3-5.0.1/lib/python3.6/site-packages/h5py/__init__.py:34: FutureWarning: Conversion of the second argument of issubdtype from `float` to `np.floating` is deprecated. In future, it will be treated as `np.float64 == np.dtype(float).type`.
  from ._conv import register_converters as _register_converters
Using TensorFlow backend.
Traceback (most recent call last):
  File "roundOneSubmit.py", line 23, in <module>
    l.learnThingsCPP(kind=0, file=f, weightFile=wf)
  File "/gpfs/home/m201560/chipboard/learn.py", line 130, in learnThingsCPP
    weights = self.getWeightArray()
  File "/gpfs/home/m201560/chipboard/learn.py", line 199, in getWeightArray
    return self.model.get_weights()[0].tolist()
  File "/gpfs/home/m201560/.local/lib/python3.6/site-packages/keras/engine/network.py", line 492, in get_weights
    return K.batch_get_value(weights)
  File "/gpfs/home/m201560/.local/lib/python3.6/site-packages/keras/backend/tensorflow_backend.py", line 2420, in batch_get_value
    return get_session().run(ops)
  File "/gpfs/home/m201560/.local/lib/python3.6/site-packages/keras/backend/tensorflow_backend.py", line 186, in get_session
    _SESSION = tf.Session(config=config)
  File "/gpfs/pkgs/mhpcc/anaconda3-5.0.1/lib/python3.6/site-packages/tensorflow/python/client/session.py", line 1563, in __init__
    super(Session, self).__init__(target, graph, config=config)
  File "/gpfs/pkgs/mhpcc/anaconda3-5.0.1/lib/python3.6/site-packages/tensorflow/python/client/session.py", line 633, in __init__
    self._session = tf_session.TF_NewSession(self._graph._c_graph, opts)
tensorflow.python.framework.errors_impl.InternalError: Failed to create session.
2019-08-02 11:20:23.758933: E tensorflow/core/common_runtime/direct_session.cc:158] Internal: failed initializing StreamExecutor for CUDA device ordinal 0: Internal: failed call to cuDevicePrimaryCtxRetain: CUDA_ERROR_INVALID_DEVICE
/gpfs/pkgs/mhpcc/anaconda3-5.0.1/lib/python3.6/site-packages/h5py/__init__.py:34: FutureWarning: Conversion of the second argument of issubdtype from `float` to `np.floating` is deprecated. In future, it will be treated as `np.float64 == np.dtype(float).type`.
  from ._conv import register_converters as _register_converters
Using TensorFlow backend.
Traceback (most recent call last):
  File "roundOneSubmit.py", line 23, in <module>
    l.learnThingsCPP(kind=0, file=f, weightFile=wf)
  File "/gpfs/home/m201560/chipboard/learn.py", line 130, in learnThingsCPP
    weights = self.getWeightArray()
  File "/gpfs/home/m201560/chipboard/learn.py", line 199, in getWeightArray
    return self.model.get_weights()[0].tolist()
  File "/gpfs/home/m201560/.local/lib/python3.6/site-packages/keras/engine/network.py", line 492, in get_weights
    return K.batch_get_value(weights)
  File "/gpfs/home/m201560/.local/lib/python3.6/site-packages/keras/backend/tensorflow_backend.py", line 2420, in batch_get_value
    return get_session().run(ops)
  File "/gpfs/home/m201560/.local/lib/python3.6/site-packages/keras/backend/tensorflow_backend.py", line 186, in get_session
    _SESSION = tf.Session(config=config)
  File "/gpfs/pkgs/mhpcc/anaconda3-5.0.1/lib/python3.6/site-packages/tensorflow/python/client/session.py", line 1563, in __init__
    super(Session, self).__init__(target, graph, config=config)
  File "/gpfs/pkgs/mhpcc/anaconda3-5.0.1/lib/python3.6/site-packages/tensorflow/python/client/session.py", line 633, in __init__
    self._session = tf_session.TF_NewSession(self._graph._c_graph, opts)
tensorflow.python.framework.errors_impl.InternalError: Failed to create session.
2019-08-02 11:20:24.013009: E tensorflow/core/common_runtime/direct_session.cc:158] Internal: failed initializing StreamExecutor for CUDA device ordinal 0: Internal: failed call to cuDevicePrimaryCtxRetain: CUDA_ERROR_INVALID_DEVICE
/gpfs/pkgs/mhpcc/anaconda3-5.0.1/lib/python3.6/site-packages/h5py/__init__.py:34: FutureWarning: Conversion of the second argument of issubdtype from `float` to `np.floating` is deprecated. In future, it will be treated as `np.float64 == np.dtype(float).type`.
  from ._conv import register_converters as _register_converters
Using TensorFlow backend.
Traceback (most recent call last):
  File "roundOneSubmit.py", line 23, in <module>
    l.learnThingsCPP(kind=0, file=f, weightFile=wf)
  File "/gpfs/home/m201560/chipboard/learn.py", line 130, in learnThingsCPP
    weights = self.getWeightArray()
  File "/gpfs/home/m201560/chipboard/learn.py", line 199, in getWeightArray
    return self.model.get_weights()[0].tolist()
  File "/gpfs/home/m201560/.local/lib/python3.6/site-packages/keras/engine/network.py", line 492, in get_weights
    return K.batch_get_value(weights)
  File "/gpfs/home/m201560/.local/lib/python3.6/site-packages/keras/backend/tensorflow_backend.py", line 2420, in batch_get_value
    return get_session().run(ops)
  File "/gpfs/home/m201560/.local/lib/python3.6/site-packages/keras/backend/tensorflow_backend.py", line 186, in get_session
    _SESSION = tf.Session(config=config)
  File "/gpfs/pkgs/mhpcc/anaconda3-5.0.1/lib/python3.6/site-packages/tensorflow/python/client/session.py", line 1563, in __init__
    super(Session, self).__init__(target, graph, config=config)
  File "/gpfs/pkgs/mhpcc/anaconda3-5.0.1/lib/python3.6/site-packages/tensorflow/python/client/session.py", line 633, in __init__
    self._session = tf_session.TF_NewSession(self._graph._c_graph, opts)
tensorflow.python.framework.errors_impl.InternalError: Failed to create session.
2019-08-02 11:20:24.036369: E tensorflow/core/common_runtime/direct_session.cc:158] Internal: failed initializing StreamExecutor for CUDA device ordinal 0: Internal: failed call to cuDevicePrimaryCtxRetain: CUDA_ERROR_INVALID_DEVICE
/gpfs/pkgs/mhpcc/anaconda3-5.0.1/lib/python3.6/site-packages/h5py/__init__.py:34: FutureWarning: Conversion of the second argument of issubdtype from `float` to `np.floating` is deprecated. In future, it will be treated as `np.float64 == np.dtype(float).type`.
  from ._conv import register_converters as _register_converters
Using TensorFlow backend.
Traceback (most recent call last):
  File "roundOneSubmit.py", line 23, in <module>
    l.learnThingsCPP(kind=0, file=f, weightFile=wf)
  File "/gpfs/home/m201560/chipboard/learn.py", line 130, in learnThingsCPP
    weights = self.getWeightArray()
  File "/gpfs/home/m201560/chipboard/learn.py", line 199, in getWeightArray
    return self.model.get_weights()[0].tolist()
  File "/gpfs/home/m201560/.local/lib/python3.6/site-packages/keras/engine/network.py", line 492, in get_weights
    return K.batch_get_value(weights)
  File "/gpfs/home/m201560/.local/lib/python3.6/site-packages/keras/backend/tensorflow_backend.py", line 2420, in batch_get_value
    return get_session().run(ops)
  File "/gpfs/home/m201560/.local/lib/python3.6/site-packages/keras/backend/tensorflow_backend.py", line 186, in get_session
    _SESSION = tf.Session(config=config)
  File "/gpfs/pkgs/mhpcc/anaconda3-5.0.1/lib/python3.6/site-packages/tensorflow/python/client/session.py", line 1563, in __init__
    super(Session, self).__init__(target, graph, config=config)
  File "/gpfs/pkgs/mhpcc/anaconda3-5.0.1/lib/python3.6/site-packages/tensorflow/python/client/session.py", line 633, in __init__
    self._session = tf_session.TF_NewSession(self._graph._c_graph, opts)
tensorflow.python.framework.errors_impl.InternalError: Failed to create session.
2019-08-02 11:20:24.106228: E tensorflow/core/common_runtime/direct_session.cc:158] Internal: failed initializing StreamExecutor for CUDA device ordinal 0: Internal: failed call to cuDevicePrimaryCtxRetain: CUDA_ERROR_INVALID_DEVICE
/gpfs/pkgs/mhpcc/anaconda3-5.0.1/lib/python3.6/site-packages/h5py/__init__.py:34: FutureWarning: Conversion of the second argument of issubdtype from `float` to `np.floating` is deprecated. In future, it will be treated as `np.float64 == np.dtype(float).type`.
  from ._conv import register_converters as _register_converters
Using TensorFlow backend.
Traceback (most recent call last):
  File "roundOneSubmit.py", line 23, in <module>
    l.learnThingsCPP(kind=0, file=f, weightFile=wf)
  File "/gpfs/home/m201560/chipboard/learn.py", line 130, in learnThingsCPP
    weights = self.getWeightArray()
  File "/gpfs/home/m201560/chipboard/learn.py", line 199, in getWeightArray
    return self.model.get_weights()[0].tolist()
  File "/gpfs/home/m201560/.local/lib/python3.6/site-packages/keras/engine/network.py", line 492, in get_weights
    return K.batch_get_value(weights)
  File "/gpfs/home/m201560/.local/lib/python3.6/site-packages/keras/backend/tensorflow_backend.py", line 2420, in batch_get_value
    return get_session().run(ops)
  File "/gpfs/home/m201560/.local/lib/python3.6/site-packages/keras/backend/tensorflow_backend.py", line 186, in get_session
    _SESSION = tf.Session(config=config)
  File "/gpfs/pkgs/mhpcc/anaconda3-5.0.1/lib/python3.6/site-packages/tensorflow/python/client/session.py", line 1563, in __init__
    super(Session, self).__init__(target, graph, config=config)
  File "/gpfs/pkgs/mhpcc/anaconda3-5.0.1/lib/python3.6/site-packages/tensorflow/python/client/session.py", line 633, in __init__
    self._session = tf_session.TF_NewSession(self._graph._c_graph, opts)
tensorflow.python.framework.errors_impl.InternalError: Failed to create session.
2019-08-02 11:20:24.211080: E tensorflow/core/common_runtime/direct_session.cc:158] Internal: failed initializing StreamExecutor for CUDA device ordinal 0: Internal: failed call to cuDevicePrimaryCtxRetain: CUDA_ERROR_INVALID_DEVICE
/gpfs/pkgs/mhpcc/anaconda3-5.0.1/lib/python3.6/site-packages/h5py/__init__.py:34: FutureWarning: Conversion of the second argument of issubdtype from `float` to `np.floating` is deprecated. In future, it will be treated as `np.float64 == np.dtype(float).type`.
  from ._conv import register_converters as _register_converters
Using TensorFlow backend.
Traceback (most recent call last):
  File "roundOneSubmit.py", line 23, in <module>
    l.learnThingsCPP(kind=0, file=f, weightFile=wf)
  File "/gpfs/home/m201560/chipboard/learn.py", line 130, in learnThingsCPP
    weights = self.getWeightArray()
  File "/gpfs/home/m201560/chipboard/learn.py", line 199, in getWeightArray
    return self.model.get_weights()[0].tolist()
  File "/gpfs/home/m201560/.local/lib/python3.6/site-packages/keras/engine/network.py", line 492, in get_weights
    return K.batch_get_value(weights)
  File "/gpfs/home/m201560/.local/lib/python3.6/site-packages/keras/backend/tensorflow_backend.py", line 2420, in batch_get_value
    return get_session().run(ops)
  File "/gpfs/home/m201560/.local/lib/python3.6/site-packages/keras/backend/tensorflow_backend.py", line 186, in get_session
    _SESSION = tf.Session(config=config)
  File "/gpfs/pkgs/mhpcc/anaconda3-5.0.1/lib/python3.6/site-packages/tensorflow/python/client/session.py", line 1563, in __init__
    super(Session, self).__init__(target, graph, config=config)
  File "/gpfs/pkgs/mhpcc/anaconda3-5.0.1/lib/python3.6/site-packages/tensorflow/python/client/session.py", line 633, in __init__
    self._session = tf_session.TF_NewSession(self._graph._c_graph, opts)
tensorflow.python.framework.errors_impl.InternalError: Failed to create session.
2019-08-02 11:20:24.343685: E tensorflow/core/common_runtime/direct_session.cc:158] Internal: failed initializing StreamExecutor for CUDA device ordinal 0: Internal: failed call to cuDevicePrimaryCtxRetain: CUDA_ERROR_INVALID_DEVICE
/gpfs/pkgs/mhpcc/anaconda3-5.0.1/lib/python3.6/site-packages/h5py/__init__.py:34: FutureWarning: Conversion of the second argument of issubdtype from `float` to `np.floating` is deprecated. In future, it will be treated as `np.float64 == np.dtype(float).type`.
  from ._conv import register_converters as _register_converters
Using TensorFlow backend.
Traceback (most recent call last):
  File "roundOneSubmit.py", line 23, in <module>
    l.learnThingsCPP(kind=0, file=f, weightFile=wf)
  File "/gpfs/home/m201560/chipboard/learn.py", line 130, in learnThingsCPP
    weights = self.getWeightArray()
  File "/gpfs/home/m201560/chipboard/learn.py", line 199, in getWeightArray
    return self.model.get_weights()[0].tolist()
  File "/gpfs/home/m201560/.local/lib/python3.6/site-packages/keras/engine/network.py", line 492, in get_weights
    return K.batch_get_value(weights)
  File "/gpfs/home/m201560/.local/lib/python3.6/site-packages/keras/backend/tensorflow_backend.py", line 2420, in batch_get_value
    return get_session().run(ops)
  File "/gpfs/home/m201560/.local/lib/python3.6/site-packages/keras/backend/tensorflow_backend.py", line 186, in get_session
    _SESSION = tf.Session(config=config)
  File "/gpfs/pkgs/mhpcc/anaconda3-5.0.1/lib/python3.6/site-packages/tensorflow/python/client/session.py", line 1563, in __init__
    super(Session, self).__init__(target, graph, config=config)
  File "/gpfs/pkgs/mhpcc/anaconda3-5.0.1/lib/python3.6/site-packages/tensorflow/python/client/session.py", line 633, in __init__
    self._session = tf_session.TF_NewSession(self._graph._c_graph, opts)
tensorflow.python.framework.errors_impl.InternalError: Failed to create session.
2019-08-02 11:20:24.378150: E tensorflow/core/common_runtime/direct_session.cc:158] Internal: failed initializing StreamExecutor for CUDA device ordinal 0: Internal: failed call to cuDevicePrimaryCtxRetain: CUDA_ERROR_INVALID_DEVICE
/gpfs/pkgs/mhpcc/anaconda3-5.0.1/lib/python3.6/site-packages/h5py/__init__.py:34: FutureWarning: Conversion of the second argument of issubdtype from `float` to `np.floating` is deprecated. In future, it will be treated as `np.float64 == np.dtype(float).type`.
  from ._conv import register_converters as _register_converters
Using TensorFlow backend.
Traceback (most recent call last):
  File "roundOneSubmit.py", line 23, in <module>
    l.learnThingsCPP(kind=0, file=f, weightFile=wf)
  File "/gpfs/home/m201560/chipboard/learn.py", line 130, in learnThingsCPP
    weights = self.getWeightArray()
  File "/gpfs/home/m201560/chipboard/learn.py", line 199, in getWeightArray
    return self.model.get_weights()[0].tolist()
  File "/gpfs/home/m201560/.local/lib/python3.6/site-packages/keras/engine/network.py", line 492, in get_weights
    return K.batch_get_value(weights)
  File "/gpfs/home/m201560/.local/lib/python3.6/site-packages/keras/backend/tensorflow_backend.py", line 2420, in batch_get_value
    return get_session().run(ops)
  File "/gpfs/home/m201560/.local/lib/python3.6/site-packages/keras/backend/tensorflow_backend.py", line 186, in get_session
    _SESSION = tf.Session(config=config)
  File "/gpfs/pkgs/mhpcc/anaconda3-5.0.1/lib/python3.6/site-packages/tensorflow/python/client/session.py", line 1563, in __init__
    super(Session, self).__init__(target, graph, config=config)
  File "/gpfs/pkgs/mhpcc/anaconda3-5.0.1/lib/python3.6/site-packages/tensorflow/python/client/session.py", line 633, in __init__
    self._session = tf_session.TF_NewSession(self._graph._c_graph, opts)
tensorflow.python.framework.errors_impl.InternalError: Failed to create session.
2019-08-02 11:20:24.475245: E tensorflow/core/common_runtime/direct_session.cc:158] Internal: failed initializing StreamExecutor for CUDA device ordinal 0: Internal: failed call to cuDevicePrimaryCtxRetain: CUDA_ERROR_INVALID_DEVICE
/gpfs/pkgs/mhpcc/anaconda3-5.0.1/lib/python3.6/site-packages/h5py/__init__.py:34: FutureWarning: Conversion of the second argument of issubdtype from `float` to `np.floating` is deprecated. In future, it will be treated as `np.float64 == np.dtype(float).type`.
  from ._conv import register_converters as _register_converters
Using TensorFlow backend.
Traceback (most recent call last):
  File "roundOneSubmit.py", line 23, in <module>
    l.learnThingsCPP(kind=0, file=f, weightFile=wf)
  File "/gpfs/home/m201560/chipboard/learn.py", line 130, in learnThingsCPP
    weights = self.getWeightArray()
  File "/gpfs/home/m201560/chipboard/learn.py", line 199, in getWeightArray
    return self.model.get_weights()[0].tolist()
  File "/gpfs/home/m201560/.local/lib/python3.6/site-packages/keras/engine/network.py", line 492, in get_weights
    return K.batch_get_value(weights)
  File "/gpfs/home/m201560/.local/lib/python3.6/site-packages/keras/backend/tensorflow_backend.py", line 2420, in batch_get_value
    return get_session().run(ops)
  File "/gpfs/home/m201560/.local/lib/python3.6/site-packages/keras/backend/tensorflow_backend.py", line 186, in get_session
    _SESSION = tf.Session(config=config)
  File "/gpfs/pkgs/mhpcc/anaconda3-5.0.1/lib/python3.6/site-packages/tensorflow/python/client/session.py", line 1563, in __init__
    super(Session, self).__init__(target, graph, config=config)
  File "/gpfs/pkgs/mhpcc/anaconda3-5.0.1/lib/python3.6/site-packages/tensorflow/python/client/session.py", line 633, in __init__
    self._session = tf_session.TF_NewSession(self._graph._c_graph, opts)
tensorflow.python.framework.errors_impl.InternalError: Failed to create session.
2019-08-02 11:20:24.559459: E tensorflow/core/common_runtime/direct_session.cc:158] Internal: failed initializing StreamExecutor for CUDA device ordinal 0: Internal: failed call to cuDevicePrimaryCtxRetain: CUDA_ERROR_INVALID_DEVICE
/gpfs/pkgs/mhpcc/anaconda3-5.0.1/lib/python3.6/site-packages/h5py/__init__.py:34: FutureWarning: Conversion of the second argument of issubdtype from `float` to `np.floating` is deprecated. In future, it will be treated as `np.float64 == np.dtype(float).type`.
  from ._conv import register_converters as _register_converters
Using TensorFlow backend.
Traceback (most recent call last):
  File "roundOneSubmit.py", line 23, in <module>
    l.learnThingsCPP(kind=0, file=f, weightFile=wf)
  File "/gpfs/home/m201560/chipboard/learn.py", line 130, in learnThingsCPP
    weights = self.getWeightArray()
  File "/gpfs/home/m201560/chipboard/learn.py", line 199, in getWeightArray
    return self.model.get_weights()[0].tolist()
  File "/gpfs/home/m201560/.local/lib/python3.6/site-packages/keras/engine/network.py", line 492, in get_weights
    return K.batch_get_value(weights)
  File "/gpfs/home/m201560/.local/lib/python3.6/site-packages/keras/backend/tensorflow_backend.py", line 2420, in batch_get_value
    return get_session().run(ops)
  File "/gpfs/home/m201560/.local/lib/python3.6/site-packages/keras/backend/tensorflow_backend.py", line 186, in get_session
    _SESSION = tf.Session(config=config)
  File "/gpfs/pkgs/mhpcc/anaconda3-5.0.1/lib/python3.6/site-packages/tensorflow/python/client/session.py", line 1563, in __init__
    super(Session, self).__init__(target, graph, config=config)
  File "/gpfs/pkgs/mhpcc/anaconda3-5.0.1/lib/python3.6/site-packages/tensorflow/python/client/session.py", line 633, in __init__
    self._session = tf_session.TF_NewSession(self._graph._c_graph, opts)
tensorflow.python.framework.errors_impl.InternalError: Failed to create session.
2019-08-02 11:20:24.573185: E tensorflow/core/common_runtime/direct_session.cc:158] Internal: failed initializing StreamExecutor for CUDA device ordinal 0: Internal: failed call to cuDevicePrimaryCtxRetain: CUDA_ERROR_INVALID_DEVICE
/gpfs/pkgs/mhpcc/anaconda3-5.0.1/lib/python3.6/site-packages/h5py/__init__.py:34: FutureWarning: Conversion of the second argument of issubdtype from `float` to `np.floating` is deprecated. In future, it will be treated as `np.float64 == np.dtype(float).type`.
  from ._conv import register_converters as _register_converters
Using TensorFlow backend.
Traceback (most recent call last):
  File "roundOneSubmit.py", line 23, in <module>
    l.learnThingsCPP(kind=0, file=f, weightFile=wf)
  File "/gpfs/home/m201560/chipboard/learn.py", line 130, in learnThingsCPP
    weights = self.getWeightArray()
  File "/gpfs/home/m201560/chipboard/learn.py", line 199, in getWeightArray
    return self.model.get_weights()[0].tolist()
  File "/gpfs/home/m201560/.local/lib/python3.6/site-packages/keras/engine/network.py", line 492, in get_weights
    return K.batch_get_value(weights)
  File "/gpfs/home/m201560/.local/lib/python3.6/site-packages/keras/backend/tensorflow_backend.py", line 2420, in batch_get_value
    return get_session().run(ops)
  File "/gpfs/home/m201560/.local/lib/python3.6/site-packages/keras/backend/tensorflow_backend.py", line 186, in get_session
    _SESSION = tf.Session(config=config)
  File "/gpfs/pkgs/mhpcc/anaconda3-5.0.1/lib/python3.6/site-packages/tensorflow/python/client/session.py", line 1563, in __init__
    super(Session, self).__init__(target, graph, config=config)
  File "/gpfs/pkgs/mhpcc/anaconda3-5.0.1/lib/python3.6/site-packages/tensorflow/python/client/session.py", line 633, in __init__
    self._session = tf_session.TF_NewSession(self._graph._c_graph, opts)
tensorflow.python.framework.errors_impl.InternalError: Failed to create session.
2019-08-02 11:20:24.681530: E tensorflow/core/common_runtime/direct_session.cc:158] Internal: failed initializing StreamExecutor for CUDA device ordinal 0: Internal: failed call to cuDevicePrimaryCtxRetain: CUDA_ERROR_INVALID_DEVICE
/gpfs/pkgs/mhpcc/anaconda3-5.0.1/lib/python3.6/site-packages/h5py/__init__.py:34: FutureWarning: Conversion of the second argument of issubdtype from `float` to `np.floating` is deprecated. In future, it will be treated as `np.float64 == np.dtype(float).type`.
  from ._conv import register_converters as _register_converters
Using TensorFlow backend.
Traceback (most recent call last):
  File "roundOneSubmit.py", line 23, in <module>
    l.learnThingsCPP(kind=0, file=f, weightFile=wf)
  File "/gpfs/home/m201560/chipboard/learn.py", line 130, in learnThingsCPP
    weights = self.getWeightArray()
  File "/gpfs/home/m201560/chipboard/learn.py", line 199, in getWeightArray
    return self.model.get_weights()[0].tolist()
  File "/gpfs/home/m201560/.local/lib/python3.6/site-packages/keras/engine/network.py", line 492, in get_weights
    return K.batch_get_value(weights)
  File "/gpfs/home/m201560/.local/lib/python3.6/site-packages/keras/backend/tensorflow_backend.py", line 2420, in batch_get_value
    return get_session().run(ops)
  File "/gpfs/home/m201560/.local/lib/python3.6/site-packages/keras/backend/tensorflow_backend.py", line 186, in get_session
    _SESSION = tf.Session(config=config)
  File "/gpfs/pkgs/mhpcc/anaconda3-5.0.1/lib/python3.6/site-packages/tensorflow/python/client/session.py", line 1563, in __init__
    super(Session, self).__init__(target, graph, config=config)
  File "/gpfs/pkgs/mhpcc/anaconda3-5.0.1/lib/python3.6/site-packages/tensorflow/python/client/session.py", line 633, in __init__
    self._session = tf_session.TF_NewSession(self._graph._c_graph, opts)
tensorflow.python.framework.errors_impl.InternalError: Failed to create session.
2019-08-02 11:20:24.710634: E tensorflow/core/common_runtime/direct_session.cc:158] Internal: failed initializing StreamExecutor for CUDA device ordinal 0: Internal: failed call to cuDevicePrimaryCtxRetain: CUDA_ERROR_INVALID_DEVICE
/gpfs/pkgs/mhpcc/anaconda3-5.0.1/lib/python3.6/site-packages/h5py/__init__.py:34: FutureWarning: Conversion of the second argument of issubdtype from `float` to `np.floating` is deprecated. In future, it will be treated as `np.float64 == np.dtype(float).type`.
  from ._conv import register_converters as _register_converters
Using TensorFlow backend.
Traceback (most recent call last):
  File "roundOneSubmit.py", line 23, in <module>
    l.learnThingsCPP(kind=0, file=f, weightFile=wf)
  File "/gpfs/home/m201560/chipboard/learn.py", line 130, in learnThingsCPP
    weights = self.getWeightArray()
  File "/gpfs/home/m201560/chipboard/learn.py", line 199, in getWeightArray
    return self.model.get_weights()[0].tolist()
  File "/gpfs/home/m201560/.local/lib/python3.6/site-packages/keras/engine/network.py", line 492, in get_weights
    return K.batch_get_value(weights)
  File "/gpfs/home/m201560/.local/lib/python3.6/site-packages/keras/backend/tensorflow_backend.py", line 2420, in batch_get_value
    return get_session().run(ops)
  File "/gpfs/home/m201560/.local/lib/python3.6/site-packages/keras/backend/tensorflow_backend.py", line 186, in get_session
    _SESSION = tf.Session(config=config)
  File "/gpfs/pkgs/mhpcc/anaconda3-5.0.1/lib/python3.6/site-packages/tensorflow/python/client/session.py", line 1563, in __init__
    super(Session, self).__init__(target, graph, config=config)
  File "/gpfs/pkgs/mhpcc/anaconda3-5.0.1/lib/python3.6/site-packages/tensorflow/python/client/session.py", line 633, in __init__
    self._session = tf_session.TF_NewSession(self._graph._c_graph, opts)
tensorflow.python.framework.errors_impl.InternalError: Failed to create session.
2019-08-02 11:20:24.789878: E tensorflow/core/common_runtime/direct_session.cc:158] Internal: failed initializing StreamExecutor for CUDA device ordinal 0: Internal: failed call to cuDevicePrimaryCtxRetain: CUDA_ERROR_INVALID_DEVICE
/gpfs/pkgs/mhpcc/anaconda3-5.0.1/lib/python3.6/site-packages/h5py/__init__.py:34: FutureWarning: Conversion of the second argument of issubdtype from `float` to `np.floating` is deprecated. In future, it will be treated as `np.float64 == np.dtype(float).type`.
  from ._conv import register_converters as _register_converters
Using TensorFlow backend.
Traceback (most recent call last):
  File "roundOneSubmit.py", line 23, in <module>
    l.learnThingsCPP(kind=0, file=f, weightFile=wf)
  File "/gpfs/home/m201560/chipboard/learn.py", line 130, in learnThingsCPP
    weights = self.getWeightArray()
  File "/gpfs/home/m201560/chipboard/learn.py", line 199, in getWeightArray
    return self.model.get_weights()[0].tolist()
  File "/gpfs/home/m201560/.local/lib/python3.6/site-packages/keras/engine/network.py", line 492, in get_weights
    return K.batch_get_value(weights)
  File "/gpfs/home/m201560/.local/lib/python3.6/site-packages/keras/backend/tensorflow_backend.py", line 2420, in batch_get_value
    return get_session().run(ops)
  File "/gpfs/home/m201560/.local/lib/python3.6/site-packages/keras/backend/tensorflow_backend.py", line 186, in get_session
    _SESSION = tf.Session(config=config)
  File "/gpfs/pkgs/mhpcc/anaconda3-5.0.1/lib/python3.6/site-packages/tensorflow/python/client/session.py", line 1563, in __init__
    super(Session, self).__init__(target, graph, config=config)
  File "/gpfs/pkgs/mhpcc/anaconda3-5.0.1/lib/python3.6/site-packages/tensorflow/python/client/session.py", line 633, in __init__
    self._session = tf_session.TF_NewSession(self._graph._c_graph, opts)
tensorflow.python.framework.errors_impl.InternalError: Failed to create session.
2019-08-02 11:20:24.802191: E tensorflow/core/common_runtime/direct_session.cc:158] Internal: failed initializing StreamExecutor for CUDA device ordinal 0: Internal: failed call to cuDevicePrimaryCtxRetain: CUDA_ERROR_INVALID_DEVICE
/gpfs/pkgs/mhpcc/anaconda3-5.0.1/lib/python3.6/site-packages/h5py/__init__.py:34: FutureWarning: Conversion of the second argument of issubdtype from `float` to `np.floating` is deprecated. In future, it will be treated as `np.float64 == np.dtype(float).type`.
  from ._conv import register_converters as _register_converters
Using TensorFlow backend.
Traceback (most recent call last):
  File "roundOneSubmit.py", line 23, in <module>
    l.learnThingsCPP(kind=0, file=f, weightFile=wf)
  File "/gpfs/home/m201560/chipboard/learn.py", line 130, in learnThingsCPP
    weights = self.getWeightArray()
  File "/gpfs/home/m201560/chipboard/learn.py", line 199, in getWeightArray
    return self.model.get_weights()[0].tolist()
  File "/gpfs/home/m201560/.local/lib/python3.6/site-packages/keras/engine/network.py", line 492, in get_weights
    return K.batch_get_value(weights)
  File "/gpfs/home/m201560/.local/lib/python3.6/site-packages/keras/backend/tensorflow_backend.py", line 2420, in batch_get_value
    return get_session().run(ops)
  File "/gpfs/home/m201560/.local/lib/python3.6/site-packages/keras/backend/tensorflow_backend.py", line 186, in get_session
    _SESSION = tf.Session(config=config)
  File "/gpfs/pkgs/mhpcc/anaconda3-5.0.1/lib/python3.6/site-packages/tensorflow/python/client/session.py", line 1563, in __init__
    super(Session, self).__init__(target, graph, config=config)
  File "/gpfs/pkgs/mhpcc/anaconda3-5.0.1/lib/python3.6/site-packages/tensorflow/python/client/session.py", line 633, in __init__
    self._session = tf_session.TF_NewSession(self._graph._c_graph, opts)
tensorflow.python.framework.errors_impl.InternalError: Failed to create session.
2019-08-02 11:20:24.849076: E tensorflow/core/common_runtime/direct_session.cc:158] Internal: failed initializing StreamExecutor for CUDA device ordinal 0: Internal: failed call to cuDevicePrimaryCtxRetain: CUDA_ERROR_INVALID_DEVICE
/gpfs/pkgs/mhpcc/anaconda3-5.0.1/lib/python3.6/site-packages/h5py/__init__.py:34: FutureWarning: Conversion of the second argument of issubdtype from `float` to `np.floating` is deprecated. In future, it will be treated as `np.float64 == np.dtype(float).type`.
  from ._conv import register_converters as _register_converters
Using TensorFlow backend.
Traceback (most recent call last):
  File "roundOneSubmit.py", line 23, in <module>
    l.learnThingsCPP(kind=0, file=f, weightFile=wf)
  File "/gpfs/home/m201560/chipboard/learn.py", line 130, in learnThingsCPP
    weights = self.getWeightArray()
  File "/gpfs/home/m201560/chipboard/learn.py", line 199, in getWeightArray
    return self.model.get_weights()[0].tolist()
  File "/gpfs/home/m201560/.local/lib/python3.6/site-packages/keras/engine/network.py", line 492, in get_weights
    return K.batch_get_value(weights)
  File "/gpfs/home/m201560/.local/lib/python3.6/site-packages/keras/backend/tensorflow_backend.py", line 2420, in batch_get_value
    return get_session().run(ops)
  File "/gpfs/home/m201560/.local/lib/python3.6/site-packages/keras/backend/tensorflow_backend.py", line 186, in get_session
    _SESSION = tf.Session(config=config)
  File "/gpfs/pkgs/mhpcc/anaconda3-5.0.1/lib/python3.6/site-packages/tensorflow/python/client/session.py", line 1563, in __init__
    super(Session, self).__init__(target, graph, config=config)
  File "/gpfs/pkgs/mhpcc/anaconda3-5.0.1/lib/python3.6/site-packages/tensorflow/python/client/session.py", line 633, in __init__
    self._session = tf_session.TF_NewSession(self._graph._c_graph, opts)
tensorflow.python.framework.errors_impl.InternalError: Failed to create session.
2019-08-02 11:20:24.889773: E tensorflow/core/common_runtime/direct_session.cc:158] Internal: failed initializing StreamExecutor for CUDA device ordinal 0: Internal: failed call to cuDevicePrimaryCtxRetain: CUDA_ERROR_INVALID_DEVICE
/gpfs/pkgs/mhpcc/anaconda3-5.0.1/lib/python3.6/site-packages/h5py/__init__.py:34: FutureWarning: Conversion of the second argument of issubdtype from `float` to `np.floating` is deprecated. In future, it will be treated as `np.float64 == np.dtype(float).type`.
  from ._conv import register_converters as _register_converters
Using TensorFlow backend.
Traceback (most recent call last):
  File "roundOneSubmit.py", line 23, in <module>
    l.learnThingsCPP(kind=0, file=f, weightFile=wf)
  File "/gpfs/home/m201560/chipboard/learn.py", line 130, in learnThingsCPP
    weights = self.getWeightArray()
  File "/gpfs/home/m201560/chipboard/learn.py", line 199, in getWeightArray
    return self.model.get_weights()[0].tolist()
  File "/gpfs/home/m201560/.local/lib/python3.6/site-packages/keras/engine/network.py", line 492, in get_weights
    return K.batch_get_value(weights)
  File "/gpfs/home/m201560/.local/lib/python3.6/site-packages/keras/backend/tensorflow_backend.py", line 2420, in batch_get_value
    return get_session().run(ops)
  File "/gpfs/home/m201560/.local/lib/python3.6/site-packages/keras/backend/tensorflow_backend.py", line 186, in get_session
    _SESSION = tf.Session(config=config)
  File "/gpfs/pkgs/mhpcc/anaconda3-5.0.1/lib/python3.6/site-packages/tensorflow/python/client/session.py", line 1563, in __init__
    super(Session, self).__init__(target, graph, config=config)
  File "/gpfs/pkgs/mhpcc/anaconda3-5.0.1/lib/python3.6/site-packages/tensorflow/python/client/session.py", line 633, in __init__
    self._session = tf_session.TF_NewSession(self._graph._c_graph, opts)
tensorflow.python.framework.errors_impl.InternalError: Failed to create session.
2019-08-02 11:20:24.964260: E tensorflow/core/common_runtime/direct_session.cc:158] Internal: failed initializing StreamExecutor for CUDA device ordinal 0: Internal: failed call to cuDevicePrimaryCtxRetain: CUDA_ERROR_INVALID_DEVICE
/gpfs/pkgs/mhpcc/anaconda3-5.0.1/lib/python3.6/site-packages/h5py/__init__.py:34: FutureWarning: Conversion of the second argument of issubdtype from `float` to `np.floating` is deprecated. In future, it will be treated as `np.float64 == np.dtype(float).type`.
  from ._conv import register_converters as _register_converters
Using TensorFlow backend.
Traceback (most recent call last):
  File "roundOneSubmit.py", line 23, in <module>
    l.learnThingsCPP(kind=0, file=f, weightFile=wf)
  File "/gpfs/home/m201560/chipboard/learn.py", line 130, in learnThingsCPP
    weights = self.getWeightArray()
  File "/gpfs/home/m201560/chipboard/learn.py", line 199, in getWeightArray
    return self.model.get_weights()[0].tolist()
  File "/gpfs/home/m201560/.local/lib/python3.6/site-packages/keras/engine/network.py", line 492, in get_weights
    return K.batch_get_value(weights)
  File "/gpfs/home/m201560/.local/lib/python3.6/site-packages/keras/backend/tensorflow_backend.py", line 2420, in batch_get_value
    return get_session().run(ops)
  File "/gpfs/home/m201560/.local/lib/python3.6/site-packages/keras/backend/tensorflow_backend.py", line 186, in get_session
    _SESSION = tf.Session(config=config)
  File "/gpfs/pkgs/mhpcc/anaconda3-5.0.1/lib/python3.6/site-packages/tensorflow/python/client/session.py", line 1563, in __init__
    super(Session, self).__init__(target, graph, config=config)
  File "/gpfs/pkgs/mhpcc/anaconda3-5.0.1/lib/python3.6/site-packages/tensorflow/python/client/session.py", line 633, in __init__
    self._session = tf_session.TF_NewSession(self._graph._c_graph, opts)
tensorflow.python.framework.errors_impl.InternalError: Failed to create session.
2019-08-02 11:20:25.044381: E tensorflow/core/common_runtime/direct_session.cc:158] Internal: failed initializing StreamExecutor for CUDA device ordinal 0: Internal: failed call to cuDevicePrimaryCtxRetain: CUDA_ERROR_INVALID_DEVICE
/gpfs/pkgs/mhpcc/anaconda3-5.0.1/lib/python3.6/site-packages/h5py/__init__.py:34: FutureWarning: Conversion of the second argument of issubdtype from `float` to `np.floating` is deprecated. In future, it will be treated as `np.float64 == np.dtype(float).type`.
  from ._conv import register_converters as _register_converters
Using TensorFlow backend.
Traceback (most recent call last):
  File "roundOneSubmit.py", line 23, in <module>
    l.learnThingsCPP(kind=0, file=f, weightFile=wf)
  File "/gpfs/home/m201560/chipboard/learn.py", line 130, in learnThingsCPP
    weights = self.getWeightArray()
  File "/gpfs/home/m201560/chipboard/learn.py", line 199, in getWeightArray
    return self.model.get_weights()[0].tolist()
  File "/gpfs/home/m201560/.local/lib/python3.6/site-packages/keras/engine/network.py", line 492, in get_weights
    return K.batch_get_value(weights)
  File "/gpfs/home/m201560/.local/lib/python3.6/site-packages/keras/backend/tensorflow_backend.py", line 2420, in batch_get_value
    return get_session().run(ops)
  File "/gpfs/home/m201560/.local/lib/python3.6/site-packages/keras/backend/tensorflow_backend.py", line 186, in get_session
    _SESSION = tf.Session(config=config)
  File "/gpfs/pkgs/mhpcc/anaconda3-5.0.1/lib/python3.6/site-packages/tensorflow/python/client/session.py", line 1563, in __init__
    super(Session, self).__init__(target, graph, config=config)
  File "/gpfs/pkgs/mhpcc/anaconda3-5.0.1/lib/python3.6/site-packages/tensorflow/python/client/session.py", line 633, in __init__
    self._session = tf_session.TF_NewSession(self._graph._c_graph, opts)
tensorflow.python.framework.errors_impl.InternalError: Failed to create session.
2019-08-02 11:20:25.108157: E tensorflow/core/common_runtime/direct_session.cc:158] Internal: failed initializing StreamExecutor for CUDA device ordinal 0: Internal: failed call to cuDevicePrimaryCtxRetain: CUDA_ERROR_INVALID_DEVICE
/gpfs/pkgs/mhpcc/anaconda3-5.0.1/lib/python3.6/site-packages/h5py/__init__.py:34: FutureWarning: Conversion of the second argument of issubdtype from `float` to `np.floating` is deprecated. In future, it will be treated as `np.float64 == np.dtype(float).type`.
  from ._conv import register_converters as _register_converters
Using TensorFlow backend.
Traceback (most recent call last):
  File "roundOneSubmit.py", line 23, in <module>
    l.learnThingsCPP(kind=0, file=f, weightFile=wf)
  File "/gpfs/home/m201560/chipboard/learn.py", line 130, in learnThingsCPP
    weights = self.getWeightArray()
  File "/gpfs/home/m201560/chipboard/learn.py", line 199, in getWeightArray
    return self.model.get_weights()[0].tolist()
  File "/gpfs/home/m201560/.local/lib/python3.6/site-packages/keras/engine/network.py", line 492, in get_weights
    return K.batch_get_value(weights)
  File "/gpfs/home/m201560/.local/lib/python3.6/site-packages/keras/backend/tensorflow_backend.py", line 2420, in batch_get_value
    return get_session().run(ops)
  File "/gpfs/home/m201560/.local/lib/python3.6/site-packages/keras/backend/tensorflow_backend.py", line 186, in get_session
    _SESSION = tf.Session(config=config)
  File "/gpfs/pkgs/mhpcc/anaconda3-5.0.1/lib/python3.6/site-packages/tensorflow/python/client/session.py", line 1563, in __init__
    super(Session, self).__init__(target, graph, config=config)
  File "/gpfs/pkgs/mhpcc/anaconda3-5.0.1/lib/python3.6/site-packages/tensorflow/python/client/session.py", line 633, in __init__
    self._session = tf_session.TF_NewSession(self._graph._c_graph, opts)
tensorflow.python.framework.errors_impl.InternalError: Failed to create session.
2019-08-02 11:20:25.122454: E tensorflow/core/common_runtime/direct_session.cc:158] Internal: failed initializing StreamExecutor for CUDA device ordinal 0: Internal: failed call to cuDevicePrimaryCtxRetain: CUDA_ERROR_INVALID_DEVICE
/gpfs/pkgs/mhpcc/anaconda3-5.0.1/lib/python3.6/site-packages/h5py/__init__.py:34: FutureWarning: Conversion of the second argument of issubdtype from `float` to `np.floating` is deprecated. In future, it will be treated as `np.float64 == np.dtype(float).type`.
  from ._conv import register_converters as _register_converters
Using TensorFlow backend.
Traceback (most recent call last):
  File "roundOneSubmit.py", line 23, in <module>
    l.learnThingsCPP(kind=0, file=f, weightFile=wf)
  File "/gpfs/home/m201560/chipboard/learn.py", line 130, in learnThingsCPP
    weights = self.getWeightArray()
  File "/gpfs/home/m201560/chipboard/learn.py", line 199, in getWeightArray
    return self.model.get_weights()[0].tolist()
  File "/gpfs/home/m201560/.local/lib/python3.6/site-packages/keras/engine/network.py", line 492, in get_weights
    return K.batch_get_value(weights)
  File "/gpfs/home/m201560/.local/lib/python3.6/site-packages/keras/backend/tensorflow_backend.py", line 2420, in batch_get_value
    return get_session().run(ops)
  File "/gpfs/home/m201560/.local/lib/python3.6/site-packages/keras/backend/tensorflow_backend.py", line 186, in get_session
    _SESSION = tf.Session(config=config)
  File "/gpfs/pkgs/mhpcc/anaconda3-5.0.1/lib/python3.6/site-packages/tensorflow/python/client/session.py", line 1563, in __init__
    super(Session, self).__init__(target, graph, config=config)
  File "/gpfs/pkgs/mhpcc/anaconda3-5.0.1/lib/python3.6/site-packages/tensorflow/python/client/session.py", line 633, in __init__
    self._session = tf_session.TF_NewSession(self._graph._c_graph, opts)
tensorflow.python.framework.errors_impl.InternalError: Failed to create session.
2019-08-02 11:20:25.176864: E tensorflow/core/common_runtime/direct_session.cc:158] Internal: failed initializing StreamExecutor for CUDA device ordinal 0: Internal: failed call to cuDevicePrimaryCtxRetain: CUDA_ERROR_INVALID_DEVICE
/gpfs/pkgs/mhpcc/anaconda3-5.0.1/lib/python3.6/site-packages/h5py/__init__.py:34: FutureWarning: Conversion of the second argument of issubdtype from `float` to `np.floating` is deprecated. In future, it will be treated as `np.float64 == np.dtype(float).type`.
  from ._conv import register_converters as _register_converters
Using TensorFlow backend.
Traceback (most recent call last):
  File "roundOneSubmit.py", line 23, in <module>
    l.learnThingsCPP(kind=0, file=f, weightFile=wf)
  File "/gpfs/home/m201560/chipboard/learn.py", line 130, in learnThingsCPP
    weights = self.getWeightArray()
  File "/gpfs/home/m201560/chipboard/learn.py", line 199, in getWeightArray
    return self.model.get_weights()[0].tolist()
  File "/gpfs/home/m201560/.local/lib/python3.6/site-packages/keras/engine/network.py", line 492, in get_weights
    return K.batch_get_value(weights)
  File "/gpfs/home/m201560/.local/lib/python3.6/site-packages/keras/backend/tensorflow_backend.py", line 2420, in batch_get_value
    return get_session().run(ops)
  File "/gpfs/home/m201560/.local/lib/python3.6/site-packages/keras/backend/tensorflow_backend.py", line 186, in get_session
    _SESSION = tf.Session(config=config)
  File "/gpfs/pkgs/mhpcc/anaconda3-5.0.1/lib/python3.6/site-packages/tensorflow/python/client/session.py", line 1563, in __init__
    super(Session, self).__init__(target, graph, config=config)
  File "/gpfs/pkgs/mhpcc/anaconda3-5.0.1/lib/python3.6/site-packages/tensorflow/python/client/session.py", line 633, in __init__
    self._session = tf_session.TF_NewSession(self._graph._c_graph, opts)
tensorflow.python.framework.errors_impl.InternalError: Failed to create session.
2019-08-02 11:20:25.193842: E tensorflow/core/common_runtime/direct_session.cc:158] Internal: failed initializing StreamExecutor for CUDA device ordinal 0: Internal: failed call to cuDevicePrimaryCtxRetain: CUDA_ERROR_INVALID_DEVICE
/gpfs/pkgs/mhpcc/anaconda3-5.0.1/lib/python3.6/site-packages/h5py/__init__.py:34: FutureWarning: Conversion of the second argument of issubdtype from `float` to `np.floating` is deprecated. In future, it will be treated as `np.float64 == np.dtype(float).type`.
  from ._conv import register_converters as _register_converters
Using TensorFlow backend.
Traceback (most recent call last):
  File "roundOneSubmit.py", line 23, in <module>
    l.learnThingsCPP(kind=0, file=f, weightFile=wf)
  File "/gpfs/home/m201560/chipboard/learn.py", line 130, in learnThingsCPP
    weights = self.getWeightArray()
  File "/gpfs/home/m201560/chipboard/learn.py", line 199, in getWeightArray
    return self.model.get_weights()[0].tolist()
  File "/gpfs/home/m201560/.local/lib/python3.6/site-packages/keras/engine/network.py", line 492, in get_weights
    return K.batch_get_value(weights)
  File "/gpfs/home/m201560/.local/lib/python3.6/site-packages/keras/backend/tensorflow_backend.py", line 2420, in batch_get_value
    return get_session().run(ops)
  File "/gpfs/home/m201560/.local/lib/python3.6/site-packages/keras/backend/tensorflow_backend.py", line 186, in get_session
    _SESSION = tf.Session(config=config)
  File "/gpfs/pkgs/mhpcc/anaconda3-5.0.1/lib/python3.6/site-packages/tensorflow/python/client/session.py", line 1563, in __init__
    super(Session, self).__init__(target, graph, config=config)
  File "/gpfs/pkgs/mhpcc/anaconda3-5.0.1/lib/python3.6/site-packages/tensorflow/python/client/session.py", line 633, in __init__
    self._session = tf_session.TF_NewSession(self._graph._c_graph, opts)
tensorflow.python.framework.errors_impl.InternalError: Failed to create session.
2019-08-02 11:20:25.221534: E tensorflow/core/common_runtime/direct_session.cc:158] Internal: failed initializing StreamExecutor for CUDA device ordinal 0: Internal: failed call to cuDevicePrimaryCtxRetain: CUDA_ERROR_INVALID_DEVICE
/gpfs/pkgs/mhpcc/anaconda3-5.0.1/lib/python3.6/site-packages/h5py/__init__.py:34: FutureWarning: Conversion of the second argument of issubdtype from `float` to `np.floating` is deprecated. In future, it will be treated as `np.float64 == np.dtype(float).type`.
  from ._conv import register_converters as _register_converters
Using TensorFlow backend.
Traceback (most recent call last):
  File "roundOneSubmit.py", line 23, in <module>
    l.learnThingsCPP(kind=0, file=f, weightFile=wf)
  File "/gpfs/home/m201560/chipboard/learn.py", line 130, in learnThingsCPP
    weights = self.getWeightArray()
  File "/gpfs/home/m201560/chipboard/learn.py", line 199, in getWeightArray
    return self.model.get_weights()[0].tolist()
  File "/gpfs/home/m201560/.local/lib/python3.6/site-packages/keras/engine/network.py", line 492, in get_weights
    return K.batch_get_value(weights)
  File "/gpfs/home/m201560/.local/lib/python3.6/site-packages/keras/backend/tensorflow_backend.py", line 2420, in batch_get_value
    return get_session().run(ops)
  File "/gpfs/home/m201560/.local/lib/python3.6/site-packages/keras/backend/tensorflow_backend.py", line 186, in get_session
    _SESSION = tf.Session(config=config)
  File "/gpfs/pkgs/mhpcc/anaconda3-5.0.1/lib/python3.6/site-packages/tensorflow/python/client/session.py", line 1563, in __init__
    super(Session, self).__init__(target, graph, config=config)
  File "/gpfs/pkgs/mhpcc/anaconda3-5.0.1/lib/python3.6/site-packages/tensorflow/python/client/session.py", line 633, in __init__
    self._session = tf_session.TF_NewSession(self._graph._c_graph, opts)
tensorflow.python.framework.errors_impl.InternalError: Failed to create session.
2019-08-02 11:20:25.251844: E tensorflow/core/common_runtime/direct_session.cc:158] Internal: failed initializing StreamExecutor for CUDA device ordinal 0: Internal: failed call to cuDevicePrimaryCtxRetain: CUDA_ERROR_INVALID_DEVICE
/gpfs/pkgs/mhpcc/anaconda3-5.0.1/lib/python3.6/site-packages/h5py/__init__.py:34: FutureWarning: Conversion of the second argument of issubdtype from `float` to `np.floating` is deprecated. In future, it will be treated as `np.float64 == np.dtype(float).type`.
  from ._conv import register_converters as _register_converters
Using TensorFlow backend.
2019-08-02 11:20:25.264580: E tensorflow/core/common_runtime/direct_session.cc:158] Internal: failed initializing StreamExecutor for CUDA device ordinal 0: Internal: failed call to cuDevicePrimaryCtxRetain: CUDA_ERROR_INVALID_DEVICE
/gpfs/pkgs/mhpcc/anaconda3-5.0.1/lib/python3.6/site-packages/h5py/__init__.py:34: FutureWarning: Conversion of the second argument of issubdtype from `float` to `np.floating` is deprecated. In future, it will be treated as `np.float64 == np.dtype(float).type`.
  from ._conv import register_converters as _register_converters
Using TensorFlow backend.
Traceback (most recent call last):
  File "roundOneSubmit.py", line 23, in <module>
    l.learnThingsCPP(kind=0, file=f, weightFile=wf)
  File "/gpfs/home/m201560/chipboard/learn.py", line 130, in learnThingsCPP
    weights = self.getWeightArray()
  File "/gpfs/home/m201560/chipboard/learn.py", line 199, in getWeightArray
    return self.model.get_weights()[0].tolist()
  File "/gpfs/home/m201560/.local/lib/python3.6/site-packages/keras/engine/network.py", line 492, in get_weights
    return K.batch_get_value(weights)
  File "/gpfs/home/m201560/.local/lib/python3.6/site-packages/keras/backend/tensorflow_backend.py", line 2420, in batch_get_value
    return get_session().run(ops)
  File "/gpfs/home/m201560/.local/lib/python3.6/site-packages/keras/backend/tensorflow_backend.py", line 186, in get_session
    _SESSION = tf.Session(config=config)
  File "/gpfs/pkgs/mhpcc/anaconda3-5.0.1/lib/python3.6/site-packages/tensorflow/python/client/session.py", line 1563, in __init__
    super(Session, self).__init__(target, graph, config=config)
  File "/gpfs/pkgs/mhpcc/anaconda3-5.0.1/lib/python3.6/site-packages/tensorflow/python/client/session.py", line 633, in __init__
    self._session = tf_session.TF_NewSession(self._graph._c_graph, opts)
tensorflow.python.framework.errors_impl.InternalError: Failed to create session.
Traceback (most recent call last):
  File "roundOneSubmit.py", line 23, in <module>
    l.learnThingsCPP(kind=0, file=f, weightFile=wf)
  File "/gpfs/home/m201560/chipboard/learn.py", line 130, in learnThingsCPP
    weights = self.getWeightArray()
  File "/gpfs/home/m201560/chipboard/learn.py", line 199, in getWeightArray
    return self.model.get_weights()[0].tolist()
  File "/gpfs/home/m201560/.local/lib/python3.6/site-packages/keras/engine/network.py", line 492, in get_weights
    return K.batch_get_value(weights)
  File "/gpfs/home/m201560/.local/lib/python3.6/site-packages/keras/backend/tensorflow_backend.py", line 2420, in batch_get_value
    return get_session().run(ops)
  File "/gpfs/home/m201560/.local/lib/python3.6/site-packages/keras/backend/tensorflow_backend.py", line 186, in get_session
    _SESSION = tf.Session(config=config)
  File "/gpfs/pkgs/mhpcc/anaconda3-5.0.1/lib/python3.6/site-packages/tensorflow/python/client/session.py", line 1563, in __init__
    super(Session, self).__init__(target, graph, config=config)
  File "/gpfs/pkgs/mhpcc/anaconda3-5.0.1/lib/python3.6/site-packages/tensorflow/python/client/session.py", line 633, in __init__
    self._session = tf_session.TF_NewSession(self._graph._c_graph, opts)
tensorflow.python.framework.errors_impl.InternalError: Failed to create session.
2019-08-02 11:20:25.275929: E tensorflow/core/common_runtime/direct_session.cc:158] Internal: failed initializing StreamExecutor for CUDA device ordinal 0: Internal: failed call to cuDevicePrimaryCtxRetain: CUDA_ERROR_INVALID_DEVICE
/gpfs/pkgs/mhpcc/anaconda3-5.0.1/lib/python3.6/site-packages/h5py/__init__.py:34: FutureWarning: Conversion of the second argument of issubdtype from `float` to `np.floating` is deprecated. In future, it will be treated as `np.float64 == np.dtype(float).type`.
  from ._conv import register_converters as _register_converters
Using TensorFlow backend.
Traceback (most recent call last):
  File "roundOneSubmit.py", line 23, in <module>
    l.learnThingsCPP(kind=0, file=f, weightFile=wf)
  File "/gpfs/home/m201560/chipboard/learn.py", line 130, in learnThingsCPP
    weights = self.getWeightArray()
  File "/gpfs/home/m201560/chipboard/learn.py", line 199, in getWeightArray
    return self.model.get_weights()[0].tolist()
  File "/gpfs/home/m201560/.local/lib/python3.6/site-packages/keras/engine/network.py", line 492, in get_weights
    return K.batch_get_value(weights)
  File "/gpfs/home/m201560/.local/lib/python3.6/site-packages/keras/backend/tensorflow_backend.py", line 2420, in batch_get_value
    return get_session().run(ops)
  File "/gpfs/home/m201560/.local/lib/python3.6/site-packages/keras/backend/tensorflow_backend.py", line 186, in get_session
    _SESSION = tf.Session(config=config)
  File "/gpfs/pkgs/mhpcc/anaconda3-5.0.1/lib/python3.6/site-packages/tensorflow/python/client/session.py", line 1563, in __init__
    super(Session, self).__init__(target, graph, config=config)
  File "/gpfs/pkgs/mhpcc/anaconda3-5.0.1/lib/python3.6/site-packages/tensorflow/python/client/session.py", line 633, in __init__
    self._session = tf_session.TF_NewSession(self._graph._c_graph, opts)
tensorflow.python.framework.errors_impl.InternalError: Failed to create session.
2019-08-02 11:20:25.312429: E tensorflow/core/common_runtime/direct_session.cc:158] Internal: failed initializing StreamExecutor for CUDA device ordinal 0: Internal: failed call to cuDevicePrimaryCtxRetain: CUDA_ERROR_INVALID_DEVICE
/gpfs/pkgs/mhpcc/anaconda3-5.0.1/lib/python3.6/site-packages/h5py/__init__.py:34: FutureWarning: Conversion of the second argument of issubdtype from `float` to `np.floating` is deprecated. In future, it will be treated as `np.float64 == np.dtype(float).type`.
  from ._conv import register_converters as _register_converters
Using TensorFlow backend.
Traceback (most recent call last):
  File "roundOneSubmit.py", line 23, in <module>
    l.learnThingsCPP(kind=0, file=f, weightFile=wf)
  File "/gpfs/home/m201560/chipboard/learn.py", line 130, in learnThingsCPP
    weights = self.getWeightArray()
  File "/gpfs/home/m201560/chipboard/learn.py", line 199, in getWeightArray
    return self.model.get_weights()[0].tolist()
  File "/gpfs/home/m201560/.local/lib/python3.6/site-packages/keras/engine/network.py", line 492, in get_weights
    return K.batch_get_value(weights)
  File "/gpfs/home/m201560/.local/lib/python3.6/site-packages/keras/backend/tensorflow_backend.py", line 2420, in batch_get_value
    return get_session().run(ops)
  File "/gpfs/home/m201560/.local/lib/python3.6/site-packages/keras/backend/tensorflow_backend.py", line 186, in get_session
    _SESSION = tf.Session(config=config)
  File "/gpfs/pkgs/mhpcc/anaconda3-5.0.1/lib/python3.6/site-packages/tensorflow/python/client/session.py", line 1563, in __init__
    super(Session, self).__init__(target, graph, config=config)
  File "/gpfs/pkgs/mhpcc/anaconda3-5.0.1/lib/python3.6/site-packages/tensorflow/python/client/session.py", line 633, in __init__
    self._session = tf_session.TF_NewSession(self._graph._c_graph, opts)
tensorflow.python.framework.errors_impl.InternalError: Failed to create session.
2019-08-02 11:20:25.345970: E tensorflow/core/common_runtime/direct_session.cc:158] Internal: failed initializing StreamExecutor for CUDA device ordinal 0: Internal: failed call to cuDevicePrimaryCtxRetain: CUDA_ERROR_INVALID_DEVICE
/gpfs/pkgs/mhpcc/anaconda3-5.0.1/lib/python3.6/site-packages/h5py/__init__.py:34: FutureWarning: Conversion of the second argument of issubdtype from `float` to `np.floating` is deprecated. In future, it will be treated as `np.float64 == np.dtype(float).type`.
  from ._conv import register_converters as _register_converters
Using TensorFlow backend.
2019-08-02 11:20:25.353718: E tensorflow/core/common_runtime/direct_session.cc:158] Internal: failed initializing StreamExecutor for CUDA device ordinal 0: Internal: failed call to cuDevicePrimaryCtxRetain: CUDA_ERROR_INVALID_DEVICE
/gpfs/pkgs/mhpcc/anaconda3-5.0.1/lib/python3.6/site-packages/h5py/__init__.py:34: FutureWarning: Conversion of the second argument of issubdtype from `float` to `np.floating` is deprecated. In future, it will be treated as `np.float64 == np.dtype(float).type`.
  from ._conv import register_converters as _register_converters
Using TensorFlow backend.
Traceback (most recent call last):
  File "roundOneSubmit.py", line 23, in <module>
    l.learnThingsCPP(kind=0, file=f, weightFile=wf)
  File "/gpfs/home/m201560/chipboard/learn.py", line 130, in learnThingsCPP
    weights = self.getWeightArray()
  File "/gpfs/home/m201560/chipboard/learn.py", line 199, in getWeightArray
    return self.model.get_weights()[0].tolist()
  File "/gpfs/home/m201560/.local/lib/python3.6/site-packages/keras/engine/network.py", line 492, in get_weights
    return K.batch_get_value(weights)
  File "/gpfs/home/m201560/.local/lib/python3.6/site-packages/keras/backend/tensorflow_backend.py", line 2420, in batch_get_value
    return get_session().run(ops)
  File "/gpfs/home/m201560/.local/lib/python3.6/site-packages/keras/backend/tensorflow_backend.py", line 186, in get_session
    _SESSION = tf.Session(config=config)
  File "/gpfs/pkgs/mhpcc/anaconda3-5.0.1/lib/python3.6/site-packages/tensorflow/python/client/session.py", line 1563, in __init__
    super(Session, self).__init__(target, graph, config=config)
  File "/gpfs/pkgs/mhpcc/anaconda3-5.0.1/lib/python3.6/site-packages/tensorflow/python/client/session.py", line 633, in __init__
    self._session = tf_session.TF_NewSession(self._graph._c_graph, opts)
tensorflow.python.framework.errors_impl.InternalError: Failed to create session.
Traceback (most recent call last):
  File "roundOneSubmit.py", line 23, in <module>
    l.learnThingsCPP(kind=0, file=f, weightFile=wf)
  File "/gpfs/home/m201560/chipboard/learn.py", line 130, in learnThingsCPP
    weights = self.getWeightArray()
  File "/gpfs/home/m201560/chipboard/learn.py", line 199, in getWeightArray
    return self.model.get_weights()[0].tolist()
  File "/gpfs/home/m201560/.local/lib/python3.6/site-packages/keras/engine/network.py", line 492, in get_weights
    return K.batch_get_value(weights)
  File "/gpfs/home/m201560/.local/lib/python3.6/site-packages/keras/backend/tensorflow_backend.py", line 2420, in batch_get_value
    return get_session().run(ops)
  File "/gpfs/home/m201560/.local/lib/python3.6/site-packages/keras/backend/tensorflow_backend.py", line 186, in get_session
    _SESSION = tf.Session(config=config)
  File "/gpfs/pkgs/mhpcc/anaconda3-5.0.1/lib/python3.6/site-packages/tensorflow/python/client/session.py", line 1563, in __init__
    super(Session, self).__init__(target, graph, config=config)
  File "/gpfs/pkgs/mhpcc/anaconda3-5.0.1/lib/python3.6/site-packages/tensorflow/python/client/session.py", line 633, in __init__
    self._session = tf_session.TF_NewSession(self._graph._c_graph, opts)
tensorflow.python.framework.errors_impl.InternalError: Failed to create session.
2019-08-02 11:20:25.406256: E tensorflow/core/common_runtime/direct_session.cc:158] Internal: failed initializing StreamExecutor for CUDA device ordinal 0: Internal: failed call to cuDevicePrimaryCtxRetain: CUDA_ERROR_INVALID_DEVICE
/gpfs/pkgs/mhpcc/anaconda3-5.0.1/lib/python3.6/site-packages/h5py/__init__.py:34: FutureWarning: Conversion of the second argument of issubdtype from `float` to `np.floating` is deprecated. In future, it will be treated as `np.float64 == np.dtype(float).type`.
  from ._conv import register_converters as _register_converters
Using TensorFlow backend.
Traceback (most recent call last):
  File "roundOneSubmit.py", line 23, in <module>
    l.learnThingsCPP(kind=0, file=f, weightFile=wf)
  File "/gpfs/home/m201560/chipboard/learn.py", line 130, in learnThingsCPP
    weights = self.getWeightArray()
  File "/gpfs/home/m201560/chipboard/learn.py", line 199, in getWeightArray
    return self.model.get_weights()[0].tolist()
  File "/gpfs/home/m201560/.local/lib/python3.6/site-packages/keras/engine/network.py", line 492, in get_weights
    return K.batch_get_value(weights)
  File "/gpfs/home/m201560/.local/lib/python3.6/site-packages/keras/backend/tensorflow_backend.py", line 2420, in batch_get_value
    return get_session().run(ops)
  File "/gpfs/home/m201560/.local/lib/python3.6/site-packages/keras/backend/tensorflow_backend.py", line 186, in get_session
    _SESSION = tf.Session(config=config)
  File "/gpfs/pkgs/mhpcc/anaconda3-5.0.1/lib/python3.6/site-packages/tensorflow/python/client/session.py", line 1563, in __init__
    super(Session, self).__init__(target, graph, config=config)
  File "/gpfs/pkgs/mhpcc/anaconda3-5.0.1/lib/python3.6/site-packages/tensorflow/python/client/session.py", line 633, in __init__
    self._session = tf_session.TF_NewSession(self._graph._c_graph, opts)
tensorflow.python.framework.errors_impl.InternalError: Failed to create session.
2019-08-02 11:20:25.424457: E tensorflow/core/common_runtime/direct_session.cc:158] Internal: failed initializing StreamExecutor for CUDA device ordinal 0: Internal: failed call to cuDevicePrimaryCtxRetain: CUDA_ERROR_INVALID_DEVICE
/gpfs/pkgs/mhpcc/anaconda3-5.0.1/lib/python3.6/site-packages/h5py/__init__.py:34: FutureWarning: Conversion of the second argument of issubdtype from `float` to `np.floating` is deprecated. In future, it will be treated as `np.float64 == np.dtype(float).type`.
  from ._conv import register_converters as _register_converters
Using TensorFlow backend.
Traceback (most recent call last):
  File "roundOneSubmit.py", line 23, in <module>
    l.learnThingsCPP(kind=0, file=f, weightFile=wf)
  File "/gpfs/home/m201560/chipboard/learn.py", line 130, in learnThingsCPP
    weights = self.getWeightArray()
  File "/gpfs/home/m201560/chipboard/learn.py", line 199, in getWeightArray
    return self.model.get_weights()[0].tolist()
  File "/gpfs/home/m201560/.local/lib/python3.6/site-packages/keras/engine/network.py", line 492, in get_weights
    return K.batch_get_value(weights)
  File "/gpfs/home/m201560/.local/lib/python3.6/site-packages/keras/backend/tensorflow_backend.py", line 2420, in batch_get_value
    return get_session().run(ops)
  File "/gpfs/home/m201560/.local/lib/python3.6/site-packages/keras/backend/tensorflow_backend.py", line 186, in get_session
    _SESSION = tf.Session(config=config)
  File "/gpfs/pkgs/mhpcc/anaconda3-5.0.1/lib/python3.6/site-packages/tensorflow/python/client/session.py", line 1563, in __init__
    super(Session, self).__init__(target, graph, config=config)
  File "/gpfs/pkgs/mhpcc/anaconda3-5.0.1/lib/python3.6/site-packages/tensorflow/python/client/session.py", line 633, in __init__
    self._session = tf_session.TF_NewSession(self._graph._c_graph, opts)
tensorflow.python.framework.errors_impl.InternalError: Failed to create session.
2019-08-02 11:20:25.438188: E tensorflow/core/common_runtime/direct_session.cc:158] Internal: failed initializing StreamExecutor for CUDA device ordinal 0: Internal: failed call to cuDevicePrimaryCtxRetain: CUDA_ERROR_INVALID_DEVICE
/gpfs/pkgs/mhpcc/anaconda3-5.0.1/lib/python3.6/site-packages/h5py/__init__.py:34: FutureWarning: Conversion of the second argument of issubdtype from `float` to `np.floating` is deprecated. In future, it will be treated as `np.float64 == np.dtype(float).type`.
  from ._conv import register_converters as _register_converters
Using TensorFlow backend.
Traceback (most recent call last):
  File "roundOneSubmit.py", line 23, in <module>
    l.learnThingsCPP(kind=0, file=f, weightFile=wf)
  File "/gpfs/home/m201560/chipboard/learn.py", line 130, in learnThingsCPP
    weights = self.getWeightArray()
  File "/gpfs/home/m201560/chipboard/learn.py", line 199, in getWeightArray
    return self.model.get_weights()[0].tolist()
  File "/gpfs/home/m201560/.local/lib/python3.6/site-packages/keras/engine/network.py", line 492, in get_weights
    return K.batch_get_value(weights)
  File "/gpfs/home/m201560/.local/lib/python3.6/site-packages/keras/backend/tensorflow_backend.py", line 2420, in batch_get_value
    return get_session().run(ops)
  File "/gpfs/home/m201560/.local/lib/python3.6/site-packages/keras/backend/tensorflow_backend.py", line 186, in get_session
    _SESSION = tf.Session(config=config)
  File "/gpfs/pkgs/mhpcc/anaconda3-5.0.1/lib/python3.6/site-packages/tensorflow/python/client/session.py", line 1563, in __init__
    super(Session, self).__init__(target, graph, config=config)
  File "/gpfs/pkgs/mhpcc/anaconda3-5.0.1/lib/python3.6/site-packages/tensorflow/python/client/session.py", line 633, in __init__
    self._session = tf_session.TF_NewSession(self._graph._c_graph, opts)
tensorflow.python.framework.errors_impl.InternalError: Failed to create session.
2019-08-02 11:20:25.456212: E tensorflow/core/common_runtime/direct_session.cc:158] Internal: failed initializing StreamExecutor for CUDA device ordinal 0: Internal: failed call to cuDevicePrimaryCtxRetain: CUDA_ERROR_INVALID_DEVICE
/gpfs/pkgs/mhpcc/anaconda3-5.0.1/lib/python3.6/site-packages/h5py/__init__.py:34: FutureWarning: Conversion of the second argument of issubdtype from `float` to `np.floating` is deprecated. In future, it will be treated as `np.float64 == np.dtype(float).type`.
  from ._conv import register_converters as _register_converters
Using TensorFlow backend.
Traceback (most recent call last):
  File "roundOneSubmit.py", line 23, in <module>
    l.learnThingsCPP(kind=0, file=f, weightFile=wf)
  File "/gpfs/home/m201560/chipboard/learn.py", line 130, in learnThingsCPP
    weights = self.getWeightArray()
  File "/gpfs/home/m201560/chipboard/learn.py", line 199, in getWeightArray
    return self.model.get_weights()[0].tolist()
  File "/gpfs/home/m201560/.local/lib/python3.6/site-packages/keras/engine/network.py", line 492, in get_weights
    return K.batch_get_value(weights)
  File "/gpfs/home/m201560/.local/lib/python3.6/site-packages/keras/backend/tensorflow_backend.py", line 2420, in batch_get_value
    return get_session().run(ops)
  File "/gpfs/home/m201560/.local/lib/python3.6/site-packages/keras/backend/tensorflow_backend.py", line 186, in get_session
    _SESSION = tf.Session(config=config)
  File "/gpfs/pkgs/mhpcc/anaconda3-5.0.1/lib/python3.6/site-packages/tensorflow/python/client/session.py", line 1563, in __init__
    super(Session, self).__init__(target, graph, config=config)
  File "/gpfs/pkgs/mhpcc/anaconda3-5.0.1/lib/python3.6/site-packages/tensorflow/python/client/session.py", line 633, in __init__
    self._session = tf_session.TF_NewSession(self._graph._c_graph, opts)
tensorflow.python.framework.errors_impl.InternalError: Failed to create session.
2019-08-02 11:20:25.463836: E tensorflow/core/common_runtime/direct_session.cc:158] Internal: failed initializing StreamExecutor for CUDA device ordinal 0: Internal: failed call to cuDevicePrimaryCtxRetain: CUDA_ERROR_INVALID_DEVICE
/gpfs/pkgs/mhpcc/anaconda3-5.0.1/lib/python3.6/site-packages/h5py/__init__.py:34: FutureWarning: Conversion of the second argument of issubdtype from `float` to `np.floating` is deprecated. In future, it will be treated as `np.float64 == np.dtype(float).type`.
  from ._conv import register_converters as _register_converters
Using TensorFlow backend.
Traceback (most recent call last):
  File "roundOneSubmit.py", line 23, in <module>
    l.learnThingsCPP(kind=0, file=f, weightFile=wf)
  File "/gpfs/home/m201560/chipboard/learn.py", line 130, in learnThingsCPP
    weights = self.getWeightArray()
  File "/gpfs/home/m201560/chipboard/learn.py", line 199, in getWeightArray
    return self.model.get_weights()[0].tolist()
  File "/gpfs/home/m201560/.local/lib/python3.6/site-packages/keras/engine/network.py", line 492, in get_weights
    return K.batch_get_value(weights)
  File "/gpfs/home/m201560/.local/lib/python3.6/site-packages/keras/backend/tensorflow_backend.py", line 2420, in batch_get_value
    return get_session().run(ops)
  File "/gpfs/home/m201560/.local/lib/python3.6/site-packages/keras/backend/tensorflow_backend.py", line 186, in get_session
    _SESSION = tf.Session(config=config)
  File "/gpfs/pkgs/mhpcc/anaconda3-5.0.1/lib/python3.6/site-packages/tensorflow/python/client/session.py", line 1563, in __init__
    super(Session, self).__init__(target, graph, config=config)
  File "/gpfs/pkgs/mhpcc/anaconda3-5.0.1/lib/python3.6/site-packages/tensorflow/python/client/session.py", line 633, in __init__
    self._session = tf_session.TF_NewSession(self._graph._c_graph, opts)
tensorflow.python.framework.errors_impl.InternalError: Failed to create session.
2019-08-02 11:20:25.479069: E tensorflow/core/common_runtime/direct_session.cc:158] Internal: failed initializing StreamExecutor for CUDA device ordinal 0: Internal: failed call to cuDevicePrimaryCtxRetain: CUDA_ERROR_INVALID_DEVICE
/gpfs/pkgs/mhpcc/anaconda3-5.0.1/lib/python3.6/site-packages/h5py/__init__.py:34: FutureWarning: Conversion of the second argument of issubdtype from `float` to `np.floating` is deprecated. In future, it will be treated as `np.float64 == np.dtype(float).type`.
  from ._conv import register_converters as _register_converters
Using TensorFlow backend.
Traceback (most recent call last):
  File "roundOneSubmit.py", line 23, in <module>
    l.learnThingsCPP(kind=0, file=f, weightFile=wf)
  File "/gpfs/home/m201560/chipboard/learn.py", line 130, in learnThingsCPP
    weights = self.getWeightArray()
  File "/gpfs/home/m201560/chipboard/learn.py", line 199, in getWeightArray
    return self.model.get_weights()[0].tolist()
  File "/gpfs/home/m201560/.local/lib/python3.6/site-packages/keras/engine/network.py", line 492, in get_weights
    return K.batch_get_value(weights)
  File "/gpfs/home/m201560/.local/lib/python3.6/site-packages/keras/backend/tensorflow_backend.py", line 2420, in batch_get_value
    return get_session().run(ops)
  File "/gpfs/home/m201560/.local/lib/python3.6/site-packages/keras/backend/tensorflow_backend.py", line 186, in get_session
    _SESSION = tf.Session(config=config)
  File "/gpfs/pkgs/mhpcc/anaconda3-5.0.1/lib/python3.6/site-packages/tensorflow/python/client/session.py", line 1563, in __init__
    super(Session, self).__init__(target, graph, config=config)
  File "/gpfs/pkgs/mhpcc/anaconda3-5.0.1/lib/python3.6/site-packages/tensorflow/python/client/session.py", line 633, in __init__
    self._session = tf_session.TF_NewSession(self._graph._c_graph, opts)
tensorflow.python.framework.errors_impl.InternalError: Failed to create session.
2019-08-02 11:20:25.494209: E tensorflow/core/common_runtime/direct_session.cc:158] Internal: failed initializing StreamExecutor for CUDA device ordinal 0: Internal: failed call to cuDevicePrimaryCtxRetain: CUDA_ERROR_INVALID_DEVICE
/gpfs/pkgs/mhpcc/anaconda3-5.0.1/lib/python3.6/site-packages/h5py/__init__.py:34: FutureWarning: Conversion of the second argument of issubdtype from `float` to `np.floating` is deprecated. In future, it will be treated as `np.float64 == np.dtype(float).type`.
  from ._conv import register_converters as _register_converters
Using TensorFlow backend.
Traceback (most recent call last):
  File "roundOneSubmit.py", line 23, in <module>
    l.learnThingsCPP(kind=0, file=f, weightFile=wf)
  File "/gpfs/home/m201560/chipboard/learn.py", line 130, in learnThingsCPP
    weights = self.getWeightArray()
  File "/gpfs/home/m201560/chipboard/learn.py", line 199, in getWeightArray
    return self.model.get_weights()[0].tolist()
  File "/gpfs/home/m201560/.local/lib/python3.6/site-packages/keras/engine/network.py", line 492, in get_weights
    return K.batch_get_value(weights)
  File "/gpfs/home/m201560/.local/lib/python3.6/site-packages/keras/backend/tensorflow_backend.py", line 2420, in batch_get_value
    return get_session().run(ops)
  File "/gpfs/home/m201560/.local/lib/python3.6/site-packages/keras/backend/tensorflow_backend.py", line 186, in get_session
    _SESSION = tf.Session(config=config)
  File "/gpfs/pkgs/mhpcc/anaconda3-5.0.1/lib/python3.6/site-packages/tensorflow/python/client/session.py", line 1563, in __init__
    super(Session, self).__init__(target, graph, config=config)
  File "/gpfs/pkgs/mhpcc/anaconda3-5.0.1/lib/python3.6/site-packages/tensorflow/python/client/session.py", line 633, in __init__
    self._session = tf_session.TF_NewSession(self._graph._c_graph, opts)
tensorflow.python.framework.errors_impl.InternalError: Failed to create session.
2019-08-02 11:20:25.512556: E tensorflow/core/common_runtime/direct_session.cc:158] Internal: failed initializing StreamExecutor for CUDA device ordinal 0: Internal: failed call to cuDevicePrimaryCtxRetain: CUDA_ERROR_INVALID_DEVICE
/gpfs/pkgs/mhpcc/anaconda3-5.0.1/lib/python3.6/site-packages/h5py/__init__.py:34: FutureWarning: Conversion of the second argument of issubdtype from `float` to `np.floating` is deprecated. In future, it will be treated as `np.float64 == np.dtype(float).type`.
  from ._conv import register_converters as _register_converters
Using TensorFlow backend.
Traceback (most recent call last):
  File "roundOneSubmit.py", line 23, in <module>
    l.learnThingsCPP(kind=0, file=f, weightFile=wf)
  File "/gpfs/home/m201560/chipboard/learn.py", line 130, in learnThingsCPP
    weights = self.getWeightArray()
  File "/gpfs/home/m201560/chipboard/learn.py", line 199, in getWeightArray
    return self.model.get_weights()[0].tolist()
  File "/gpfs/home/m201560/.local/lib/python3.6/site-packages/keras/engine/network.py", line 492, in get_weights
    return K.batch_get_value(weights)
  File "/gpfs/home/m201560/.local/lib/python3.6/site-packages/keras/backend/tensorflow_backend.py", line 2420, in batch_get_value
    return get_session().run(ops)
  File "/gpfs/home/m201560/.local/lib/python3.6/site-packages/keras/backend/tensorflow_backend.py", line 186, in get_session
    _SESSION = tf.Session(config=config)
  File "/gpfs/pkgs/mhpcc/anaconda3-5.0.1/lib/python3.6/site-packages/tensorflow/python/client/session.py", line 1563, in __init__
    super(Session, self).__init__(target, graph, config=config)
  File "/gpfs/pkgs/mhpcc/anaconda3-5.0.1/lib/python3.6/site-packages/tensorflow/python/client/session.py", line 633, in __init__
    self._session = tf_session.TF_NewSession(self._graph._c_graph, opts)
tensorflow.python.framework.errors_impl.InternalError: Failed to create session.
2019-08-02 11:20:25.521353: E tensorflow/core/common_runtime/direct_session.cc:158] Internal: failed initializing StreamExecutor for CUDA device ordinal 0: Internal: failed call to cuDevicePrimaryCtxRetain: CUDA_ERROR_INVALID_DEVICE
/gpfs/pkgs/mhpcc/anaconda3-5.0.1/lib/python3.6/site-packages/h5py/__init__.py:34: FutureWarning: Conversion of the second argument of issubdtype from `float` to `np.floating` is deprecated. In future, it will be treated as `np.float64 == np.dtype(float).type`.
  from ._conv import register_converters as _register_converters
Using TensorFlow backend.
Traceback (most recent call last):
  File "roundOneSubmit.py", line 23, in <module>
    l.learnThingsCPP(kind=0, file=f, weightFile=wf)
  File "/gpfs/home/m201560/chipboard/learn.py", line 130, in learnThingsCPP
    weights = self.getWeightArray()
  File "/gpfs/home/m201560/chipboard/learn.py", line 199, in getWeightArray
    return self.model.get_weights()[0].tolist()
  File "/gpfs/home/m201560/.local/lib/python3.6/site-packages/keras/engine/network.py", line 492, in get_weights
    return K.batch_get_value(weights)
  File "/gpfs/home/m201560/.local/lib/python3.6/site-packages/keras/backend/tensorflow_backend.py", line 2420, in batch_get_value
    return get_session().run(ops)
  File "/gpfs/home/m201560/.local/lib/python3.6/site-packages/keras/backend/tensorflow_backend.py", line 186, in get_session
    _SESSION = tf.Session(config=config)
  File "/gpfs/pkgs/mhpcc/anaconda3-5.0.1/lib/python3.6/site-packages/tensorflow/python/client/session.py", line 1563, in __init__
    super(Session, self).__init__(target, graph, config=config)
  File "/gpfs/pkgs/mhpcc/anaconda3-5.0.1/lib/python3.6/site-packages/tensorflow/python/client/session.py", line 633, in __init__
    self._session = tf_session.TF_NewSession(self._graph._c_graph, opts)
tensorflow.python.framework.errors_impl.InternalError: Failed to create session.
2019-08-02 11:20:25.538307: E tensorflow/core/common_runtime/direct_session.cc:158] Internal: failed initializing StreamExecutor for CUDA device ordinal 0: Internal: failed call to cuDevicePrimaryCtxRetain: CUDA_ERROR_INVALID_DEVICE
/gpfs/pkgs/mhpcc/anaconda3-5.0.1/lib/python3.6/site-packages/h5py/__init__.py:34: FutureWarning: Conversion of the second argument of issubdtype from `float` to `np.floating` is deprecated. In future, it will be treated as `np.float64 == np.dtype(float).type`.
  from ._conv import register_converters as _register_converters
Using TensorFlow backend.
2019-08-02 11:20:25.546908: E tensorflow/core/common_runtime/direct_session.cc:158] Internal: failed initializing StreamExecutor for CUDA device ordinal 0: Internal: failed call to cuDevicePrimaryCtxRetain: CUDA_ERROR_INVALID_DEVICE
/gpfs/pkgs/mhpcc/anaconda3-5.0.1/lib/python3.6/site-packages/h5py/__init__.py:34: FutureWarning: Conversion of the second argument of issubdtype from `float` to `np.floating` is deprecated. In future, it will be treated as `np.float64 == np.dtype(float).type`.
  from ._conv import register_converters as _register_converters
Using TensorFlow backend.
Traceback (most recent call last):
  File "roundOneSubmit.py", line 23, in <module>
    l.learnThingsCPP(kind=0, file=f, weightFile=wf)
  File "/gpfs/home/m201560/chipboard/learn.py", line 130, in learnThingsCPP
    weights = self.getWeightArray()
  File "/gpfs/home/m201560/chipboard/learn.py", line 199, in getWeightArray
    return self.model.get_weights()[0].tolist()
  File "/gpfs/home/m201560/.local/lib/python3.6/site-packages/keras/engine/network.py", line 492, in get_weights
    return K.batch_get_value(weights)
  File "/gpfs/home/m201560/.local/lib/python3.6/site-packages/keras/backend/tensorflow_backend.py", line 2420, in batch_get_value
    return get_session().run(ops)
  File "/gpfs/home/m201560/.local/lib/python3.6/site-packages/keras/backend/tensorflow_backend.py", line 186, in get_session
    _SESSION = tf.Session(config=config)
  File "/gpfs/pkgs/mhpcc/anaconda3-5.0.1/lib/python3.6/site-packages/tensorflow/python/client/session.py", line 1563, in __init__
    super(Session, self).__init__(target, graph, config=config)
  File "/gpfs/pkgs/mhpcc/anaconda3-5.0.1/lib/python3.6/site-packages/tensorflow/python/client/session.py", line 633, in __init__
    self._session = tf_session.TF_NewSession(self._graph._c_graph, opts)
tensorflow.python.framework.errors_impl.InternalError: Failed to create session.
2019-08-02 11:20:25.554527: E tensorflow/core/common_runtime/direct_session.cc:158] Internal: failed initializing StreamExecutor for CUDA device ordinal 0: Internal: failed call to cuDevicePrimaryCtxRetain: CUDA_ERROR_INVALID_DEVICE
/gpfs/pkgs/mhpcc/anaconda3-5.0.1/lib/python3.6/site-packages/h5py/__init__.py:34: FutureWarning: Conversion of the second argument of issubdtype from `float` to `np.floating` is deprecated. In future, it will be treated as `np.float64 == np.dtype(float).type`.
  from ._conv import register_converters as _register_converters
Using TensorFlow backend.
Traceback (most recent call last):
  File "roundOneSubmit.py", line 23, in <module>
    l.learnThingsCPP(kind=0, file=f, weightFile=wf)
  File "/gpfs/home/m201560/chipboard/learn.py", line 130, in learnThingsCPP
    weights = self.getWeightArray()
  File "/gpfs/home/m201560/chipboard/learn.py", line 199, in getWeightArray
    return self.model.get_weights()[0].tolist()
  File "/gpfs/home/m201560/.local/lib/python3.6/site-packages/keras/engine/network.py", line 492, in get_weights
    return K.batch_get_value(weights)
  File "/gpfs/home/m201560/.local/lib/python3.6/site-packages/keras/backend/tensorflow_backend.py", line 2420, in batch_get_value
    return get_session().run(ops)
  File "/gpfs/home/m201560/.local/lib/python3.6/site-packages/keras/backend/tensorflow_backend.py", line 186, in get_session
    _SESSION = tf.Session(config=config)
  File "/gpfs/pkgs/mhpcc/anaconda3-5.0.1/lib/python3.6/site-packages/tensorflow/python/client/session.py", line 1563, in __init__
    super(Session, self).__init__(target, graph, config=config)
  File "/gpfs/pkgs/mhpcc/anaconda3-5.0.1/lib/python3.6/site-packages/tensorflow/python/client/session.py", line 633, in __init__
    self._session = tf_session.TF_NewSession(self._graph._c_graph, opts)
tensorflow.python.framework.errors_impl.InternalError: Failed to create session.
Traceback (most recent call last):
  File "roundOneSubmit.py", line 23, in <module>
    l.learnThingsCPP(kind=0, file=f, weightFile=wf)
  File "/gpfs/home/m201560/chipboard/learn.py", line 130, in learnThingsCPP
    weights = self.getWeightArray()
  File "/gpfs/home/m201560/chipboard/learn.py", line 199, in getWeightArray
    return self.model.get_weights()[0].tolist()
  File "/gpfs/home/m201560/.local/lib/python3.6/site-packages/keras/engine/network.py", line 492, in get_weights
    return K.batch_get_value(weights)
  File "/gpfs/home/m201560/.local/lib/python3.6/site-packages/keras/backend/tensorflow_backend.py", line 2420, in batch_get_value
    return get_session().run(ops)
  File "/gpfs/home/m201560/.local/lib/python3.6/site-packages/keras/backend/tensorflow_backend.py", line 186, in get_session
    _SESSION = tf.Session(config=config)
  File "/gpfs/pkgs/mhpcc/anaconda3-5.0.1/lib/python3.6/site-packages/tensorflow/python/client/session.py", line 1563, in __init__
    super(Session, self).__init__(target, graph, config=config)
  File "/gpfs/pkgs/mhpcc/anaconda3-5.0.1/lib/python3.6/site-packages/tensorflow/python/client/session.py", line 633, in __init__
    self._session = tf_session.TF_NewSession(self._graph._c_graph, opts)
tensorflow.python.framework.errors_impl.InternalError: Failed to create session.
2019-08-02 11:20:25.568587: E tensorflow/core/common_runtime/direct_session.cc:158] Internal: failed initializing StreamExecutor for CUDA device ordinal 0: Internal: failed call to cuDevicePrimaryCtxRetain: CUDA_ERROR_INVALID_DEVICE
/gpfs/pkgs/mhpcc/anaconda3-5.0.1/lib/python3.6/site-packages/h5py/__init__.py:34: FutureWarning: Conversion of the second argument of issubdtype from `float` to `np.floating` is deprecated. In future, it will be treated as `np.float64 == np.dtype(float).type`.
  from ._conv import register_converters as _register_converters
Using TensorFlow backend.
2019-08-02 11:20:25.579552: E tensorflow/core/common_runtime/direct_session.cc:158] Internal: failed initializing StreamExecutor for CUDA device ordinal 0: Internal: failed call to cuDevicePrimaryCtxRetain: CUDA_ERROR_INVALID_DEVICE
/gpfs/pkgs/mhpcc/anaconda3-5.0.1/lib/python3.6/site-packages/h5py/__init__.py:34: FutureWarning: Conversion of the second argument of issubdtype from `float` to `np.floating` is deprecated. In future, it will be treated as `np.float64 == np.dtype(float).type`.
  from ._conv import register_converters as _register_converters
Using TensorFlow backend.
Traceback (most recent call last):
  File "roundOneSubmit.py", line 23, in <module>
    l.learnThingsCPP(kind=0, file=f, weightFile=wf)
  File "/gpfs/home/m201560/chipboard/learn.py", line 130, in learnThingsCPP
    weights = self.getWeightArray()
  File "/gpfs/home/m201560/chipboard/learn.py", line 199, in getWeightArray
    return self.model.get_weights()[0].tolist()
  File "/gpfs/home/m201560/.local/lib/python3.6/site-packages/keras/engine/network.py", line 492, in get_weights
    return K.batch_get_value(weights)
  File "/gpfs/home/m201560/.local/lib/python3.6/site-packages/keras/backend/tensorflow_backend.py", line 2420, in batch_get_value
    return get_session().run(ops)
  File "/gpfs/home/m201560/.local/lib/python3.6/site-packages/keras/backend/tensorflow_backend.py", line 186, in get_session
    _SESSION = tf.Session(config=config)
  File "/gpfs/pkgs/mhpcc/anaconda3-5.0.1/lib/python3.6/site-packages/tensorflow/python/client/session.py", line 1563, in __init__
    super(Session, self).__init__(target, graph, config=config)
  File "/gpfs/pkgs/mhpcc/anaconda3-5.0.1/lib/python3.6/site-packages/tensorflow/python/client/session.py", line 633, in __init__
    self._session = tf_session.TF_NewSession(self._graph._c_graph, opts)
tensorflow.python.framework.errors_impl.InternalError: Failed to create session.
Traceback (most recent call last):
  File "roundOneSubmit.py", line 23, in <module>
    l.learnThingsCPP(kind=0, file=f, weightFile=wf)
  File "/gpfs/home/m201560/chipboard/learn.py", line 130, in learnThingsCPP
    weights = self.getWeightArray()
  File "/gpfs/home/m201560/chipboard/learn.py", line 199, in getWeightArray
    return self.model.get_weights()[0].tolist()
  File "/gpfs/home/m201560/.local/lib/python3.6/site-packages/keras/engine/network.py", line 492, in get_weights
    return K.batch_get_value(weights)
  File "/gpfs/home/m201560/.local/lib/python3.6/site-packages/keras/backend/tensorflow_backend.py", line 2420, in batch_get_value
    return get_session().run(ops)
  File "/gpfs/home/m201560/.local/lib/python3.6/site-packages/keras/backend/tensorflow_backend.py", line 186, in get_session
    _SESSION = tf.Session(config=config)
  File "/gpfs/pkgs/mhpcc/anaconda3-5.0.1/lib/python3.6/site-packages/tensorflow/python/client/session.py", line 1563, in __init__
    super(Session, self).__init__(target, graph, config=config)
  File "/gpfs/pkgs/mhpcc/anaconda3-5.0.1/lib/python3.6/site-packages/tensorflow/python/client/session.py", line 633, in __init__
    self._session = tf_session.TF_NewSession(self._graph._c_graph, opts)
tensorflow.python.framework.errors_impl.InternalError: Failed to create session.
2019-08-02 11:20:25.589669: E tensorflow/core/common_runtime/direct_session.cc:158] Internal: failed initializing StreamExecutor for CUDA device ordinal 0: Internal: failed call to cuDevicePrimaryCtxRetain: CUDA_ERROR_INVALID_DEVICE
/gpfs/pkgs/mhpcc/anaconda3-5.0.1/lib/python3.6/site-packages/h5py/__init__.py:34: FutureWarning: Conversion of the second argument of issubdtype from `float` to `np.floating` is deprecated. In future, it will be treated as `np.float64 == np.dtype(float).type`.
  from ._conv import register_converters as _register_converters
Using TensorFlow backend.
2019-08-02 11:20:25.591035: E tensorflow/core/common_runtime/direct_session.cc:158] Internal: failed initializing StreamExecutor for CUDA device ordinal 0: Internal: failed call to cuDevicePrimaryCtxRetain: CUDA_ERROR_INVALID_DEVICE
/gpfs/pkgs/mhpcc/anaconda3-5.0.1/lib/python3.6/site-packages/h5py/__init__.py:34: FutureWarning: Conversion of the second argument of issubdtype from `float` to `np.floating` is deprecated. In future, it will be treated as `np.float64 == np.dtype(float).type`.
  from ._conv import register_converters as _register_converters
Using TensorFlow backend.
2019-08-02 11:20:25.594822: E tensorflow/core/common_runtime/direct_session.cc:158] Internal: failed initializing StreamExecutor for CUDA device ordinal 0: Internal: failed call to cuDevicePrimaryCtxRetain: CUDA_ERROR_INVALID_DEVICE
/gpfs/pkgs/mhpcc/anaconda3-5.0.1/lib/python3.6/site-packages/h5py/__init__.py:34: FutureWarning: Conversion of the second argument of issubdtype from `float` to `np.floating` is deprecated. In future, it will be treated as `np.float64 == np.dtype(float).type`.
  from ._conv import register_converters as _register_converters
Using TensorFlow backend.
Traceback (most recent call last):
  File "roundOneSubmit.py", line 23, in <module>
    l.learnThingsCPP(kind=0, file=f, weightFile=wf)
  File "/gpfs/home/m201560/chipboard/learn.py", line 130, in learnThingsCPP
    weights = self.getWeightArray()
  File "/gpfs/home/m201560/chipboard/learn.py", line 199, in getWeightArray
    return self.model.get_weights()[0].tolist()
  File "/gpfs/home/m201560/.local/lib/python3.6/site-packages/keras/engine/network.py", line 492, in get_weights
    return K.batch_get_value(weights)
  File "/gpfs/home/m201560/.local/lib/python3.6/site-packages/keras/backend/tensorflow_backend.py", line 2420, in batch_get_value
    return get_session().run(ops)
  File "/gpfs/home/m201560/.local/lib/python3.6/site-packages/keras/backend/tensorflow_backend.py", line 186, in get_session
    _SESSION = tf.Session(config=config)
  File "/gpfs/pkgs/mhpcc/anaconda3-5.0.1/lib/python3.6/site-packages/tensorflow/python/client/session.py", line 1563, in __init__
    super(Session, self).__init__(target, graph, config=config)
  File "/gpfs/pkgs/mhpcc/anaconda3-5.0.1/lib/python3.6/site-packages/tensorflow/python/client/session.py", line 633, in __init__
    self._session = tf_session.TF_NewSession(self._graph._c_graph, opts)
tensorflow.python.framework.errors_impl.InternalError: Failed to create session.
Traceback (most recent call last):
  File "roundOneSubmit.py", line 23, in <module>
    l.learnThingsCPP(kind=0, file=f, weightFile=wf)
  File "/gpfs/home/m201560/chipboard/learn.py", line 130, in learnThingsCPP
    weights = self.getWeightArray()
  File "/gpfs/home/m201560/chipboard/learn.py", line 199, in getWeightArray
    return self.model.get_weights()[0].tolist()
  File "/gpfs/home/m201560/.local/lib/python3.6/site-packages/keras/engine/network.py", line 492, in get_weights
    return K.batch_get_value(weights)
  File "/gpfs/home/m201560/.local/lib/python3.6/site-packages/keras/backend/tensorflow_backend.py", line 2420, in batch_get_value
    return get_session().run(ops)
  File "/gpfs/home/m201560/.local/lib/python3.6/site-packages/keras/backend/tensorflow_backend.py", line 186, in get_session
    _SESSION = tf.Session(config=config)
  File "/gpfs/pkgs/mhpcc/anaconda3-5.0.1/lib/python3.6/site-packages/tensorflow/python/client/session.py", line 1563, in __init__
    super(Session, self).__init__(target, graph, config=config)
  File "/gpfs/pkgs/mhpcc/anaconda3-5.0.1/lib/python3.6/site-packages/tensorflow/python/client/session.py", line 633, in __init__
    self._session = tf_session.TF_NewSession(self._graph._c_graph, opts)
tensorflow.python.framework.errors_impl.InternalError: Failed to create session.
Traceback (most recent call last):
  File "roundOneSubmit.py", line 23, in <module>
    l.learnThingsCPP(kind=0, file=f, weightFile=wf)
  File "/gpfs/home/m201560/chipboard/learn.py", line 130, in learnThingsCPP
    weights = self.getWeightArray()
  File "/gpfs/home/m201560/chipboard/learn.py", line 199, in getWeightArray
    return self.model.get_weights()[0].tolist()
  File "/gpfs/home/m201560/.local/lib/python3.6/site-packages/keras/engine/network.py", line 492, in get_weights
    return K.batch_get_value(weights)
  File "/gpfs/home/m201560/.local/lib/python3.6/site-packages/keras/backend/tensorflow_backend.py", line 2420, in batch_get_value
    return get_session().run(ops)
  File "/gpfs/home/m201560/.local/lib/python3.6/site-packages/keras/backend/tensorflow_backend.py", line 186, in get_session
    _SESSION = tf.Session(config=config)
  File "/gpfs/pkgs/mhpcc/anaconda3-5.0.1/lib/python3.6/site-packages/tensorflow/python/client/session.py", line 1563, in __init__
    super(Session, self).__init__(target, graph, config=config)
  File "/gpfs/pkgs/mhpcc/anaconda3-5.0.1/lib/python3.6/site-packages/tensorflow/python/client/session.py", line 633, in __init__
    self._session = tf_session.TF_NewSession(self._graph._c_graph, opts)
tensorflow.python.framework.errors_impl.InternalError: Failed to create session.
2019-08-02 11:20:25.610777: E tensorflow/core/common_runtime/direct_session.cc:158] Internal: failed initializing StreamExecutor for CUDA device ordinal 0: Internal: failed call to cuDevicePrimaryCtxRetain: CUDA_ERROR_INVALID_DEVICE
/gpfs/pkgs/mhpcc/anaconda3-5.0.1/lib/python3.6/site-packages/h5py/__init__.py:34: FutureWarning: Conversion of the second argument of issubdtype from `float` to `np.floating` is deprecated. In future, it will be treated as `np.float64 == np.dtype(float).type`.
  from ._conv import register_converters as _register_converters
Using TensorFlow backend.
2019-08-02 11:20:25.613447: E tensorflow/core/common_runtime/direct_session.cc:158] Internal: failed initializing StreamExecutor for CUDA device ordinal 0: Internal: failed call to cuDevicePrimaryCtxRetain: CUDA_ERROR_INVALID_DEVICE
/gpfs/pkgs/mhpcc/anaconda3-5.0.1/lib/python3.6/site-packages/h5py/__init__.py:34: FutureWarning: Conversion of the second argument of issubdtype from `float` to `np.floating` is deprecated. In future, it will be treated as `np.float64 == np.dtype(float).type`.
  from ._conv import register_converters as _register_converters
Using TensorFlow backend.
2019-08-02 11:20:25.615856: E tensorflow/core/common_runtime/direct_session.cc:158] Internal: failed initializing StreamExecutor for CUDA device ordinal 0: Internal: failed call to cuDevicePrimaryCtxRetain: CUDA_ERROR_INVALID_DEVICE
/gpfs/pkgs/mhpcc/anaconda3-5.0.1/lib/python3.6/site-packages/h5py/__init__.py:34: FutureWarning: Conversion of the second argument of issubdtype from `float` to `np.floating` is deprecated. In future, it will be treated as `np.float64 == np.dtype(float).type`.
  from ._conv import register_converters as _register_converters
Using TensorFlow backend.
2019-08-02 11:20:25.618108: E tensorflow/core/common_runtime/direct_session.cc:158] Internal: failed initializing StreamExecutor for CUDA device ordinal 0: Internal: failed call to cuDevicePrimaryCtxRetain: CUDA_ERROR_INVALID_DEVICE
/gpfs/pkgs/mhpcc/anaconda3-5.0.1/lib/python3.6/site-packages/h5py/__init__.py:34: FutureWarning: Conversion of the second argument of issubdtype from `float` to `np.floating` is deprecated. In future, it will be treated as `np.float64 == np.dtype(float).type`.
  from ._conv import register_converters as _register_converters
Using TensorFlow backend.
2019-08-02 11:20:25.620160: E tensorflow/core/common_runtime/direct_session.cc:158] Internal: failed initializing StreamExecutor for CUDA device ordinal 0: Internal: failed call to cuDevicePrimaryCtxRetain: CUDA_ERROR_INVALID_DEVICE
/gpfs/pkgs/mhpcc/anaconda3-5.0.1/lib/python3.6/site-packages/h5py/__init__.py:34: FutureWarning: Conversion of the second argument of issubdtype from `float` to `np.floating` is deprecated. In future, it will be treated as `np.float64 == np.dtype(float).type`.
  from ._conv import register_converters as _register_converters
Using TensorFlow backend.
Traceback (most recent call last):
  File "roundOneSubmit.py", line 23, in <module>
    l.learnThingsCPP(kind=0, file=f, weightFile=wf)
  File "/gpfs/home/m201560/chipboard/learn.py", line 130, in learnThingsCPP
    weights = self.getWeightArray()
  File "/gpfs/home/m201560/chipboard/learn.py", line 199, in getWeightArray
    return self.model.get_weights()[0].tolist()
  File "/gpfs/home/m201560/.local/lib/python3.6/site-packages/keras/engine/network.py", line 492, in get_weights
    return K.batch_get_value(weights)
  File "/gpfs/home/m201560/.local/lib/python3.6/site-packages/keras/backend/tensorflow_backend.py", line 2420, in batch_get_value
    return get_session().run(ops)
  File "/gpfs/home/m201560/.local/lib/python3.6/site-packages/keras/backend/tensorflow_backend.py", line 186, in get_session
    _SESSION = tf.Session(config=config)
  File "/gpfs/pkgs/mhpcc/anaconda3-5.0.1/lib/python3.6/site-packages/tensorflow/python/client/session.py", line 1563, in __init__
    super(Session, self).__init__(target, graph, config=config)
  File "/gpfs/pkgs/mhpcc/anaconda3-5.0.1/lib/python3.6/site-packages/tensorflow/python/client/session.py", line 633, in __init__
    self._session = tf_session.TF_NewSession(self._graph._c_graph, opts)
tensorflow.python.framework.errors_impl.InternalError: Failed to create session.
2019-08-02 11:20:25.620933: E tensorflow/core/common_runtime/direct_session.cc:158] Internal: failed initializing StreamExecutor for CUDA device ordinal 0: Internal: failed call to cuDevicePrimaryCtxRetain: CUDA_ERROR_INVALID_DEVICE
/gpfs/pkgs/mhpcc/anaconda3-5.0.1/lib/python3.6/site-packages/h5py/__init__.py:34: FutureWarning: Conversion of the second argument of issubdtype from `float` to `np.floating` is deprecated. In future, it will be treated as `np.float64 == np.dtype(float).type`.
  from ._conv import register_converters as _register_converters
Using TensorFlow backend.
2019-08-02 11:20:25.621261: E tensorflow/core/common_runtime/direct_session.cc:158] Internal: failed initializing StreamExecutor for CUDA device ordinal 0: Internal: failed call to cuDevicePrimaryCtxRetain: CUDA_ERROR_INVALID_DEVICE
/gpfs/pkgs/mhpcc/anaconda3-5.0.1/lib/python3.6/site-packages/h5py/__init__.py:34: FutureWarning: Conversion of the second argument of issubdtype from `float` to `np.floating` is deprecated. In future, it will be treated as `np.float64 == np.dtype(float).type`.
  from ._conv import register_converters as _register_converters
Using TensorFlow backend.
2019-08-02 11:20:25.621539: E tensorflow/core/common_runtime/direct_session.cc:158] Internal: failed initializing StreamExecutor for CUDA device ordinal 0: Internal: failed call to cuDevicePrimaryCtxRetain: CUDA_ERROR_INVALID_DEVICE
/gpfs/pkgs/mhpcc/anaconda3-5.0.1/lib/python3.6/site-packages/h5py/__init__.py:34: FutureWarning: Conversion of the second argument of issubdtype from `float` to `np.floating` is deprecated. In future, it will be treated as `np.float64 == np.dtype(float).type`.
  from ._conv import register_converters as _register_converters
Using TensorFlow backend.
Traceback (most recent call last):
  File "roundOneSubmit.py", line 23, in <module>
    l.learnThingsCPP(kind=0, file=f, weightFile=wf)
  File "/gpfs/home/m201560/chipboard/learn.py", line 130, in learnThingsCPP
    weights = self.getWeightArray()
  File "/gpfs/home/m201560/chipboard/learn.py", line 199, in getWeightArray
    return self.model.get_weights()[0].tolist()
  File "/gpfs/home/m201560/.local/lib/python3.6/site-packages/keras/engine/network.py", line 492, in get_weights
    return K.batch_get_value(weights)
  File "/gpfs/home/m201560/.local/lib/python3.6/site-packages/keras/backend/tensorflow_backend.py", line 2420, in batch_get_value
    return get_session().run(ops)
  File "/gpfs/home/m201560/.local/lib/python3.6/site-packages/keras/backend/tensorflow_backend.py", line 186, in get_session
    _SESSION = tf.Session(config=config)
  File "/gpfs/pkgs/mhpcc/anaconda3-5.0.1/lib/python3.6/site-packages/tensorflow/python/client/session.py", line 1563, in __init__
    super(Session, self).__init__(target, graph, config=config)
  File "/gpfs/pkgs/mhpcc/anaconda3-5.0.1/lib/python3.6/site-packages/tensorflow/python/client/session.py", line 633, in __init__
    self._session = tf_session.TF_NewSession(self._graph._c_graph, opts)
tensorflow.python.framework.errors_impl.InternalError: Failed to create session.
Traceback (most recent call last):
  File "roundOneSubmit.py", line 23, in <module>
    l.learnThingsCPP(kind=0, file=f, weightFile=wf)
  File "/gpfs/home/m201560/chipboard/learn.py", line 130, in learnThingsCPP
    weights = self.getWeightArray()
  File "/gpfs/home/m201560/chipboard/learn.py", line 199, in getWeightArray
    return self.model.get_weights()[0].tolist()
  File "/gpfs/home/m201560/.local/lib/python3.6/site-packages/keras/engine/network.py", line 492, in get_weights
    return K.batch_get_value(weights)
  File "/gpfs/home/m201560/.local/lib/python3.6/site-packages/keras/backend/tensorflow_backend.py", line 2420, in batch_get_value
    return get_session().run(ops)
  File "/gpfs/home/m201560/.local/lib/python3.6/site-packages/keras/backend/tensorflow_backend.py", line 186, in get_session
    _SESSION = tf.Session(config=config)
  File "/gpfs/pkgs/mhpcc/anaconda3-5.0.1/lib/python3.6/site-packages/tensorflow/python/client/session.py", line 1563, in __init__
    super(Session, self).__init__(target, graph, config=config)
  File "/gpfs/pkgs/mhpcc/anaconda3-5.0.1/lib/python3.6/site-packages/tensorflow/python/client/session.py", line 633, in __init__
    self._session = tf_session.TF_NewSession(self._graph._c_graph, opts)
tensorflow.python.framework.errors_impl.InternalError: Failed to create session.
Traceback (most recent call last):
  File "roundOneSubmit.py", line 23, in <module>
    l.learnThingsCPP(kind=0, file=f, weightFile=wf)
  File "/gpfs/home/m201560/chipboard/learn.py", line 130, in learnThingsCPP
    weights = self.getWeightArray()
  File "/gpfs/home/m201560/chipboard/learn.py", line 199, in getWeightArray
    return self.model.get_weights()[0].tolist()
  File "/gpfs/home/m201560/.local/lib/python3.6/site-packages/keras/engine/network.py", line 492, in get_weights
    return K.batch_get_value(weights)
  File "/gpfs/home/m201560/.local/lib/python3.6/site-packages/keras/backend/tensorflow_backend.py", line 2420, in batch_get_value
    return get_session().run(ops)
  File "/gpfs/home/m201560/.local/lib/python3.6/site-packages/keras/backend/tensorflow_backend.py", line 186, in get_session
    _SESSION = tf.Session(config=config)
  File "/gpfs/pkgs/mhpcc/anaconda3-5.0.1/lib/python3.6/site-packages/tensorflow/python/client/session.py", line 1563, in __init__
    super(Session, self).__init__(target, graph, config=config)
  File "/gpfs/pkgs/mhpcc/anaconda3-5.0.1/lib/python3.6/site-packages/tensorflow/python/client/session.py", line 633, in __init__
    self._session = tf_session.TF_NewSession(self._graph._c_graph, opts)
tensorflow.python.framework.errors_impl.InternalError: Failed to create session.
Traceback (most recent call last):
  File "roundOneSubmit.py", line 23, in <module>
    l.learnThingsCPP(kind=0, file=f, weightFile=wf)
  File "/gpfs/home/m201560/chipboard/learn.py", line 130, in learnThingsCPP
    weights = self.getWeightArray()
  File "/gpfs/home/m201560/chipboard/learn.py", line 199, in getWeightArray
    return self.model.get_weights()[0].tolist()
  File "/gpfs/home/m201560/.local/lib/python3.6/site-packages/keras/engine/network.py", line 492, in get_weights
    return K.batch_get_value(weights)
  File "/gpfs/home/m201560/.local/lib/python3.6/site-packages/keras/backend/tensorflow_backend.py", line 2420, in batch_get_value
    return get_session().run(ops)
  File "/gpfs/home/m201560/.local/lib/python3.6/site-packages/keras/backend/tensorflow_backend.py", line 186, in get_session
    _SESSION = tf.Session(config=config)
  File "/gpfs/pkgs/mhpcc/anaconda3-5.0.1/lib/python3.6/site-packages/tensorflow/python/client/session.py", line 1563, in __init__
    super(Session, self).__init__(target, graph, config=config)
  File "/gpfs/pkgs/mhpcc/anaconda3-5.0.1/lib/python3.6/site-packages/tensorflow/python/client/session.py", line 633, in __init__
    self._session = tf_session.TF_NewSession(self._graph._c_graph, opts)
tensorflow.python.framework.errors_impl.InternalError: Failed to create session.
Traceback (most recent call last):
  File "roundOneSubmit.py", line 23, in <module>
    l.learnThingsCPP(kind=0, file=f, weightFile=wf)
  File "/gpfs/home/m201560/chipboard/learn.py", line 130, in learnThingsCPP
    weights = self.getWeightArray()
  File "/gpfs/home/m201560/chipboard/learn.py", line 199, in getWeightArray
    return self.model.get_weights()[0].tolist()
  File "/gpfs/home/m201560/.local/lib/python3.6/site-packages/keras/engine/network.py", line 492, in get_weights
    return K.batch_get_value(weights)
  File "/gpfs/home/m201560/.local/lib/python3.6/site-packages/keras/backend/tensorflow_backend.py", line 2420, in batch_get_value
    return get_session().run(ops)
  File "/gpfs/home/m201560/.local/lib/python3.6/site-packages/keras/backend/tensorflow_backend.py", line 186, in get_session
    _SESSION = tf.Session(config=config)
  File "/gpfs/pkgs/mhpcc/anaconda3-5.0.1/lib/python3.6/site-packages/tensorflow/python/client/session.py", line 1563, in __init__
    super(Session, self).__init__(target, graph, config=config)
  File "/gpfs/pkgs/mhpcc/anaconda3-5.0.1/lib/python3.6/site-packages/tensorflow/python/client/session.py", line 633, in __init__
    self._session = tf_session.TF_NewSession(self._graph._c_graph, opts)
tensorflow.python.framework.errors_impl.InternalError: Failed to create session.
Traceback (most recent call last):
  File "roundOneSubmit.py", line 23, in <module>
    l.learnThingsCPP(kind=0, file=f, weightFile=wf)
  File "/gpfs/home/m201560/chipboard/learn.py", line 130, in learnThingsCPP
    weights = self.getWeightArray()
  File "/gpfs/home/m201560/chipboard/learn.py", line 199, in getWeightArray
    return self.model.get_weights()[0].tolist()
  File "/gpfs/home/m201560/.local/lib/python3.6/site-packages/keras/engine/network.py", line 492, in get_weights
    return K.batch_get_value(weights)
  File "/gpfs/home/m201560/.local/lib/python3.6/site-packages/keras/backend/tensorflow_backend.py", line 2420, in batch_get_value
    return get_session().run(ops)
  File "/gpfs/home/m201560/.local/lib/python3.6/site-packages/keras/backend/tensorflow_backend.py", line 186, in get_session
    _SESSION = tf.Session(config=config)
  File "/gpfs/pkgs/mhpcc/anaconda3-5.0.1/lib/python3.6/site-packages/tensorflow/python/client/session.py", line 1563, in __init__
    super(Session, self).__init__(target, graph, config=config)
  File "/gpfs/pkgs/mhpcc/anaconda3-5.0.1/lib/python3.6/site-packages/tensorflow/python/client/session.py", line 633, in __init__
    self._session = tf_session.TF_NewSession(self._graph._c_graph, opts)
tensorflow.python.framework.errors_impl.InternalError: Failed to create session.
Traceback (most recent call last):
  File "roundOneSubmit.py", line 23, in <module>
    l.learnThingsCPP(kind=0, file=f, weightFile=wf)
  File "/gpfs/home/m201560/chipboard/learn.py", line 130, in learnThingsCPP
    weights = self.getWeightArray()
  File "/gpfs/home/m201560/chipboard/learn.py", line 199, in getWeightArray
    return self.model.get_weights()[0].tolist()
  File "/gpfs/home/m201560/.local/lib/python3.6/site-packages/keras/engine/network.py", line 492, in get_weights
    return K.batch_get_value(weights)
  File "/gpfs/home/m201560/.local/lib/python3.6/site-packages/keras/backend/tensorflow_backend.py", line 2420, in batch_get_value
    return get_session().run(ops)
  File "/gpfs/home/m201560/.local/lib/python3.6/site-packages/keras/backend/tensorflow_backend.py", line 186, in get_session
    _SESSION = tf.Session(config=config)
  File "/gpfs/pkgs/mhpcc/anaconda3-5.0.1/lib/python3.6/site-packages/tensorflow/python/client/session.py", line 1563, in __init__
    super(Session, self).__init__(target, graph, config=config)
  File "/gpfs/pkgs/mhpcc/anaconda3-5.0.1/lib/python3.6/site-packages/tensorflow/python/client/session.py", line 633, in __init__
    self._session = tf_session.TF_NewSession(self._graph._c_graph, opts)
tensorflow.python.framework.errors_impl.InternalError: Failed to create session.
[cr1cn06:80490] 79 more processes have sent help message help-mpi-btl-openib.txt / default subnet prefix
[cr1cn06:80490] Set MCA parameter "orte_base_help_aggregate" to 0 to see all help / error messages
2019-08-02 11:20:27.120429: I tensorflow/core/common_runtime/gpu/gpu_device.cc:952] Device interconnect StreamExecutor with strength 1 edge matrix:
2019-08-02 11:20:27.120478: I tensorflow/core/common_runtime/gpu/gpu_device.cc:958]      0 1 2 3 
2019-08-02 11:20:27.120491: I tensorflow/core/common_runtime/gpu/gpu_device.cc:971] 0:   N Y N N 
2019-08-02 11:20:27.120500: I tensorflow/core/common_runtime/gpu/gpu_device.cc:971] 1:   Y N N N 
2019-08-02 11:20:27.120508: I tensorflow/core/common_runtime/gpu/gpu_device.cc:971] 2:   N N N Y 
2019-08-02 11:20:27.120517: I tensorflow/core/common_runtime/gpu/gpu_device.cc:971] 3:   N N Y N 
2019-08-02 11:20:27.121184: I tensorflow/core/common_runtime/gpu/gpu_device.cc:1084] Created TensorFlow device (/job:localhost/replica:0/task:0/device:GPU:0 with 15163 MB memory) -> physical GPU (device: 0, name: Tesla P100-SXM2-16GB, pci bus id: 0002:01:00.0, compute capability: 6.0)
2019-08-02 11:20:27.251877: I tensorflow/core/common_runtime/gpu/gpu_device.cc:1084] Created TensorFlow device (/job:localhost/replica:0/task:0/device:GPU:1 with 15163 MB memory) -> physical GPU (device: 1, name: Tesla P100-SXM2-16GB, pci bus id: 0003:01:00.0, compute capability: 6.0)
2019-08-02 11:20:27.382644: I tensorflow/core/common_runtime/gpu/gpu_device.cc:1084] Created TensorFlow device (/job:localhost/replica:0/task:0/device:GPU:2 with 15163 MB memory) -> physical GPU (device: 2, name: Tesla P100-SXM2-16GB, pci bus id: 0006:01:00.0, compute capability: 6.0)
2019-08-02 11:20:27.532506: I tensorflow/core/common_runtime/gpu/gpu_device.cc:1084] Created TensorFlow device (/job:localhost/replica:0/task:0/device:GPU:3 with 15163 MB memory) -> physical GPU (device: 3, name: Tesla P100-SXM2-16GB, pci bus id: 0007:01:00.0, compute capability: 6.0)
=>> PBS: job killed: walltime 1824 exceeded limit 1800
[warn] Epoll ADD(4) on fd 349 failed.  Old events were 0; read change was 0 (none); write change was 1 (add): Bad file descriptor
[cr1cn06:80490] pmix_usock_msg_send_bytes: write failed: Broken pipe (32) [sd = 322]
[warn] Epoll ADD(4) on fd 307 failed.  Old events were 0; read change was 0 (none); write change was 1 (add): Bad file descriptor
[warn] Epoll ADD(4) on fd 335 failed.  Old events were 0; read change was 0 (none); write change was 1 (add): Bad file descriptor
[warn] Epoll ADD(4) on fd 313 failed.  Old events were 0; read change was 0 (none); write change was 1 (add): Bad file descriptor
[warn] Epoll ADD(4) on fd 363 failed.  Old events were 0; read change was 0 (none); write change was 1 (add): Bad file descriptor
[warn] Epoll ADD(4) on fd 329 failed.  Old events were 0; read change was 0 (none); write change was 1 (add): Bad file descriptor
[warn] Epoll ADD(4) on fd 364 failed.  Old events were 0; read change was 0 (none); write change was 1 (add): Bad file descriptor
[warn] Epoll ADD(4) on fd 0 failed.  Old events were 0; read change was 0 (none); write change was 1 (add): Bad file descriptor
[warn] Epoll ADD(4) on fd 339 failed.  Old events were 0; read change was 0 (none); write change was 1 (add): Bad file descriptor
[warn] Epoll ADD(4) on fd 298 failed.  Old events were 0; read change was 0 (none); write change was 1 (add): Bad file descriptor
[warn] Epoll ADD(4) on fd 351 failed.  Old events were 0; read change was 0 (none); write change was 1 (add): Bad file descriptor
[warn] Epoll ADD(4) on fd 293 failed.  Old events were 0; read change was 0 (none); write change was 1 (add): Bad file descriptor
[warn] Epoll ADD(4) on fd 301 failed.  Old events were 0; read change was 0 (none); write change was 1 (add): Bad file descriptor
[warn] Epoll ADD(4) on fd 336 failed.  Old events were 0; read change was 0 (none); write change was 1 (add): Bad file descriptor
[warn] Epoll ADD(4) on fd 280 failed.  Old events were 0; read change was 0 (none); write change was 1 (add): Bad file descriptor
[warn] Epoll ADD(4) on fd 357 failed.  Old events were 0; read change was 0 (none); write change was 1 (add): Bad file descriptor
[warn] Epoll ADD(4) on fd 319 failed.  Old events were 0; read change was 0 (none); write change was 1 (add): Bad file descriptor
[warn] Epoll ADD(4) on fd 373 failed.  Old events were 0; read change was 0 (none); write change was 1 (add): Bad file descriptor
[warn] Epoll ADD(4) on fd 295 failed.  Old events were 0; read change was 0 (none); write change was 1 (add): Bad file descriptor
[warn] Epoll ADD(4) on fd 304 failed.  Old events were 0; read change was 0 (none); write change was 1 (add): Bad file descriptor
[warn] Epoll ADD(4) on fd 302 failed.  Old events were 0; read change was 0 (none); write change was 1 (add): Bad file descriptor
[warn] Epoll ADD(4) on fd 286 failed.  Old events were 0; read change was 0 (none); write change was 1 (add): Bad file descriptor
[warn] Epoll ADD(4) on fd 289 failed.  Old events were 0; read change was 0 (none); write change was 1 (add): Bad file descriptor
[warn] Epoll ADD(4) on fd 310 failed.  Old events were 0; read change was 0 (none); write change was 1 (add): Bad file descriptor
[warn] Epoll ADD(4) on fd 331 failed.  Old events were 0; read change was 0 (none); write change was 1 (add): Bad file descriptor
[warn] Epoll ADD(4) on fd 326 failed.  Old events were 0; read change was 0 (none); write change was 1 (add): Bad file descriptor
[warn] Epoll ADD(4) on fd 299 failed.  Old events were 0; read change was 0 (none); write change was 1 (add): Bad file descriptor
[warn] Epoll ADD(4) on fd 291 failed.  Old events were 0; read change was 0 (none); write change was 1 (add): Bad file descriptor
[warn] Epoll ADD(4) on fd 337 failed.  Old events were 0; read change was 0 (none); write change was 1 (add): Bad file descriptor
[warn] Epoll ADD(4) on fd 350 failed.  Old events were 0; read change was 0 (none); write change was 1 (add): Bad file descriptor
[warn] Epoll ADD(4) on fd 382 failed.  Old events were 0; read change was 0 (none); write change was 1 (add): Bad file descriptor
[warn] Epoll ADD(4) on fd 362 failed.  Old events were 0; read change was 0 (none); write change was 1 (add): Bad file descriptor
[warn] Epoll ADD(4) on fd 315 failed.  Old events were 0; read change was 0 (none); write change was 1 (add): Bad file descriptor
[warn] Epoll ADD(4) on fd 334 failed.  Old events were 0; read change was 0 (none); write change was 1 (add): Bad file descriptor
[warn] Epoll ADD(4) on fd 311 failed.  Old events were 0; read change was 0 (none); write change was 1 (add): Bad file descriptor
[warn] Epoll ADD(4) on fd 377 failed.  Old events were 0; read change was 0 (none); write change was 1 (add): Bad file descriptor
[warn] Epoll ADD(4) on fd 296 failed.  Old events were 0; read change was 0 (none); write change was 1 (add): Bad file descriptor
[warn] Epoll ADD(4) on fd 359 failed.  Old events were 0; read change was 0 (none); write change was 1 (add): Bad file descriptor
[warn] Epoll ADD(4) on fd 297 failed.  Old events were 0; read change was 0 (none); write change was 1 (add): Bad file descriptor
[warn] Epoll ADD(4) on fd 312 failed.  Old events were 0; read change was 0 (none); write change was 1 (add): Bad file descriptor
[warn] Epoll ADD(4) on fd 327 failed.  Old events were 0; read change was 0 (none); write change was 1 (add): Bad file descriptor
[warn] Epoll ADD(4) on fd 367 failed.  Old events were 0; read change was 0 (none); write change was 1 (add): Bad file descriptor
[warn] Epoll ADD(4) on fd 325 failed.  Old events were 0; read change was 0 (none); write change was 1 (add): Bad file descriptor
[warn] Epoll ADD(4) on fd 314 failed.  Old events were 0; read change was 0 (none); write change was 1 (add): Bad file descriptor
[warn] Epoll ADD(4) on fd 342 failed.  Old events were 0; read change was 0 (none); write change was 1 (add): Bad file descriptor
[warn] Epoll ADD(4) on fd 328 failed.  Old events were 0; read change was 0 (none); write change was 1 (add): Bad file descriptor
[warn] Epoll ADD(4) on fd 306 failed.  Old events were 0; read change was 0 (none); write change was 1 (add): Bad file descriptor
[warn] Epoll ADD(4) on fd 318 failed.  Old events were 0; read change was 0 (none); write change was 1 (add): Bad file descriptor
[warn] Epoll ADD(4) on fd 346 failed.  Old events were 0; read change was 0 (none); write change was 1 (add): Bad file descriptor
[warn] Epoll ADD(4) on fd 340 failed.  Old events were 0; read change was 0 (none); write change was 1 (add): Bad file descriptor
[warn] Epoll ADD(4) on fd 348 failed.  Old events were 0; read change was 0 (none); write change was 1 (add): Bad file descriptor
[warn] Epoll ADD(4) on fd 338 failed.  Old events were 0; read change was 0 (none); write change was 1 (add): Bad file descriptor
[warn] Epoll ADD(4) on fd 352 failed.  Old events were 0; read change was 0 (none); write change was 1 (add): Bad file descriptor
[warn] Epoll ADD(4) on fd 379 failed.  Old events were 0; read change was 0 (none); write change was 1 (add): Bad file descriptor
[warn] Epoll ADD(4) on fd 317 failed.  Old events were 0; read change was 0 (none); write change was 1 (add): Bad file descriptor
[warn] Epoll ADD(4) on fd 292 failed.  Old events were 0; read change was 0 (none); write change was 1 (add): Bad file descriptor
