gcc(3):ERROR:105: Unable to locate a modulefile for 'gcc/5.3.1'
2019-08-01 22:16:53.105115: E tensorflow/core/common_runtime/direct_session.cc:158] Internal: failed initializing StreamExecutor for CUDA device ordinal 0: Internal: failed call to cuDevicePrimaryCtxRetain: CUDA_ERROR_INVALID_DEVICE
/gpfs/pkgs/mhpcc/anaconda3-5.0.1/lib/python3.6/site-packages/h5py/__init__.py:34: FutureWarning: Conversion of the second argument of issubdtype from `float` to `np.floating` is deprecated. In future, it will be treated as `np.float64 == np.dtype(float).type`.
  from ._conv import register_converters as _register_converters
Using TensorFlow backend.
2019-08-01 22:16:53.112615: E tensorflow/core/common_runtime/direct_session.cc:158] Internal: failed initializing StreamExecutor for CUDA device ordinal 0: Internal: failed call to cuDevicePrimaryCtxRetain: CUDA_ERROR_INVALID_DEVICE
/gpfs/pkgs/mhpcc/anaconda3-5.0.1/lib/python3.6/site-packages/h5py/__init__.py:34: FutureWarning: Conversion of the second argument of issubdtype from `float` to `np.floating` is deprecated. In future, it will be treated as `np.float64 == np.dtype(float).type`.
  from ._conv import register_converters as _register_converters
Using TensorFlow backend.
2019-08-01 22:16:53.129127: E tensorflow/core/common_runtime/direct_session.cc:158] Internal: failed initializing StreamExecutor for CUDA device ordinal 0: Internal: failed call to cuDevicePrimaryCtxRetain: CUDA_ERROR_INVALID_DEVICE
/gpfs/pkgs/mhpcc/anaconda3-5.0.1/lib/python3.6/site-packages/h5py/__init__.py:34: FutureWarning: Conversion of the second argument of issubdtype from `float` to `np.floating` is deprecated. In future, it will be treated as `np.float64 == np.dtype(float).type`.
  from ._conv import register_converters as _register_converters
Using TensorFlow backend.
2019-08-01 22:16:53.132548: E tensorflow/core/common_runtime/direct_session.cc:158] Internal: failed initializing StreamExecutor for CUDA device ordinal 0: Internal: failed call to cuDevicePrimaryCtxRetain: CUDA_ERROR_INVALID_DEVICE
/gpfs/pkgs/mhpcc/anaconda3-5.0.1/lib/python3.6/site-packages/h5py/__init__.py:34: FutureWarning: Conversion of the second argument of issubdtype from `float` to `np.floating` is deprecated. In future, it will be treated as `np.float64 == np.dtype(float).type`.
  from ._conv import register_converters as _register_converters
Using TensorFlow backend.
2019-08-01 22:16:53.134864: E tensorflow/core/common_runtime/direct_session.cc:158] Internal: failed initializing StreamExecutor for CUDA device ordinal 0: Internal: failed call to cuDevicePrimaryCtxRetain: CUDA_ERROR_INVALID_DEVICE
/gpfs/pkgs/mhpcc/anaconda3-5.0.1/lib/python3.6/site-packages/h5py/__init__.py:34: FutureWarning: Conversion of the second argument of issubdtype from `float` to `np.floating` is deprecated. In future, it will be treated as `np.float64 == np.dtype(float).type`.
  from ._conv import register_converters as _register_converters
Using TensorFlow backend.
2019-08-01 22:16:53.135895: E tensorflow/core/common_runtime/direct_session.cc:158] Internal: failed initializing StreamExecutor for CUDA device ordinal 0: Internal: failed call to cuDevicePrimaryCtxRetain: CUDA_ERROR_INVALID_DEVICE
/gpfs/pkgs/mhpcc/anaconda3-5.0.1/lib/python3.6/site-packages/h5py/__init__.py:34: FutureWarning: Conversion of the second argument of issubdtype from `float` to `np.floating` is deprecated. In future, it will be treated as `np.float64 == np.dtype(float).type`.
  from ._conv import register_converters as _register_converters
Using TensorFlow backend.
2019-08-01 22:16:53.136871: E tensorflow/core/common_runtime/direct_session.cc:158] Internal: failed initializing StreamExecutor for CUDA device ordinal 0: Internal: failed call to cuDevicePrimaryCtxRetain: CUDA_ERROR_INVALID_DEVICE
/gpfs/pkgs/mhpcc/anaconda3-5.0.1/lib/python3.6/site-packages/h5py/__init__.py:34: FutureWarning: Conversion of the second argument of issubdtype from `float` to `np.floating` is deprecated. In future, it will be treated as `np.float64 == np.dtype(float).type`.
  from ._conv import register_converters as _register_converters
Using TensorFlow backend.
2019-08-01 22:16:53.137930: E tensorflow/core/common_runtime/direct_session.cc:158] Internal: failed initializing StreamExecutor for CUDA device ordinal 0: Internal: failed call to cuDevicePrimaryCtxRetain: CUDA_ERROR_INVALID_DEVICE
2019-08-01 22:16:53.137144: E tensorflow/core/common_runtime/direct_session.cc:158] Internal: failed initializing StreamExecutor for CUDA device ordinal 0: Internal: failed call to cuDevicePrimaryCtxRetain: CUDA_ERROR_INVALID_DEVICE
/gpfs/pkgs/mhpcc/anaconda3-5.0.1/lib/python3.6/site-packages/h5py/__init__.py:34: FutureWarning: Conversion of the second argument of issubdtype from `float` to `np.floating` is deprecated. In future, it will be treated as `np.float64 == np.dtype(float).type`.
  from ._conv import register_converters as _register_converters
Using TensorFlow backend.
/gpfs/pkgs/mhpcc/anaconda3-5.0.1/lib/python3.6/site-packages/h5py/__init__.py:34: FutureWarning: Conversion of the second argument of issubdtype from `float` to `np.floating` is deprecated. In future, it will be treated as `np.float64 == np.dtype(float).type`.
  from ._conv import register_converters as _register_converters
Using TensorFlow backend.
2019-08-01 22:16:53.138342: E tensorflow/core/common_runtime/direct_session.cc:158] Internal: failed initializing StreamExecutor for CUDA device ordinal 0: Internal: failed call to cuDevicePrimaryCtxRetain: CUDA_ERROR_INVALID_DEVICE
/gpfs/pkgs/mhpcc/anaconda3-5.0.1/lib/python3.6/site-packages/h5py/__init__.py:34: FutureWarning: Conversion of the second argument of issubdtype from `float` to `np.floating` is deprecated. In future, it will be treated as `np.float64 == np.dtype(float).type`.
  from ._conv import register_converters as _register_converters
Using TensorFlow backend.
2019-08-01 22:16:53.139092: E tensorflow/core/common_runtime/direct_session.cc:158] Internal: failed initializing StreamExecutor for CUDA device ordinal 0: Internal: failed call to cuDevicePrimaryCtxRetain: CUDA_ERROR_INVALID_DEVICE
/gpfs/pkgs/mhpcc/anaconda3-5.0.1/lib/python3.6/site-packages/h5py/__init__.py:34: FutureWarning: Conversion of the second argument of issubdtype from `float` to `np.floating` is deprecated. In future, it will be treated as `np.float64 == np.dtype(float).type`.
  from ._conv import register_converters as _register_converters
Using TensorFlow backend.
2019-08-01 22:16:53.139226: E tensorflow/core/common_runtime/direct_session.cc:158] Internal: failed initializing StreamExecutor for CUDA device ordinal 0: Internal: failed call to cuDevicePrimaryCtxRetain: CUDA_ERROR_INVALID_DEVICE
/gpfs/pkgs/mhpcc/anaconda3-5.0.1/lib/python3.6/site-packages/h5py/__init__.py:34: FutureWarning: Conversion of the second argument of issubdtype from `float` to `np.floating` is deprecated. In future, it will be treated as `np.float64 == np.dtype(float).type`.
  from ._conv import register_converters as _register_converters
Using TensorFlow backend.
2019-08-01 22:16:53.164712: E tensorflow/core/common_runtime/direct_session.cc:158] Internal: failed initializing StreamExecutor for CUDA device ordinal 0: Internal: failed call to cuDevicePrimaryCtxRetain: CUDA_ERROR_INVALID_DEVICE
/gpfs/pkgs/mhpcc/anaconda3-5.0.1/lib/python3.6/site-packages/h5py/__init__.py:34: FutureWarning: Conversion of the second argument of issubdtype from `float` to `np.floating` is deprecated. In future, it will be treated as `np.float64 == np.dtype(float).type`.
  from ._conv import register_converters as _register_converters
Using TensorFlow backend.
2019-08-01 22:16:53.166059: E tensorflow/core/common_runtime/direct_session.cc:158] Internal: failed initializing StreamExecutor for CUDA device ordinal 0: Internal: failed call to cuDevicePrimaryCtxRetain: CUDA_ERROR_INVALID_DEVICE
/gpfs/pkgs/mhpcc/anaconda3-5.0.1/lib/python3.6/site-packages/h5py/__init__.py:34: FutureWarning: Conversion of the second argument of issubdtype from `float` to `np.floating` is deprecated. In future, it will be treated as `np.float64 == np.dtype(float).type`.
  from ._conv import register_converters as _register_converters
Using TensorFlow backend.
2019-08-01 22:16:53.166421: E tensorflow/core/common_runtime/direct_session.cc:158] Internal: failed initializing StreamExecutor for CUDA device ordinal 0: Internal: failed call to cuDevicePrimaryCtxRetain: CUDA_ERROR_INVALID_DEVICE
/gpfs/pkgs/mhpcc/anaconda3-5.0.1/lib/python3.6/site-packages/h5py/__init__.py:34: FutureWarning: Conversion of the second argument of issubdtype from `float` to `np.floating` is deprecated. In future, it will be treated as `np.float64 == np.dtype(float).type`.
  from ._conv import register_converters as _register_converters
Using TensorFlow backend.
2019-08-01 22:16:53.245471: I tensorflow/core/common_runtime/gpu/gpu_device.cc:1392] Found device 0 with properties: 
name: Tesla P100-SXM2-16GB major: 6 minor: 0 memoryClockRate(GHz): 1.4805
pciBusID: 0002:01:00.0
totalMemory: 15.90GiB freeMemory: 15.64GiB
2019-08-01 22:16:53.327697: I tensorflow/core/common_runtime/gpu/gpu_device.cc:1392] Found device 1 with properties: 
name: Tesla P100-SXM2-16GB major: 6 minor: 0 memoryClockRate(GHz): 1.4805
pciBusID: 0003:01:00.0
totalMemory: 15.90GiB freeMemory: 15.64GiB
2019-08-01 22:16:53.412670: I tensorflow/core/common_runtime/gpu/gpu_device.cc:1392] Found device 2 with properties: 
name: Tesla P100-SXM2-16GB major: 6 minor: 0 memoryClockRate(GHz): 1.4805
pciBusID: 0006:01:00.0
totalMemory: 15.90GiB freeMemory: 15.64GiB
2019-08-01 22:16:53.503136: I tensorflow/core/common_runtime/gpu/gpu_device.cc:1392] Found device 3 with properties: 
name: Tesla P100-SXM2-16GB major: 6 minor: 0 memoryClockRate(GHz): 1.4805
pciBusID: 0007:01:00.0
totalMemory: 15.90GiB freeMemory: 15.64GiB
2019-08-01 22:16:53.503910: I tensorflow/core/common_runtime/gpu/gpu_device.cc:1471] Adding visible gpu devices: 0, 1, 2, 3
Traceback (most recent call last):
  File "roundTwoSubmit.py", line 23, in <module>
    l.learnThingsCPP(kind=0, file=f, weightFile=wf)
  File "/gpfs/home/m201560/chipboard/learn.py", line 130, in learnThingsCPP
    weights = self.getWeightArray()
  File "/gpfs/home/m201560/chipboard/learn.py", line 187, in getWeightArray
    w = self.model.get_weights()
  File "/gpfs/home/m201560/.local/lib/python3.6/site-packages/keras/engine/network.py", line 492, in get_weights
    return K.batch_get_value(weights)
  File "/gpfs/home/m201560/.local/lib/python3.6/site-packages/keras/backend/tensorflow_backend.py", line 2420, in batch_get_value
    return get_session().run(ops)
  File "/gpfs/home/m201560/.local/lib/python3.6/site-packages/keras/backend/tensorflow_backend.py", line 186, in get_session
    _SESSION = tf.Session(config=config)
  File "/gpfs/pkgs/mhpcc/anaconda3-5.0.1/lib/python3.6/site-packages/tensorflow/python/client/session.py", line 1563, in __init__
    super(Session, self).__init__(target, graph, config=config)
  File "/gpfs/pkgs/mhpcc/anaconda3-5.0.1/lib/python3.6/site-packages/tensorflow/python/client/session.py", line 633, in __init__
    self._session = tf_session.TF_NewSession(self._graph._c_graph, opts)
tensorflow.python.framework.errors_impl.InternalError: Failed to create session.
Traceback (most recent call last):
  File "roundTwoSubmit.py", line 23, in <module>
    l.learnThingsCPP(kind=0, file=f, weightFile=wf)
  File "/gpfs/home/m201560/chipboard/learn.py", line 130, in learnThingsCPP
    weights = self.getWeightArray()
  File "/gpfs/home/m201560/chipboard/learn.py", line 187, in getWeightArray
    w = self.model.get_weights()
  File "/gpfs/home/m201560/.local/lib/python3.6/site-packages/keras/engine/network.py", line 492, in get_weights
    return K.batch_get_value(weights)
  File "/gpfs/home/m201560/.local/lib/python3.6/site-packages/keras/backend/tensorflow_backend.py", line 2420, in batch_get_value
    return get_session().run(ops)
  File "/gpfs/home/m201560/.local/lib/python3.6/site-packages/keras/backend/tensorflow_backend.py", line 186, in get_session
    _SESSION = tf.Session(config=config)
  File "/gpfs/pkgs/mhpcc/anaconda3-5.0.1/lib/python3.6/site-packages/tensorflow/python/client/session.py", line 1563, in __init__
    super(Session, self).__init__(target, graph, config=config)
  File "/gpfs/pkgs/mhpcc/anaconda3-5.0.1/lib/python3.6/site-packages/tensorflow/python/client/session.py", line 633, in __init__
    self._session = tf_session.TF_NewSession(self._graph._c_graph, opts)
tensorflow.python.framework.errors_impl.InternalError: Failed to create session.
Traceback (most recent call last):
  File "roundTwoSubmit.py", line 23, in <module>
    l.learnThingsCPP(kind=0, file=f, weightFile=wf)
  File "/gpfs/home/m201560/chipboard/learn.py", line 130, in learnThingsCPP
    weights = self.getWeightArray()
  File "/gpfs/home/m201560/chipboard/learn.py", line 187, in getWeightArray
    w = self.model.get_weights()
  File "/gpfs/home/m201560/.local/lib/python3.6/site-packages/keras/engine/network.py", line 492, in get_weights
    return K.batch_get_value(weights)
  File "/gpfs/home/m201560/.local/lib/python3.6/site-packages/keras/backend/tensorflow_backend.py", line 2420, in batch_get_value
    return get_session().run(ops)
  File "/gpfs/home/m201560/.local/lib/python3.6/site-packages/keras/backend/tensorflow_backend.py", line 186, in get_session
    _SESSION = tf.Session(config=config)
  File "/gpfs/pkgs/mhpcc/anaconda3-5.0.1/lib/python3.6/site-packages/tensorflow/python/client/session.py", line 1563, in __init__
    super(Session, self).__init__(target, graph, config=config)
  File "/gpfs/pkgs/mhpcc/anaconda3-5.0.1/lib/python3.6/site-packages/tensorflow/python/client/session.py", line 633, in __init__
    self._session = tf_session.TF_NewSession(self._graph._c_graph, opts)
tensorflow.python.framework.errors_impl.InternalError: Failed to create session.
Traceback (most recent call last):
  File "roundTwoSubmit.py", line 23, in <module>
    l.learnThingsCPP(kind=0, file=f, weightFile=wf)
  File "/gpfs/home/m201560/chipboard/learn.py", line 130, in learnThingsCPP
    weights = self.getWeightArray()
  File "/gpfs/home/m201560/chipboard/learn.py", line 187, in getWeightArray
    w = self.model.get_weights()
  File "/gpfs/home/m201560/.local/lib/python3.6/site-packages/keras/engine/network.py", line 492, in get_weights
    return K.batch_get_value(weights)
  File "/gpfs/home/m201560/.local/lib/python3.6/site-packages/keras/backend/tensorflow_backend.py", line 2420, in batch_get_value
    return get_session().run(ops)
  File "/gpfs/home/m201560/.local/lib/python3.6/site-packages/keras/backend/tensorflow_backend.py", line 186, in get_session
    _SESSION = tf.Session(config=config)
  File "/gpfs/pkgs/mhpcc/anaconda3-5.0.1/lib/python3.6/site-packages/tensorflow/python/client/session.py", line 1563, in __init__
    super(Session, self).__init__(target, graph, config=config)
  File "/gpfs/pkgs/mhpcc/anaconda3-5.0.1/lib/python3.6/site-packages/tensorflow/python/client/session.py", line 633, in __init__
    self._session = tf_session.TF_NewSession(self._graph._c_graph, opts)
tensorflow.python.framework.errors_impl.InternalError: Failed to create session.
Traceback (most recent call last):
  File "roundTwoSubmit.py", line 23, in <module>
    l.learnThingsCPP(kind=0, file=f, weightFile=wf)
  File "/gpfs/home/m201560/chipboard/learn.py", line 130, in learnThingsCPP
    weights = self.getWeightArray()
  File "/gpfs/home/m201560/chipboard/learn.py", line 187, in getWeightArray
    w = self.model.get_weights()
  File "/gpfs/home/m201560/.local/lib/python3.6/site-packages/keras/engine/network.py", line 492, in get_weights
    return K.batch_get_value(weights)
  File "/gpfs/home/m201560/.local/lib/python3.6/site-packages/keras/backend/tensorflow_backend.py", line 2420, in batch_get_value
    return get_session().run(ops)
  File "/gpfs/home/m201560/.local/lib/python3.6/site-packages/keras/backend/tensorflow_backend.py", line 186, in get_session
    _SESSION = tf.Session(config=config)
  File "/gpfs/pkgs/mhpcc/anaconda3-5.0.1/lib/python3.6/site-packages/tensorflow/python/client/session.py", line 1563, in __init__
    super(Session, self).__init__(target, graph, config=config)
  File "/gpfs/pkgs/mhpcc/anaconda3-5.0.1/lib/python3.6/site-packages/tensorflow/python/client/session.py", line 633, in __init__
    self._session = tf_session.TF_NewSession(self._graph._c_graph, opts)
tensorflow.python.framework.errors_impl.InternalError: Failed to create session.
Traceback (most recent call last):
  File "roundTwoSubmit.py", line 23, in <module>
    l.learnThingsCPP(kind=0, file=f, weightFile=wf)
  File "/gpfs/home/m201560/chipboard/learn.py", line 130, in learnThingsCPP
    weights = self.getWeightArray()
  File "/gpfs/home/m201560/chipboard/learn.py", line 187, in getWeightArray
    w = self.model.get_weights()
  File "/gpfs/home/m201560/.local/lib/python3.6/site-packages/keras/engine/network.py", line 492, in get_weights
    return K.batch_get_value(weights)
  File "/gpfs/home/m201560/.local/lib/python3.6/site-packages/keras/backend/tensorflow_backend.py", line 2420, in batch_get_value
    return get_session().run(ops)
  File "/gpfs/home/m201560/.local/lib/python3.6/site-packages/keras/backend/tensorflow_backend.py", line 186, in get_session
    _SESSION = tf.Session(config=config)
  File "/gpfs/pkgs/mhpcc/anaconda3-5.0.1/lib/python3.6/site-packages/tensorflow/python/client/session.py", line 1563, in __init__
    super(Session, self).__init__(target, graph, config=config)
  File "/gpfs/pkgs/mhpcc/anaconda3-5.0.1/lib/python3.6/site-packages/tensorflow/python/client/session.py", line 633, in __init__
    self._session = tf_session.TF_NewSession(self._graph._c_graph, opts)
tensorflow.python.framework.errors_impl.InternalError: Failed to create session.
Traceback (most recent call last):
  File "roundTwoSubmit.py", line 23, in <module>
    l.learnThingsCPP(kind=0, file=f, weightFile=wf)
  File "/gpfs/home/m201560/chipboard/learn.py", line 130, in learnThingsCPP
    weights = self.getWeightArray()
  File "/gpfs/home/m201560/chipboard/learn.py", line 187, in getWeightArray
    w = self.model.get_weights()
  File "/gpfs/home/m201560/.local/lib/python3.6/site-packages/keras/engine/network.py", line 492, in get_weights
    return K.batch_get_value(weights)
  File "/gpfs/home/m201560/.local/lib/python3.6/site-packages/keras/backend/tensorflow_backend.py", line 2420, in batch_get_value
    return get_session().run(ops)
  File "/gpfs/home/m201560/.local/lib/python3.6/site-packages/keras/backend/tensorflow_backend.py", line 186, in get_session
    _SESSION = tf.Session(config=config)
  File "/gpfs/pkgs/mhpcc/anaconda3-5.0.1/lib/python3.6/site-packages/tensorflow/python/client/session.py", line 1563, in __init__
    super(Session, self).__init__(target, graph, config=config)
  File "/gpfs/pkgs/mhpcc/anaconda3-5.0.1/lib/python3.6/site-packages/tensorflow/python/client/session.py", line 633, in __init__
    self._session = tf_session.TF_NewSession(self._graph._c_graph, opts)
tensorflow.python.framework.errors_impl.InternalError: Failed to create session.
Traceback (most recent call last):
  File "roundTwoSubmit.py", line 23, in <module>
    l.learnThingsCPP(kind=0, file=f, weightFile=wf)
  File "/gpfs/home/m201560/chipboard/learn.py", line 130, in learnThingsCPP
    weights = self.getWeightArray()
  File "/gpfs/home/m201560/chipboard/learn.py", line 187, in getWeightArray
    w = self.model.get_weights()
  File "/gpfs/home/m201560/.local/lib/python3.6/site-packages/keras/engine/network.py", line 492, in get_weights
    return K.batch_get_value(weights)
  File "/gpfs/home/m201560/.local/lib/python3.6/site-packages/keras/backend/tensorflow_backend.py", line 2420, in batch_get_value
    return get_session().run(ops)
  File "/gpfs/home/m201560/.local/lib/python3.6/site-packages/keras/backend/tensorflow_backend.py", line 186, in get_session
    _SESSION = tf.Session(config=config)
  File "/gpfs/pkgs/mhpcc/anaconda3-5.0.1/lib/python3.6/site-packages/tensorflow/python/client/session.py", line 1563, in __init__
    super(Session, self).__init__(target, graph, config=config)
  File "/gpfs/pkgs/mhpcc/anaconda3-5.0.1/lib/python3.6/site-packages/tensorflow/python/client/session.py", line 633, in __init__
    self._session = tf_session.TF_NewSession(self._graph._c_graph, opts)
tensorflow.python.framework.errors_impl.InternalError: Failed to create session.
Traceback (most recent call last):
  File "roundTwoSubmit.py", line 23, in <module>
    l.learnThingsCPP(kind=0, file=f, weightFile=wf)
  File "/gpfs/home/m201560/chipboard/learn.py", line 130, in learnThingsCPP
    weights = self.getWeightArray()
  File "/gpfs/home/m201560/chipboard/learn.py", line 187, in getWeightArray
    w = self.model.get_weights()
  File "/gpfs/home/m201560/.local/lib/python3.6/site-packages/keras/engine/network.py", line 492, in get_weights
    return K.batch_get_value(weights)
  File "/gpfs/home/m201560/.local/lib/python3.6/site-packages/keras/backend/tensorflow_backend.py", line 2420, in batch_get_value
    return get_session().run(ops)
  File "/gpfs/home/m201560/.local/lib/python3.6/site-packages/keras/backend/tensorflow_backend.py", line 186, in get_session
    _SESSION = tf.Session(config=config)
  File "/gpfs/pkgs/mhpcc/anaconda3-5.0.1/lib/python3.6/site-packages/tensorflow/python/client/session.py", line 1563, in __init__
    super(Session, self).__init__(target, graph, config=config)
  File "/gpfs/pkgs/mhpcc/anaconda3-5.0.1/lib/python3.6/site-packages/tensorflow/python/client/session.py", line 633, in __init__
    self._session = tf_session.TF_NewSession(self._graph._c_graph, opts)
tensorflow.python.framework.errors_impl.InternalError: Failed to create session.
Traceback (most recent call last):
  File "roundTwoSubmit.py", line 23, in <module>
    l.learnThingsCPP(kind=0, file=f, weightFile=wf)
  File "/gpfs/home/m201560/chipboard/learn.py", line 130, in learnThingsCPP
    weights = self.getWeightArray()
  File "/gpfs/home/m201560/chipboard/learn.py", line 187, in getWeightArray
    w = self.model.get_weights()
  File "/gpfs/home/m201560/.local/lib/python3.6/site-packages/keras/engine/network.py", line 492, in get_weights
    return K.batch_get_value(weights)
  File "/gpfs/home/m201560/.local/lib/python3.6/site-packages/keras/backend/tensorflow_backend.py", line 2420, in batch_get_value
    return get_session().run(ops)
  File "/gpfs/home/m201560/.local/lib/python3.6/site-packages/keras/backend/tensorflow_backend.py", line 186, in get_session
    _SESSION = tf.Session(config=config)
  File "/gpfs/pkgs/mhpcc/anaconda3-5.0.1/lib/python3.6/site-packages/tensorflow/python/client/session.py", line 1563, in __init__
    super(Session, self).__init__(target, graph, config=config)
  File "/gpfs/pkgs/mhpcc/anaconda3-5.0.1/lib/python3.6/site-packages/tensorflow/python/client/session.py", line 633, in __init__
    self._session = tf_session.TF_NewSession(self._graph._c_graph, opts)
tensorflow.python.framework.errors_impl.InternalError: Failed to create session.
Traceback (most recent call last):
  File "roundTwoSubmit.py", line 23, in <module>
    l.learnThingsCPP(kind=0, file=f, weightFile=wf)
  File "/gpfs/home/m201560/chipboard/learn.py", line 130, in learnThingsCPP
    weights = self.getWeightArray()
  File "/gpfs/home/m201560/chipboard/learn.py", line 187, in getWeightArray
    w = self.model.get_weights()
  File "/gpfs/home/m201560/.local/lib/python3.6/site-packages/keras/engine/network.py", line 492, in get_weights
    return K.batch_get_value(weights)
  File "/gpfs/home/m201560/.local/lib/python3.6/site-packages/keras/backend/tensorflow_backend.py", line 2420, in batch_get_value
    return get_session().run(ops)
  File "/gpfs/home/m201560/.local/lib/python3.6/site-packages/keras/backend/tensorflow_backend.py", line 186, in get_session
    _SESSION = tf.Session(config=config)
  File "/gpfs/pkgs/mhpcc/anaconda3-5.0.1/lib/python3.6/site-packages/tensorflow/python/client/session.py", line 1563, in __init__
    super(Session, self).__init__(target, graph, config=config)
  File "/gpfs/pkgs/mhpcc/anaconda3-5.0.1/lib/python3.6/site-packages/tensorflow/python/client/session.py", line 633, in __init__
    self._session = tf_session.TF_NewSession(self._graph._c_graph, opts)
tensorflow.python.framework.errors_impl.InternalError: Failed to create session.
Traceback (most recent call last):
  File "roundTwoSubmit.py", line 23, in <module>
    l.learnThingsCPP(kind=0, file=f, weightFile=wf)
  File "/gpfs/home/m201560/chipboard/learn.py", line 130, in learnThingsCPP
    weights = self.getWeightArray()
  File "/gpfs/home/m201560/chipboard/learn.py", line 187, in getWeightArray
    w = self.model.get_weights()
  File "/gpfs/home/m201560/.local/lib/python3.6/site-packages/keras/engine/network.py", line 492, in get_weights
    return K.batch_get_value(weights)
  File "/gpfs/home/m201560/.local/lib/python3.6/site-packages/keras/backend/tensorflow_backend.py", line 2420, in batch_get_value
    return get_session().run(ops)
  File "/gpfs/home/m201560/.local/lib/python3.6/site-packages/keras/backend/tensorflow_backend.py", line 186, in get_session
    _SESSION = tf.Session(config=config)
  File "/gpfs/pkgs/mhpcc/anaconda3-5.0.1/lib/python3.6/site-packages/tensorflow/python/client/session.py", line 1563, in __init__
    super(Session, self).__init__(target, graph, config=config)
  File "/gpfs/pkgs/mhpcc/anaconda3-5.0.1/lib/python3.6/site-packages/tensorflow/python/client/session.py", line 633, in __init__
    self._session = tf_session.TF_NewSession(self._graph._c_graph, opts)
tensorflow.python.framework.errors_impl.InternalError: Failed to create session.
Traceback (most recent call last):
  File "roundTwoSubmit.py", line 23, in <module>
    l.learnThingsCPP(kind=0, file=f, weightFile=wf)
  File "/gpfs/home/m201560/chipboard/learn.py", line 130, in learnThingsCPP
    weights = self.getWeightArray()
  File "/gpfs/home/m201560/chipboard/learn.py", line 187, in getWeightArray
    w = self.model.get_weights()
  File "/gpfs/home/m201560/.local/lib/python3.6/site-packages/keras/engine/network.py", line 492, in get_weights
    return K.batch_get_value(weights)
  File "/gpfs/home/m201560/.local/lib/python3.6/site-packages/keras/backend/tensorflow_backend.py", line 2420, in batch_get_value
    return get_session().run(ops)
  File "/gpfs/home/m201560/.local/lib/python3.6/site-packages/keras/backend/tensorflow_backend.py", line 186, in get_session
    _SESSION = tf.Session(config=config)
  File "/gpfs/pkgs/mhpcc/anaconda3-5.0.1/lib/python3.6/site-packages/tensorflow/python/client/session.py", line 1563, in __init__
    super(Session, self).__init__(target, graph, config=config)
  File "/gpfs/pkgs/mhpcc/anaconda3-5.0.1/lib/python3.6/site-packages/tensorflow/python/client/session.py", line 633, in __init__
    self._session = tf_session.TF_NewSession(self._graph._c_graph, opts)
tensorflow.python.framework.errors_impl.InternalError: Failed to create session.
Traceback (most recent call last):
  File "roundTwoSubmit.py", line 23, in <module>
    l.learnThingsCPP(kind=0, file=f, weightFile=wf)
  File "/gpfs/home/m201560/chipboard/learn.py", line 130, in learnThingsCPP
    weights = self.getWeightArray()
  File "/gpfs/home/m201560/chipboard/learn.py", line 187, in getWeightArray
    w = self.model.get_weights()
  File "/gpfs/home/m201560/.local/lib/python3.6/site-packages/keras/engine/network.py", line 492, in get_weights
    return K.batch_get_value(weights)
  File "/gpfs/home/m201560/.local/lib/python3.6/site-packages/keras/backend/tensorflow_backend.py", line 2420, in batch_get_value
    return get_session().run(ops)
  File "/gpfs/home/m201560/.local/lib/python3.6/site-packages/keras/backend/tensorflow_backend.py", line 186, in get_session
    _SESSION = tf.Session(config=config)
  File "/gpfs/pkgs/mhpcc/anaconda3-5.0.1/lib/python3.6/site-packages/tensorflow/python/client/session.py", line 1563, in __init__
    super(Session, self).__init__(target, graph, config=config)
  File "/gpfs/pkgs/mhpcc/anaconda3-5.0.1/lib/python3.6/site-packages/tensorflow/python/client/session.py", line 633, in __init__
    self._session = tf_session.TF_NewSession(self._graph._c_graph, opts)
tensorflow.python.framework.errors_impl.InternalError: Failed to create session.
Traceback (most recent call last):
  File "roundTwoSubmit.py", line 23, in <module>
    l.learnThingsCPP(kind=0, file=f, weightFile=wf)
  File "/gpfs/home/m201560/chipboard/learn.py", line 130, in learnThingsCPP
    weights = self.getWeightArray()
  File "/gpfs/home/m201560/chipboard/learn.py", line 187, in getWeightArray
    w = self.model.get_weights()
  File "/gpfs/home/m201560/.local/lib/python3.6/site-packages/keras/engine/network.py", line 492, in get_weights
    return K.batch_get_value(weights)
  File "/gpfs/home/m201560/.local/lib/python3.6/site-packages/keras/backend/tensorflow_backend.py", line 2420, in batch_get_value
    return get_session().run(ops)
  File "/gpfs/home/m201560/.local/lib/python3.6/site-packages/keras/backend/tensorflow_backend.py", line 186, in get_session
    _SESSION = tf.Session(config=config)
  File "/gpfs/pkgs/mhpcc/anaconda3-5.0.1/lib/python3.6/site-packages/tensorflow/python/client/session.py", line 1563, in __init__
    super(Session, self).__init__(target, graph, config=config)
  File "/gpfs/pkgs/mhpcc/anaconda3-5.0.1/lib/python3.6/site-packages/tensorflow/python/client/session.py", line 633, in __init__
    self._session = tf_session.TF_NewSession(self._graph._c_graph, opts)
tensorflow.python.framework.errors_impl.InternalError: Failed to create session.
2019-08-01 22:16:55.657821: I tensorflow/core/common_runtime/gpu/gpu_device.cc:952] Device interconnect StreamExecutor with strength 1 edge matrix:
2019-08-01 22:16:55.657861: I tensorflow/core/common_runtime/gpu/gpu_device.cc:958]      0 1 2 3 
2019-08-01 22:16:55.657874: I tensorflow/core/common_runtime/gpu/gpu_device.cc:971] 0:   N Y N N 
2019-08-01 22:16:55.657883: I tensorflow/core/common_runtime/gpu/gpu_device.cc:971] 1:   Y N N N 
2019-08-01 22:16:55.657891: I tensorflow/core/common_runtime/gpu/gpu_device.cc:971] 2:   N N N Y 
2019-08-01 22:16:55.657900: I tensorflow/core/common_runtime/gpu/gpu_device.cc:971] 3:   N N Y N 
2019-08-01 22:16:55.658534: I tensorflow/core/common_runtime/gpu/gpu_device.cc:1084] Created TensorFlow device (/job:localhost/replica:0/task:0/device:GPU:0 with 15163 MB memory) -> physical GPU (device: 0, name: Tesla P100-SXM2-16GB, pci bus id: 0002:01:00.0, compute capability: 6.0)
2019-08-01 22:16:55.789700: I tensorflow/core/common_runtime/gpu/gpu_device.cc:1084] Created TensorFlow device (/job:localhost/replica:0/task:0/device:GPU:1 with 15163 MB memory) -> physical GPU (device: 1, name: Tesla P100-SXM2-16GB, pci bus id: 0003:01:00.0, compute capability: 6.0)
2019-08-01 22:16:55.920992: I tensorflow/core/common_runtime/gpu/gpu_device.cc:1084] Created TensorFlow device (/job:localhost/replica:0/task:0/device:GPU:2 with 15163 MB memory) -> physical GPU (device: 2, name: Tesla P100-SXM2-16GB, pci bus id: 0006:01:00.0, compute capability: 6.0)
2019-08-01 22:16:56.051997: I tensorflow/core/common_runtime/gpu/gpu_device.cc:1084] Created TensorFlow device (/job:localhost/replica:0/task:0/device:GPU:3 with 15163 MB memory) -> physical GPU (device: 3, name: Tesla P100-SXM2-16GB, pci bus id: 0007:01:00.0, compute capability: 6.0)
=>> PBS: job killed: walltime 1834 exceeded limit 1800
[warn] Epoll ADD(4) on fd 94 failed.  Old events were 0; read change was 0 (none); write change was 1 (add): Bad file descriptor
[warn] Epoll ADD(4) on fd 97 failed.  Old events were 0; read change was 0 (none); write change was 1 (add): Bad file descriptor
[warn] Epoll ADD(4) on fd 107 failed.  Old events were 0; read change was 0 (none); write change was 1 (add): Bad file descriptor
[warn] Epoll ADD(4) on fd 108 failed.  Old events were 0; read change was 0 (none); write change was 1 (add): Bad file descriptor
[warn] Epoll ADD(4) on fd 102 failed.  Old events were 0; read change was 0 (none); write change was 1 (add): Bad file descriptor
[warn] Epoll ADD(4) on fd 103 failed.  Old events were 0; read change was 0 (none); write change was 1 (add): Bad file descriptor
[warn] Epoll ADD(4) on fd 49 failed.  Old events were 0; read change was 0 (none); write change was 1 (add): Bad file descriptor
[warn] Epoll ADD(4) on fd 100 failed.  Old events were 0; read change was 0 (none); write change was 1 (add): Bad file descriptor
[warn] Epoll ADD(4) on fd 91 failed.  Old events were 0; read change was 0 (none); write change was 1 (add): Bad file descriptor
[warn] Epoll ADD(4) on fd 105 failed.  Old events were 0; read change was 0 (none); write change was 1 (add): Bad file descriptor
[warn] Epoll ADD(4) on fd 106 failed.  Old events were 0; read change was 0 (none); write change was 1 (add): Bad file descriptor
[warn] Epoll ADD(4) on fd 101 failed.  Old events were 0; read change was 0 (none); write change was 1 (add): Bad file descriptor
[warn] Epoll ADD(4) on fd 104 failed.  Old events were 0; read change was 0 (none); write change was 1 (add): Bad file descriptor
[warn] Epoll ADD(4) on fd 0 failed.  Old events were 0; read change was 0 (none); write change was 1 (add): Bad file descriptor
[warn] Epoll ADD(4) on fd 99 failed.  Old events were 0; read change was 0 (none); write change was 1 (add): Bad file descriptor
