--------------------------------------------------------------------------
WARNING: There are more than one active ports on host 'cr2cn16', but the
default subnet GID prefix was detected on more than one of these
ports.  If these ports are connected to different physical IB
networks, this configuration will fail in Open MPI.  This version of
Open MPI requires that every physically separate IB subnet that is
used between connected MPI processes must have different subnet ID
values.

Please see this FAQ entry for more details:

  http://www.open-mpi.org/faq/?category=openfabrics#ofa-default-subnet-gid

NOTE: You can turn off this warning by setting the MCA parameter
      btl_openib_warn_default_gid_prefix to 0.
--------------------------------------------------------------------------
2019-08-01 21:32:11.560216: E tensorflow/core/common_runtime/direct_session.cc:158] Internal: failed initializing StreamExecutor for CUDA device ordinal 0: Internal: failed call to cuDevicePrimaryCtxRetain: CUDA_ERROR_INVALID_DEVICE
/gpfs/pkgs/mhpcc/anaconda3-5.0.1/lib/python3.6/site-packages/h5py/__init__.py:34: FutureWarning: Conversion of the second argument of issubdtype from `float` to `np.floating` is deprecated. In future, it will be treated as `np.float64 == np.dtype(float).type`.
  from ._conv import register_converters as _register_converters
Using TensorFlow backend.
2019-08-01 21:32:11.613047: E tensorflow/core/common_runtime/direct_session.cc:158] Internal: failed initializing StreamExecutor for CUDA device ordinal 0: Internal: failed call to cuDevicePrimaryCtxRetain: CUDA_ERROR_INVALID_DEVICE
/gpfs/pkgs/mhpcc/anaconda3-5.0.1/lib/python3.6/site-packages/h5py/__init__.py:34: FutureWarning: Conversion of the second argument of issubdtype from `float` to `np.floating` is deprecated. In future, it will be treated as `np.float64 == np.dtype(float).type`.
  from ._conv import register_converters as _register_converters
Using TensorFlow backend.
2019-08-01 21:32:11.727527: E tensorflow/core/common_runtime/direct_session.cc:158] Internal: failed initializing StreamExecutor for CUDA device ordinal 0: Internal: failed call to cuDevicePrimaryCtxRetain: CUDA_ERROR_INVALID_DEVICE
/gpfs/pkgs/mhpcc/anaconda3-5.0.1/lib/python3.6/site-packages/h5py/__init__.py:34: FutureWarning: Conversion of the second argument of issubdtype from `float` to `np.floating` is deprecated. In future, it will be treated as `np.float64 == np.dtype(float).type`.
  from ._conv import register_converters as _register_converters
Using TensorFlow backend.
Traceback (most recent call last):
  File "roundOneSubmit.py", line 23, in <module>
    l.learnThingsCPP(kind=0, file=f, weightFile=wf)
  File "/gpfs/home/m201560/chipboard/learn.py", line 130, in learnThingsCPP
    weights = self.getWeightArray()
  File "/gpfs/home/m201560/chipboard/learn.py", line 193, in getWeightArray
    return self.model.get_weights()[0].tolist()
  File "/gpfs/home/m201560/.local/lib/python3.6/site-packages/keras/engine/network.py", line 492, in get_weights
    return K.batch_get_value(weights)
  File "/gpfs/home/m201560/.local/lib/python3.6/site-packages/keras/backend/tensorflow_backend.py", line 2420, in batch_get_value
    return get_session().run(ops)
  File "/gpfs/home/m201560/.local/lib/python3.6/site-packages/keras/backend/tensorflow_backend.py", line 186, in get_session
    _SESSION = tf.Session(config=config)
  File "/gpfs/pkgs/mhpcc/anaconda3-5.0.1/lib/python3.6/site-packages/tensorflow/python/client/session.py", line 1563, in __init__
    super(Session, self).__init__(target, graph, config=config)
  File "/gpfs/pkgs/mhpcc/anaconda3-5.0.1/lib/python3.6/site-packages/tensorflow/python/client/session.py", line 633, in __init__
    self._session = tf_session.TF_NewSession(self._graph._c_graph, opts)
tensorflow.python.framework.errors_impl.InternalError: Failed to create session.
Traceback (most recent call last):
  File "roundOneSubmit.py", line 23, in <module>
    l.learnThingsCPP(kind=0, file=f, weightFile=wf)
  File "/gpfs/home/m201560/chipboard/learn.py", line 130, in learnThingsCPP
    weights = self.getWeightArray()
  File "/gpfs/home/m201560/chipboard/learn.py", line 193, in getWeightArray
    return self.model.get_weights()[0].tolist()
  File "/gpfs/home/m201560/.local/lib/python3.6/site-packages/keras/engine/network.py", line 492, in get_weights
    return K.batch_get_value(weights)
  File "/gpfs/home/m201560/.local/lib/python3.6/site-packages/keras/backend/tensorflow_backend.py", line 2420, in batch_get_value
    return get_session().run(ops)
  File "/gpfs/home/m201560/.local/lib/python3.6/site-packages/keras/backend/tensorflow_backend.py", line 186, in get_session
    _SESSION = tf.Session(config=config)
  File "/gpfs/pkgs/mhpcc/anaconda3-5.0.1/lib/python3.6/site-packages/tensorflow/python/client/session.py", line 1563, in __init__
    super(Session, self).__init__(target, graph, config=config)
  File "/gpfs/pkgs/mhpcc/anaconda3-5.0.1/lib/python3.6/site-packages/tensorflow/python/client/session.py", line 633, in __init__
    self._session = tf_session.TF_NewSession(self._graph._c_graph, opts)
tensorflow.python.framework.errors_impl.InternalError: Failed to create session.
Traceback (most recent call last):
  File "roundOneSubmit.py", line 23, in <module>
    l.learnThingsCPP(kind=0, file=f, weightFile=wf)
  File "/gpfs/home/m201560/chipboard/learn.py", line 130, in learnThingsCPP
    weights = self.getWeightArray()
  File "/gpfs/home/m201560/chipboard/learn.py", line 193, in getWeightArray
    return self.model.get_weights()[0].tolist()
  File "/gpfs/home/m201560/.local/lib/python3.6/site-packages/keras/engine/network.py", line 492, in get_weights
    return K.batch_get_value(weights)
  File "/gpfs/home/m201560/.local/lib/python3.6/site-packages/keras/backend/tensorflow_backend.py", line 2420, in batch_get_value
    return get_session().run(ops)
  File "/gpfs/home/m201560/.local/lib/python3.6/site-packages/keras/backend/tensorflow_backend.py", line 186, in get_session
    _SESSION = tf.Session(config=config)
  File "/gpfs/pkgs/mhpcc/anaconda3-5.0.1/lib/python3.6/site-packages/tensorflow/python/client/session.py", line 1563, in __init__
    super(Session, self).__init__(target, graph, config=config)
  File "/gpfs/pkgs/mhpcc/anaconda3-5.0.1/lib/python3.6/site-packages/tensorflow/python/client/session.py", line 633, in __init__
    self._session = tf_session.TF_NewSession(self._graph._c_graph, opts)
tensorflow.python.framework.errors_impl.InternalError: Failed to create session.
2019-08-01 21:32:11.804440: E tensorflow/core/common_runtime/direct_session.cc:158] Internal: failed initializing StreamExecutor for CUDA device ordinal 0: Internal: failed call to cuDevicePrimaryCtxRetain: CUDA_ERROR_INVALID_DEVICE
/gpfs/pkgs/mhpcc/anaconda3-5.0.1/lib/python3.6/site-packages/h5py/__init__.py:34: FutureWarning: Conversion of the second argument of issubdtype from `float` to `np.floating` is deprecated. In future, it will be treated as `np.float64 == np.dtype(float).type`.
  from ._conv import register_converters as _register_converters
Using TensorFlow backend.
Traceback (most recent call last):
  File "roundOneSubmit.py", line 23, in <module>
    l.learnThingsCPP(kind=0, file=f, weightFile=wf)
  File "/gpfs/home/m201560/chipboard/learn.py", line 130, in learnThingsCPP
    weights = self.getWeightArray()
  File "/gpfs/home/m201560/chipboard/learn.py", line 193, in getWeightArray
    return self.model.get_weights()[0].tolist()
  File "/gpfs/home/m201560/.local/lib/python3.6/site-packages/keras/engine/network.py", line 492, in get_weights
    return K.batch_get_value(weights)
  File "/gpfs/home/m201560/.local/lib/python3.6/site-packages/keras/backend/tensorflow_backend.py", line 2420, in batch_get_value
    return get_session().run(ops)
  File "/gpfs/home/m201560/.local/lib/python3.6/site-packages/keras/backend/tensorflow_backend.py", line 186, in get_session
    _SESSION = tf.Session(config=config)
  File "/gpfs/pkgs/mhpcc/anaconda3-5.0.1/lib/python3.6/site-packages/tensorflow/python/client/session.py", line 1563, in __init__
    super(Session, self).__init__(target, graph, config=config)
  File "/gpfs/pkgs/mhpcc/anaconda3-5.0.1/lib/python3.6/site-packages/tensorflow/python/client/session.py", line 633, in __init__
    self._session = tf_session.TF_NewSession(self._graph._c_graph, opts)
tensorflow.python.framework.errors_impl.InternalError: Failed to create session.
2019-08-01 21:32:11.819325: E tensorflow/core/common_runtime/direct_session.cc:158] Internal: failed initializing StreamExecutor for CUDA device ordinal 0: Internal: failed call to cuDevicePrimaryCtxRetain: CUDA_ERROR_INVALID_DEVICE
/gpfs/pkgs/mhpcc/anaconda3-5.0.1/lib/python3.6/site-packages/h5py/__init__.py:34: FutureWarning: Conversion of the second argument of issubdtype from `float` to `np.floating` is deprecated. In future, it will be treated as `np.float64 == np.dtype(float).type`.
  from ._conv import register_converters as _register_converters
Using TensorFlow backend.
Traceback (most recent call last):
  File "roundOneSubmit.py", line 23, in <module>
    l.learnThingsCPP(kind=0, file=f, weightFile=wf)
  File "/gpfs/home/m201560/chipboard/learn.py", line 130, in learnThingsCPP
    weights = self.getWeightArray()
  File "/gpfs/home/m201560/chipboard/learn.py", line 193, in getWeightArray
    return self.model.get_weights()[0].tolist()
  File "/gpfs/home/m201560/.local/lib/python3.6/site-packages/keras/engine/network.py", line 492, in get_weights
    return K.batch_get_value(weights)
  File "/gpfs/home/m201560/.local/lib/python3.6/site-packages/keras/backend/tensorflow_backend.py", line 2420, in batch_get_value
    return get_session().run(ops)
  File "/gpfs/home/m201560/.local/lib/python3.6/site-packages/keras/backend/tensorflow_backend.py", line 186, in get_session
    _SESSION = tf.Session(config=config)
  File "/gpfs/pkgs/mhpcc/anaconda3-5.0.1/lib/python3.6/site-packages/tensorflow/python/client/session.py", line 1563, in __init__
    super(Session, self).__init__(target, graph, config=config)
  File "/gpfs/pkgs/mhpcc/anaconda3-5.0.1/lib/python3.6/site-packages/tensorflow/python/client/session.py", line 633, in __init__
    self._session = tf_session.TF_NewSession(self._graph._c_graph, opts)
tensorflow.python.framework.errors_impl.InternalError: Failed to create session.
2019-08-01 21:32:11.840355: E tensorflow/core/common_runtime/direct_session.cc:158] Internal: failed initializing StreamExecutor for CUDA device ordinal 0: Internal: failed call to cuDevicePrimaryCtxRetain: CUDA_ERROR_INVALID_DEVICE
/gpfs/pkgs/mhpcc/anaconda3-5.0.1/lib/python3.6/site-packages/h5py/__init__.py:34: FutureWarning: Conversion of the second argument of issubdtype from `float` to `np.floating` is deprecated. In future, it will be treated as `np.float64 == np.dtype(float).type`.
  from ._conv import register_converters as _register_converters
Using TensorFlow backend.
Traceback (most recent call last):
  File "roundOneSubmit.py", line 23, in <module>
    l.learnThingsCPP(kind=0, file=f, weightFile=wf)
  File "/gpfs/home/m201560/chipboard/learn.py", line 130, in learnThingsCPP
    weights = self.getWeightArray()
  File "/gpfs/home/m201560/chipboard/learn.py", line 193, in getWeightArray
    return self.model.get_weights()[0].tolist()
  File "/gpfs/home/m201560/.local/lib/python3.6/site-packages/keras/engine/network.py", line 492, in get_weights
    return K.batch_get_value(weights)
  File "/gpfs/home/m201560/.local/lib/python3.6/site-packages/keras/backend/tensorflow_backend.py", line 2420, in batch_get_value
    return get_session().run(ops)
  File "/gpfs/home/m201560/.local/lib/python3.6/site-packages/keras/backend/tensorflow_backend.py", line 186, in get_session
    _SESSION = tf.Session(config=config)
  File "/gpfs/pkgs/mhpcc/anaconda3-5.0.1/lib/python3.6/site-packages/tensorflow/python/client/session.py", line 1563, in __init__
    super(Session, self).__init__(target, graph, config=config)
  File "/gpfs/pkgs/mhpcc/anaconda3-5.0.1/lib/python3.6/site-packages/tensorflow/python/client/session.py", line 633, in __init__
    self._session = tf_session.TF_NewSession(self._graph._c_graph, opts)
tensorflow.python.framework.errors_impl.InternalError: Failed to create session.
2019-08-01 21:32:11.846852: E tensorflow/core/common_runtime/direct_session.cc:158] Internal: failed initializing StreamExecutor for CUDA device ordinal 0: Internal: failed call to cuDevicePrimaryCtxRetain: CUDA_ERROR_INVALID_DEVICE
2019-08-01 21:32:11.846836: E tensorflow/core/common_runtime/direct_session.cc:158] Internal: failed initializing StreamExecutor for CUDA device ordinal 0: Internal: failed call to cuDevicePrimaryCtxRetain: CUDA_ERROR_INVALID_DEVICE
/gpfs/pkgs/mhpcc/anaconda3-5.0.1/lib/python3.6/site-packages/h5py/__init__.py:34: FutureWarning: Conversion of the second argument of issubdtype from `float` to `np.floating` is deprecated. In future, it will be treated as `np.float64 == np.dtype(float).type`.
  from ._conv import register_converters as _register_converters
Using TensorFlow backend.
/gpfs/pkgs/mhpcc/anaconda3-5.0.1/lib/python3.6/site-packages/h5py/__init__.py:34: FutureWarning: Conversion of the second argument of issubdtype from `float` to `np.floating` is deprecated. In future, it will be treated as `np.float64 == np.dtype(float).type`.
  from ._conv import register_converters as _register_converters
Using TensorFlow backend.
Traceback (most recent call last):
  File "roundOneSubmit.py", line 23, in <module>
    l.learnThingsCPP(kind=0, file=f, weightFile=wf)
  File "/gpfs/home/m201560/chipboard/learn.py", line 130, in learnThingsCPP
    weights = self.getWeightArray()
  File "/gpfs/home/m201560/chipboard/learn.py", line 193, in getWeightArray
    return self.model.get_weights()[0].tolist()
  File "/gpfs/home/m201560/.local/lib/python3.6/site-packages/keras/engine/network.py", line 492, in get_weights
    return K.batch_get_value(weights)
  File "/gpfs/home/m201560/.local/lib/python3.6/site-packages/keras/backend/tensorflow_backend.py", line 2420, in batch_get_value
    return get_session().run(ops)
  File "/gpfs/home/m201560/.local/lib/python3.6/site-packages/keras/backend/tensorflow_backend.py", line 186, in get_session
    _SESSION = tf.Session(config=config)
  File "/gpfs/pkgs/mhpcc/anaconda3-5.0.1/lib/python3.6/site-packages/tensorflow/python/client/session.py", line 1563, in __init__
    super(Session, self).__init__(target, graph, config=config)
  File "/gpfs/pkgs/mhpcc/anaconda3-5.0.1/lib/python3.6/site-packages/tensorflow/python/client/session.py", line 633, in __init__
    self._session = tf_session.TF_NewSession(self._graph._c_graph, opts)
tensorflow.python.framework.errors_impl.InternalError: Failed to create session.
Traceback (most recent call last):
  File "roundOneSubmit.py", line 23, in <module>
    l.learnThingsCPP(kind=0, file=f, weightFile=wf)
  File "/gpfs/home/m201560/chipboard/learn.py", line 130, in learnThingsCPP
    weights = self.getWeightArray()
  File "/gpfs/home/m201560/chipboard/learn.py", line 193, in getWeightArray
    return self.model.get_weights()[0].tolist()
  File "/gpfs/home/m201560/.local/lib/python3.6/site-packages/keras/engine/network.py", line 492, in get_weights
    return K.batch_get_value(weights)
  File "/gpfs/home/m201560/.local/lib/python3.6/site-packages/keras/backend/tensorflow_backend.py", line 2420, in batch_get_value
    return get_session().run(ops)
  File "/gpfs/home/m201560/.local/lib/python3.6/site-packages/keras/backend/tensorflow_backend.py", line 186, in get_session
    _SESSION = tf.Session(config=config)
  File "/gpfs/pkgs/mhpcc/anaconda3-5.0.1/lib/python3.6/site-packages/tensorflow/python/client/session.py", line 1563, in __init__
    super(Session, self).__init__(target, graph, config=config)
  File "/gpfs/pkgs/mhpcc/anaconda3-5.0.1/lib/python3.6/site-packages/tensorflow/python/client/session.py", line 633, in __init__
    self._session = tf_session.TF_NewSession(self._graph._c_graph, opts)
tensorflow.python.framework.errors_impl.InternalError: Failed to create session.
2019-08-01 21:32:12.134834: E tensorflow/core/common_runtime/direct_session.cc:158] Internal: failed initializing StreamExecutor for CUDA device ordinal 0: Internal: failed call to cuDevicePrimaryCtxRetain: CUDA_ERROR_INVALID_DEVICE
/gpfs/pkgs/mhpcc/anaconda3-5.0.1/lib/python3.6/site-packages/h5py/__init__.py:34: FutureWarning: Conversion of the second argument of issubdtype from `float` to `np.floating` is deprecated. In future, it will be treated as `np.float64 == np.dtype(float).type`.
  from ._conv import register_converters as _register_converters
Using TensorFlow backend.
Traceback (most recent call last):
  File "roundOneSubmit.py", line 23, in <module>
    l.learnThingsCPP(kind=0, file=f, weightFile=wf)
  File "/gpfs/home/m201560/chipboard/learn.py", line 130, in learnThingsCPP
    weights = self.getWeightArray()
  File "/gpfs/home/m201560/chipboard/learn.py", line 193, in getWeightArray
    return self.model.get_weights()[0].tolist()
  File "/gpfs/home/m201560/.local/lib/python3.6/site-packages/keras/engine/network.py", line 492, in get_weights
    return K.batch_get_value(weights)
  File "/gpfs/home/m201560/.local/lib/python3.6/site-packages/keras/backend/tensorflow_backend.py", line 2420, in batch_get_value
    return get_session().run(ops)
  File "/gpfs/home/m201560/.local/lib/python3.6/site-packages/keras/backend/tensorflow_backend.py", line 186, in get_session
    _SESSION = tf.Session(config=config)
  File "/gpfs/pkgs/mhpcc/anaconda3-5.0.1/lib/python3.6/site-packages/tensorflow/python/client/session.py", line 1563, in __init__
    super(Session, self).__init__(target, graph, config=config)
  File "/gpfs/pkgs/mhpcc/anaconda3-5.0.1/lib/python3.6/site-packages/tensorflow/python/client/session.py", line 633, in __init__
    self._session = tf_session.TF_NewSession(self._graph._c_graph, opts)
tensorflow.python.framework.errors_impl.InternalError: Failed to create session.
2019-08-01 21:32:12.161550: E tensorflow/core/common_runtime/direct_session.cc:158] Internal: failed initializing StreamExecutor for CUDA device ordinal 0: Internal: failed call to cuDevicePrimaryCtxRetain: CUDA_ERROR_INVALID_DEVICE
/gpfs/pkgs/mhpcc/anaconda3-5.0.1/lib/python3.6/site-packages/h5py/__init__.py:34: FutureWarning: Conversion of the second argument of issubdtype from `float` to `np.floating` is deprecated. In future, it will be treated as `np.float64 == np.dtype(float).type`.
  from ._conv import register_converters as _register_converters
Using TensorFlow backend.
Traceback (most recent call last):
  File "roundOneSubmit.py", line 23, in <module>
    l.learnThingsCPP(kind=0, file=f, weightFile=wf)
  File "/gpfs/home/m201560/chipboard/learn.py", line 130, in learnThingsCPP
    weights = self.getWeightArray()
  File "/gpfs/home/m201560/chipboard/learn.py", line 193, in getWeightArray
    return self.model.get_weights()[0].tolist()
  File "/gpfs/home/m201560/.local/lib/python3.6/site-packages/keras/engine/network.py", line 492, in get_weights
    return K.batch_get_value(weights)
  File "/gpfs/home/m201560/.local/lib/python3.6/site-packages/keras/backend/tensorflow_backend.py", line 2420, in batch_get_value
    return get_session().run(ops)
  File "/gpfs/home/m201560/.local/lib/python3.6/site-packages/keras/backend/tensorflow_backend.py", line 186, in get_session
    _SESSION = tf.Session(config=config)
  File "/gpfs/pkgs/mhpcc/anaconda3-5.0.1/lib/python3.6/site-packages/tensorflow/python/client/session.py", line 1563, in __init__
    super(Session, self).__init__(target, graph, config=config)
  File "/gpfs/pkgs/mhpcc/anaconda3-5.0.1/lib/python3.6/site-packages/tensorflow/python/client/session.py", line 633, in __init__
    self._session = tf_session.TF_NewSession(self._graph._c_graph, opts)
tensorflow.python.framework.errors_impl.InternalError: Failed to create session.
2019-08-01 21:32:12.212003: E tensorflow/core/common_runtime/direct_session.cc:158] Internal: failed initializing StreamExecutor for CUDA device ordinal 0: Internal: failed call to cuDevicePrimaryCtxRetain: CUDA_ERROR_INVALID_DEVICE
/gpfs/pkgs/mhpcc/anaconda3-5.0.1/lib/python3.6/site-packages/h5py/__init__.py:34: FutureWarning: Conversion of the second argument of issubdtype from `float` to `np.floating` is deprecated. In future, it will be treated as `np.float64 == np.dtype(float).type`.
  from ._conv import register_converters as _register_converters
Using TensorFlow backend.
Traceback (most recent call last):
  File "roundOneSubmit.py", line 23, in <module>
    l.learnThingsCPP(kind=0, file=f, weightFile=wf)
  File "/gpfs/home/m201560/chipboard/learn.py", line 130, in learnThingsCPP
    weights = self.getWeightArray()
  File "/gpfs/home/m201560/chipboard/learn.py", line 193, in getWeightArray
    return self.model.get_weights()[0].tolist()
  File "/gpfs/home/m201560/.local/lib/python3.6/site-packages/keras/engine/network.py", line 492, in get_weights
    return K.batch_get_value(weights)
  File "/gpfs/home/m201560/.local/lib/python3.6/site-packages/keras/backend/tensorflow_backend.py", line 2420, in batch_get_value
    return get_session().run(ops)
  File "/gpfs/home/m201560/.local/lib/python3.6/site-packages/keras/backend/tensorflow_backend.py", line 186, in get_session
    _SESSION = tf.Session(config=config)
  File "/gpfs/pkgs/mhpcc/anaconda3-5.0.1/lib/python3.6/site-packages/tensorflow/python/client/session.py", line 1563, in __init__
    super(Session, self).__init__(target, graph, config=config)
  File "/gpfs/pkgs/mhpcc/anaconda3-5.0.1/lib/python3.6/site-packages/tensorflow/python/client/session.py", line 633, in __init__
    self._session = tf_session.TF_NewSession(self._graph._c_graph, opts)
tensorflow.python.framework.errors_impl.InternalError: Failed to create session.
2019-08-01 21:32:12.250082: E tensorflow/core/common_runtime/direct_session.cc:158] Internal: failed initializing StreamExecutor for CUDA device ordinal 0: Internal: failed call to cuDevicePrimaryCtxRetain: CUDA_ERROR_INVALID_DEVICE
/gpfs/pkgs/mhpcc/anaconda3-5.0.1/lib/python3.6/site-packages/h5py/__init__.py:34: FutureWarning: Conversion of the second argument of issubdtype from `float` to `np.floating` is deprecated. In future, it will be treated as `np.float64 == np.dtype(float).type`.
  from ._conv import register_converters as _register_converters
Using TensorFlow backend.
2019-08-01 21:32:12.254906: E tensorflow/core/common_runtime/direct_session.cc:158] Internal: failed initializing StreamExecutor for CUDA device ordinal 0: Internal: failed call to cuDevicePrimaryCtxRetain: CUDA_ERROR_INVALID_DEVICE
/gpfs/pkgs/mhpcc/anaconda3-5.0.1/lib/python3.6/site-packages/h5py/__init__.py:34: FutureWarning: Conversion of the second argument of issubdtype from `float` to `np.floating` is deprecated. In future, it will be treated as `np.float64 == np.dtype(float).type`.
  from ._conv import register_converters as _register_converters
Using TensorFlow backend.
Traceback (most recent call last):
  File "roundOneSubmit.py", line 23, in <module>
    l.learnThingsCPP(kind=0, file=f, weightFile=wf)
  File "/gpfs/home/m201560/chipboard/learn.py", line 130, in learnThingsCPP
    weights = self.getWeightArray()
  File "/gpfs/home/m201560/chipboard/learn.py", line 193, in getWeightArray
    return self.model.get_weights()[0].tolist()
  File "/gpfs/home/m201560/.local/lib/python3.6/site-packages/keras/engine/network.py", line 492, in get_weights
    return K.batch_get_value(weights)
  File "/gpfs/home/m201560/.local/lib/python3.6/site-packages/keras/backend/tensorflow_backend.py", line 2420, in batch_get_value
    return get_session().run(ops)
  File "/gpfs/home/m201560/.local/lib/python3.6/site-packages/keras/backend/tensorflow_backend.py", line 186, in get_session
    _SESSION = tf.Session(config=config)
  File "/gpfs/pkgs/mhpcc/anaconda3-5.0.1/lib/python3.6/site-packages/tensorflow/python/client/session.py", line 1563, in __init__
    super(Session, self).__init__(target, graph, config=config)
  File "/gpfs/pkgs/mhpcc/anaconda3-5.0.1/lib/python3.6/site-packages/tensorflow/python/client/session.py", line 633, in __init__
    self._session = tf_session.TF_NewSession(self._graph._c_graph, opts)
tensorflow.python.framework.errors_impl.InternalError: Failed to create session.
Traceback (most recent call last):
  File "roundOneSubmit.py", line 23, in <module>
    l.learnThingsCPP(kind=0, file=f, weightFile=wf)
  File "/gpfs/home/m201560/chipboard/learn.py", line 130, in learnThingsCPP
    weights = self.getWeightArray()
  File "/gpfs/home/m201560/chipboard/learn.py", line 193, in getWeightArray
    return self.model.get_weights()[0].tolist()
  File "/gpfs/home/m201560/.local/lib/python3.6/site-packages/keras/engine/network.py", line 492, in get_weights
    return K.batch_get_value(weights)
  File "/gpfs/home/m201560/.local/lib/python3.6/site-packages/keras/backend/tensorflow_backend.py", line 2420, in batch_get_value
    return get_session().run(ops)
  File "/gpfs/home/m201560/.local/lib/python3.6/site-packages/keras/backend/tensorflow_backend.py", line 186, in get_session
    _SESSION = tf.Session(config=config)
  File "/gpfs/pkgs/mhpcc/anaconda3-5.0.1/lib/python3.6/site-packages/tensorflow/python/client/session.py", line 1563, in __init__
    super(Session, self).__init__(target, graph, config=config)
  File "/gpfs/pkgs/mhpcc/anaconda3-5.0.1/lib/python3.6/site-packages/tensorflow/python/client/session.py", line 633, in __init__
    self._session = tf_session.TF_NewSession(self._graph._c_graph, opts)
tensorflow.python.framework.errors_impl.InternalError: Failed to create session.
2019-08-01 21:32:12.262450: E tensorflow/core/common_runtime/direct_session.cc:158] Internal: failed initializing StreamExecutor for CUDA device ordinal 0: Internal: failed call to cuDevicePrimaryCtxRetain: CUDA_ERROR_INVALID_DEVICE
/gpfs/pkgs/mhpcc/anaconda3-5.0.1/lib/python3.6/site-packages/h5py/__init__.py:34: FutureWarning: Conversion of the second argument of issubdtype from `float` to `np.floating` is deprecated. In future, it will be treated as `np.float64 == np.dtype(float).type`.
  from ._conv import register_converters as _register_converters
Using TensorFlow backend.
Traceback (most recent call last):
  File "roundOneSubmit.py", line 23, in <module>
    l.learnThingsCPP(kind=0, file=f, weightFile=wf)
  File "/gpfs/home/m201560/chipboard/learn.py", line 130, in learnThingsCPP
    weights = self.getWeightArray()
  File "/gpfs/home/m201560/chipboard/learn.py", line 193, in getWeightArray
    return self.model.get_weights()[0].tolist()
  File "/gpfs/home/m201560/.local/lib/python3.6/site-packages/keras/engine/network.py", line 492, in get_weights
    return K.batch_get_value(weights)
  File "/gpfs/home/m201560/.local/lib/python3.6/site-packages/keras/backend/tensorflow_backend.py", line 2420, in batch_get_value
    return get_session().run(ops)
  File "/gpfs/home/m201560/.local/lib/python3.6/site-packages/keras/backend/tensorflow_backend.py", line 186, in get_session
    _SESSION = tf.Session(config=config)
  File "/gpfs/pkgs/mhpcc/anaconda3-5.0.1/lib/python3.6/site-packages/tensorflow/python/client/session.py", line 1563, in __init__
    super(Session, self).__init__(target, graph, config=config)
  File "/gpfs/pkgs/mhpcc/anaconda3-5.0.1/lib/python3.6/site-packages/tensorflow/python/client/session.py", line 633, in __init__
    self._session = tf_session.TF_NewSession(self._graph._c_graph, opts)
tensorflow.python.framework.errors_impl.InternalError: Failed to create session.
2019-08-01 21:32:12.273858: E tensorflow/core/common_runtime/direct_session.cc:158] Internal: failed initializing StreamExecutor for CUDA device ordinal 0: Internal: failed call to cuDevicePrimaryCtxRetain: CUDA_ERROR_INVALID_DEVICE
/gpfs/pkgs/mhpcc/anaconda3-5.0.1/lib/python3.6/site-packages/h5py/__init__.py:34: FutureWarning: Conversion of the second argument of issubdtype from `float` to `np.floating` is deprecated. In future, it will be treated as `np.float64 == np.dtype(float).type`.
  from ._conv import register_converters as _register_converters
Using TensorFlow backend.
2019-08-01 21:32:12.275187: E tensorflow/core/common_runtime/direct_session.cc:158] Internal: failed initializing StreamExecutor for CUDA device ordinal 0: Internal: failed call to cuDevicePrimaryCtxRetain: CUDA_ERROR_INVALID_DEVICE
/gpfs/pkgs/mhpcc/anaconda3-5.0.1/lib/python3.6/site-packages/h5py/__init__.py:34: FutureWarning: Conversion of the second argument of issubdtype from `float` to `np.floating` is deprecated. In future, it will be treated as `np.float64 == np.dtype(float).type`.
  from ._conv import register_converters as _register_converters
Using TensorFlow backend.
Traceback (most recent call last):
  File "roundOneSubmit.py", line 23, in <module>
    l.learnThingsCPP(kind=0, file=f, weightFile=wf)
  File "/gpfs/home/m201560/chipboard/learn.py", line 130, in learnThingsCPP
    weights = self.getWeightArray()
  File "/gpfs/home/m201560/chipboard/learn.py", line 193, in getWeightArray
    return self.model.get_weights()[0].tolist()
  File "/gpfs/home/m201560/.local/lib/python3.6/site-packages/keras/engine/network.py", line 492, in get_weights
    return K.batch_get_value(weights)
  File "/gpfs/home/m201560/.local/lib/python3.6/site-packages/keras/backend/tensorflow_backend.py", line 2420, in batch_get_value
    return get_session().run(ops)
  File "/gpfs/home/m201560/.local/lib/python3.6/site-packages/keras/backend/tensorflow_backend.py", line 186, in get_session
    _SESSION = tf.Session(config=config)
  File "/gpfs/pkgs/mhpcc/anaconda3-5.0.1/lib/python3.6/site-packages/tensorflow/python/client/session.py", line 1563, in __init__
    super(Session, self).__init__(target, graph, config=config)
  File "/gpfs/pkgs/mhpcc/anaconda3-5.0.1/lib/python3.6/site-packages/tensorflow/python/client/session.py", line 633, in __init__
    self._session = tf_session.TF_NewSession(self._graph._c_graph, opts)
tensorflow.python.framework.errors_impl.InternalError: Failed to create session.
Traceback (most recent call last):
  File "roundOneSubmit.py", line 23, in <module>
    l.learnThingsCPP(kind=0, file=f, weightFile=wf)
  File "/gpfs/home/m201560/chipboard/learn.py", line 130, in learnThingsCPP
    weights = self.getWeightArray()
  File "/gpfs/home/m201560/chipboard/learn.py", line 193, in getWeightArray
    return self.model.get_weights()[0].tolist()
  File "/gpfs/home/m201560/.local/lib/python3.6/site-packages/keras/engine/network.py", line 492, in get_weights
    return K.batch_get_value(weights)
  File "/gpfs/home/m201560/.local/lib/python3.6/site-packages/keras/backend/tensorflow_backend.py", line 2420, in batch_get_value
    return get_session().run(ops)
  File "/gpfs/home/m201560/.local/lib/python3.6/site-packages/keras/backend/tensorflow_backend.py", line 186, in get_session
    _SESSION = tf.Session(config=config)
  File "/gpfs/pkgs/mhpcc/anaconda3-5.0.1/lib/python3.6/site-packages/tensorflow/python/client/session.py", line 1563, in __init__
    super(Session, self).__init__(target, graph, config=config)
  File "/gpfs/pkgs/mhpcc/anaconda3-5.0.1/lib/python3.6/site-packages/tensorflow/python/client/session.py", line 633, in __init__
    self._session = tf_session.TF_NewSession(self._graph._c_graph, opts)
tensorflow.python.framework.errors_impl.InternalError: Failed to create session.
2019-08-01 21:32:12.286340: E tensorflow/core/common_runtime/direct_session.cc:158] Internal: failed initializing StreamExecutor for CUDA device ordinal 0: Internal: failed call to cuDevicePrimaryCtxRetain: CUDA_ERROR_INVALID_DEVICE
/gpfs/pkgs/mhpcc/anaconda3-5.0.1/lib/python3.6/site-packages/h5py/__init__.py:34: FutureWarning: Conversion of the second argument of issubdtype from `float` to `np.floating` is deprecated. In future, it will be treated as `np.float64 == np.dtype(float).type`.
  from ._conv import register_converters as _register_converters
Using TensorFlow backend.
Traceback (most recent call last):
  File "roundOneSubmit.py", line 23, in <module>
    l.learnThingsCPP(kind=0, file=f, weightFile=wf)
  File "/gpfs/home/m201560/chipboard/learn.py", line 130, in learnThingsCPP
    weights = self.getWeightArray()
  File "/gpfs/home/m201560/chipboard/learn.py", line 193, in getWeightArray
    return self.model.get_weights()[0].tolist()
  File "/gpfs/home/m201560/.local/lib/python3.6/site-packages/keras/engine/network.py", line 492, in get_weights
    return K.batch_get_value(weights)
  File "/gpfs/home/m201560/.local/lib/python3.6/site-packages/keras/backend/tensorflow_backend.py", line 2420, in batch_get_value
    return get_session().run(ops)
  File "/gpfs/home/m201560/.local/lib/python3.6/site-packages/keras/backend/tensorflow_backend.py", line 186, in get_session
    _SESSION = tf.Session(config=config)
  File "/gpfs/pkgs/mhpcc/anaconda3-5.0.1/lib/python3.6/site-packages/tensorflow/python/client/session.py", line 1563, in __init__
    super(Session, self).__init__(target, graph, config=config)
  File "/gpfs/pkgs/mhpcc/anaconda3-5.0.1/lib/python3.6/site-packages/tensorflow/python/client/session.py", line 633, in __init__
    self._session = tf_session.TF_NewSession(self._graph._c_graph, opts)
tensorflow.python.framework.errors_impl.InternalError: Failed to create session.
2019-08-01 21:32:12.450244: E tensorflow/core/common_runtime/direct_session.cc:158] Internal: failed initializing StreamExecutor for CUDA device ordinal 0: Internal: failed call to cuDevicePrimaryCtxRetain: CUDA_ERROR_INVALID_DEVICE
/gpfs/pkgs/mhpcc/anaconda3-5.0.1/lib/python3.6/site-packages/h5py/__init__.py:34: FutureWarning: Conversion of the second argument of issubdtype from `float` to `np.floating` is deprecated. In future, it will be treated as `np.float64 == np.dtype(float).type`.
  from ._conv import register_converters as _register_converters
Using TensorFlow backend.
Traceback (most recent call last):
  File "roundOneSubmit.py", line 23, in <module>
    l.learnThingsCPP(kind=0, file=f, weightFile=wf)
  File "/gpfs/home/m201560/chipboard/learn.py", line 130, in learnThingsCPP
    weights = self.getWeightArray()
  File "/gpfs/home/m201560/chipboard/learn.py", line 193, in getWeightArray
    return self.model.get_weights()[0].tolist()
  File "/gpfs/home/m201560/.local/lib/python3.6/site-packages/keras/engine/network.py", line 492, in get_weights
    return K.batch_get_value(weights)
  File "/gpfs/home/m201560/.local/lib/python3.6/site-packages/keras/backend/tensorflow_backend.py", line 2420, in batch_get_value
    return get_session().run(ops)
  File "/gpfs/home/m201560/.local/lib/python3.6/site-packages/keras/backend/tensorflow_backend.py", line 186, in get_session
    _SESSION = tf.Session(config=config)
  File "/gpfs/pkgs/mhpcc/anaconda3-5.0.1/lib/python3.6/site-packages/tensorflow/python/client/session.py", line 1563, in __init__
    super(Session, self).__init__(target, graph, config=config)
  File "/gpfs/pkgs/mhpcc/anaconda3-5.0.1/lib/python3.6/site-packages/tensorflow/python/client/session.py", line 633, in __init__
    self._session = tf_session.TF_NewSession(self._graph._c_graph, opts)
tensorflow.python.framework.errors_impl.InternalError: Failed to create session.
2019-08-01 21:32:12.475536: E tensorflow/core/common_runtime/direct_session.cc:158] Internal: failed initializing StreamExecutor for CUDA device ordinal 0: Internal: failed call to cuDevicePrimaryCtxRetain: CUDA_ERROR_INVALID_DEVICE
/gpfs/pkgs/mhpcc/anaconda3-5.0.1/lib/python3.6/site-packages/h5py/__init__.py:34: FutureWarning: Conversion of the second argument of issubdtype from `float` to `np.floating` is deprecated. In future, it will be treated as `np.float64 == np.dtype(float).type`.
  from ._conv import register_converters as _register_converters
Using TensorFlow backend.
Traceback (most recent call last):
  File "roundOneSubmit.py", line 23, in <module>
    l.learnThingsCPP(kind=0, file=f, weightFile=wf)
  File "/gpfs/home/m201560/chipboard/learn.py", line 130, in learnThingsCPP
    weights = self.getWeightArray()
  File "/gpfs/home/m201560/chipboard/learn.py", line 193, in getWeightArray
    return self.model.get_weights()[0].tolist()
  File "/gpfs/home/m201560/.local/lib/python3.6/site-packages/keras/engine/network.py", line 492, in get_weights
    return K.batch_get_value(weights)
  File "/gpfs/home/m201560/.local/lib/python3.6/site-packages/keras/backend/tensorflow_backend.py", line 2420, in batch_get_value
    return get_session().run(ops)
  File "/gpfs/home/m201560/.local/lib/python3.6/site-packages/keras/backend/tensorflow_backend.py", line 186, in get_session
    _SESSION = tf.Session(config=config)
  File "/gpfs/pkgs/mhpcc/anaconda3-5.0.1/lib/python3.6/site-packages/tensorflow/python/client/session.py", line 1563, in __init__
    super(Session, self).__init__(target, graph, config=config)
  File "/gpfs/pkgs/mhpcc/anaconda3-5.0.1/lib/python3.6/site-packages/tensorflow/python/client/session.py", line 633, in __init__
    self._session = tf_session.TF_NewSession(self._graph._c_graph, opts)
tensorflow.python.framework.errors_impl.InternalError: Failed to create session.
2019-08-01 21:32:12.543949: E tensorflow/core/common_runtime/direct_session.cc:158] Internal: failed initializing StreamExecutor for CUDA device ordinal 0: Internal: failed call to cuDevicePrimaryCtxRetain: CUDA_ERROR_INVALID_DEVICE
/gpfs/pkgs/mhpcc/anaconda3-5.0.1/lib/python3.6/site-packages/h5py/__init__.py:34: FutureWarning: Conversion of the second argument of issubdtype from `float` to `np.floating` is deprecated. In future, it will be treated as `np.float64 == np.dtype(float).type`.
  from ._conv import register_converters as _register_converters
Using TensorFlow backend.
Traceback (most recent call last):
  File "roundOneSubmit.py", line 23, in <module>
    l.learnThingsCPP(kind=0, file=f, weightFile=wf)
  File "/gpfs/home/m201560/chipboard/learn.py", line 130, in learnThingsCPP
    weights = self.getWeightArray()
  File "/gpfs/home/m201560/chipboard/learn.py", line 193, in getWeightArray
    return self.model.get_weights()[0].tolist()
  File "/gpfs/home/m201560/.local/lib/python3.6/site-packages/keras/engine/network.py", line 492, in get_weights
    return K.batch_get_value(weights)
  File "/gpfs/home/m201560/.local/lib/python3.6/site-packages/keras/backend/tensorflow_backend.py", line 2420, in batch_get_value
    return get_session().run(ops)
  File "/gpfs/home/m201560/.local/lib/python3.6/site-packages/keras/backend/tensorflow_backend.py", line 186, in get_session
    _SESSION = tf.Session(config=config)
  File "/gpfs/pkgs/mhpcc/anaconda3-5.0.1/lib/python3.6/site-packages/tensorflow/python/client/session.py", line 1563, in __init__
    super(Session, self).__init__(target, graph, config=config)
  File "/gpfs/pkgs/mhpcc/anaconda3-5.0.1/lib/python3.6/site-packages/tensorflow/python/client/session.py", line 633, in __init__
    self._session = tf_session.TF_NewSession(self._graph._c_graph, opts)
tensorflow.python.framework.errors_impl.InternalError: Failed to create session.
2019-08-01 21:32:12.580384: E tensorflow/core/common_runtime/direct_session.cc:158] Internal: failed initializing StreamExecutor for CUDA device ordinal 0: Internal: failed call to cuDevicePrimaryCtxRetain: CUDA_ERROR_INVALID_DEVICE
/gpfs/pkgs/mhpcc/anaconda3-5.0.1/lib/python3.6/site-packages/h5py/__init__.py:34: FutureWarning: Conversion of the second argument of issubdtype from `float` to `np.floating` is deprecated. In future, it will be treated as `np.float64 == np.dtype(float).type`.
  from ._conv import register_converters as _register_converters
Using TensorFlow backend.
Traceback (most recent call last):
  File "roundOneSubmit.py", line 23, in <module>
    l.learnThingsCPP(kind=0, file=f, weightFile=wf)
  File "/gpfs/home/m201560/chipboard/learn.py", line 130, in learnThingsCPP
    weights = self.getWeightArray()
  File "/gpfs/home/m201560/chipboard/learn.py", line 193, in getWeightArray
    return self.model.get_weights()[0].tolist()
  File "/gpfs/home/m201560/.local/lib/python3.6/site-packages/keras/engine/network.py", line 492, in get_weights
    return K.batch_get_value(weights)
  File "/gpfs/home/m201560/.local/lib/python3.6/site-packages/keras/backend/tensorflow_backend.py", line 2420, in batch_get_value
    return get_session().run(ops)
  File "/gpfs/home/m201560/.local/lib/python3.6/site-packages/keras/backend/tensorflow_backend.py", line 186, in get_session
    _SESSION = tf.Session(config=config)
  File "/gpfs/pkgs/mhpcc/anaconda3-5.0.1/lib/python3.6/site-packages/tensorflow/python/client/session.py", line 1563, in __init__
    super(Session, self).__init__(target, graph, config=config)
  File "/gpfs/pkgs/mhpcc/anaconda3-5.0.1/lib/python3.6/site-packages/tensorflow/python/client/session.py", line 633, in __init__
    self._session = tf_session.TF_NewSession(self._graph._c_graph, opts)
tensorflow.python.framework.errors_impl.InternalError: Failed to create session.
2019-08-01 21:32:12.609555: E tensorflow/core/common_runtime/direct_session.cc:158] Internal: failed initializing StreamExecutor for CUDA device ordinal 0: Internal: failed call to cuDevicePrimaryCtxRetain: CUDA_ERROR_INVALID_DEVICE
/gpfs/pkgs/mhpcc/anaconda3-5.0.1/lib/python3.6/site-packages/h5py/__init__.py:34: FutureWarning: Conversion of the second argument of issubdtype from `float` to `np.floating` is deprecated. In future, it will be treated as `np.float64 == np.dtype(float).type`.
  from ._conv import register_converters as _register_converters
Using TensorFlow backend.
Traceback (most recent call last):
  File "roundOneSubmit.py", line 23, in <module>
    l.learnThingsCPP(kind=0, file=f, weightFile=wf)
  File "/gpfs/home/m201560/chipboard/learn.py", line 130, in learnThingsCPP
    weights = self.getWeightArray()
  File "/gpfs/home/m201560/chipboard/learn.py", line 193, in getWeightArray
    return self.model.get_weights()[0].tolist()
  File "/gpfs/home/m201560/.local/lib/python3.6/site-packages/keras/engine/network.py", line 492, in get_weights
    return K.batch_get_value(weights)
  File "/gpfs/home/m201560/.local/lib/python3.6/site-packages/keras/backend/tensorflow_backend.py", line 2420, in batch_get_value
    return get_session().run(ops)
  File "/gpfs/home/m201560/.local/lib/python3.6/site-packages/keras/backend/tensorflow_backend.py", line 186, in get_session
    _SESSION = tf.Session(config=config)
  File "/gpfs/pkgs/mhpcc/anaconda3-5.0.1/lib/python3.6/site-packages/tensorflow/python/client/session.py", line 1563, in __init__
    super(Session, self).__init__(target, graph, config=config)
  File "/gpfs/pkgs/mhpcc/anaconda3-5.0.1/lib/python3.6/site-packages/tensorflow/python/client/session.py", line 633, in __init__
    self._session = tf_session.TF_NewSession(self._graph._c_graph, opts)
tensorflow.python.framework.errors_impl.InternalError: Failed to create session.
2019-08-01 21:32:12.648144: E tensorflow/core/common_runtime/direct_session.cc:158] Internal: failed initializing StreamExecutor for CUDA device ordinal 0: Internal: failed call to cuDevicePrimaryCtxRetain: CUDA_ERROR_INVALID_DEVICE
/gpfs/pkgs/mhpcc/anaconda3-5.0.1/lib/python3.6/site-packages/h5py/__init__.py:34: FutureWarning: Conversion of the second argument of issubdtype from `float` to `np.floating` is deprecated. In future, it will be treated as `np.float64 == np.dtype(float).type`.
  from ._conv import register_converters as _register_converters
Using TensorFlow backend.
Traceback (most recent call last):
  File "roundOneSubmit.py", line 23, in <module>
    l.learnThingsCPP(kind=0, file=f, weightFile=wf)
  File "/gpfs/home/m201560/chipboard/learn.py", line 130, in learnThingsCPP
    weights = self.getWeightArray()
  File "/gpfs/home/m201560/chipboard/learn.py", line 193, in getWeightArray
    return self.model.get_weights()[0].tolist()
  File "/gpfs/home/m201560/.local/lib/python3.6/site-packages/keras/engine/network.py", line 492, in get_weights
    return K.batch_get_value(weights)
  File "/gpfs/home/m201560/.local/lib/python3.6/site-packages/keras/backend/tensorflow_backend.py", line 2420, in batch_get_value
    return get_session().run(ops)
  File "/gpfs/home/m201560/.local/lib/python3.6/site-packages/keras/backend/tensorflow_backend.py", line 186, in get_session
    _SESSION = tf.Session(config=config)
  File "/gpfs/pkgs/mhpcc/anaconda3-5.0.1/lib/python3.6/site-packages/tensorflow/python/client/session.py", line 1563, in __init__
    super(Session, self).__init__(target, graph, config=config)
  File "/gpfs/pkgs/mhpcc/anaconda3-5.0.1/lib/python3.6/site-packages/tensorflow/python/client/session.py", line 633, in __init__
    self._session = tf_session.TF_NewSession(self._graph._c_graph, opts)
tensorflow.python.framework.errors_impl.InternalError: Failed to create session.
2019-08-01 21:32:12.658167: E tensorflow/core/common_runtime/direct_session.cc:158] Internal: failed initializing StreamExecutor for CUDA device ordinal 0: Internal: failed call to cuDevicePrimaryCtxRetain: CUDA_ERROR_INVALID_DEVICE
/gpfs/pkgs/mhpcc/anaconda3-5.0.1/lib/python3.6/site-packages/h5py/__init__.py:34: FutureWarning: Conversion of the second argument of issubdtype from `float` to `np.floating` is deprecated. In future, it will be treated as `np.float64 == np.dtype(float).type`.
  from ._conv import register_converters as _register_converters
Using TensorFlow backend.
2019-08-01 21:32:12.659966: E tensorflow/core/common_runtime/direct_session.cc:158] Internal: failed initializing StreamExecutor for CUDA device ordinal 0: Internal: failed call to cuDevicePrimaryCtxRetain: CUDA_ERROR_INVALID_DEVICE
/gpfs/pkgs/mhpcc/anaconda3-5.0.1/lib/python3.6/site-packages/h5py/__init__.py:34: FutureWarning: Conversion of the second argument of issubdtype from `float` to `np.floating` is deprecated. In future, it will be treated as `np.float64 == np.dtype(float).type`.
  from ._conv import register_converters as _register_converters
Using TensorFlow backend.
Traceback (most recent call last):
  File "roundOneSubmit.py", line 23, in <module>
    l.learnThingsCPP(kind=0, file=f, weightFile=wf)
  File "/gpfs/home/m201560/chipboard/learn.py", line 130, in learnThingsCPP
    weights = self.getWeightArray()
  File "/gpfs/home/m201560/chipboard/learn.py", line 193, in getWeightArray
    return self.model.get_weights()[0].tolist()
  File "/gpfs/home/m201560/.local/lib/python3.6/site-packages/keras/engine/network.py", line 492, in get_weights
    return K.batch_get_value(weights)
  File "/gpfs/home/m201560/.local/lib/python3.6/site-packages/keras/backend/tensorflow_backend.py", line 2420, in batch_get_value
    return get_session().run(ops)
  File "/gpfs/home/m201560/.local/lib/python3.6/site-packages/keras/backend/tensorflow_backend.py", line 186, in get_session
    _SESSION = tf.Session(config=config)
  File "/gpfs/pkgs/mhpcc/anaconda3-5.0.1/lib/python3.6/site-packages/tensorflow/python/client/session.py", line 1563, in __init__
    super(Session, self).__init__(target, graph, config=config)
  File "/gpfs/pkgs/mhpcc/anaconda3-5.0.1/lib/python3.6/site-packages/tensorflow/python/client/session.py", line 633, in __init__
    self._session = tf_session.TF_NewSession(self._graph._c_graph, opts)
tensorflow.python.framework.errors_impl.InternalError: Failed to create session.
Traceback (most recent call last):
  File "roundOneSubmit.py", line 23, in <module>
    l.learnThingsCPP(kind=0, file=f, weightFile=wf)
  File "/gpfs/home/m201560/chipboard/learn.py", line 130, in learnThingsCPP
    weights = self.getWeightArray()
  File "/gpfs/home/m201560/chipboard/learn.py", line 193, in getWeightArray
    return self.model.get_weights()[0].tolist()
  File "/gpfs/home/m201560/.local/lib/python3.6/site-packages/keras/engine/network.py", line 492, in get_weights
    return K.batch_get_value(weights)
  File "/gpfs/home/m201560/.local/lib/python3.6/site-packages/keras/backend/tensorflow_backend.py", line 2420, in batch_get_value
    return get_session().run(ops)
  File "/gpfs/home/m201560/.local/lib/python3.6/site-packages/keras/backend/tensorflow_backend.py", line 186, in get_session
    _SESSION = tf.Session(config=config)
  File "/gpfs/pkgs/mhpcc/anaconda3-5.0.1/lib/python3.6/site-packages/tensorflow/python/client/session.py", line 1563, in __init__
    super(Session, self).__init__(target, graph, config=config)
  File "/gpfs/pkgs/mhpcc/anaconda3-5.0.1/lib/python3.6/site-packages/tensorflow/python/client/session.py", line 633, in __init__
    self._session = tf_session.TF_NewSession(self._graph._c_graph, opts)
tensorflow.python.framework.errors_impl.InternalError: Failed to create session.
2019-08-01 21:32:12.674828: E tensorflow/core/common_runtime/direct_session.cc:158] Internal: failed initializing StreamExecutor for CUDA device ordinal 0: Internal: failed call to cuDevicePrimaryCtxRetain: CUDA_ERROR_INVALID_DEVICE
/gpfs/pkgs/mhpcc/anaconda3-5.0.1/lib/python3.6/site-packages/h5py/__init__.py:34: FutureWarning: Conversion of the second argument of issubdtype from `float` to `np.floating` is deprecated. In future, it will be treated as `np.float64 == np.dtype(float).type`.
  from ._conv import register_converters as _register_converters
Using TensorFlow backend.
2019-08-01 21:32:12.682818: E tensorflow/core/common_runtime/direct_session.cc:158] Internal: failed initializing StreamExecutor for CUDA device ordinal 0: Internal: failed call to cuDevicePrimaryCtxRetain: CUDA_ERROR_INVALID_DEVICE
/gpfs/pkgs/mhpcc/anaconda3-5.0.1/lib/python3.6/site-packages/h5py/__init__.py:34: FutureWarning: Conversion of the second argument of issubdtype from `float` to `np.floating` is deprecated. In future, it will be treated as `np.float64 == np.dtype(float).type`.
  from ._conv import register_converters as _register_converters
Using TensorFlow backend.
Traceback (most recent call last):
  File "roundOneSubmit.py", line 23, in <module>
    l.learnThingsCPP(kind=0, file=f, weightFile=wf)
  File "/gpfs/home/m201560/chipboard/learn.py", line 130, in learnThingsCPP
    weights = self.getWeightArray()
  File "/gpfs/home/m201560/chipboard/learn.py", line 193, in getWeightArray
    return self.model.get_weights()[0].tolist()
  File "/gpfs/home/m201560/.local/lib/python3.6/site-packages/keras/engine/network.py", line 492, in get_weights
    return K.batch_get_value(weights)
  File "/gpfs/home/m201560/.local/lib/python3.6/site-packages/keras/backend/tensorflow_backend.py", line 2420, in batch_get_value
    return get_session().run(ops)
  File "/gpfs/home/m201560/.local/lib/python3.6/site-packages/keras/backend/tensorflow_backend.py", line 186, in get_session
    _SESSION = tf.Session(config=config)
  File "/gpfs/pkgs/mhpcc/anaconda3-5.0.1/lib/python3.6/site-packages/tensorflow/python/client/session.py", line 1563, in __init__
    super(Session, self).__init__(target, graph, config=config)
  File "/gpfs/pkgs/mhpcc/anaconda3-5.0.1/lib/python3.6/site-packages/tensorflow/python/client/session.py", line 633, in __init__
    self._session = tf_session.TF_NewSession(self._graph._c_graph, opts)
tensorflow.python.framework.errors_impl.InternalError: Failed to create session.
Traceback (most recent call last):
  File "roundOneSubmit.py", line 23, in <module>
    l.learnThingsCPP(kind=0, file=f, weightFile=wf)
  File "/gpfs/home/m201560/chipboard/learn.py", line 130, in learnThingsCPP
    weights = self.getWeightArray()
  File "/gpfs/home/m201560/chipboard/learn.py", line 193, in getWeightArray
    return self.model.get_weights()[0].tolist()
  File "/gpfs/home/m201560/.local/lib/python3.6/site-packages/keras/engine/network.py", line 492, in get_weights
    return K.batch_get_value(weights)
  File "/gpfs/home/m201560/.local/lib/python3.6/site-packages/keras/backend/tensorflow_backend.py", line 2420, in batch_get_value
    return get_session().run(ops)
  File "/gpfs/home/m201560/.local/lib/python3.6/site-packages/keras/backend/tensorflow_backend.py", line 186, in get_session
    _SESSION = tf.Session(config=config)
  File "/gpfs/pkgs/mhpcc/anaconda3-5.0.1/lib/python3.6/site-packages/tensorflow/python/client/session.py", line 1563, in __init__
    super(Session, self).__init__(target, graph, config=config)
  File "/gpfs/pkgs/mhpcc/anaconda3-5.0.1/lib/python3.6/site-packages/tensorflow/python/client/session.py", line 633, in __init__
    self._session = tf_session.TF_NewSession(self._graph._c_graph, opts)
tensorflow.python.framework.errors_impl.InternalError: Failed to create session.
2019-08-01 21:32:12.691252: E tensorflow/core/common_runtime/direct_session.cc:158] Internal: failed initializing StreamExecutor for CUDA device ordinal 0: Internal: failed call to cuDevicePrimaryCtxRetain: CUDA_ERROR_INVALID_DEVICE
/gpfs/pkgs/mhpcc/anaconda3-5.0.1/lib/python3.6/site-packages/h5py/__init__.py:34: FutureWarning: Conversion of the second argument of issubdtype from `float` to `np.floating` is deprecated. In future, it will be treated as `np.float64 == np.dtype(float).type`.
  from ._conv import register_converters as _register_converters
Using TensorFlow backend.
2019-08-01 21:32:12.697599: E tensorflow/core/common_runtime/direct_session.cc:158] Internal: failed initializing StreamExecutor for CUDA device ordinal 0: Internal: failed call to cuDevicePrimaryCtxRetain: CUDA_ERROR_INVALID_DEVICE
/gpfs/pkgs/mhpcc/anaconda3-5.0.1/lib/python3.6/site-packages/h5py/__init__.py:34: FutureWarning: Conversion of the second argument of issubdtype from `float` to `np.floating` is deprecated. In future, it will be treated as `np.float64 == np.dtype(float).type`.
  from ._conv import register_converters as _register_converters
Using TensorFlow backend.
Traceback (most recent call last):
  File "roundOneSubmit.py", line 23, in <module>
    l.learnThingsCPP(kind=0, file=f, weightFile=wf)
  File "/gpfs/home/m201560/chipboard/learn.py", line 130, in learnThingsCPP
    weights = self.getWeightArray()
  File "/gpfs/home/m201560/chipboard/learn.py", line 193, in getWeightArray
    return self.model.get_weights()[0].tolist()
  File "/gpfs/home/m201560/.local/lib/python3.6/site-packages/keras/engine/network.py", line 492, in get_weights
    return K.batch_get_value(weights)
  File "/gpfs/home/m201560/.local/lib/python3.6/site-packages/keras/backend/tensorflow_backend.py", line 2420, in batch_get_value
    return get_session().run(ops)
  File "/gpfs/home/m201560/.local/lib/python3.6/site-packages/keras/backend/tensorflow_backend.py", line 186, in get_session
    _SESSION = tf.Session(config=config)
  File "/gpfs/pkgs/mhpcc/anaconda3-5.0.1/lib/python3.6/site-packages/tensorflow/python/client/session.py", line 1563, in __init__
    super(Session, self).__init__(target, graph, config=config)
  File "/gpfs/pkgs/mhpcc/anaconda3-5.0.1/lib/python3.6/site-packages/tensorflow/python/client/session.py", line 633, in __init__
    self._session = tf_session.TF_NewSession(self._graph._c_graph, opts)
tensorflow.python.framework.errors_impl.InternalError: Failed to create session.
Traceback (most recent call last):
  File "roundOneSubmit.py", line 23, in <module>
    l.learnThingsCPP(kind=0, file=f, weightFile=wf)
  File "/gpfs/home/m201560/chipboard/learn.py", line 130, in learnThingsCPP
    weights = self.getWeightArray()
  File "/gpfs/home/m201560/chipboard/learn.py", line 193, in getWeightArray
    return self.model.get_weights()[0].tolist()
  File "/gpfs/home/m201560/.local/lib/python3.6/site-packages/keras/engine/network.py", line 492, in get_weights
    return K.batch_get_value(weights)
  File "/gpfs/home/m201560/.local/lib/python3.6/site-packages/keras/backend/tensorflow_backend.py", line 2420, in batch_get_value
    return get_session().run(ops)
  File "/gpfs/home/m201560/.local/lib/python3.6/site-packages/keras/backend/tensorflow_backend.py", line 186, in get_session
    _SESSION = tf.Session(config=config)
  File "/gpfs/pkgs/mhpcc/anaconda3-5.0.1/lib/python3.6/site-packages/tensorflow/python/client/session.py", line 1563, in __init__
    super(Session, self).__init__(target, graph, config=config)
  File "/gpfs/pkgs/mhpcc/anaconda3-5.0.1/lib/python3.6/site-packages/tensorflow/python/client/session.py", line 633, in __init__
    self._session = tf_session.TF_NewSession(self._graph._c_graph, opts)
tensorflow.python.framework.errors_impl.InternalError: Failed to create session.
2019-08-01 21:32:12.707368: E tensorflow/core/common_runtime/direct_session.cc:158] Internal: failed initializing StreamExecutor for CUDA device ordinal 0: Internal: failed call to cuDevicePrimaryCtxRetain: CUDA_ERROR_INVALID_DEVICE
/gpfs/pkgs/mhpcc/anaconda3-5.0.1/lib/python3.6/site-packages/h5py/__init__.py:34: FutureWarning: Conversion of the second argument of issubdtype from `float` to `np.floating` is deprecated. In future, it will be treated as `np.float64 == np.dtype(float).type`.
  from ._conv import register_converters as _register_converters
Using TensorFlow backend.
2019-08-01 21:32:12.714766: E tensorflow/core/common_runtime/direct_session.cc:158] Internal: failed initializing StreamExecutor for CUDA device ordinal 0: Internal: failed call to cuDevicePrimaryCtxRetain: CUDA_ERROR_INVALID_DEVICE
/gpfs/pkgs/mhpcc/anaconda3-5.0.1/lib/python3.6/site-packages/h5py/__init__.py:34: FutureWarning: Conversion of the second argument of issubdtype from `float` to `np.floating` is deprecated. In future, it will be treated as `np.float64 == np.dtype(float).type`.
  from ._conv import register_converters as _register_converters
Using TensorFlow backend.
Traceback (most recent call last):
  File "roundOneSubmit.py", line 23, in <module>
    l.learnThingsCPP(kind=0, file=f, weightFile=wf)
  File "/gpfs/home/m201560/chipboard/learn.py", line 130, in learnThingsCPP
    weights = self.getWeightArray()
  File "/gpfs/home/m201560/chipboard/learn.py", line 193, in getWeightArray
    return self.model.get_weights()[0].tolist()
  File "/gpfs/home/m201560/.local/lib/python3.6/site-packages/keras/engine/network.py", line 492, in get_weights
    return K.batch_get_value(weights)
  File "/gpfs/home/m201560/.local/lib/python3.6/site-packages/keras/backend/tensorflow_backend.py", line 2420, in batch_get_value
    return get_session().run(ops)
  File "/gpfs/home/m201560/.local/lib/python3.6/site-packages/keras/backend/tensorflow_backend.py", line 186, in get_session
    _SESSION = tf.Session(config=config)
  File "/gpfs/pkgs/mhpcc/anaconda3-5.0.1/lib/python3.6/site-packages/tensorflow/python/client/session.py", line 1563, in __init__
    super(Session, self).__init__(target, graph, config=config)
  File "/gpfs/pkgs/mhpcc/anaconda3-5.0.1/lib/python3.6/site-packages/tensorflow/python/client/session.py", line 633, in __init__
    self._session = tf_session.TF_NewSession(self._graph._c_graph, opts)
tensorflow.python.framework.errors_impl.InternalError: Failed to create session.
Traceback (most recent call last):
  File "roundOneSubmit.py", line 23, in <module>
    l.learnThingsCPP(kind=0, file=f, weightFile=wf)
  File "/gpfs/home/m201560/chipboard/learn.py", line 130, in learnThingsCPP
    weights = self.getWeightArray()
  File "/gpfs/home/m201560/chipboard/learn.py", line 193, in getWeightArray
    return self.model.get_weights()[0].tolist()
  File "/gpfs/home/m201560/.local/lib/python3.6/site-packages/keras/engine/network.py", line 492, in get_weights
    return K.batch_get_value(weights)
  File "/gpfs/home/m201560/.local/lib/python3.6/site-packages/keras/backend/tensorflow_backend.py", line 2420, in batch_get_value
    return get_session().run(ops)
  File "/gpfs/home/m201560/.local/lib/python3.6/site-packages/keras/backend/tensorflow_backend.py", line 186, in get_session
    _SESSION = tf.Session(config=config)
  File "/gpfs/pkgs/mhpcc/anaconda3-5.0.1/lib/python3.6/site-packages/tensorflow/python/client/session.py", line 1563, in __init__
    super(Session, self).__init__(target, graph, config=config)
  File "/gpfs/pkgs/mhpcc/anaconda3-5.0.1/lib/python3.6/site-packages/tensorflow/python/client/session.py", line 633, in __init__
    self._session = tf_session.TF_NewSession(self._graph._c_graph, opts)
tensorflow.python.framework.errors_impl.InternalError: Failed to create session.
2019-08-01 21:32:12.723918: E tensorflow/core/common_runtime/direct_session.cc:158] Internal: failed initializing StreamExecutor for CUDA device ordinal 0: Internal: failed call to cuDevicePrimaryCtxRetain: CUDA_ERROR_INVALID_DEVICE
/gpfs/pkgs/mhpcc/anaconda3-5.0.1/lib/python3.6/site-packages/h5py/__init__.py:34: FutureWarning: Conversion of the second argument of issubdtype from `float` to `np.floating` is deprecated. In future, it will be treated as `np.float64 == np.dtype(float).type`.
  from ._conv import register_converters as _register_converters
Using TensorFlow backend.
Traceback (most recent call last):
  File "roundOneSubmit.py", line 23, in <module>
    l.learnThingsCPP(kind=0, file=f, weightFile=wf)
  File "/gpfs/home/m201560/chipboard/learn.py", line 130, in learnThingsCPP
    weights = self.getWeightArray()
  File "/gpfs/home/m201560/chipboard/learn.py", line 193, in getWeightArray
    return self.model.get_weights()[0].tolist()
  File "/gpfs/home/m201560/.local/lib/python3.6/site-packages/keras/engine/network.py", line 492, in get_weights
    return K.batch_get_value(weights)
  File "/gpfs/home/m201560/.local/lib/python3.6/site-packages/keras/backend/tensorflow_backend.py", line 2420, in batch_get_value
    return get_session().run(ops)
  File "/gpfs/home/m201560/.local/lib/python3.6/site-packages/keras/backend/tensorflow_backend.py", line 186, in get_session
    _SESSION = tf.Session(config=config)
  File "/gpfs/pkgs/mhpcc/anaconda3-5.0.1/lib/python3.6/site-packages/tensorflow/python/client/session.py", line 1563, in __init__
    super(Session, self).__init__(target, graph, config=config)
  File "/gpfs/pkgs/mhpcc/anaconda3-5.0.1/lib/python3.6/site-packages/tensorflow/python/client/session.py", line 633, in __init__
    self._session = tf_session.TF_NewSession(self._graph._c_graph, opts)
tensorflow.python.framework.errors_impl.InternalError: Failed to create session.
2019-08-01 21:32:12.731221: E tensorflow/core/common_runtime/direct_session.cc:158] Internal: failed initializing StreamExecutor for CUDA device ordinal 0: Internal: failed call to cuDevicePrimaryCtxRetain: CUDA_ERROR_INVALID_DEVICE
/gpfs/pkgs/mhpcc/anaconda3-5.0.1/lib/python3.6/site-packages/h5py/__init__.py:34: FutureWarning: Conversion of the second argument of issubdtype from `float` to `np.floating` is deprecated. In future, it will be treated as `np.float64 == np.dtype(float).type`.
  from ._conv import register_converters as _register_converters
Using TensorFlow backend.
Traceback (most recent call last):
  File "roundOneSubmit.py", line 23, in <module>
    l.learnThingsCPP(kind=0, file=f, weightFile=wf)
  File "/gpfs/home/m201560/chipboard/learn.py", line 130, in learnThingsCPP
    weights = self.getWeightArray()
  File "/gpfs/home/m201560/chipboard/learn.py", line 193, in getWeightArray
    return self.model.get_weights()[0].tolist()
  File "/gpfs/home/m201560/.local/lib/python3.6/site-packages/keras/engine/network.py", line 492, in get_weights
    return K.batch_get_value(weights)
  File "/gpfs/home/m201560/.local/lib/python3.6/site-packages/keras/backend/tensorflow_backend.py", line 2420, in batch_get_value
    return get_session().run(ops)
  File "/gpfs/home/m201560/.local/lib/python3.6/site-packages/keras/backend/tensorflow_backend.py", line 186, in get_session
    _SESSION = tf.Session(config=config)
  File "/gpfs/pkgs/mhpcc/anaconda3-5.0.1/lib/python3.6/site-packages/tensorflow/python/client/session.py", line 1563, in __init__
    super(Session, self).__init__(target, graph, config=config)
  File "/gpfs/pkgs/mhpcc/anaconda3-5.0.1/lib/python3.6/site-packages/tensorflow/python/client/session.py", line 633, in __init__
    self._session = tf_session.TF_NewSession(self._graph._c_graph, opts)
tensorflow.python.framework.errors_impl.InternalError: Failed to create session.
2019-08-01 21:32:12.819679: E tensorflow/core/common_runtime/direct_session.cc:158] Internal: failed initializing StreamExecutor for CUDA device ordinal 0: Internal: failed call to cuDevicePrimaryCtxRetain: CUDA_ERROR_INVALID_DEVICE
/gpfs/pkgs/mhpcc/anaconda3-5.0.1/lib/python3.6/site-packages/h5py/__init__.py:34: FutureWarning: Conversion of the second argument of issubdtype from `float` to `np.floating` is deprecated. In future, it will be treated as `np.float64 == np.dtype(float).type`.
  from ._conv import register_converters as _register_converters
Using TensorFlow backend.
Traceback (most recent call last):
  File "roundOneSubmit.py", line 23, in <module>
    l.learnThingsCPP(kind=0, file=f, weightFile=wf)
  File "/gpfs/home/m201560/chipboard/learn.py", line 130, in learnThingsCPP
    weights = self.getWeightArray()
  File "/gpfs/home/m201560/chipboard/learn.py", line 193, in getWeightArray
    return self.model.get_weights()[0].tolist()
  File "/gpfs/home/m201560/.local/lib/python3.6/site-packages/keras/engine/network.py", line 492, in get_weights
    return K.batch_get_value(weights)
  File "/gpfs/home/m201560/.local/lib/python3.6/site-packages/keras/backend/tensorflow_backend.py", line 2420, in batch_get_value
    return get_session().run(ops)
  File "/gpfs/home/m201560/.local/lib/python3.6/site-packages/keras/backend/tensorflow_backend.py", line 186, in get_session
    _SESSION = tf.Session(config=config)
  File "/gpfs/pkgs/mhpcc/anaconda3-5.0.1/lib/python3.6/site-packages/tensorflow/python/client/session.py", line 1563, in __init__
    super(Session, self).__init__(target, graph, config=config)
  File "/gpfs/pkgs/mhpcc/anaconda3-5.0.1/lib/python3.6/site-packages/tensorflow/python/client/session.py", line 633, in __init__
    self._session = tf_session.TF_NewSession(self._graph._c_graph, opts)
tensorflow.python.framework.errors_impl.InternalError: Failed to create session.
2019-08-01 21:32:12.861149: E tensorflow/core/common_runtime/direct_session.cc:158] Internal: failed initializing StreamExecutor for CUDA device ordinal 0: Internal: failed call to cuDevicePrimaryCtxRetain: CUDA_ERROR_INVALID_DEVICE
/gpfs/pkgs/mhpcc/anaconda3-5.0.1/lib/python3.6/site-packages/h5py/__init__.py:34: FutureWarning: Conversion of the second argument of issubdtype from `float` to `np.floating` is deprecated. In future, it will be treated as `np.float64 == np.dtype(float).type`.
  from ._conv import register_converters as _register_converters
Using TensorFlow backend.
Traceback (most recent call last):
  File "roundOneSubmit.py", line 23, in <module>
    l.learnThingsCPP(kind=0, file=f, weightFile=wf)
  File "/gpfs/home/m201560/chipboard/learn.py", line 130, in learnThingsCPP
    weights = self.getWeightArray()
  File "/gpfs/home/m201560/chipboard/learn.py", line 193, in getWeightArray
    return self.model.get_weights()[0].tolist()
  File "/gpfs/home/m201560/.local/lib/python3.6/site-packages/keras/engine/network.py", line 492, in get_weights
    return K.batch_get_value(weights)
  File "/gpfs/home/m201560/.local/lib/python3.6/site-packages/keras/backend/tensorflow_backend.py", line 2420, in batch_get_value
    return get_session().run(ops)
  File "/gpfs/home/m201560/.local/lib/python3.6/site-packages/keras/backend/tensorflow_backend.py", line 186, in get_session
    _SESSION = tf.Session(config=config)
  File "/gpfs/pkgs/mhpcc/anaconda3-5.0.1/lib/python3.6/site-packages/tensorflow/python/client/session.py", line 1563, in __init__
    super(Session, self).__init__(target, graph, config=config)
  File "/gpfs/pkgs/mhpcc/anaconda3-5.0.1/lib/python3.6/site-packages/tensorflow/python/client/session.py", line 633, in __init__
    self._session = tf_session.TF_NewSession(self._graph._c_graph, opts)
tensorflow.python.framework.errors_impl.InternalError: Failed to create session.
2019-08-01 21:32:12.880643: E tensorflow/core/common_runtime/direct_session.cc:158] Internal: failed initializing StreamExecutor for CUDA device ordinal 0: Internal: failed call to cuDevicePrimaryCtxRetain: CUDA_ERROR_INVALID_DEVICE
/gpfs/pkgs/mhpcc/anaconda3-5.0.1/lib/python3.6/site-packages/h5py/__init__.py:34: FutureWarning: Conversion of the second argument of issubdtype from `float` to `np.floating` is deprecated. In future, it will be treated as `np.float64 == np.dtype(float).type`.
  from ._conv import register_converters as _register_converters
Using TensorFlow backend.
Traceback (most recent call last):
  File "roundOneSubmit.py", line 23, in <module>
    l.learnThingsCPP(kind=0, file=f, weightFile=wf)
  File "/gpfs/home/m201560/chipboard/learn.py", line 130, in learnThingsCPP
    weights = self.getWeightArray()
  File "/gpfs/home/m201560/chipboard/learn.py", line 193, in getWeightArray
    return self.model.get_weights()[0].tolist()
  File "/gpfs/home/m201560/.local/lib/python3.6/site-packages/keras/engine/network.py", line 492, in get_weights
    return K.batch_get_value(weights)
  File "/gpfs/home/m201560/.local/lib/python3.6/site-packages/keras/backend/tensorflow_backend.py", line 2420, in batch_get_value
    return get_session().run(ops)
  File "/gpfs/home/m201560/.local/lib/python3.6/site-packages/keras/backend/tensorflow_backend.py", line 186, in get_session
    _SESSION = tf.Session(config=config)
  File "/gpfs/pkgs/mhpcc/anaconda3-5.0.1/lib/python3.6/site-packages/tensorflow/python/client/session.py", line 1563, in __init__
    super(Session, self).__init__(target, graph, config=config)
  File "/gpfs/pkgs/mhpcc/anaconda3-5.0.1/lib/python3.6/site-packages/tensorflow/python/client/session.py", line 633, in __init__
    self._session = tf_session.TF_NewSession(self._graph._c_graph, opts)
tensorflow.python.framework.errors_impl.InternalError: Failed to create session.
2019-08-01 21:32:12.889535: E tensorflow/core/common_runtime/direct_session.cc:158] Internal: failed initializing StreamExecutor for CUDA device ordinal 0: Internal: failed call to cuDevicePrimaryCtxRetain: CUDA_ERROR_INVALID_DEVICE
/gpfs/pkgs/mhpcc/anaconda3-5.0.1/lib/python3.6/site-packages/h5py/__init__.py:34: FutureWarning: Conversion of the second argument of issubdtype from `float` to `np.floating` is deprecated. In future, it will be treated as `np.float64 == np.dtype(float).type`.
  from ._conv import register_converters as _register_converters
Using TensorFlow backend.
Traceback (most recent call last):
  File "roundOneSubmit.py", line 23, in <module>
    l.learnThingsCPP(kind=0, file=f, weightFile=wf)
  File "/gpfs/home/m201560/chipboard/learn.py", line 130, in learnThingsCPP
    weights = self.getWeightArray()
  File "/gpfs/home/m201560/chipboard/learn.py", line 193, in getWeightArray
    return self.model.get_weights()[0].tolist()
  File "/gpfs/home/m201560/.local/lib/python3.6/site-packages/keras/engine/network.py", line 492, in get_weights
    return K.batch_get_value(weights)
  File "/gpfs/home/m201560/.local/lib/python3.6/site-packages/keras/backend/tensorflow_backend.py", line 2420, in batch_get_value
    return get_session().run(ops)
  File "/gpfs/home/m201560/.local/lib/python3.6/site-packages/keras/backend/tensorflow_backend.py", line 186, in get_session
    _SESSION = tf.Session(config=config)
  File "/gpfs/pkgs/mhpcc/anaconda3-5.0.1/lib/python3.6/site-packages/tensorflow/python/client/session.py", line 1563, in __init__
    super(Session, self).__init__(target, graph, config=config)
  File "/gpfs/pkgs/mhpcc/anaconda3-5.0.1/lib/python3.6/site-packages/tensorflow/python/client/session.py", line 633, in __init__
    self._session = tf_session.TF_NewSession(self._graph._c_graph, opts)
tensorflow.python.framework.errors_impl.InternalError: Failed to create session.
2019-08-01 21:32:12.922189: E tensorflow/core/common_runtime/direct_session.cc:158] Internal: failed initializing StreamExecutor for CUDA device ordinal 0: Internal: failed call to cuDevicePrimaryCtxRetain: CUDA_ERROR_INVALID_DEVICE
/gpfs/pkgs/mhpcc/anaconda3-5.0.1/lib/python3.6/site-packages/h5py/__init__.py:34: FutureWarning: Conversion of the second argument of issubdtype from `float` to `np.floating` is deprecated. In future, it will be treated as `np.float64 == np.dtype(float).type`.
  from ._conv import register_converters as _register_converters
Using TensorFlow backend.
Traceback (most recent call last):
  File "roundOneSubmit.py", line 23, in <module>
    l.learnThingsCPP(kind=0, file=f, weightFile=wf)
  File "/gpfs/home/m201560/chipboard/learn.py", line 130, in learnThingsCPP
    weights = self.getWeightArray()
  File "/gpfs/home/m201560/chipboard/learn.py", line 193, in getWeightArray
    return self.model.get_weights()[0].tolist()
  File "/gpfs/home/m201560/.local/lib/python3.6/site-packages/keras/engine/network.py", line 492, in get_weights
    return K.batch_get_value(weights)
  File "/gpfs/home/m201560/.local/lib/python3.6/site-packages/keras/backend/tensorflow_backend.py", line 2420, in batch_get_value
    return get_session().run(ops)
  File "/gpfs/home/m201560/.local/lib/python3.6/site-packages/keras/backend/tensorflow_backend.py", line 186, in get_session
    _SESSION = tf.Session(config=config)
  File "/gpfs/pkgs/mhpcc/anaconda3-5.0.1/lib/python3.6/site-packages/tensorflow/python/client/session.py", line 1563, in __init__
    super(Session, self).__init__(target, graph, config=config)
  File "/gpfs/pkgs/mhpcc/anaconda3-5.0.1/lib/python3.6/site-packages/tensorflow/python/client/session.py", line 633, in __init__
    self._session = tf_session.TF_NewSession(self._graph._c_graph, opts)
tensorflow.python.framework.errors_impl.InternalError: Failed to create session.
2019-08-01 21:32:12.939918: E tensorflow/core/common_runtime/direct_session.cc:158] Internal: failed initializing StreamExecutor for CUDA device ordinal 0: Internal: failed call to cuDevicePrimaryCtxRetain: CUDA_ERROR_INVALID_DEVICE
/gpfs/pkgs/mhpcc/anaconda3-5.0.1/lib/python3.6/site-packages/h5py/__init__.py:34: FutureWarning: Conversion of the second argument of issubdtype from `float` to `np.floating` is deprecated. In future, it will be treated as `np.float64 == np.dtype(float).type`.
  from ._conv import register_converters as _register_converters
Using TensorFlow backend.
Traceback (most recent call last):
  File "roundOneSubmit.py", line 23, in <module>
    l.learnThingsCPP(kind=0, file=f, weightFile=wf)
  File "/gpfs/home/m201560/chipboard/learn.py", line 130, in learnThingsCPP
    weights = self.getWeightArray()
  File "/gpfs/home/m201560/chipboard/learn.py", line 193, in getWeightArray
    return self.model.get_weights()[0].tolist()
  File "/gpfs/home/m201560/.local/lib/python3.6/site-packages/keras/engine/network.py", line 492, in get_weights
    return K.batch_get_value(weights)
  File "/gpfs/home/m201560/.local/lib/python3.6/site-packages/keras/backend/tensorflow_backend.py", line 2420, in batch_get_value
    return get_session().run(ops)
  File "/gpfs/home/m201560/.local/lib/python3.6/site-packages/keras/backend/tensorflow_backend.py", line 186, in get_session
    _SESSION = tf.Session(config=config)
  File "/gpfs/pkgs/mhpcc/anaconda3-5.0.1/lib/python3.6/site-packages/tensorflow/python/client/session.py", line 1563, in __init__
    super(Session, self).__init__(target, graph, config=config)
  File "/gpfs/pkgs/mhpcc/anaconda3-5.0.1/lib/python3.6/site-packages/tensorflow/python/client/session.py", line 633, in __init__
    self._session = tf_session.TF_NewSession(self._graph._c_graph, opts)
tensorflow.python.framework.errors_impl.InternalError: Failed to create session.
2019-08-01 21:32:12.959929: E tensorflow/core/common_runtime/direct_session.cc:158] Internal: failed initializing StreamExecutor for CUDA device ordinal 0: Internal: failed call to cuDevicePrimaryCtxRetain: CUDA_ERROR_INVALID_DEVICE
/gpfs/pkgs/mhpcc/anaconda3-5.0.1/lib/python3.6/site-packages/h5py/__init__.py:34: FutureWarning: Conversion of the second argument of issubdtype from `float` to `np.floating` is deprecated. In future, it will be treated as `np.float64 == np.dtype(float).type`.
  from ._conv import register_converters as _register_converters
Using TensorFlow backend.
Traceback (most recent call last):
  File "roundOneSubmit.py", line 23, in <module>
    l.learnThingsCPP(kind=0, file=f, weightFile=wf)
  File "/gpfs/home/m201560/chipboard/learn.py", line 130, in learnThingsCPP
    weights = self.getWeightArray()
  File "/gpfs/home/m201560/chipboard/learn.py", line 193, in getWeightArray
    return self.model.get_weights()[0].tolist()
  File "/gpfs/home/m201560/.local/lib/python3.6/site-packages/keras/engine/network.py", line 492, in get_weights
    return K.batch_get_value(weights)
  File "/gpfs/home/m201560/.local/lib/python3.6/site-packages/keras/backend/tensorflow_backend.py", line 2420, in batch_get_value
    return get_session().run(ops)
  File "/gpfs/home/m201560/.local/lib/python3.6/site-packages/keras/backend/tensorflow_backend.py", line 186, in get_session
    _SESSION = tf.Session(config=config)
  File "/gpfs/pkgs/mhpcc/anaconda3-5.0.1/lib/python3.6/site-packages/tensorflow/python/client/session.py", line 1563, in __init__
    super(Session, self).__init__(target, graph, config=config)
  File "/gpfs/pkgs/mhpcc/anaconda3-5.0.1/lib/python3.6/site-packages/tensorflow/python/client/session.py", line 633, in __init__
    self._session = tf_session.TF_NewSession(self._graph._c_graph, opts)
tensorflow.python.framework.errors_impl.InternalError: Failed to create session.
2019-08-01 21:32:13.070788: E tensorflow/core/common_runtime/direct_session.cc:158] Internal: failed initializing StreamExecutor for CUDA device ordinal 0: Internal: failed call to cuDevicePrimaryCtxRetain: CUDA_ERROR_INVALID_DEVICE
/gpfs/pkgs/mhpcc/anaconda3-5.0.1/lib/python3.6/site-packages/h5py/__init__.py:34: FutureWarning: Conversion of the second argument of issubdtype from `float` to `np.floating` is deprecated. In future, it will be treated as `np.float64 == np.dtype(float).type`.
  from ._conv import register_converters as _register_converters
Using TensorFlow backend.
2019-08-01 21:32:13.076632: E tensorflow/core/common_runtime/direct_session.cc:158] Internal: failed initializing StreamExecutor for CUDA device ordinal 0: Internal: failed call to cuDevicePrimaryCtxRetain: CUDA_ERROR_INVALID_DEVICE
/gpfs/pkgs/mhpcc/anaconda3-5.0.1/lib/python3.6/site-packages/h5py/__init__.py:34: FutureWarning: Conversion of the second argument of issubdtype from `float` to `np.floating` is deprecated. In future, it will be treated as `np.float64 == np.dtype(float).type`.
  from ._conv import register_converters as _register_converters
Using TensorFlow backend.
2019-08-01 21:32:13.076803: E tensorflow/core/common_runtime/direct_session.cc:158] Internal: failed initializing StreamExecutor for CUDA device ordinal 0: Internal: failed call to cuDevicePrimaryCtxRetain: CUDA_ERROR_INVALID_DEVICE
/gpfs/pkgs/mhpcc/anaconda3-5.0.1/lib/python3.6/site-packages/h5py/__init__.py:34: FutureWarning: Conversion of the second argument of issubdtype from `float` to `np.floating` is deprecated. In future, it will be treated as `np.float64 == np.dtype(float).type`.
  from ._conv import register_converters as _register_converters
Using TensorFlow backend.
Traceback (most recent call last):
  File "roundOneSubmit.py", line 23, in <module>
    l.learnThingsCPP(kind=0, file=f, weightFile=wf)
  File "/gpfs/home/m201560/chipboard/learn.py", line 130, in learnThingsCPP
    weights = self.getWeightArray()
  File "/gpfs/home/m201560/chipboard/learn.py", line 193, in getWeightArray
    return self.model.get_weights()[0].tolist()
  File "/gpfs/home/m201560/.local/lib/python3.6/site-packages/keras/engine/network.py", line 492, in get_weights
    return K.batch_get_value(weights)
  File "/gpfs/home/m201560/.local/lib/python3.6/site-packages/keras/backend/tensorflow_backend.py", line 2420, in batch_get_value
    return get_session().run(ops)
  File "/gpfs/home/m201560/.local/lib/python3.6/site-packages/keras/backend/tensorflow_backend.py", line 186, in get_session
    _SESSION = tf.Session(config=config)
  File "/gpfs/pkgs/mhpcc/anaconda3-5.0.1/lib/python3.6/site-packages/tensorflow/python/client/session.py", line 1563, in __init__
    super(Session, self).__init__(target, graph, config=config)
  File "/gpfs/pkgs/mhpcc/anaconda3-5.0.1/lib/python3.6/site-packages/tensorflow/python/client/session.py", line 633, in __init__
    self._session = tf_session.TF_NewSession(self._graph._c_graph, opts)
tensorflow.python.framework.errors_impl.InternalError: Failed to create session.
Traceback (most recent call last):
  File "roundOneSubmit.py", line 23, in <module>
    l.learnThingsCPP(kind=0, file=f, weightFile=wf)
  File "/gpfs/home/m201560/chipboard/learn.py", line 130, in learnThingsCPP
    weights = self.getWeightArray()
  File "/gpfs/home/m201560/chipboard/learn.py", line 193, in getWeightArray
    return self.model.get_weights()[0].tolist()
  File "/gpfs/home/m201560/.local/lib/python3.6/site-packages/keras/engine/network.py", line 492, in get_weights
    return K.batch_get_value(weights)
  File "/gpfs/home/m201560/.local/lib/python3.6/site-packages/keras/backend/tensorflow_backend.py", line 2420, in batch_get_value
    return get_session().run(ops)
  File "/gpfs/home/m201560/.local/lib/python3.6/site-packages/keras/backend/tensorflow_backend.py", line 186, in get_session
    _SESSION = tf.Session(config=config)
  File "/gpfs/pkgs/mhpcc/anaconda3-5.0.1/lib/python3.6/site-packages/tensorflow/python/client/session.py", line 1563, in __init__
    super(Session, self).__init__(target, graph, config=config)
  File "/gpfs/pkgs/mhpcc/anaconda3-5.0.1/lib/python3.6/site-packages/tensorflow/python/client/session.py", line 633, in __init__
    self._session = tf_session.TF_NewSession(self._graph._c_graph, opts)
tensorflow.python.framework.errors_impl.InternalError: Failed to create session.
Traceback (most recent call last):
  File "roundOneSubmit.py", line 23, in <module>
    l.learnThingsCPP(kind=0, file=f, weightFile=wf)
  File "/gpfs/home/m201560/chipboard/learn.py", line 130, in learnThingsCPP
    weights = self.getWeightArray()
  File "/gpfs/home/m201560/chipboard/learn.py", line 193, in getWeightArray
    return self.model.get_weights()[0].tolist()
  File "/gpfs/home/m201560/.local/lib/python3.6/site-packages/keras/engine/network.py", line 492, in get_weights
    return K.batch_get_value(weights)
  File "/gpfs/home/m201560/.local/lib/python3.6/site-packages/keras/backend/tensorflow_backend.py", line 2420, in batch_get_value
    return get_session().run(ops)
  File "/gpfs/home/m201560/.local/lib/python3.6/site-packages/keras/backend/tensorflow_backend.py", line 186, in get_session
    _SESSION = tf.Session(config=config)
  File "/gpfs/pkgs/mhpcc/anaconda3-5.0.1/lib/python3.6/site-packages/tensorflow/python/client/session.py", line 1563, in __init__
    super(Session, self).__init__(target, graph, config=config)
  File "/gpfs/pkgs/mhpcc/anaconda3-5.0.1/lib/python3.6/site-packages/tensorflow/python/client/session.py", line 633, in __init__
    self._session = tf_session.TF_NewSession(self._graph._c_graph, opts)
tensorflow.python.framework.errors_impl.InternalError: Failed to create session.
2019-08-01 21:32:13.092422: E tensorflow/core/common_runtime/direct_session.cc:158] Internal: failed initializing StreamExecutor for CUDA device ordinal 0: Internal: failed call to cuDevicePrimaryCtxRetain: CUDA_ERROR_INVALID_DEVICE
/gpfs/pkgs/mhpcc/anaconda3-5.0.1/lib/python3.6/site-packages/h5py/__init__.py:34: FutureWarning: Conversion of the second argument of issubdtype from `float` to `np.floating` is deprecated. In future, it will be treated as `np.float64 == np.dtype(float).type`.
  from ._conv import register_converters as _register_converters
Using TensorFlow backend.
Traceback (most recent call last):
  File "roundOneSubmit.py", line 23, in <module>
    l.learnThingsCPP(kind=0, file=f, weightFile=wf)
  File "/gpfs/home/m201560/chipboard/learn.py", line 130, in learnThingsCPP
    weights = self.getWeightArray()
  File "/gpfs/home/m201560/chipboard/learn.py", line 193, in getWeightArray
    return self.model.get_weights()[0].tolist()
  File "/gpfs/home/m201560/.local/lib/python3.6/site-packages/keras/engine/network.py", line 492, in get_weights
    return K.batch_get_value(weights)
  File "/gpfs/home/m201560/.local/lib/python3.6/site-packages/keras/backend/tensorflow_backend.py", line 2420, in batch_get_value
    return get_session().run(ops)
  File "/gpfs/home/m201560/.local/lib/python3.6/site-packages/keras/backend/tensorflow_backend.py", line 186, in get_session
    _SESSION = tf.Session(config=config)
  File "/gpfs/pkgs/mhpcc/anaconda3-5.0.1/lib/python3.6/site-packages/tensorflow/python/client/session.py", line 1563, in __init__
    super(Session, self).__init__(target, graph, config=config)
  File "/gpfs/pkgs/mhpcc/anaconda3-5.0.1/lib/python3.6/site-packages/tensorflow/python/client/session.py", line 633, in __init__
    self._session = tf_session.TF_NewSession(self._graph._c_graph, opts)
tensorflow.python.framework.errors_impl.InternalError: Failed to create session.
2019-08-01 21:32:13.100755: E tensorflow/core/common_runtime/direct_session.cc:158] Internal: failed initializing StreamExecutor for CUDA device ordinal 0: Internal: failed call to cuDevicePrimaryCtxRetain: CUDA_ERROR_INVALID_DEVICE
/gpfs/pkgs/mhpcc/anaconda3-5.0.1/lib/python3.6/site-packages/h5py/__init__.py:34: FutureWarning: Conversion of the second argument of issubdtype from `float` to `np.floating` is deprecated. In future, it will be treated as `np.float64 == np.dtype(float).type`.
  from ._conv import register_converters as _register_converters
Using TensorFlow backend.
Traceback (most recent call last):
  File "roundOneSubmit.py", line 23, in <module>
    l.learnThingsCPP(kind=0, file=f, weightFile=wf)
  File "/gpfs/home/m201560/chipboard/learn.py", line 130, in learnThingsCPP
    weights = self.getWeightArray()
  File "/gpfs/home/m201560/chipboard/learn.py", line 193, in getWeightArray
    return self.model.get_weights()[0].tolist()
  File "/gpfs/home/m201560/.local/lib/python3.6/site-packages/keras/engine/network.py", line 492, in get_weights
    return K.batch_get_value(weights)
  File "/gpfs/home/m201560/.local/lib/python3.6/site-packages/keras/backend/tensorflow_backend.py", line 2420, in batch_get_value
    return get_session().run(ops)
  File "/gpfs/home/m201560/.local/lib/python3.6/site-packages/keras/backend/tensorflow_backend.py", line 186, in get_session
    _SESSION = tf.Session(config=config)
  File "/gpfs/pkgs/mhpcc/anaconda3-5.0.1/lib/python3.6/site-packages/tensorflow/python/client/session.py", line 1563, in __init__
    super(Session, self).__init__(target, graph, config=config)
  File "/gpfs/pkgs/mhpcc/anaconda3-5.0.1/lib/python3.6/site-packages/tensorflow/python/client/session.py", line 633, in __init__
    self._session = tf_session.TF_NewSession(self._graph._c_graph, opts)
tensorflow.python.framework.errors_impl.InternalError: Failed to create session.
2019-08-01 21:32:13.113271: E tensorflow/core/common_runtime/direct_session.cc:158] Internal: failed initializing StreamExecutor for CUDA device ordinal 0: Internal: failed call to cuDevicePrimaryCtxRetain: CUDA_ERROR_INVALID_DEVICE
/gpfs/pkgs/mhpcc/anaconda3-5.0.1/lib/python3.6/site-packages/h5py/__init__.py:34: FutureWarning: Conversion of the second argument of issubdtype from `float` to `np.floating` is deprecated. In future, it will be treated as `np.float64 == np.dtype(float).type`.
  from ._conv import register_converters as _register_converters
Using TensorFlow backend.
2019-08-01 21:32:13.117811: E tensorflow/core/common_runtime/direct_session.cc:158] Internal: failed initializing StreamExecutor for CUDA device ordinal 0: Internal: failed call to cuDevicePrimaryCtxRetain: CUDA_ERROR_INVALID_DEVICE
/gpfs/pkgs/mhpcc/anaconda3-5.0.1/lib/python3.6/site-packages/h5py/__init__.py:34: FutureWarning: Conversion of the second argument of issubdtype from `float` to `np.floating` is deprecated. In future, it will be treated as `np.float64 == np.dtype(float).type`.
  from ._conv import register_converters as _register_converters
Using TensorFlow backend.
Traceback (most recent call last):
  File "roundOneSubmit.py", line 23, in <module>
    l.learnThingsCPP(kind=0, file=f, weightFile=wf)
  File "/gpfs/home/m201560/chipboard/learn.py", line 130, in learnThingsCPP
    weights = self.getWeightArray()
  File "/gpfs/home/m201560/chipboard/learn.py", line 193, in getWeightArray
    return self.model.get_weights()[0].tolist()
  File "/gpfs/home/m201560/.local/lib/python3.6/site-packages/keras/engine/network.py", line 492, in get_weights
    return K.batch_get_value(weights)
  File "/gpfs/home/m201560/.local/lib/python3.6/site-packages/keras/backend/tensorflow_backend.py", line 2420, in batch_get_value
    return get_session().run(ops)
  File "/gpfs/home/m201560/.local/lib/python3.6/site-packages/keras/backend/tensorflow_backend.py", line 186, in get_session
    _SESSION = tf.Session(config=config)
  File "/gpfs/pkgs/mhpcc/anaconda3-5.0.1/lib/python3.6/site-packages/tensorflow/python/client/session.py", line 1563, in __init__
    super(Session, self).__init__(target, graph, config=config)
  File "/gpfs/pkgs/mhpcc/anaconda3-5.0.1/lib/python3.6/site-packages/tensorflow/python/client/session.py", line 633, in __init__
    self._session = tf_session.TF_NewSession(self._graph._c_graph, opts)
tensorflow.python.framework.errors_impl.InternalError: Failed to create session.
2019-08-01 21:32:13.126475: E tensorflow/core/common_runtime/direct_session.cc:158] Internal: failed initializing StreamExecutor for CUDA device ordinal 0: Internal: failed call to cuDevicePrimaryCtxRetain: CUDA_ERROR_INVALID_DEVICE
/gpfs/pkgs/mhpcc/anaconda3-5.0.1/lib/python3.6/site-packages/h5py/__init__.py:34: FutureWarning: Conversion of the second argument of issubdtype from `float` to `np.floating` is deprecated. In future, it will be treated as `np.float64 == np.dtype(float).type`.
  from ._conv import register_converters as _register_converters
Using TensorFlow backend.
Traceback (most recent call last):
  File "roundOneSubmit.py", line 23, in <module>
    l.learnThingsCPP(kind=0, file=f, weightFile=wf)
  File "/gpfs/home/m201560/chipboard/learn.py", line 130, in learnThingsCPP
    weights = self.getWeightArray()
  File "/gpfs/home/m201560/chipboard/learn.py", line 193, in getWeightArray
    return self.model.get_weights()[0].tolist()
  File "/gpfs/home/m201560/.local/lib/python3.6/site-packages/keras/engine/network.py", line 492, in get_weights
    return K.batch_get_value(weights)
  File "/gpfs/home/m201560/.local/lib/python3.6/site-packages/keras/backend/tensorflow_backend.py", line 2420, in batch_get_value
    return get_session().run(ops)
  File "/gpfs/home/m201560/.local/lib/python3.6/site-packages/keras/backend/tensorflow_backend.py", line 186, in get_session
    _SESSION = tf.Session(config=config)
  File "/gpfs/pkgs/mhpcc/anaconda3-5.0.1/lib/python3.6/site-packages/tensorflow/python/client/session.py", line 1563, in __init__
    super(Session, self).__init__(target, graph, config=config)
  File "/gpfs/pkgs/mhpcc/anaconda3-5.0.1/lib/python3.6/site-packages/tensorflow/python/client/session.py", line 633, in __init__
    self._session = tf_session.TF_NewSession(self._graph._c_graph, opts)
tensorflow.python.framework.errors_impl.InternalError: Failed to create session.
2019-08-01 21:32:13.131021: E tensorflow/core/common_runtime/direct_session.cc:158] Internal: failed initializing StreamExecutor for CUDA device ordinal 0: Internal: failed call to cuDevicePrimaryCtxRetain: CUDA_ERROR_INVALID_DEVICE
/gpfs/pkgs/mhpcc/anaconda3-5.0.1/lib/python3.6/site-packages/h5py/__init__.py:34: FutureWarning: Conversion of the second argument of issubdtype from `float` to `np.floating` is deprecated. In future, it will be treated as `np.float64 == np.dtype(float).type`.
  from ._conv import register_converters as _register_converters
Using TensorFlow backend.
2019-08-01 21:32:13.133596: E tensorflow/core/common_runtime/direct_session.cc:158] Internal: failed initializing StreamExecutor for CUDA device ordinal 0: Internal: failed call to cuDevicePrimaryCtxRetain: CUDA_ERROR_INVALID_DEVICE
/gpfs/pkgs/mhpcc/anaconda3-5.0.1/lib/python3.6/site-packages/h5py/__init__.py:34: FutureWarning: Conversion of the second argument of issubdtype from `float` to `np.floating` is deprecated. In future, it will be treated as `np.float64 == np.dtype(float).type`.
  from ._conv import register_converters as _register_converters
Using TensorFlow backend.
2019-08-01 21:32:13.137853: E tensorflow/core/common_runtime/direct_session.cc:158] Internal: failed initializing StreamExecutor for CUDA device ordinal 0: Internal: failed call to cuDevicePrimaryCtxRetain: CUDA_ERROR_INVALID_DEVICE
/gpfs/pkgs/mhpcc/anaconda3-5.0.1/lib/python3.6/site-packages/h5py/__init__.py:34: FutureWarning: Conversion of the second argument of issubdtype from `float` to `np.floating` is deprecated. In future, it will be treated as `np.float64 == np.dtype(float).type`.
  from ._conv import register_converters as _register_converters
Using TensorFlow backend.
Traceback (most recent call last):
  File "roundOneSubmit.py", line 23, in <module>
    l.learnThingsCPP(kind=0, file=f, weightFile=wf)
  File "/gpfs/home/m201560/chipboard/learn.py", line 130, in learnThingsCPP
    weights = self.getWeightArray()
  File "/gpfs/home/m201560/chipboard/learn.py", line 193, in getWeightArray
    return self.model.get_weights()[0].tolist()
  File "/gpfs/home/m201560/.local/lib/python3.6/site-packages/keras/engine/network.py", line 492, in get_weights
    return K.batch_get_value(weights)
  File "/gpfs/home/m201560/.local/lib/python3.6/site-packages/keras/backend/tensorflow_backend.py", line 2420, in batch_get_value
    return get_session().run(ops)
  File "/gpfs/home/m201560/.local/lib/python3.6/site-packages/keras/backend/tensorflow_backend.py", line 186, in get_session
    _SESSION = tf.Session(config=config)
  File "/gpfs/pkgs/mhpcc/anaconda3-5.0.1/lib/python3.6/site-packages/tensorflow/python/client/session.py", line 1563, in __init__
    super(Session, self).__init__(target, graph, config=config)
  File "/gpfs/pkgs/mhpcc/anaconda3-5.0.1/lib/python3.6/site-packages/tensorflow/python/client/session.py", line 633, in __init__
    self._session = tf_session.TF_NewSession(self._graph._c_graph, opts)
tensorflow.python.framework.errors_impl.InternalError: Failed to create session.
2019-08-01 21:32:13.140129: E tensorflow/core/common_runtime/direct_session.cc:158] Internal: failed initializing StreamExecutor for CUDA device ordinal 0: Internal: failed call to cuDevicePrimaryCtxRetain: CUDA_ERROR_INVALID_DEVICE
/gpfs/pkgs/mhpcc/anaconda3-5.0.1/lib/python3.6/site-packages/h5py/__init__.py:34: FutureWarning: Conversion of the second argument of issubdtype from `float` to `np.floating` is deprecated. In future, it will be treated as `np.float64 == np.dtype(float).type`.
  from ._conv import register_converters as _register_converters
Using TensorFlow backend.
Traceback (most recent call last):
  File "roundOneSubmit.py", line 23, in <module>
    l.learnThingsCPP(kind=0, file=f, weightFile=wf)
  File "/gpfs/home/m201560/chipboard/learn.py", line 130, in learnThingsCPP
    weights = self.getWeightArray()
  File "/gpfs/home/m201560/chipboard/learn.py", line 193, in getWeightArray
    return self.model.get_weights()[0].tolist()
  File "/gpfs/home/m201560/.local/lib/python3.6/site-packages/keras/engine/network.py", line 492, in get_weights
    return K.batch_get_value(weights)
  File "/gpfs/home/m201560/.local/lib/python3.6/site-packages/keras/backend/tensorflow_backend.py", line 2420, in batch_get_value
    return get_session().run(ops)
  File "/gpfs/home/m201560/.local/lib/python3.6/site-packages/keras/backend/tensorflow_backend.py", line 186, in get_session
    _SESSION = tf.Session(config=config)
  File "/gpfs/pkgs/mhpcc/anaconda3-5.0.1/lib/python3.6/site-packages/tensorflow/python/client/session.py", line 1563, in __init__
    super(Session, self).__init__(target, graph, config=config)
  File "/gpfs/pkgs/mhpcc/anaconda3-5.0.1/lib/python3.6/site-packages/tensorflow/python/client/session.py", line 633, in __init__
    self._session = tf_session.TF_NewSession(self._graph._c_graph, opts)
tensorflow.python.framework.errors_impl.InternalError: Failed to create session.
Traceback (most recent call last):
  File "roundOneSubmit.py", line 23, in <module>
    l.learnThingsCPP(kind=0, file=f, weightFile=wf)
  File "/gpfs/home/m201560/chipboard/learn.py", line 130, in learnThingsCPP
    weights = self.getWeightArray()
  File "/gpfs/home/m201560/chipboard/learn.py", line 193, in getWeightArray
    return self.model.get_weights()[0].tolist()
  File "/gpfs/home/m201560/.local/lib/python3.6/site-packages/keras/engine/network.py", line 492, in get_weights
    return K.batch_get_value(weights)
  File "/gpfs/home/m201560/.local/lib/python3.6/site-packages/keras/backend/tensorflow_backend.py", line 2420, in batch_get_value
    return get_session().run(ops)
  File "/gpfs/home/m201560/.local/lib/python3.6/site-packages/keras/backend/tensorflow_backend.py", line 186, in get_session
    _SESSION = tf.Session(config=config)
  File "/gpfs/pkgs/mhpcc/anaconda3-5.0.1/lib/python3.6/site-packages/tensorflow/python/client/session.py", line 1563, in __init__
    super(Session, self).__init__(target, graph, config=config)
  File "/gpfs/pkgs/mhpcc/anaconda3-5.0.1/lib/python3.6/site-packages/tensorflow/python/client/session.py", line 633, in __init__
    self._session = tf_session.TF_NewSession(self._graph._c_graph, opts)
tensorflow.python.framework.errors_impl.InternalError: Failed to create session.
Traceback (most recent call last):
  File "roundOneSubmit.py", line 23, in <module>
    l.learnThingsCPP(kind=0, file=f, weightFile=wf)
  File "/gpfs/home/m201560/chipboard/learn.py", line 130, in learnThingsCPP
    weights = self.getWeightArray()
  File "/gpfs/home/m201560/chipboard/learn.py", line 193, in getWeightArray
    return self.model.get_weights()[0].tolist()
  File "/gpfs/home/m201560/.local/lib/python3.6/site-packages/keras/engine/network.py", line 492, in get_weights
    return K.batch_get_value(weights)
  File "/gpfs/home/m201560/.local/lib/python3.6/site-packages/keras/backend/tensorflow_backend.py", line 2420, in batch_get_value
    return get_session().run(ops)
  File "/gpfs/home/m201560/.local/lib/python3.6/site-packages/keras/backend/tensorflow_backend.py", line 186, in get_session
    _SESSION = tf.Session(config=config)
  File "/gpfs/pkgs/mhpcc/anaconda3-5.0.1/lib/python3.6/site-packages/tensorflow/python/client/session.py", line 1563, in __init__
    super(Session, self).__init__(target, graph, config=config)
  File "/gpfs/pkgs/mhpcc/anaconda3-5.0.1/lib/python3.6/site-packages/tensorflow/python/client/session.py", line 633, in __init__
    self._session = tf_session.TF_NewSession(self._graph._c_graph, opts)
tensorflow.python.framework.errors_impl.InternalError: Failed to create session.
2019-08-01 21:32:13.148217: E tensorflow/core/common_runtime/direct_session.cc:158] Internal: failed initializing StreamExecutor for CUDA device ordinal 0: Internal: failed call to cuDevicePrimaryCtxRetain: CUDA_ERROR_INVALID_DEVICE
/gpfs/pkgs/mhpcc/anaconda3-5.0.1/lib/python3.6/site-packages/h5py/__init__.py:34: FutureWarning: Conversion of the second argument of issubdtype from `float` to `np.floating` is deprecated. In future, it will be treated as `np.float64 == np.dtype(float).type`.
  from ._conv import register_converters as _register_converters
Using TensorFlow backend.
2019-08-01 21:32:13.149079: E tensorflow/core/common_runtime/direct_session.cc:158] Internal: failed initializing StreamExecutor for CUDA device ordinal 0: Internal: failed call to cuDevicePrimaryCtxRetain: CUDA_ERROR_INVALID_DEVICE
/gpfs/pkgs/mhpcc/anaconda3-5.0.1/lib/python3.6/site-packages/h5py/__init__.py:34: FutureWarning: Conversion of the second argument of issubdtype from `float` to `np.floating` is deprecated. In future, it will be treated as `np.float64 == np.dtype(float).type`.
  from ._conv import register_converters as _register_converters
Using TensorFlow backend.
Traceback (most recent call last):
  File "roundOneSubmit.py", line 23, in <module>
    l.learnThingsCPP(kind=0, file=f, weightFile=wf)
  File "/gpfs/home/m201560/chipboard/learn.py", line 130, in learnThingsCPP
    weights = self.getWeightArray()
  File "/gpfs/home/m201560/chipboard/learn.py", line 193, in getWeightArray
    return self.model.get_weights()[0].tolist()
  File "/gpfs/home/m201560/.local/lib/python3.6/site-packages/keras/engine/network.py", line 492, in get_weights
    return K.batch_get_value(weights)
  File "/gpfs/home/m201560/.local/lib/python3.6/site-packages/keras/backend/tensorflow_backend.py", line 2420, in batch_get_value
    return get_session().run(ops)
  File "/gpfs/home/m201560/.local/lib/python3.6/site-packages/keras/backend/tensorflow_backend.py", line 186, in get_session
    _SESSION = tf.Session(config=config)
  File "/gpfs/pkgs/mhpcc/anaconda3-5.0.1/lib/python3.6/site-packages/tensorflow/python/client/session.py", line 1563, in __init__
    super(Session, self).__init__(target, graph, config=config)
  File "/gpfs/pkgs/mhpcc/anaconda3-5.0.1/lib/python3.6/site-packages/tensorflow/python/client/session.py", line 633, in __init__
    self._session = tf_session.TF_NewSession(self._graph._c_graph, opts)
tensorflow.python.framework.errors_impl.InternalError: Failed to create session.
2019-08-01 21:32:13.153025: E tensorflow/core/common_runtime/direct_session.cc:158] Internal: failed initializing StreamExecutor for CUDA device ordinal 0: Internal: failed call to cuDevicePrimaryCtxRetain: CUDA_ERROR_INVALID_DEVICE
/gpfs/pkgs/mhpcc/anaconda3-5.0.1/lib/python3.6/site-packages/h5py/__init__.py:34: FutureWarning: Conversion of the second argument of issubdtype from `float` to `np.floating` is deprecated. In future, it will be treated as `np.float64 == np.dtype(float).type`.
  from ._conv import register_converters as _register_converters
Using TensorFlow backend.
Traceback (most recent call last):
  File "roundOneSubmit.py", line 23, in <module>
    l.learnThingsCPP(kind=0, file=f, weightFile=wf)
  File "/gpfs/home/m201560/chipboard/learn.py", line 130, in learnThingsCPP
    weights = self.getWeightArray()
  File "/gpfs/home/m201560/chipboard/learn.py", line 193, in getWeightArray
    return self.model.get_weights()[0].tolist()
  File "/gpfs/home/m201560/.local/lib/python3.6/site-packages/keras/engine/network.py", line 492, in get_weights
    return K.batch_get_value(weights)
  File "/gpfs/home/m201560/.local/lib/python3.6/site-packages/keras/backend/tensorflow_backend.py", line 2420, in batch_get_value
    return get_session().run(ops)
  File "/gpfs/home/m201560/.local/lib/python3.6/site-packages/keras/backend/tensorflow_backend.py", line 186, in get_session
    _SESSION = tf.Session(config=config)
  File "/gpfs/pkgs/mhpcc/anaconda3-5.0.1/lib/python3.6/site-packages/tensorflow/python/client/session.py", line 1563, in __init__
    super(Session, self).__init__(target, graph, config=config)
  File "/gpfs/pkgs/mhpcc/anaconda3-5.0.1/lib/python3.6/site-packages/tensorflow/python/client/session.py", line 633, in __init__
    self._session = tf_session.TF_NewSession(self._graph._c_graph, opts)
tensorflow.python.framework.errors_impl.InternalError: Failed to create session.
Traceback (most recent call last):
  File "roundOneSubmit.py", line 23, in <module>
    l.learnThingsCPP(kind=0, file=f, weightFile=wf)
  File "/gpfs/home/m201560/chipboard/learn.py", line 130, in learnThingsCPP
    weights = self.getWeightArray()
  File "/gpfs/home/m201560/chipboard/learn.py", line 193, in getWeightArray
    return self.model.get_weights()[0].tolist()
  File "/gpfs/home/m201560/.local/lib/python3.6/site-packages/keras/engine/network.py", line 492, in get_weights
    return K.batch_get_value(weights)
  File "/gpfs/home/m201560/.local/lib/python3.6/site-packages/keras/backend/tensorflow_backend.py", line 2420, in batch_get_value
    return get_session().run(ops)
  File "/gpfs/home/m201560/.local/lib/python3.6/site-packages/keras/backend/tensorflow_backend.py", line 186, in get_session
    _SESSION = tf.Session(config=config)
  File "/gpfs/pkgs/mhpcc/anaconda3-5.0.1/lib/python3.6/site-packages/tensorflow/python/client/session.py", line 1563, in __init__
    super(Session, self).__init__(target, graph, config=config)
  File "/gpfs/pkgs/mhpcc/anaconda3-5.0.1/lib/python3.6/site-packages/tensorflow/python/client/session.py", line 633, in __init__
    self._session = tf_session.TF_NewSession(self._graph._c_graph, opts)
tensorflow.python.framework.errors_impl.InternalError: Failed to create session.
2019-08-01 21:32:13.157117: E tensorflow/core/common_runtime/direct_session.cc:158] Internal: failed initializing StreamExecutor for CUDA device ordinal 0: Internal: failed call to cuDevicePrimaryCtxRetain: CUDA_ERROR_INVALID_DEVICE
/gpfs/pkgs/mhpcc/anaconda3-5.0.1/lib/python3.6/site-packages/h5py/__init__.py:34: FutureWarning: Conversion of the second argument of issubdtype from `float` to `np.floating` is deprecated. In future, it will be treated as `np.float64 == np.dtype(float).type`.
  from ._conv import register_converters as _register_converters
Using TensorFlow backend.
2019-08-01 21:32:13.160381: E tensorflow/core/common_runtime/direct_session.cc:158] Internal: failed initializing StreamExecutor for CUDA device ordinal 0: Internal: failed call to cuDevicePrimaryCtxRetain: CUDA_ERROR_INVALID_DEVICE
/gpfs/pkgs/mhpcc/anaconda3-5.0.1/lib/python3.6/site-packages/h5py/__init__.py:34: FutureWarning: Conversion of the second argument of issubdtype from `float` to `np.floating` is deprecated. In future, it will be treated as `np.float64 == np.dtype(float).type`.
  from ._conv import register_converters as _register_converters
Using TensorFlow backend.
2019-08-01 21:32:13.162463: E tensorflow/core/common_runtime/direct_session.cc:158] Internal: failed initializing StreamExecutor for CUDA device ordinal 0: Internal: failed call to cuDevicePrimaryCtxRetain: CUDA_ERROR_INVALID_DEVICE
/gpfs/pkgs/mhpcc/anaconda3-5.0.1/lib/python3.6/site-packages/h5py/__init__.py:34: FutureWarning: Conversion of the second argument of issubdtype from `float` to `np.floating` is deprecated. In future, it will be treated as `np.float64 == np.dtype(float).type`.
  from ._conv import register_converters as _register_converters
Using TensorFlow backend.
2019-08-01 21:32:13.164790: E tensorflow/core/common_runtime/direct_session.cc:158] Internal: failed initializing StreamExecutor for CUDA device ordinal 0: Internal: failed call to cuDevicePrimaryCtxRetain: CUDA_ERROR_INVALID_DEVICE
/gpfs/pkgs/mhpcc/anaconda3-5.0.1/lib/python3.6/site-packages/h5py/__init__.py:34: FutureWarning: Conversion of the second argument of issubdtype from `float` to `np.floating` is deprecated. In future, it will be treated as `np.float64 == np.dtype(float).type`.
  from ._conv import register_converters as _register_converters
Using TensorFlow backend.
Traceback (most recent call last):
  File "roundOneSubmit.py", line 23, in <module>
    l.learnThingsCPP(kind=0, file=f, weightFile=wf)
  File "/gpfs/home/m201560/chipboard/learn.py", line 130, in learnThingsCPP
    weights = self.getWeightArray()
  File "/gpfs/home/m201560/chipboard/learn.py", line 193, in getWeightArray
    return self.model.get_weights()[0].tolist()
  File "/gpfs/home/m201560/.local/lib/python3.6/site-packages/keras/engine/network.py", line 492, in get_weights
    return K.batch_get_value(weights)
  File "/gpfs/home/m201560/.local/lib/python3.6/site-packages/keras/backend/tensorflow_backend.py", line 2420, in batch_get_value
    return get_session().run(ops)
  File "/gpfs/home/m201560/.local/lib/python3.6/site-packages/keras/backend/tensorflow_backend.py", line 186, in get_session
    _SESSION = tf.Session(config=config)
  File "/gpfs/pkgs/mhpcc/anaconda3-5.0.1/lib/python3.6/site-packages/tensorflow/python/client/session.py", line 1563, in __init__
    super(Session, self).__init__(target, graph, config=config)
  File "/gpfs/pkgs/mhpcc/anaconda3-5.0.1/lib/python3.6/site-packages/tensorflow/python/client/session.py", line 633, in __init__
    self._session = tf_session.TF_NewSession(self._graph._c_graph, opts)
tensorflow.python.framework.errors_impl.InternalError: Failed to create session.
2019-08-01 21:32:13.167468: E tensorflow/core/common_runtime/direct_session.cc:158] Internal: failed initializing StreamExecutor for CUDA device ordinal 0: Internal: failed call to cuDevicePrimaryCtxRetain: CUDA_ERROR_INVALID_DEVICE
/gpfs/pkgs/mhpcc/anaconda3-5.0.1/lib/python3.6/site-packages/h5py/__init__.py:34: FutureWarning: Conversion of the second argument of issubdtype from `float` to `np.floating` is deprecated. In future, it will be treated as `np.float64 == np.dtype(float).type`.
  from ._conv import register_converters as _register_converters
Using TensorFlow backend.
2019-08-01 21:32:13.168673: E tensorflow/core/common_runtime/direct_session.cc:158] Internal: failed initializing StreamExecutor for CUDA device ordinal 0: Internal: failed call to cuDevicePrimaryCtxRetain: CUDA_ERROR_INVALID_DEVICE
/gpfs/pkgs/mhpcc/anaconda3-5.0.1/lib/python3.6/site-packages/h5py/__init__.py:34: FutureWarning: Conversion of the second argument of issubdtype from `float` to `np.floating` is deprecated. In future, it will be treated as `np.float64 == np.dtype(float).type`.
  from ._conv import register_converters as _register_converters
Using TensorFlow backend.
Traceback (most recent call last):
  File "roundOneSubmit.py", line 23, in <module>
    l.learnThingsCPP(kind=0, file=f, weightFile=wf)
  File "/gpfs/home/m201560/chipboard/learn.py", line 130, in learnThingsCPP
    weights = self.getWeightArray()
  File "/gpfs/home/m201560/chipboard/learn.py", line 193, in getWeightArray
    return self.model.get_weights()[0].tolist()
  File "/gpfs/home/m201560/.local/lib/python3.6/site-packages/keras/engine/network.py", line 492, in get_weights
    return K.batch_get_value(weights)
  File "/gpfs/home/m201560/.local/lib/python3.6/site-packages/keras/backend/tensorflow_backend.py", line 2420, in batch_get_value
    return get_session().run(ops)
  File "/gpfs/home/m201560/.local/lib/python3.6/site-packages/keras/backend/tensorflow_backend.py", line 186, in get_session
    _SESSION = tf.Session(config=config)
  File "/gpfs/pkgs/mhpcc/anaconda3-5.0.1/lib/python3.6/site-packages/tensorflow/python/client/session.py", line 1563, in __init__
    super(Session, self).__init__(target, graph, config=config)
  File "/gpfs/pkgs/mhpcc/anaconda3-5.0.1/lib/python3.6/site-packages/tensorflow/python/client/session.py", line 633, in __init__
    self._session = tf_session.TF_NewSession(self._graph._c_graph, opts)
tensorflow.python.framework.errors_impl.InternalError: Failed to create session.
2019-08-01 21:32:13.170528: E tensorflow/core/common_runtime/direct_session.cc:158] Internal: failed initializing StreamExecutor for CUDA device ordinal 0: Internal: failed call to cuDevicePrimaryCtxRetain: CUDA_ERROR_INVALID_DEVICE
/gpfs/pkgs/mhpcc/anaconda3-5.0.1/lib/python3.6/site-packages/h5py/__init__.py:34: FutureWarning: Conversion of the second argument of issubdtype from `float` to `np.floating` is deprecated. In future, it will be treated as `np.float64 == np.dtype(float).type`.
  from ._conv import register_converters as _register_converters
Using TensorFlow backend.
Traceback (most recent call last):
  File "roundOneSubmit.py", line 23, in <module>
    l.learnThingsCPP(kind=0, file=f, weightFile=wf)
  File "/gpfs/home/m201560/chipboard/learn.py", line 130, in learnThingsCPP
    weights = self.getWeightArray()
  File "/gpfs/home/m201560/chipboard/learn.py", line 193, in getWeightArray
    return self.model.get_weights()[0].tolist()
  File "/gpfs/home/m201560/.local/lib/python3.6/site-packages/keras/engine/network.py", line 492, in get_weights
    return K.batch_get_value(weights)
  File "/gpfs/home/m201560/.local/lib/python3.6/site-packages/keras/backend/tensorflow_backend.py", line 2420, in batch_get_value
    return get_session().run(ops)
  File "/gpfs/home/m201560/.local/lib/python3.6/site-packages/keras/backend/tensorflow_backend.py", line 186, in get_session
    _SESSION = tf.Session(config=config)
  File "/gpfs/pkgs/mhpcc/anaconda3-5.0.1/lib/python3.6/site-packages/tensorflow/python/client/session.py", line 1563, in __init__
    super(Session, self).__init__(target, graph, config=config)
  File "/gpfs/pkgs/mhpcc/anaconda3-5.0.1/lib/python3.6/site-packages/tensorflow/python/client/session.py", line 633, in __init__
    self._session = tf_session.TF_NewSession(self._graph._c_graph, opts)
tensorflow.python.framework.errors_impl.InternalError: Failed to create session.
2019-08-01 21:32:13.171766: E tensorflow/core/common_runtime/direct_session.cc:158] Internal: failed initializing StreamExecutor for CUDA device ordinal 0: Internal: failed call to cuDevicePrimaryCtxRetain: CUDA_ERROR_INVALID_DEVICE
/gpfs/pkgs/mhpcc/anaconda3-5.0.1/lib/python3.6/site-packages/h5py/__init__.py:34: FutureWarning: Conversion of the second argument of issubdtype from `float` to `np.floating` is deprecated. In future, it will be treated as `np.float64 == np.dtype(float).type`.
  from ._conv import register_converters as _register_converters
Using TensorFlow backend.
Traceback (most recent call last):
  File "roundOneSubmit.py", line 23, in <module>
    l.learnThingsCPP(kind=0, file=f, weightFile=wf)
  File "/gpfs/home/m201560/chipboard/learn.py", line 130, in learnThingsCPP
    weights = self.getWeightArray()
  File "/gpfs/home/m201560/chipboard/learn.py", line 193, in getWeightArray
    return self.model.get_weights()[0].tolist()
  File "/gpfs/home/m201560/.local/lib/python3.6/site-packages/keras/engine/network.py", line 492, in get_weights
    return K.batch_get_value(weights)
  File "/gpfs/home/m201560/.local/lib/python3.6/site-packages/keras/backend/tensorflow_backend.py", line 2420, in batch_get_value
    return get_session().run(ops)
  File "/gpfs/home/m201560/.local/lib/python3.6/site-packages/keras/backend/tensorflow_backend.py", line 186, in get_session
    _SESSION = tf.Session(config=config)
  File "/gpfs/pkgs/mhpcc/anaconda3-5.0.1/lib/python3.6/site-packages/tensorflow/python/client/session.py", line 1563, in __init__
    super(Session, self).__init__(target, graph, config=config)
  File "/gpfs/pkgs/mhpcc/anaconda3-5.0.1/lib/python3.6/site-packages/tensorflow/python/client/session.py", line 633, in __init__
    self._session = tf_session.TF_NewSession(self._graph._c_graph, opts)
tensorflow.python.framework.errors_impl.InternalError: Failed to create session.
2019-08-01 21:32:13.173055: E tensorflow/core/common_runtime/direct_session.cc:158] Internal: failed initializing StreamExecutor for CUDA device ordinal 0: Internal: failed call to cuDevicePrimaryCtxRetain: CUDA_ERROR_INVALID_DEVICE
/gpfs/pkgs/mhpcc/anaconda3-5.0.1/lib/python3.6/site-packages/h5py/__init__.py:34: FutureWarning: Conversion of the second argument of issubdtype from `float` to `np.floating` is deprecated. In future, it will be treated as `np.float64 == np.dtype(float).type`.
  from ._conv import register_converters as _register_converters
Using TensorFlow backend.
Traceback (most recent call last):
  File "roundOneSubmit.py", line 23, in <module>
    l.learnThingsCPP(kind=0, file=f, weightFile=wf)
  File "/gpfs/home/m201560/chipboard/learn.py", line 130, in learnThingsCPP
    weights = self.getWeightArray()
  File "/gpfs/home/m201560/chipboard/learn.py", line 193, in getWeightArray
    return self.model.get_weights()[0].tolist()
  File "/gpfs/home/m201560/.local/lib/python3.6/site-packages/keras/engine/network.py", line 492, in get_weights
    return K.batch_get_value(weights)
  File "/gpfs/home/m201560/.local/lib/python3.6/site-packages/keras/backend/tensorflow_backend.py", line 2420, in batch_get_value
    return get_session().run(ops)
  File "/gpfs/home/m201560/.local/lib/python3.6/site-packages/keras/backend/tensorflow_backend.py", line 186, in get_session
    _SESSION = tf.Session(config=config)
  File "/gpfs/pkgs/mhpcc/anaconda3-5.0.1/lib/python3.6/site-packages/tensorflow/python/client/session.py", line 1563, in __init__
    super(Session, self).__init__(target, graph, config=config)
  File "/gpfs/pkgs/mhpcc/anaconda3-5.0.1/lib/python3.6/site-packages/tensorflow/python/client/session.py", line 633, in __init__
    self._session = tf_session.TF_NewSession(self._graph._c_graph, opts)
tensorflow.python.framework.errors_impl.InternalError: Failed to create session.
Traceback (most recent call last):
  File "roundOneSubmit.py", line 23, in <module>
    l.learnThingsCPP(kind=0, file=f, weightFile=wf)
  File "/gpfs/home/m201560/chipboard/learn.py", line 130, in learnThingsCPP
    weights = self.getWeightArray()
  File "/gpfs/home/m201560/chipboard/learn.py", line 193, in getWeightArray
    return self.model.get_weights()[0].tolist()
  File "/gpfs/home/m201560/.local/lib/python3.6/site-packages/keras/engine/network.py", line 492, in get_weights
    return K.batch_get_value(weights)
  File "/gpfs/home/m201560/.local/lib/python3.6/site-packages/keras/backend/tensorflow_backend.py", line 2420, in batch_get_value
    return get_session().run(ops)
  File "/gpfs/home/m201560/.local/lib/python3.6/site-packages/keras/backend/tensorflow_backend.py", line 186, in get_session
    _SESSION = tf.Session(config=config)
  File "/gpfs/pkgs/mhpcc/anaconda3-5.0.1/lib/python3.6/site-packages/tensorflow/python/client/session.py", line 1563, in __init__
    super(Session, self).__init__(target, graph, config=config)
  File "/gpfs/pkgs/mhpcc/anaconda3-5.0.1/lib/python3.6/site-packages/tensorflow/python/client/session.py", line 633, in __init__
    self._session = tf_session.TF_NewSession(self._graph._c_graph, opts)
tensorflow.python.framework.errors_impl.InternalError: Failed to create session.
Traceback (most recent call last):
  File "roundOneSubmit.py", line 23, in <module>
    l.learnThingsCPP(kind=0, file=f, weightFile=wf)
  File "/gpfs/home/m201560/chipboard/learn.py", line 130, in learnThingsCPP
    weights = self.getWeightArray()
  File "/gpfs/home/m201560/chipboard/learn.py", line 193, in getWeightArray
    return self.model.get_weights()[0].tolist()
  File "/gpfs/home/m201560/.local/lib/python3.6/site-packages/keras/engine/network.py", line 492, in get_weights
    return K.batch_get_value(weights)
  File "/gpfs/home/m201560/.local/lib/python3.6/site-packages/keras/backend/tensorflow_backend.py", line 2420, in batch_get_value
    return get_session().run(ops)
  File "/gpfs/home/m201560/.local/lib/python3.6/site-packages/keras/backend/tensorflow_backend.py", line 186, in get_session
    _SESSION = tf.Session(config=config)
  File "/gpfs/pkgs/mhpcc/anaconda3-5.0.1/lib/python3.6/site-packages/tensorflow/python/client/session.py", line 1563, in __init__
    super(Session, self).__init__(target, graph, config=config)
  File "/gpfs/pkgs/mhpcc/anaconda3-5.0.1/lib/python3.6/site-packages/tensorflow/python/client/session.py", line 633, in __init__
    self._session = tf_session.TF_NewSession(self._graph._c_graph, opts)
tensorflow.python.framework.errors_impl.InternalError: Failed to create session.
Traceback (most recent call last):
  File "roundOneSubmit.py", line 23, in <module>
    l.learnThingsCPP(kind=0, file=f, weightFile=wf)
  File "/gpfs/home/m201560/chipboard/learn.py", line 130, in learnThingsCPP
    weights = self.getWeightArray()
  File "/gpfs/home/m201560/chipboard/learn.py", line 193, in getWeightArray
    return self.model.get_weights()[0].tolist()
  File "/gpfs/home/m201560/.local/lib/python3.6/site-packages/keras/engine/network.py", line 492, in get_weights
    return K.batch_get_value(weights)
  File "/gpfs/home/m201560/.local/lib/python3.6/site-packages/keras/backend/tensorflow_backend.py", line 2420, in batch_get_value
    return get_session().run(ops)
  File "/gpfs/home/m201560/.local/lib/python3.6/site-packages/keras/backend/tensorflow_backend.py", line 186, in get_session
    _SESSION = tf.Session(config=config)
  File "/gpfs/pkgs/mhpcc/anaconda3-5.0.1/lib/python3.6/site-packages/tensorflow/python/client/session.py", line 1563, in __init__
    super(Session, self).__init__(target, graph, config=config)
  File "/gpfs/pkgs/mhpcc/anaconda3-5.0.1/lib/python3.6/site-packages/tensorflow/python/client/session.py", line 633, in __init__
    self._session = tf_session.TF_NewSession(self._graph._c_graph, opts)
tensorflow.python.framework.errors_impl.InternalError: Failed to create session.
Traceback (most recent call last):
  File "roundOneSubmit.py", line 23, in <module>
    l.learnThingsCPP(kind=0, file=f, weightFile=wf)
  File "/gpfs/home/m201560/chipboard/learn.py", line 130, in learnThingsCPP
    weights = self.getWeightArray()
  File "/gpfs/home/m201560/chipboard/learn.py", line 193, in getWeightArray
    return self.model.get_weights()[0].tolist()
  File "/gpfs/home/m201560/.local/lib/python3.6/site-packages/keras/engine/network.py", line 492, in get_weights
    return K.batch_get_value(weights)
  File "/gpfs/home/m201560/.local/lib/python3.6/site-packages/keras/backend/tensorflow_backend.py", line 2420, in batch_get_value
    return get_session().run(ops)
  File "/gpfs/home/m201560/.local/lib/python3.6/site-packages/keras/backend/tensorflow_backend.py", line 186, in get_session
    _SESSION = tf.Session(config=config)
  File "/gpfs/pkgs/mhpcc/anaconda3-5.0.1/lib/python3.6/site-packages/tensorflow/python/client/session.py", line 1563, in __init__
    super(Session, self).__init__(target, graph, config=config)
  File "/gpfs/pkgs/mhpcc/anaconda3-5.0.1/lib/python3.6/site-packages/tensorflow/python/client/session.py", line 633, in __init__
    self._session = tf_session.TF_NewSession(self._graph._c_graph, opts)
tensorflow.python.framework.errors_impl.InternalError: Failed to create session.
Traceback (most recent call last):
  File "roundOneSubmit.py", line 23, in <module>
    l.learnThingsCPP(kind=0, file=f, weightFile=wf)
  File "/gpfs/home/m201560/chipboard/learn.py", line 130, in learnThingsCPP
    weights = self.getWeightArray()
  File "/gpfs/home/m201560/chipboard/learn.py", line 193, in getWeightArray
    return self.model.get_weights()[0].tolist()
  File "/gpfs/home/m201560/.local/lib/python3.6/site-packages/keras/engine/network.py", line 492, in get_weights
    return K.batch_get_value(weights)
  File "/gpfs/home/m201560/.local/lib/python3.6/site-packages/keras/backend/tensorflow_backend.py", line 2420, in batch_get_value
    return get_session().run(ops)
  File "/gpfs/home/m201560/.local/lib/python3.6/site-packages/keras/backend/tensorflow_backend.py", line 186, in get_session
    _SESSION = tf.Session(config=config)
  File "/gpfs/pkgs/mhpcc/anaconda3-5.0.1/lib/python3.6/site-packages/tensorflow/python/client/session.py", line 1563, in __init__
    super(Session, self).__init__(target, graph, config=config)
  File "/gpfs/pkgs/mhpcc/anaconda3-5.0.1/lib/python3.6/site-packages/tensorflow/python/client/session.py", line 633, in __init__
    self._session = tf_session.TF_NewSession(self._graph._c_graph, opts)
tensorflow.python.framework.errors_impl.InternalError: Failed to create session.
2019-08-01 21:32:13.195275: E tensorflow/core/common_runtime/direct_session.cc:158] Internal: failed initializing StreamExecutor for CUDA device ordinal 0: Internal: failed call to cuDevicePrimaryCtxRetain: CUDA_ERROR_INVALID_DEVICE
/gpfs/pkgs/mhpcc/anaconda3-5.0.1/lib/python3.6/site-packages/h5py/__init__.py:34: FutureWarning: Conversion of the second argument of issubdtype from `float` to `np.floating` is deprecated. In future, it will be treated as `np.float64 == np.dtype(float).type`.
  from ._conv import register_converters as _register_converters
Using TensorFlow backend.
2019-08-01 21:32:13.195737: E tensorflow/core/common_runtime/direct_session.cc:158] Internal: failed initializing StreamExecutor for CUDA device ordinal 0: Internal: failed call to cuDevicePrimaryCtxRetain: CUDA_ERROR_INVALID_DEVICE
/gpfs/pkgs/mhpcc/anaconda3-5.0.1/lib/python3.6/site-packages/h5py/__init__.py:34: FutureWarning: Conversion of the second argument of issubdtype from `float` to `np.floating` is deprecated. In future, it will be treated as `np.float64 == np.dtype(float).type`.
  from ._conv import register_converters as _register_converters
Using TensorFlow backend.
2019-08-01 21:32:13.199516: E tensorflow/core/common_runtime/direct_session.cc:158] Internal: failed initializing StreamExecutor for CUDA device ordinal 0: Internal: failed call to cuDevicePrimaryCtxRetain: CUDA_ERROR_INVALID_DEVICE
/gpfs/pkgs/mhpcc/anaconda3-5.0.1/lib/python3.6/site-packages/h5py/__init__.py:34: FutureWarning: Conversion of the second argument of issubdtype from `float` to `np.floating` is deprecated. In future, it will be treated as `np.float64 == np.dtype(float).type`.
  from ._conv import register_converters as _register_converters
Using TensorFlow backend.
Traceback (most recent call last):
  File "roundOneSubmit.py", line 23, in <module>
    l.learnThingsCPP(kind=0, file=f, weightFile=wf)
  File "/gpfs/home/m201560/chipboard/learn.py", line 130, in learnThingsCPP
    weights = self.getWeightArray()
  File "/gpfs/home/m201560/chipboard/learn.py", line 193, in getWeightArray
    return self.model.get_weights()[0].tolist()
  File "/gpfs/home/m201560/.local/lib/python3.6/site-packages/keras/engine/network.py", line 492, in get_weights
    return K.batch_get_value(weights)
  File "/gpfs/home/m201560/.local/lib/python3.6/site-packages/keras/backend/tensorflow_backend.py", line 2420, in batch_get_value
    return get_session().run(ops)
  File "/gpfs/home/m201560/.local/lib/python3.6/site-packages/keras/backend/tensorflow_backend.py", line 186, in get_session
    _SESSION = tf.Session(config=config)
  File "/gpfs/pkgs/mhpcc/anaconda3-5.0.1/lib/python3.6/site-packages/tensorflow/python/client/session.py", line 1563, in __init__
    super(Session, self).__init__(target, graph, config=config)
  File "/gpfs/pkgs/mhpcc/anaconda3-5.0.1/lib/python3.6/site-packages/tensorflow/python/client/session.py", line 633, in __init__
    self._session = tf_session.TF_NewSession(self._graph._c_graph, opts)
tensorflow.python.framework.errors_impl.InternalError: Failed to create session.
2019-08-01 21:32:13.204181: E tensorflow/core/common_runtime/direct_session.cc:158] Internal: failed initializing StreamExecutor for CUDA device ordinal 0: Internal: failed call to cuDevicePrimaryCtxRetain: CUDA_ERROR_INVALID_DEVICE
/gpfs/pkgs/mhpcc/anaconda3-5.0.1/lib/python3.6/site-packages/h5py/__init__.py:34: FutureWarning: Conversion of the second argument of issubdtype from `float` to `np.floating` is deprecated. In future, it will be treated as `np.float64 == np.dtype(float).type`.
  from ._conv import register_converters as _register_converters
Using TensorFlow backend.
2019-08-01 21:32:13.205275: E tensorflow/core/common_runtime/direct_session.cc:158] Internal: failed initializing StreamExecutor for CUDA device ordinal 0: Internal: failed call to cuDevicePrimaryCtxRetain: CUDA_ERROR_INVALID_DEVICE
Traceback (most recent call last):
  File "roundOneSubmit.py", line 23, in <module>
    l.learnThingsCPP(kind=0, file=f, weightFile=wf)
  File "/gpfs/home/m201560/chipboard/learn.py", line 130, in learnThingsCPP
    weights = self.getWeightArray()
  File "/gpfs/home/m201560/chipboard/learn.py", line 193, in getWeightArray
    return self.model.get_weights()[0].tolist()
  File "/gpfs/home/m201560/.local/lib/python3.6/site-packages/keras/engine/network.py", line 492, in get_weights
    return K.batch_get_value(weights)
  File "/gpfs/home/m201560/.local/lib/python3.6/site-packages/keras/backend/tensorflow_backend.py", line 2420, in batch_get_value
    return get_session().run(ops)
  File "/gpfs/home/m201560/.local/lib/python3.6/site-packages/keras/backend/tensorflow_backend.py", line 186, in get_session
    _SESSION = tf.Session(config=config)
  File "/gpfs/pkgs/mhpcc/anaconda3-5.0.1/lib/python3.6/site-packages/tensorflow/python/client/session.py", line 1563, in __init__
    super(Session, self).__init__(target, graph, config=config)
  File "/gpfs/pkgs/mhpcc/anaconda3-5.0.1/lib/python3.6/site-packages/tensorflow/python/client/session.py", line 633, in __init__
    self._session = tf_session.TF_NewSession(self._graph._c_graph, opts)
tensorflow.python.framework.errors_impl.InternalError: Failed to create session.
/gpfs/pkgs/mhpcc/anaconda3-5.0.1/lib/python3.6/site-packages/h5py/__init__.py:34: FutureWarning: Conversion of the second argument of issubdtype from `float` to `np.floating` is deprecated. In future, it will be treated as `np.float64 == np.dtype(float).type`.
  from ._conv import register_converters as _register_converters
Using TensorFlow backend.
Traceback (most recent call last):
  File "roundOneSubmit.py", line 23, in <module>
    l.learnThingsCPP(kind=0, file=f, weightFile=wf)
  File "/gpfs/home/m201560/chipboard/learn.py", line 130, in learnThingsCPP
    weights = self.getWeightArray()
  File "/gpfs/home/m201560/chipboard/learn.py", line 193, in getWeightArray
    return self.model.get_weights()[0].tolist()
  File "/gpfs/home/m201560/.local/lib/python3.6/site-packages/keras/engine/network.py", line 492, in get_weights
    return K.batch_get_value(weights)
  File "/gpfs/home/m201560/.local/lib/python3.6/site-packages/keras/backend/tensorflow_backend.py", line 2420, in batch_get_value
    return get_session().run(ops)
  File "/gpfs/home/m201560/.local/lib/python3.6/site-packages/keras/backend/tensorflow_backend.py", line 186, in get_session
    _SESSION = tf.Session(config=config)
  File "/gpfs/pkgs/mhpcc/anaconda3-5.0.1/lib/python3.6/site-packages/tensorflow/python/client/session.py", line 1563, in __init__
    super(Session, self).__init__(target, graph, config=config)
  File "/gpfs/pkgs/mhpcc/anaconda3-5.0.1/lib/python3.6/site-packages/tensorflow/python/client/session.py", line 633, in __init__
    self._session = tf_session.TF_NewSession(self._graph._c_graph, opts)
tensorflow.python.framework.errors_impl.InternalError: Failed to create session.
2019-08-01 21:32:13.209437: E tensorflow/core/common_runtime/direct_session.cc:158] Internal: failed initializing StreamExecutor for CUDA device ordinal 0: Internal: failed call to cuDevicePrimaryCtxRetain: CUDA_ERROR_INVALID_DEVICE
/gpfs/pkgs/mhpcc/anaconda3-5.0.1/lib/python3.6/site-packages/h5py/__init__.py:34: FutureWarning: Conversion of the second argument of issubdtype from `float` to `np.floating` is deprecated. In future, it will be treated as `np.float64 == np.dtype(float).type`.
  from ._conv import register_converters as _register_converters
Using TensorFlow backend.
2019-08-01 21:32:13.211276: E tensorflow/core/common_runtime/direct_session.cc:158] Internal: failed initializing StreamExecutor for CUDA device ordinal 0: Internal: failed call to cuDevicePrimaryCtxRetain: CUDA_ERROR_INVALID_DEVICE
/gpfs/pkgs/mhpcc/anaconda3-5.0.1/lib/python3.6/site-packages/h5py/__init__.py:34: FutureWarning: Conversion of the second argument of issubdtype from `float` to `np.floating` is deprecated. In future, it will be treated as `np.float64 == np.dtype(float).type`.
  from ._conv import register_converters as _register_converters
Using TensorFlow backend.
2019-08-01 21:32:13.214027: E tensorflow/core/common_runtime/direct_session.cc:158] Internal: failed initializing StreamExecutor for CUDA device ordinal 0: Internal: failed call to cuDevicePrimaryCtxRetain: CUDA_ERROR_INVALID_DEVICE
/gpfs/pkgs/mhpcc/anaconda3-5.0.1/lib/python3.6/site-packages/h5py/__init__.py:34: FutureWarning: Conversion of the second argument of issubdtype from `float` to `np.floating` is deprecated. In future, it will be treated as `np.float64 == np.dtype(float).type`.
  from ._conv import register_converters as _register_converters
Using TensorFlow backend.
Traceback (most recent call last):
  File "roundOneSubmit.py", line 23, in <module>
    l.learnThingsCPP(kind=0, file=f, weightFile=wf)
  File "/gpfs/home/m201560/chipboard/learn.py", line 130, in learnThingsCPP
    weights = self.getWeightArray()
  File "/gpfs/home/m201560/chipboard/learn.py", line 193, in getWeightArray
    return self.model.get_weights()[0].tolist()
  File "/gpfs/home/m201560/.local/lib/python3.6/site-packages/keras/engine/network.py", line 492, in get_weights
    return K.batch_get_value(weights)
  File "/gpfs/home/m201560/.local/lib/python3.6/site-packages/keras/backend/tensorflow_backend.py", line 2420, in batch_get_value
    return get_session().run(ops)
  File "/gpfs/home/m201560/.local/lib/python3.6/site-packages/keras/backend/tensorflow_backend.py", line 186, in get_session
    _SESSION = tf.Session(config=config)
  File "/gpfs/pkgs/mhpcc/anaconda3-5.0.1/lib/python3.6/site-packages/tensorflow/python/client/session.py", line 1563, in __init__
    super(Session, self).__init__(target, graph, config=config)
  File "/gpfs/pkgs/mhpcc/anaconda3-5.0.1/lib/python3.6/site-packages/tensorflow/python/client/session.py", line 633, in __init__
    self._session = tf_session.TF_NewSession(self._graph._c_graph, opts)
tensorflow.python.framework.errors_impl.InternalError: Failed to create session.
2019-08-01 21:32:13.216849: E tensorflow/core/common_runtime/direct_session.cc:158] Internal: failed initializing StreamExecutor for CUDA device ordinal 0: Internal: failed call to cuDevicePrimaryCtxRetain: CUDA_ERROR_INVALID_DEVICE
/gpfs/pkgs/mhpcc/anaconda3-5.0.1/lib/python3.6/site-packages/h5py/__init__.py:34: FutureWarning: Conversion of the second argument of issubdtype from `float` to `np.floating` is deprecated. In future, it will be treated as `np.float64 == np.dtype(float).type`.
  from ._conv import register_converters as _register_converters
Using TensorFlow backend.
2019-08-01 21:32:13.218145: E tensorflow/core/common_runtime/direct_session.cc:158] Internal: failed initializing StreamExecutor for CUDA device ordinal 0: Internal: failed call to cuDevicePrimaryCtxRetain: CUDA_ERROR_INVALID_DEVICE
/gpfs/pkgs/mhpcc/anaconda3-5.0.1/lib/python3.6/site-packages/h5py/__init__.py:34: FutureWarning: Conversion of the second argument of issubdtype from `float` to `np.floating` is deprecated. In future, it will be treated as `np.float64 == np.dtype(float).type`.
  from ._conv import register_converters as _register_converters
Using TensorFlow backend.
2019-08-01 21:32:13.219112: E tensorflow/core/common_runtime/direct_session.cc:158] Internal: failed initializing StreamExecutor for CUDA device ordinal 0: Internal: failed call to cuDevicePrimaryCtxRetain: CUDA_ERROR_INVALID_DEVICE
/gpfs/pkgs/mhpcc/anaconda3-5.0.1/lib/python3.6/site-packages/h5py/__init__.py:34: FutureWarning: Conversion of the second argument of issubdtype from `float` to `np.floating` is deprecated. In future, it will be treated as `np.float64 == np.dtype(float).type`.
  from ._conv import register_converters as _register_converters
Using TensorFlow backend.
Traceback (most recent call last):
  File "roundOneSubmit.py", line 23, in <module>
    l.learnThingsCPP(kind=0, file=f, weightFile=wf)
  File "/gpfs/home/m201560/chipboard/learn.py", line 130, in learnThingsCPP
    weights = self.getWeightArray()
  File "/gpfs/home/m201560/chipboard/learn.py", line 193, in getWeightArray
    return self.model.get_weights()[0].tolist()
  File "/gpfs/home/m201560/.local/lib/python3.6/site-packages/keras/engine/network.py", line 492, in get_weights
    return K.batch_get_value(weights)
  File "/gpfs/home/m201560/.local/lib/python3.6/site-packages/keras/backend/tensorflow_backend.py", line 2420, in batch_get_value
    return get_session().run(ops)
  File "/gpfs/home/m201560/.local/lib/python3.6/site-packages/keras/backend/tensorflow_backend.py", line 186, in get_session
    _SESSION = tf.Session(config=config)
  File "/gpfs/pkgs/mhpcc/anaconda3-5.0.1/lib/python3.6/site-packages/tensorflow/python/client/session.py", line 1563, in __init__
    super(Session, self).__init__(target, graph, config=config)
  File "/gpfs/pkgs/mhpcc/anaconda3-5.0.1/lib/python3.6/site-packages/tensorflow/python/client/session.py", line 633, in __init__
    self._session = tf_session.TF_NewSession(self._graph._c_graph, opts)
tensorflow.python.framework.errors_impl.InternalError: Failed to create session.
2019-08-01 21:32:13.220932: E tensorflow/core/common_runtime/direct_session.cc:158] Internal: failed initializing StreamExecutor for CUDA device ordinal 0: Internal: failed call to cuDevicePrimaryCtxRetain: CUDA_ERROR_INVALID_DEVICE
/gpfs/pkgs/mhpcc/anaconda3-5.0.1/lib/python3.6/site-packages/h5py/__init__.py:34: FutureWarning: Conversion of the second argument of issubdtype from `float` to `np.floating` is deprecated. In future, it will be treated as `np.float64 == np.dtype(float).type`.
  from ._conv import register_converters as _register_converters
Using TensorFlow backend.
2019-08-01 21:32:13.221448: E tensorflow/core/common_runtime/direct_session.cc:158] Internal: failed initializing StreamExecutor for CUDA device ordinal 0: Internal: failed call to cuDevicePrimaryCtxRetain: CUDA_ERROR_INVALID_DEVICE
/gpfs/pkgs/mhpcc/anaconda3-5.0.1/lib/python3.6/site-packages/h5py/__init__.py:34: FutureWarning: Conversion of the second argument of issubdtype from `float` to `np.floating` is deprecated. In future, it will be treated as `np.float64 == np.dtype(float).type`.
  from ._conv import register_converters as _register_converters
Using TensorFlow backend.
2019-08-01 21:32:13.222508: E tensorflow/core/common_runtime/direct_session.cc:158] Internal: failed initializing StreamExecutor for CUDA device ordinal 0: Internal: failed call to cuDevicePrimaryCtxRetain: CUDA_ERROR_INVALID_DEVICE
/gpfs/pkgs/mhpcc/anaconda3-5.0.1/lib/python3.6/site-packages/h5py/__init__.py:34: FutureWarning: Conversion of the second argument of issubdtype from `float` to `np.floating` is deprecated. In future, it will be treated as `np.float64 == np.dtype(float).type`.
  from ._conv import register_converters as _register_converters
Using TensorFlow backend.
2019-08-01 21:32:13.222841: E tensorflow/core/common_runtime/direct_session.cc:158] Internal: failed initializing StreamExecutor for CUDA device ordinal 0: Internal: failed call to cuDevicePrimaryCtxRetain: CUDA_ERROR_INVALID_DEVICE
/gpfs/pkgs/mhpcc/anaconda3-5.0.1/lib/python3.6/site-packages/h5py/__init__.py:34: FutureWarning: Conversion of the second argument of issubdtype from `float` to `np.floating` is deprecated. In future, it will be treated as `np.float64 == np.dtype(float).type`.
  from ._conv import register_converters as _register_converters
Using TensorFlow backend.
Traceback (most recent call last):
  File "roundOneSubmit.py", line 23, in <module>
    l.learnThingsCPP(kind=0, file=f, weightFile=wf)
  File "/gpfs/home/m201560/chipboard/learn.py", line 130, in learnThingsCPP
    weights = self.getWeightArray()
  File "/gpfs/home/m201560/chipboard/learn.py", line 193, in getWeightArray
    return self.model.get_weights()[0].tolist()
  File "/gpfs/home/m201560/.local/lib/python3.6/site-packages/keras/engine/network.py", line 492, in get_weights
    return K.batch_get_value(weights)
  File "/gpfs/home/m201560/.local/lib/python3.6/site-packages/keras/backend/tensorflow_backend.py", line 2420, in batch_get_value
    return get_session().run(ops)
  File "/gpfs/home/m201560/.local/lib/python3.6/site-packages/keras/backend/tensorflow_backend.py", line 186, in get_session
    _SESSION = tf.Session(config=config)
  File "/gpfs/pkgs/mhpcc/anaconda3-5.0.1/lib/python3.6/site-packages/tensorflow/python/client/session.py", line 1563, in __init__
    super(Session, self).__init__(target, graph, config=config)
  File "/gpfs/pkgs/mhpcc/anaconda3-5.0.1/lib/python3.6/site-packages/tensorflow/python/client/session.py", line 633, in __init__
    self._session = tf_session.TF_NewSession(self._graph._c_graph, opts)
tensorflow.python.framework.errors_impl.InternalError: Failed to create session.
Traceback (most recent call last):
  File "roundOneSubmit.py", line 23, in <module>
    l.learnThingsCPP(kind=0, file=f, weightFile=wf)
  File "/gpfs/home/m201560/chipboard/learn.py", line 130, in learnThingsCPP
    weights = self.getWeightArray()
  File "/gpfs/home/m201560/chipboard/learn.py", line 193, in getWeightArray
    return self.model.get_weights()[0].tolist()
  File "/gpfs/home/m201560/.local/lib/python3.6/site-packages/keras/engine/network.py", line 492, in get_weights
    return K.batch_get_value(weights)
  File "/gpfs/home/m201560/.local/lib/python3.6/site-packages/keras/backend/tensorflow_backend.py", line 2420, in batch_get_value
    return get_session().run(ops)
  File "/gpfs/home/m201560/.local/lib/python3.6/site-packages/keras/backend/tensorflow_backend.py", line 186, in get_session
    _SESSION = tf.Session(config=config)
  File "/gpfs/pkgs/mhpcc/anaconda3-5.0.1/lib/python3.6/site-packages/tensorflow/python/client/session.py", line 1563, in __init__
    super(Session, self).__init__(target, graph, config=config)
  File "/gpfs/pkgs/mhpcc/anaconda3-5.0.1/lib/python3.6/site-packages/tensorflow/python/client/session.py", line 633, in __init__
    self._session = tf_session.TF_NewSession(self._graph._c_graph, opts)
tensorflow.python.framework.errors_impl.InternalError: Failed to create session.
Traceback (most recent call last):
  File "roundOneSubmit.py", line 23, in <module>
    l.learnThingsCPP(kind=0, file=f, weightFile=wf)
  File "/gpfs/home/m201560/chipboard/learn.py", line 130, in learnThingsCPP
    weights = self.getWeightArray()
  File "/gpfs/home/m201560/chipboard/learn.py", line 193, in getWeightArray
    return self.model.get_weights()[0].tolist()
  File "/gpfs/home/m201560/.local/lib/python3.6/site-packages/keras/engine/network.py", line 492, in get_weights
    return K.batch_get_value(weights)
  File "/gpfs/home/m201560/.local/lib/python3.6/site-packages/keras/backend/tensorflow_backend.py", line 2420, in batch_get_value
    return get_session().run(ops)
  File "/gpfs/home/m201560/.local/lib/python3.6/site-packages/keras/backend/tensorflow_backend.py", line 186, in get_session
    _SESSION = tf.Session(config=config)
  File "/gpfs/pkgs/mhpcc/anaconda3-5.0.1/lib/python3.6/site-packages/tensorflow/python/client/session.py", line 1563, in __init__
    super(Session, self).__init__(target, graph, config=config)
  File "/gpfs/pkgs/mhpcc/anaconda3-5.0.1/lib/python3.6/site-packages/tensorflow/python/client/session.py", line 633, in __init__
    self._session = tf_session.TF_NewSession(self._graph._c_graph, opts)
tensorflow.python.framework.errors_impl.InternalError: Failed to create session.
Traceback (most recent call last):
  File "roundOneSubmit.py", line 23, in <module>
    l.learnThingsCPP(kind=0, file=f, weightFile=wf)
  File "/gpfs/home/m201560/chipboard/learn.py", line 130, in learnThingsCPP
    weights = self.getWeightArray()
  File "/gpfs/home/m201560/chipboard/learn.py", line 193, in getWeightArray
    return self.model.get_weights()[0].tolist()
  File "/gpfs/home/m201560/.local/lib/python3.6/site-packages/keras/engine/network.py", line 492, in get_weights
    return K.batch_get_value(weights)
  File "/gpfs/home/m201560/.local/lib/python3.6/site-packages/keras/backend/tensorflow_backend.py", line 2420, in batch_get_value
    return get_session().run(ops)
  File "/gpfs/home/m201560/.local/lib/python3.6/site-packages/keras/backend/tensorflow_backend.py", line 186, in get_session
    _SESSION = tf.Session(config=config)
  File "/gpfs/pkgs/mhpcc/anaconda3-5.0.1/lib/python3.6/site-packages/tensorflow/python/client/session.py", line 1563, in __init__
    super(Session, self).__init__(target, graph, config=config)
  File "/gpfs/pkgs/mhpcc/anaconda3-5.0.1/lib/python3.6/site-packages/tensorflow/python/client/session.py", line 633, in __init__
    self._session = tf_session.TF_NewSession(self._graph._c_graph, opts)
tensorflow.python.framework.errors_impl.InternalError: Failed to create session.
Traceback (most recent call last):
  File "roundOneSubmit.py", line 23, in <module>
    l.learnThingsCPP(kind=0, file=f, weightFile=wf)
  File "/gpfs/home/m201560/chipboard/learn.py", line 130, in learnThingsCPP
    weights = self.getWeightArray()
  File "/gpfs/home/m201560/chipboard/learn.py", line 193, in getWeightArray
    return self.model.get_weights()[0].tolist()
  File "/gpfs/home/m201560/.local/lib/python3.6/site-packages/keras/engine/network.py", line 492, in get_weights
    return K.batch_get_value(weights)
  File "/gpfs/home/m201560/.local/lib/python3.6/site-packages/keras/backend/tensorflow_backend.py", line 2420, in batch_get_value
    return get_session().run(ops)
  File "/gpfs/home/m201560/.local/lib/python3.6/site-packages/keras/backend/tensorflow_backend.py", line 186, in get_session
    _SESSION = tf.Session(config=config)
  File "/gpfs/pkgs/mhpcc/anaconda3-5.0.1/lib/python3.6/site-packages/tensorflow/python/client/session.py", line 1563, in __init__
    super(Session, self).__init__(target, graph, config=config)
  File "/gpfs/pkgs/mhpcc/anaconda3-5.0.1/lib/python3.6/site-packages/tensorflow/python/client/session.py", line 633, in __init__
    self._session = tf_session.TF_NewSession(self._graph._c_graph, opts)
tensorflow.python.framework.errors_impl.InternalError: Failed to create session.
Traceback (most recent call last):
  File "roundOneSubmit.py", line 23, in <module>
    l.learnThingsCPP(kind=0, file=f, weightFile=wf)
  File "/gpfs/home/m201560/chipboard/learn.py", line 130, in learnThingsCPP
    weights = self.getWeightArray()
  File "/gpfs/home/m201560/chipboard/learn.py", line 193, in getWeightArray
    return self.model.get_weights()[0].tolist()
  File "/gpfs/home/m201560/.local/lib/python3.6/site-packages/keras/engine/network.py", line 492, in get_weights
    return K.batch_get_value(weights)
  File "/gpfs/home/m201560/.local/lib/python3.6/site-packages/keras/backend/tensorflow_backend.py", line 2420, in batch_get_value
    return get_session().run(ops)
  File "/gpfs/home/m201560/.local/lib/python3.6/site-packages/keras/backend/tensorflow_backend.py", line 186, in get_session
    _SESSION = tf.Session(config=config)
  File "/gpfs/pkgs/mhpcc/anaconda3-5.0.1/lib/python3.6/site-packages/tensorflow/python/client/session.py", line 1563, in __init__
    super(Session, self).__init__(target, graph, config=config)
  File "/gpfs/pkgs/mhpcc/anaconda3-5.0.1/lib/python3.6/site-packages/tensorflow/python/client/session.py", line 633, in __init__
    self._session = tf_session.TF_NewSession(self._graph._c_graph, opts)
tensorflow.python.framework.errors_impl.InternalError: Failed to create session.
Traceback (most recent call last):
  File "roundOneSubmit.py", line 23, in <module>
    l.learnThingsCPP(kind=0, file=f, weightFile=wf)
  File "/gpfs/home/m201560/chipboard/learn.py", line 130, in learnThingsCPP
    weights = self.getWeightArray()
  File "/gpfs/home/m201560/chipboard/learn.py", line 193, in getWeightArray
    return self.model.get_weights()[0].tolist()
  File "/gpfs/home/m201560/.local/lib/python3.6/site-packages/keras/engine/network.py", line 492, in get_weights
    return K.batch_get_value(weights)
  File "/gpfs/home/m201560/.local/lib/python3.6/site-packages/keras/backend/tensorflow_backend.py", line 2420, in batch_get_value
    return get_session().run(ops)
  File "/gpfs/home/m201560/.local/lib/python3.6/site-packages/keras/backend/tensorflow_backend.py", line 186, in get_session
    _SESSION = tf.Session(config=config)
  File "/gpfs/pkgs/mhpcc/anaconda3-5.0.1/lib/python3.6/site-packages/tensorflow/python/client/session.py", line 1563, in __init__
    super(Session, self).__init__(target, graph, config=config)
  File "/gpfs/pkgs/mhpcc/anaconda3-5.0.1/lib/python3.6/site-packages/tensorflow/python/client/session.py", line 633, in __init__
    self._session = tf_session.TF_NewSession(self._graph._c_graph, opts)
tensorflow.python.framework.errors_impl.InternalError: Failed to create session.
Traceback (most recent call last):
  File "roundOneSubmit.py", line 23, in <module>
    l.learnThingsCPP(kind=0, file=f, weightFile=wf)
  File "/gpfs/home/m201560/chipboard/learn.py", line 130, in learnThingsCPP
    weights = self.getWeightArray()
  File "/gpfs/home/m201560/chipboard/learn.py", line 193, in getWeightArray
    return self.model.get_weights()[0].tolist()
  File "/gpfs/home/m201560/.local/lib/python3.6/site-packages/keras/engine/network.py", line 492, in get_weights
    return K.batch_get_value(weights)
  File "/gpfs/home/m201560/.local/lib/python3.6/site-packages/keras/backend/tensorflow_backend.py", line 2420, in batch_get_value
    return get_session().run(ops)
  File "/gpfs/home/m201560/.local/lib/python3.6/site-packages/keras/backend/tensorflow_backend.py", line 186, in get_session
    _SESSION = tf.Session(config=config)
  File "/gpfs/pkgs/mhpcc/anaconda3-5.0.1/lib/python3.6/site-packages/tensorflow/python/client/session.py", line 1563, in __init__
    super(Session, self).__init__(target, graph, config=config)
  File "/gpfs/pkgs/mhpcc/anaconda3-5.0.1/lib/python3.6/site-packages/tensorflow/python/client/session.py", line 633, in __init__
    self._session = tf_session.TF_NewSession(self._graph._c_graph, opts)
tensorflow.python.framework.errors_impl.InternalError: Failed to create session.
Traceback (most recent call last):
  File "roundOneSubmit.py", line 23, in <module>
    l.learnThingsCPP(kind=0, file=f, weightFile=wf)
  File "/gpfs/home/m201560/chipboard/learn.py", line 130, in learnThingsCPP
    weights = self.getWeightArray()
  File "/gpfs/home/m201560/chipboard/learn.py", line 193, in getWeightArray
    return self.model.get_weights()[0].tolist()
  File "/gpfs/home/m201560/.local/lib/python3.6/site-packages/keras/engine/network.py", line 492, in get_weights
    return K.batch_get_value(weights)
  File "/gpfs/home/m201560/.local/lib/python3.6/site-packages/keras/backend/tensorflow_backend.py", line 2420, in batch_get_value
    return get_session().run(ops)
  File "/gpfs/home/m201560/.local/lib/python3.6/site-packages/keras/backend/tensorflow_backend.py", line 186, in get_session
    _SESSION = tf.Session(config=config)
  File "/gpfs/pkgs/mhpcc/anaconda3-5.0.1/lib/python3.6/site-packages/tensorflow/python/client/session.py", line 1563, in __init__
    super(Session, self).__init__(target, graph, config=config)
  File "/gpfs/pkgs/mhpcc/anaconda3-5.0.1/lib/python3.6/site-packages/tensorflow/python/client/session.py", line 633, in __init__
    self._session = tf_session.TF_NewSession(self._graph._c_graph, opts)
tensorflow.python.framework.errors_impl.InternalError: Failed to create session.
Traceback (most recent call last):
  File "roundOneSubmit.py", line 23, in <module>
    l.learnThingsCPP(kind=0, file=f, weightFile=wf)
  File "/gpfs/home/m201560/chipboard/learn.py", line 130, in learnThingsCPP
    weights = self.getWeightArray()
  File "/gpfs/home/m201560/chipboard/learn.py", line 193, in getWeightArray
    return self.model.get_weights()[0].tolist()
  File "/gpfs/home/m201560/.local/lib/python3.6/site-packages/keras/engine/network.py", line 492, in get_weights
    return K.batch_get_value(weights)
  File "/gpfs/home/m201560/.local/lib/python3.6/site-packages/keras/backend/tensorflow_backend.py", line 2420, in batch_get_value
    return get_session().run(ops)
  File "/gpfs/home/m201560/.local/lib/python3.6/site-packages/keras/backend/tensorflow_backend.py", line 186, in get_session
    _SESSION = tf.Session(config=config)
  File "/gpfs/pkgs/mhpcc/anaconda3-5.0.1/lib/python3.6/site-packages/tensorflow/python/client/session.py", line 1563, in __init__
    super(Session, self).__init__(target, graph, config=config)
  File "/gpfs/pkgs/mhpcc/anaconda3-5.0.1/lib/python3.6/site-packages/tensorflow/python/client/session.py", line 633, in __init__
    self._session = tf_session.TF_NewSession(self._graph._c_graph, opts)
tensorflow.python.framework.errors_impl.InternalError: Failed to create session.
2019-08-01 21:32:13.278311: I tensorflow/core/common_runtime/gpu/gpu_device.cc:1392] Found device 0 with properties: 
name: Tesla P100-SXM2-16GB major: 6 minor: 0 memoryClockRate(GHz): 1.4805
pciBusID: 0002:01:00.0
totalMemory: 15.90GiB freeMemory: 15.64GiB
2019-08-01 21:32:13.390140: I tensorflow/core/common_runtime/gpu/gpu_device.cc:1392] Found device 1 with properties: 
name: Tesla P100-SXM2-16GB major: 6 minor: 0 memoryClockRate(GHz): 1.4805
pciBusID: 0003:01:00.0
totalMemory: 15.90GiB freeMemory: 15.64GiB
2019-08-01 21:32:13.533774: I tensorflow/core/common_runtime/gpu/gpu_device.cc:1392] Found device 2 with properties: 
name: Tesla P100-SXM2-16GB major: 6 minor: 0 memoryClockRate(GHz): 1.4805
pciBusID: 0006:01:00.0
totalMemory: 15.90GiB freeMemory: 15.64GiB
2019-08-01 21:32:13.708874: I tensorflow/core/common_runtime/gpu/gpu_device.cc:1392] Found device 3 with properties: 
name: Tesla P100-SXM2-16GB major: 6 minor: 0 memoryClockRate(GHz): 1.4805
pciBusID: 0007:01:00.0
totalMemory: 15.90GiB freeMemory: 15.64GiB
2019-08-01 21:32:13.709609: I tensorflow/core/common_runtime/gpu/gpu_device.cc:1471] Adding visible gpu devices: 0, 1, 2, 3
[cr2cn16:70866] 79 more processes have sent help message help-mpi-btl-openib.txt / default subnet prefix
[cr2cn16:70866] Set MCA parameter "orte_base_help_aggregate" to 0 to see all help / error messages
2019-08-01 21:32:25.245266: I tensorflow/core/common_runtime/gpu/gpu_device.cc:952] Device interconnect StreamExecutor with strength 1 edge matrix:
2019-08-01 21:32:25.245308: I tensorflow/core/common_runtime/gpu/gpu_device.cc:958]      0 1 2 3 
2019-08-01 21:32:25.245320: I tensorflow/core/common_runtime/gpu/gpu_device.cc:971] 0:   N Y N N 
2019-08-01 21:32:25.245328: I tensorflow/core/common_runtime/gpu/gpu_device.cc:971] 1:   Y N N N 
2019-08-01 21:32:25.245336: I tensorflow/core/common_runtime/gpu/gpu_device.cc:971] 2:   N N N Y 
2019-08-01 21:32:25.245344: I tensorflow/core/common_runtime/gpu/gpu_device.cc:971] 3:   N N Y N 
2019-08-01 21:32:25.246057: I tensorflow/core/common_runtime/gpu/gpu_device.cc:1084] Created TensorFlow device (/job:localhost/replica:0/task:0/device:GPU:0 with 15163 MB memory) -> physical GPU (device: 0, name: Tesla P100-SXM2-16GB, pci bus id: 0002:01:00.0, compute capability: 6.0)
2019-08-01 21:32:25.372505: I tensorflow/core/common_runtime/gpu/gpu_device.cc:1084] Created TensorFlow device (/job:localhost/replica:0/task:0/device:GPU:1 with 15163 MB memory) -> physical GPU (device: 1, name: Tesla P100-SXM2-16GB, pci bus id: 0003:01:00.0, compute capability: 6.0)
2019-08-01 21:32:25.499235: I tensorflow/core/common_runtime/gpu/gpu_device.cc:1084] Created TensorFlow device (/job:localhost/replica:0/task:0/device:GPU:2 with 15163 MB memory) -> physical GPU (device: 2, name: Tesla P100-SXM2-16GB, pci bus id: 0006:01:00.0, compute capability: 6.0)
2019-08-01 21:32:25.646494: I tensorflow/core/common_runtime/gpu/gpu_device.cc:1084] Created TensorFlow device (/job:localhost/replica:0/task:0/device:GPU:3 with 15163 MB memory) -> physical GPU (device: 3, name: Tesla P100-SXM2-16GB, pci bus id: 0007:01:00.0, compute capability: 6.0)
=>> PBS: job killed: walltime 605 exceeded limit 600
[warn] Epoll ADD(4) on fd 363 failed.  Old events were 0; read change was 0 (none); write change was 1 (add): Bad file descriptor
[warn] Epoll ADD(4) on fd 333 failed.  Old events were 0; read change was 0 (none); write change was 1 (add): Bad file descriptor
[warn] Epoll ADD(4) on fd 309 failed.  Old events were 0; read change was 0 (none); write change was 1 (add): Bad file descriptor
[warn] Epoll ADD(4) on fd 329 failed.  Old events were 0; read change was 0 (none); write change was 1 (add): Bad file descriptor
[warn] Epoll ADD(4) on fd 49 failed.  Old events were 0; read change was 0 (none); write change was 1 (add): Bad file descriptor
[warn] Epoll ADD(4) on fd 349 failed.  Old events were 0; read change was 0 (none); write change was 1 (add): Bad file descriptor
[warn] Epoll ADD(4) on fd 298 failed.  Old events were 0; read change was 0 (none); write change was 1 (add): Bad file descriptor
[warn] Epoll ADD(4) on fd 364 failed.  Old events were 0; read change was 0 (none); write change was 1 (add): Bad file descriptor
[warn] Epoll ADD(4) on fd 311 failed.  Old events were 0; read change was 0 (none); write change was 1 (add): Bad file descriptor
[warn] Epoll ADD(4) on fd 341 failed.  Old events were 0; read change was 0 (none); write change was 1 (add): Bad file descriptor
[warn] Epoll ADD(4) on fd 320 failed.  Old events were 0; read change was 0 (none); write change was 1 (add): Bad file descriptor
[warn] Epoll ADD(4) on fd 360 failed.  Old events were 0; read change was 0 (none); write change was 1 (add): Bad file descriptor
[warn] Epoll ADD(4) on fd 352 failed.  Old events were 0; read change was 0 (none); write change was 1 (add): Bad file descriptor
[warn] Epoll ADD(4) on fd 338 failed.  Old events were 0; read change was 0 (none); write change was 1 (add): Bad file descriptor
[warn] Epoll ADD(4) on fd 359 failed.  Old events were 0; read change was 0 (none); write change was 1 (add): Bad file descriptor
